
# +-----------------------------------------------------------------+ #
# |                            BO3 object                           | #
# +-----------------------------------------------------------------+ #
#######################################################################

# This is the config file of a custom object.
# If you add this object correctly to your BiomeConfigs, it will spawn in the world.

# This is the creator of this BO3 object
Author: NLBlackEagle

# A short description of this BO3 object
Description: Converted version of the BO2 27

# The BO3 version, don't change this! It can be used by external applications to do a version check.
Version: 3

# The settings mode, WriteAll, WriteWithoutComments or WriteDisable. See WorldConfig.
SettingsMode: WriteDisable


#######################################################################
# +-----------------------------------------------------------------+ #
# |                          Main settings                          | #
# +-----------------------------------------------------------------+ #
#######################################################################

# This needs to be set to true to spawn the object in the Tree and Sapling resources.
Tree: true

# The frequency of the BO3 from 1 to 200. Tries this many times to spawn this BO3 when using the CustomObject(...) resource.
# Ignored by Tree(..), Sapling(..) and CustomStructure(..)
Frequency: 1

# The rarity of the BO3 from 0 to 100. Each spawn attempt has rarity% chance to succeed when using the CustomObject(...) resource.
# Ignored by Tree(..), Sapling(..) and CustomStructure(..)
Rarity: 100.0

# If you set this to true, the BO3 will be placed with a random rotation.
RotateRandomly: true

# The spawn height of the BO3 - randomY, highestBlock or highestSolidBlock.
SpawnHeight: highestSolidBlock

# The height limits for the BO3.
MinHeight: 70

MaxHeight: 256

# Objects can have other objects attacthed to it: branches. Branches can also
# have branches attached to it, which can also have branches, etc. This is the
# maximum branch depth for this objects.
MaxBranchDepth: 10

# When spawned with the UseWorld keyword, this BO3 should NOT spawn in the following biomes.
# If you writer.write the BO3 name directly in the BiomeConfigs, this will be ignored.
ExcludedBiomes: 


#######################################################################
# +-----------------------------------------------------------------+ #
# |                      Source block settings                      | #
# +-----------------------------------------------------------------+ #
#######################################################################

# The block(s) the BO3 should spawn in.
SourceBlocks: AIR

# The maximum percentage of the BO3 that can be outside the SourceBlock.
# The BO3 won't be placed on a location with more blocks outside the SourceBlock than this percentage.
MaxPercentageOutsideSourceBlock: 20

# What to do when a block is about to be placed outside the SourceBlock? (dontPlace, placeAnyway)
OutsideSourceBlock: placeAnyway


#######################################################################
# +-----------------------------------------------------------------+ #
# |                              Blocks                             | #
# +-----------------------------------------------------------------+ #
#######################################################################

# All the blocks used in the BO3 are listed here. Possible blocks:
# Block(x,y,z,id[.data][,nbtfile.nbt)
# RandomBlock(x,y,z,id[:data][,nbtfile.nbt],chance[,id[:data][,nbtfile.nbt],chance[,...]])
# So RandomBlock(0,0,0,CHEST,chest.nbt,50,CHEST,anotherchest.nbt,100) will spawn a chest at
# the BO3 origin, and give it a 50% chance to have the contents of chest.nbt, or, if that
# fails, a 100% percent chance to have the contents of anotherchest.nbt.
Block(6,8,-8,LEAVES:12)
Block(4,10,-5,LEAVES:12)
Block(6,5,-8,LEAVES:12)
Block(4,11,-5,LEAVES:12)
Block(4,12,-5,LEAVES:12)
Block(6,6,-8,LEAVES:12)
Block(3,14,-6,LEAVES:12)
Block(3,13,-6,LEAVES:12)
Block(3,10,-6,LEAVES:12)
Block(2,9,2,LEAVES:4)
Block(9,11,-7,LEAVES:12)
Block(4,16,-5,LEAVES:12)
Block(1,14,-4,LEAVES:12)
Block(6,6,-6,LEAVES:12)
Block(1,13,-4,LEAVES:12)
Block(4,7,-11,LEAVES:4)
Block(3,6,1,LEAVES:12)
Block(3,5,0,LEAVES:12)
Block(8,15,-4,LEAVES:12)
Block(3,6,0,LEAVES:12)
Block(8,16,-4,LEAVES:12)
Block(8,17,-4,LEAVES:12)
Block(8,10,-4,LEAVES:12)
Block(-1,9,0,LEAVES:12)
Block(8,11,-4,LEAVES:12)
Block(8,12,-4,LEAVES:12)
Block(8,13,-4,LEAVES:12)
Block(0,10,0,LEAVES:12)
Block(6,-4,-4,LOG:13)
Block(6,-5,-4,LOG:13)
Block(6,-2,-4,LOG:13)
Block(6,-3,-4,LOG:13)
Block(6,-1,-4,LOG:13)
Block(6,7,-10,LEAVES:12)
Block(6,6,-10,LEAVES:4)
Block(0,9,2,LEAVES:4)
Block(8,12,-7,LEAVES:12)
Block(8,11,-7,LEAVES:12)
Block(1,7,-5,LOG:13)
Block(11,8,-3,LEAVES:12)
Block(3,16,-4,LEAVES:12)
Block(3,15,-4,LEAVES:12)
Block(3,17,-2,LEAVES:12)
Block(3,11,-5,LEAVES:12)
Block(3,18,-2,LEAVES:12)
Block(3,12,-4,LEAVES:12)
Block(3,13,-4,LEAVES:12)
Block(6,5,-5,LOG:13)
Block(3,14,-4,LEAVES:12)
Block(3,13,-5,LEAVES:12)
Block(3,12,-5,LEAVES:12)
Block(6,6,-5,LEAVES:12)
Block(5,6,1,LEAVES:12)
Block(4,5,-3,LEAVES:12)
Block(8,9,-5,LEAVES:12)
Block(4,4,-3,LEAVES:12)
Block(4,9,-2,LEAVES:12)
Block(8,8,-4,LEAVES:12)
Block(1,8,-2,LEAVES:12)
Block(4,8,-2,LEAVES:12)
Block(1,9,-2,LEAVES:12)
Block(1,8,-1,LEAVES:12)
Block(4,5,-2,LEAVES:12)
Block(4,8,-3,LOG:13)
Block(4,7,-3,LEAVES:12)
Block(4,4,-2,LOG:13)
Block(1,9,-1,LEAVES:12)
Block(8,6,-3,LEAVES:12)
Block(10,11,-5,LEAVES:12)
Block(8,7,-3,LEAVES:12)
Block(10,10,-5,LEAVES:12)
Block(8,8,-3,LEAVES:12)
Block(8,7,-2,LEAVES:12)
Block(6,6,-7,LEAVES:12)
Block(6,7,-7,LEAVES:12)
Block(1,8,-4,LOG:13)
Block(8,8,-2,LEAVES:12)
Block(6,20,-2,LEAVES:4)
Block(8,6,-2,LEAVES:12)
Block(6,12,-2,LEAVES:12)
Block(6,13,-2,LEAVES:12)
Block(7,11,-6,LEAVES:12)
Block(3,8,-10,LEAVES:4)
Block(6,17,-2,LEAVES:12)
Block(3,7,-10,LEAVES:4)
Block(3,6,-10,LEAVES:4)
Block(6,18,-2,LEAVES:12)
Block(6,19,-2,LEAVES:12)
Block(3,10,0,LEAVES:12)
Block(4,12,0,LEAVES:12)
Block(4,13,0,LEAVES:12)
Block(4,14,0,LEAVES:12)
Block(4,10,0,LEAVES:12)
Block(7,17,-6,LEAVES:12)
Block(7,16,-6,LEAVES:12)
Block(5,14,-4,LEAVES:12)
Block(5,13,-4,LOG:13)
Block(5,15,-4,LEAVES:12)
Block(5,18,-4,LEAVES:12)
Block(5,17,-4,LEAVES:12)
Block(3,7,-9,LEAVES:12)
Block(5,19,-4,LEAVES:12)
Block(3,8,-9,LEAVES:12)
Block(5,10,-4,LOG:13)
Block(5,11,-4,LOG:13)
Block(5,12,-4,LOG:13)
Block(9,11,-8,LEAVES:12)
Block(9,12,-8,LEAVES:12)
Block(10,7,0,LEAVES:12)
Block(3,-6,-4,LOG:13)
Block(5,0,-3,LOG:13)
Block(5,1,-3,LOG:13)
Block(5,2,-3,LOG:13)
Block(5,6,0,LEAVES:12)
Block(5,3,-3,LOG:13)
Block(5,4,-3,LOG:13)
Block(5,5,-3,LOG:13)
Block(5,6,-3,LOG:13)
Block(5,7,-3,LOG:13)
Block(5,8,-3,LOG:13)
Block(5,9,-3,LOG:13)
Block(7,7,-6,LEAVES:12)
Block(12,7,0,LEAVES:4)
Block(5,8,-7,LEAVES:12)
Block(5,7,-7,LEAVES:12)
Block(6,13,1,LEAVES:12)
Block(7,9,-4,LEAVES:12)
Block(7,8,-4,LEAVES:12)
Block(5,9,-7,LEAVES:12)
Block(11,11,-3,LEAVES:12)
Block(6,14,1,LEAVES:12)
Block(5,20,-4,LEAVES:4)
Block(5,6,-7,LEAVES:12)
Block(5,21,-4,LEAVES:4)
Block(5,5,-7,LEAVES:12)
Block(9,10,-4,LEAVES:12)
Block(5,11,-6,LEAVES:12)
Block(5,13,-6,LEAVES:12)
Block(5,5,-8,LEAVES:12)
Block(12,7,1,LEAVES:4)
Block(9,11,-4,LEAVES:12)
Block(5,7,-8,LEAVES:12)
Block(9,13,-4,LEAVES:12)
Block(5,6,-8,LEAVES:12)
Block(5,9,-8,LEAVES:12)
Block(5,8,-8,LEAVES:12)
Block(5,10,-6,LEAVES:12)
Block(2,9,0,LEAVES:12)
Block(5,-2,-5,LOG:13)
Block(5,-3,-5,LOG:13)
Block(5,-1,-5,LOG:13)
Block(2,9,1,LEAVES:12)
Block(5,-6,-5,LOG:13)
Block(5,-5,-5,LOG:13)
Block(7,6,-10,LEAVES:4)
Block(3,10,-1,LEAVES:12)
Block(7,7,-10,LEAVES:12)
Block(1,9,2,LEAVES:4)
Block(5,17,-2,LEAVES:12)
Block(5,18,-2,LEAVES:12)
Block(5,12,-2,LEAVES:12)
Block(5,13,-2,LEAVES:12)
Block(5,14,-2,LEAVES:12)
Block(4,10,-7,LEAVES:12)
Block(5,12,0,LEAVES:12)
Block(5,13,0,LEAVES:12)
Block(5,14,0,LEAVES:12)
Block(1,10,-1,LEAVES:12)
Block(8,16,-3,LEAVES:12)
Block(8,12,-3,LEAVES:12)
Block(8,11,-3,LEAVES:12)
Block(9,13,-2,LEAVES:12)
Block(9,12,-2,LEAVES:12)
Block(7,11,-2,LEAVES:12)
Block(7,12,-2,LEAVES:12)
Block(7,14,-2,LEAVES:12)
Block(7,15,-2,LEAVES:12)
Block(7,16,-2,LEAVES:12)
Block(7,18,-2,LEAVES:12)
Block(7,19,-2,LEAVES:12)
Block(0,9,-1,LEAVES:12)
Block(0,8,-1,LEAVES:12)
Block(2,14,-3,LEAVES:12)
Block(9,7,0,LEAVES:12)
Block(7,14,1,LEAVES:12)
Block(12,8,-1,LEAVES:12)
Block(12,7,-1,LEAVES:12)
Block(6,13,0,LEAVES:12)
Block(12,8,-2,LEAVES:12)
Block(4,17,-3,LEAVES:12)
Block(4,18,-3,LEAVES:12)
Block(4,15,-3,LEAVES:12)
Block(4,16,-3,LEAVES:12)
Block(4,13,-3,LEAVES:12)
Block(6,12,0,LEAVES:12)
Block(12,7,-2,LEAVES:12)
Block(9,6,0,LEAVES:12)
Block(4,12,-3,LEAVES:12)
Block(7,20,-2,LEAVES:4)
Block(5,5,-2,LEAVES:12)
Block(2,10,-1,LEAVES:12)
Block(6,8,-3,LOG:13)
Block(6,9,-3,LOG:13)
Block(3,9,-1,LEAVES:12)
Block(6,6,-3,LOG:13)
Block(3,4,-1,LEAVES:12)
Block(6,7,-3,LOG:13)
Block(6,4,-3,LOG:13)
Block(3,5,-1,LEAVES:12)
Block(6,5,-3,LOG:13)
Block(6,2,-3,LOG:13)
Block(6,3,-3,LOG:13)
Block(6,0,-3,LOG:13)
Block(5,9,-2,LEAVES:12)
Block(6,1,-3,LOG:13)
Block(4,-4,-5,LOG:13)
Block(4,-8,-5,LOG:13)
Block(4,-5,-5,LOG:13)
Block(10,10,-7,LEAVES:12)
Block(4,-6,-5,LOG:13)
Block(9,9,-4,LEAVES:12)
Block(10,11,-7,LEAVES:12)
Block(1,10,0,LEAVES:12)
Block(2,11,-7,LEAVES:12)
Block(7,6,-11,LEAVES:4)
Block(0,8,-4,LOG:13)
Block(11,7,0,LEAVES:12)
Block(3,10,-8,LEAVES:12)
Block(3,11,-8,LEAVES:12)
Block(-1,9,-2,LEAVES:12)
Block(7,11,-4,LEAVES:12)
Block(7,12,-4,LEAVES:12)
Block(7,14,-4,LEAVES:12)
Block(7,15,-4,LEAVES:12)
Block(7,17,-4,LEAVES:12)
Block(7,19,-4,LEAVES:12)
Block(7,14,0,LEAVES:12)
Block(10,11,-9,LOG:13)
Block(10,12,-9,LEAVES:12)
Block(7,10,-4,LEAVES:12)
Block(5,6,-9,LEAVES:12)
Block(2,10,-2,LEAVES:12)
Block(5,8,-9,LEAVES:12)
Block(6,10,-4,LOG:13)
Block(5,7,-9,LEAVES:12)
Block(6,11,-4,LOG:13)
Block(6,17,-4,LEAVES:12)
Block(10,12,-3,LEAVES:12)
Block(6,16,-4,LOG:1)
Block(2,10,1,LEAVES:12)
Block(6,19,-4,LEAVES:12)
Block(10,10,-3,LEAVES:12)
Block(6,18,-4,LEAVES:12)
Block(10,11,-3,LEAVES:12)
Block(6,13,-4,LOG:13)
Block(11,8,-2,LEAVES:12)
Block(6,12,-4,LOG:13)
Block(11,7,-2,LEAVES:12)
Block(6,15,-4,LEAVES:12)
Block(2,9,-3,LEAVES:12)
Block(6,14,-4,LEAVES:12)
Block(2,8,-4,LOG:13)
Block(6,1,-4,LOG:13)
Block(10,11,-4,LEAVES:12)
Block(6,2,-4,LOG:13)
Block(6,0,-4,LOG:13)
Block(6,5,-4,LOG:13)
Block(6,6,-4,LOG:13)
Block(4,-7,-3,LOG:13)
Block(6,3,-4,LOG:13)
Block(4,-8,-3,LOG:13)
Block(6,4,-4,LOG:13)
Block(4,-5,-3,LOG:13)
Block(6,9,-4,LOG:13)
Block(4,-6,-3,LOG:13)
Block(6,7,-4,LOG:13)
Block(6,20,-4,LEAVES:4)
Block(6,8,-4,LOG:13)
Block(4,-1,-3,LOG:13)
Block(4,-2,-3,LOG:13)
Block(4,14,-1,LEAVES:12)
Block(5,6,-1,LEAVES:12)
Block(10,10,-4,LEAVES:12)
Block(8,8,0,LEAVES:12)
Block(2,9,-2,LEAVES:12)
Block(4,10,-1,LEAVES:12)
Block(2,8,-2,LEAVES:12)
Block(2,9,-1,LEAVES:12)
Block(2,8,-1,LEAVES:12)
Block(11,11,-7,LEAVES:12)
Block(9,7,1,LEAVES:12)
Block(8,6,0,LEAVES:12)
Block(8,7,0,LEAVES:12)
Block(12,11,-7,LEAVES:12)
Block(12,11,-8,LEAVES:12)
Block(1,10,2,LEAVES:4)
Block(1,10,1,LEAVES:12)
Block(8,8,1,LEAVES:12)
Block(8,7,1,LEAVES:12)
Block(3,8,-3,LEAVES:12)
Block(3,6,-3,LEAVES:12)
Block(13,7,0,LEAVES:4)
Block(3,9,-3,LEAVES:12)
Block(10,7,-2,LEAVES:12)
Block(5,7,-10,LEAVES:4)
Block(5,8,-10,LEAVES:4)
Block(3,8,-7,LEAVES:12)
Block(3,9,-7,LEAVES:12)
Block(5,-3,-3,LOG:13)
Block(5,-2,-3,LOG:13)
Block(5,-1,-3,LOG:13)
Block(5,-6,-3,LOG:13)
Block(7,13,-1,LEAVES:12)
Block(7,14,-1,LEAVES:12)
Block(6,14,-3,LOG:13)
Block(11,6,-1,LEAVES:12)
Block(6,13,-3,LOG:13)
Block(11,7,-1,LEAVES:12)
Block(6,12,-3,LOG:13)
Block(6,11,-3,LOG:13)
Block(6,18,-3,LEAVES:12)
Block(6,17,-3,LEAVES:12)
Block(3,-7,-3,LOG:13)
Block(6,16,-3,LOG:1)
Block(6,15,-3,LOG:13)
Block(6,19,-3,LOG:1)
Block(11,7,1,LEAVES:12)
Block(2,10,-4,LEAVES:12)
Block(12,11,-6,LEAVES:12)
Block(2,13,-4,LEAVES:12)
Block(-1,10,-2,LEAVES:12)
Block(6,10,-3,LOG:13)
Block(11,12,-8,LEAVES:12)
Block(3,4,-2,LEAVES:12)
Block(3,5,-2,LEAVES:12)
Block(8,9,-6,LEAVES:12)
Block(11,11,-8,LEAVES:12)
Block(10,8,-3,LEAVES:12)
Block(5,-7,-4,LOG:13)
Block(5,-6,-4,LOG:13)
Block(5,-5,-4,LOG:13)
Block(7,7,-9,LEAVES:12)
Block(5,-4,-4,LOG:13)
Block(-2,9,0,LEAVES:12)
Block(4,10,-6,LEAVES:12)
Block(5,-3,-4,LOG:13)
Block(4,12,-6,LEAVES:12)
Block(5,-2,-4,LOG:13)
Block(3,8,-2,LEAVES:12)
Block(4,13,-6,LEAVES:12)
Block(7,6,-9,LEAVES:12)
Block(5,-1,-4,LOG:13)
Block(3,9,-2,LEAVES:12)
Block(3,6,-2,LEAVES:12)
Block(3,7,-2,LEAVES:12)
Block(3,9,-4,LEAVES:12)
Block(3,7,-4,LOG:13)
Block(0,10,1,LEAVES:12)
Block(10,7,-1,LEAVES:12)
Block(10,8,-1,LEAVES:12)
Block(11,11,-4,LEAVES:12)
Block(5,20,-3,LEAVES:4)
Block(10,13,-2,LEAVES:12)
Block(3,8,-6,LEAVES:12)
Block(3,8,-8,LEAVES:12)
Block(3,11,-7,LEAVES:12)
Block(3,10,-7,LEAVES:12)
Block(5,16,-3,LOG:1)
Block(5,17,-3,LEAVES:12)
Block(5,18,-3,LEAVES:12)
Block(5,19,-3,LEAVES:12)
Block(4,17,-2,LEAVES:12)
Block(5,12,-3,LOG:13)
Block(5,13,-3,LOG:13)
Block(5,14,-3,LEAVES:12)
Block(4,18,-2,LEAVES:12)
Block(5,15,-3,LEAVES:12)
Block(4,5,1,LEAVES:12)
Block(5,14,-1,LEAVES:12)
Block(4,6,1,LEAVES:12)
Block(5,11,-3,LOG:13)
Block(4,11,-8,LEAVES:12)
Block(4,10,-8,LEAVES:12)
Block(5,10,-3,LOG:13)
Block(4,7,-7,LEAVES:12)
Block(5,13,-1,LEAVES:12)
Block(5,12,-1,LEAVES:12)
Block(4,9,-7,LEAVES:12)
Block(4,4,0,LEAVES:12)
Block(4,5,0,LEAVES:12)
Block(5,10,-5,LEAVES:12)
Block(5,11,-5,LEAVES:12)
Block(5,12,-5,LEAVES:12)
Block(1,9,1,LEAVES:12)
Block(7,8,-1,LEAVES:12)
Block(0,8,-2,LEAVES:12)
Block(0,9,-2,LEAVES:12)
Block(6,-1,-3,LOG:13)
Block(6,-2,-3,LOG:13)
Block(1,9,0,LEAVES:12)
Block(7,7,-2,LEAVES:12)
Block(7,6,-2,LEAVES:12)
Block(7,8,-2,LEAVES:12)
Block(7,5,-2,LEAVES:12)
Block(5,18,-5,LEAVES:12)
Block(8,6,-1,LEAVES:12)
Block(8,7,-1,LEAVES:12)
Block(5,15,-5,LEAVES:12)
Block(7,6,-3,LEAVES:12)
Block(8,8,-1,LEAVES:12)
Block(5,14,-5,LEAVES:12)
Block(7,8,-3,LEAVES:12)
Block(11,11,-6,LEAVES:12)
Block(7,7,-3,LEAVES:12)
Block(6,10,-5,LEAVES:12)
Block(6,11,-5,LEAVES:12)
Block(6,18,-6,LEAVES:12)
Block(5,8,-6,LEAVES:12)
Block(5,9,-6,LEAVES:12)
Block(5,6,-6,LEAVES:12)
Block(6,17,-6,LEAVES:12)
Block(6,16,-6,LEAVES:12)
Block(5,5,-6,LEAVES:12)
Block(5,9,-4,LOG:13)
Block(5,8,-4,LOG:13)
Block(5,7,-4,LOG:13)
Block(5,6,-4,LOG:13)
Block(6,14,-5,LEAVES:12)
Block(5,5,-4,LOG:13)
Block(10,11,-6,LEAVES:12)
Block(10,12,-6,LEAVES:12)
Block(5,4,-4,LOG:13)
Block(6,16,-5,LEAVES:12)
Block(5,3,-4,LOG:13)
Block(6,15,-5,LEAVES:12)
Block(5,2,-4,LOG:13)
Block(6,18,-5,LEAVES:12)
Block(5,1,-4,LOG:13)
Block(6,17,-5,LEAVES:12)
Block(5,0,-4,LOG:13)
Block(6,7,-11,LEAVES:12)
Block(8,13,-2,LEAVES:12)
Block(8,12,-2,LEAVES:12)
Block(8,11,-2,LEAVES:12)
Block(4,7,-10,LEAVES:4)
Block(4,6,-10,LEAVES:4)
Block(4,7,-8,LEAVES:12)
Block(11,11,-5,LEAVES:12)
Block(2,13,-5,LEAVES:12)
Block(2,12,-5,LEAVES:12)
Block(2,11,-5,LEAVES:12)
Block(7,19,-3,LEAVES:12)
Block(2,14,-6,LEAVES:12)
Block(7,11,-3,LOG:13)
Block(7,12,-3,LEAVES:12)
Block(7,15,-3,LEAVES:12)
Block(7,14,-3,LEAVES:12)
Block(7,17,-3,LEAVES:12)
Block(9,10,-5,LEAVES:12)
Block(2,13,-6,LEAVES:12)
Block(9,11,-5,LEAVES:12)
Block(4,16,-4,LEAVES:12)
Block(9,11,-3,LEAVES:12)
Block(4,14,-4,LEAVES:12)
Block(4,15,-4,LEAVES:12)
Block(4,18,-4,LEAVES:12)
Block(9,12,-3,LEAVES:12)
Block(13,7,-2,LEAVES:4)
Block(4,7,-6,LEAVES:12)
Block(4,9,-6,LEAVES:12)
Block(4,9,-4,LEAVES:12)
Block(4,9,-1,LEAVES:12)
Block(5,10,-7,LEAVES:12)
Block(9,6,-2,LEAVES:12)
Block(0,9,0,LEAVES:12)
Block(9,7,-2,LEAVES:12)
Block(4,7,-4,LOG:13)
Block(4,1,-4,LOG:13)
Block(4,2,-4,LOG:13)
Block(4,3,-4,LOG:13)
Block(-2,9,-2,LEAVES:12)
Block(4,4,-4,LOG:13)
Block(0,9,1,LEAVES:12)
Block(4,13,-4,LEAVES:12)
Block(4,5,-1,LEAVES:12)
Block(4,12,-4,LEAVES:12)
Block(4,4,-1,LEAVES:12)
Block(4,11,-4,LEAVES:12)
Block(4,0,-4,LOG:13)
Block(4,10,-4,LEAVES:12)
Block(6,10,-7,LEAVES:12)
Block(6,20,-3,LOG:1)
Block(8,17,-6,LEAVES:12)
Block(8,16,-6,LEAVES:12)
Block(9,10,-6,LEAVES:12)
Block(1,14,-6,LEAVES:12)
Block(8,15,-6,LEAVES:12)
Block(5,8,-5,LEAVES:12)
Block(5,5,-5,LOG:13)
Block(8,10,-6,LEAVES:12)
Block(5,6,-5,LEAVES:12)
Block(6,-2,-5,LOG:13)
Block(8,11,-6,LEAVES:12)
Block(9,11,-6,LEAVES:12)
Block(5,9,-5,LOG:13)
Block(6,14,2,LEAVES:4)
Block(5,0,-5,LOG:13)
Block(5,1,-5,LOG:13)
Block(10,11,-8,LEAVES:12)
Block(0,10,-1,LEAVES:12)
Block(5,13,1,LEAVES:12)
Block(5,14,1,LEAVES:12)
Block(8,10,-5,LOG:13)
Block(6,12,-1,LEAVES:12)
Block(6,13,-1,LEAVES:12)
Block(6,14,-1,LEAVES:12)
Block(7,8,0,LEAVES:12)
Block(8,17,-5,LEAVES:12)
Block(1,13,-5,LEAVES:12)
Block(8,16,-5,LEAVES:12)
Block(8,15,-5,LEAVES:12)
Block(8,14,-5,LEAVES:12)
Block(8,11,-5,LEAVES:12)
Block(4,7,-9,LEAVES:12)
Block(4,6,-9,LEAVES:12)
Block(2,10,0,LEAVES:12)
Block(4,-8,-4,LOG:13)
Block(3,13,-3,LEAVES:12)
Block(4,3,-5,LOG:13)
Block(-2,9,-1,LEAVES:12)
Block(4,13,1,LEAVES:12)
Block(4,4,-5,LOG:13)
Block(9,7,-1,LEAVES:12)
Block(4,-2,-4,LOG:13)
Block(4,6,-5,LEAVES:12)
Block(4,-1,-4,LOG:13)
Block(4,7,-5,LEAVES:12)
Block(4,-7,-4,LOG:13)
Block(8,7,-11,LEAVES:12)
Block(4,-6,-4,LOG:13)
Block(4,9,-5,LEAVES:12)
Block(4,-5,-4,LOG:13)
Block(9,8,-3,LEAVES:12)
Block(9,7,-3,LEAVES:12)
Block(6,6,-9,LEAVES:12)
Block(-1,8,-1,LEAVES:12)
Block(3,16,-3,LEAVES:12)
Block(6,8,-9,LEAVES:12)
Block(-1,9,-1,LEAVES:12)
Block(3,18,-3,LEAVES:12)

#######################################################################
# +-----------------------------------------------------------------+ #
# |                            BO3 checks                           | #
# +-----------------------------------------------------------------+ #
#######################################################################

# Require a condition at a certain location in order for the BO3 to be spawned.
# BlockCheck(x,y,z,BlockName[,BlockName[,...]]) - one of the blocks must be at the location
# BlockCheckNot(x,y,z,BlockName[,BlockName[,...]]) - all the blocks must not be at the location
# LightCheck(x,y,z,minLightLevel,maxLightLevel) - light must be between min and max (inclusive)

# You can use "Solid" as a BlockName for matching all solid blocks or "All" to match all blocks that aren't air.

# Examples:

#   BlockCheck(0,-1,0,Solid)       Require any solid block just below the object
#   BlockCheck(0,-1,0,WOOL)        Require any type of wool just below the object
#   BlockCheck(0,-1,0,WOOL:0)      Require white wool just below the object
#   BlockCheckNot(0,-1,0,WOOL:0)   Require that there is no white wool below the object
#   LightCheck(0,0,0,0,1)          Require almost complete darkness just below the object
BlockCheck(0,-1,0,GRASS,DIRT,DIRT:1,DIRT:2)
#######################################################################
# +-----------------------------------------------------------------+ #
# |                             Branches                            | #
# +-----------------------------------------------------------------+ #
#######################################################################

# Branches are objects that will spawn when this object spawns when it is used in
# the CustomStructure resource. Branches can also have branches, making complex
# structures possible. See the wiki for more details.

# Regular Branches spawn each branch with an independent chance of spawning.
# Branch(x,y,z,branchName,rotation,chance[,anotherBranchName,rotation,chance[,...]][IndividualChance])
# branchName - name of the object to spawn.
# rotation - NORTH, SOUTH, EAST or WEST.
# IndividualChance - The chance each branch has to spawn, assumed to be 100 when left blank

# Weighted Branches spawn branches with a dependent chance of spawning.
# WeightedBranch(x,y,z,branchName,rotation,chance[,anotherBranchName,rotation,chance[,...]][MaxChanceOutOf])
# MaxChanceOutOf - The chance all branches have to spawn out of, assumed to be 100 when left blank
