
#######################################################################
# +-----------------------------------------------------------------+ #
# |                            BO3 object                           | #
# +-----------------------------------------------------------------+ #
#######################################################################

# This is the config file of a custom object.
# If you add this object correctly to your BiomeConfigs, it will spawn in the world.

# This is the creator of this BO3 object
Author: NLBlackEagle

# A short description of this BO3 object
Description: Converted version of the BO2 28

# The BO3 version, don't change this! It can be used by external applications to do a version check.
Version: 3

# The settings mode, WriteAll, WriteWithoutComments or WriteDisable. See WorldConfig.
SettingsMode: WriteDisable


#######################################################################
# +-----------------------------------------------------------------+ #
# |                          Main settings                          | #
# +-----------------------------------------------------------------+ #
#######################################################################

# This needs to be set to true to spawn the object in the Tree and Sapling resources.
Tree: true

# The frequency of the BO3 from 1 to 200. Tries this many times to spawn this BO3 when using the CustomObject(...) resource.
# Ignored by Tree(..), Sapling(..) and CustomStructure(..)
Frequency: 1

# The rarity of the BO3 from 0 to 100. Each spawn attempt has rarity% chance to succeed when using the CustomObject(...) resource.
# Ignored by Tree(..), Sapling(..) and CustomStructure(..)
Rarity: 100.0

# If you set this to true, the BO3 will be placed with a random rotation.
RotateRandomly: true

# The spawn height of the BO3 - randomY, highestBlock or highestSolidBlock.
SpawnHeight: highestSolidBlock

# The height limits for the BO3.
MinHeight: 0

MaxHeight: 85

# Objects can have other objects attacthed to it: branches. Branches can also
# have branches attached to it, which can also have branches, etc. This is the
# maximum branch depth for this objects.
MaxBranchDepth: 10

# When spawned with the UseWorld keyword, this BO3 should NOT spawn in the following biomes.
# If you writer.write the BO3 name directly in the BiomeConfigs, this will be ignored.
ExcludedBiomes: 


#######################################################################
# +-----------------------------------------------------------------+ #
# |                      Source block settings                      | #
# +-----------------------------------------------------------------+ #
#######################################################################

# The block(s) the BO3 should spawn in.
SourceBlocks: AIR

# The maximum percentage of the BO3 that can be outside the SourceBlock.
# The BO3 won't be placed on a location with more blocks outside the SourceBlock than this percentage.
MaxPercentageOutsideSourceBlock: 20

# What to do when a block is about to be placed outside the SourceBlock? (dontPlace, placeAnyway)
OutsideSourceBlock: placeAnyway


#######################################################################
# +-----------------------------------------------------------------+ #
# |                              Blocks                             | #
# +-----------------------------------------------------------------+ #
#######################################################################

# All the blocks used in the BO3 are listed here. Possible blocks:
# Block(x,y,z,id[.data][,nbtfile.nbt)
# RandomBlock(x,y,z,id[:data][,nbtfile.nbt],chance[,id[:data][,nbtfile.nbt],chance[,...]])
# So RandomBlock(0,0,0,CHEST,chest.nbt,50,CHEST,anotherchest.nbt,100) will spawn a chest at
# the BO3 origin, and give it a 50% chance to have the contents of chest.nbt, or, if that
# fails, a 100% percent chance to have the contents of anotherchest.nbt.
Block(1,19,-4,LEAVES:12)
Block(10,15,1,LEAVES:12)
Block(10,16,1,LEAVES:12)
Block(4,13,-5,LOG:13)
Block(3,16,-6,LEAVES:12)
Block(9,19,-7,LEAVES:12)
Block(3,17,-6,LEAVES:12)
Block(3,18,-6,LEAVES:12)
Block(8,25,-4,LEAVES:12)
Block(4,17,-5,LEAVES:12)
Block(3,25,-6,LEAVES:12)
Block(3,23,-6,LEAVES:12)
Block(3,22,-6,LEAVES:12)
Block(3,21,-6,LEAVES:12)
Block(3,20,-6,LEAVES:12)
Block(8,18,-4,LEAVES:12)
Block(8,16,-4,LEAVES:12)
Block(8,17,-4,LEAVES:12)
Block(8,18,-7,LEAVES:12)
Block(8,15,-7,LEAVES:12)
Block(6,-6,-4,LOG:13)
Block(6,-4,-4,LOG:13)
Block(6,-5,-4,LOG:13)
Block(6,-3,-4,LOG:13)
Block(6,-1,-4,LOG:13)
Block(3,24,-4,LEAVES:12)
Block(3,25,-4,LEAVES:12)
Block(3,22,-4,LEAVES:12)
Block(3,23,-4,LEAVES:12)
Block(4,24,-5,LEAVES:12)
Block(4,22,-5,LEAVES:12)
Block(4,23,-5,LEAVES:12)
Block(4,20,-5,LEAVES:12)
Block(4,21,-5,LEAVES:12)
Block(3,18,-5,LEAVES:12)
Block(3,19,-4,LEAVES:12)
Block(3,17,-5,LEAVES:12)
Block(3,18,-4,LEAVES:12)
Block(3,19,-2,LEAVES:12)
Block(3,15,-2,LEAVES:12)
Block(9,20,-7,LEAVES:12)
Block(3,16,-2,LEAVES:12)
Block(6,7,-5,LOG:13)
Block(6,6,-5,LOG:13)
Block(4,26,-5,LEAVES:12)
Block(6,21,-2,LEAVES:12)
Block(6,15,-8,LEAVES:12)
Block(6,22,-2,LEAVES:12)
Block(7,20,-6,LEAVES:12)
Block(6,25,-2,LEAVES:12)
Block(6,20,1,LEAVES:12)
Block(4,20,0,LEAVES:12)
Block(4,21,0,LEAVES:12)
Block(7,26,-6,LEAVES:12)
Block(6,18,-8,LEAVES:12)
Block(10,19,-5,LEAVES:12)
Block(10,18,-5,LEAVES:12)
Block(7,24,-6,LEAVES:12)
Block(6,20,-2,LEAVES:12)
Block(7,25,-6,LEAVES:12)
Block(6,12,-2,LEAVES:12)
Block(6,13,-2,LEAVES:12)
Block(3,17,0,LEAVES:12)
Block(6,11,-2,LEAVES:12)
Block(6,16,-2,LEAVES:12)
Block(6,17,-2,LEAVES:12)
Block(6,15,-2,LEAVES:12)
Block(6,18,-2,LEAVES:12)
Block(6,19,-2,LEAVES:12)
Block(8,15,-1,LEAVES:12)
Block(8,17,-1,LEAVES:12)
Block(7,18,-6,LEAVES:12)
Block(7,19,-6,LEAVES:12)
Block(7,13,-6,LEAVES:12)
Block(8,12,-1,LEAVES:12)
Block(7,14,-6,LEAVES:12)
Block(8,11,-1,LEAVES:12)
Block(0,19,-5,LEAVES:12)
Block(5,26,-6,LEAVES:12)
Block(5,14,-4,LOG:13)
Block(5,13,-4,LOG:13)
Block(5,16,-4,LOG:13)
Block(5,15,-4,LOG:13)
Block(5,18,-4,LOG:13)
Block(5,17,-4,LOG:13)
Block(11,17,-3,LEAVES:12)
Block(5,19,-4,LOG:13)
Block(5,10,-4,LOG:13)
Block(5,11,-4,LOG:13)
Block(5,12,-4,LOG:13)
Block(5,24,-6,LEAVES:12)
Block(5,25,-6,LEAVES:12)
Block(5,23,-6,LEAVES:12)
Block(9,20,-4,LEAVES:12)
Block(5,20,-6,LEAVES:12)
Block(5,21,-6,LEAVES:12)
Block(5,0,-3,LOG:13)
Block(5,19,-6,LEAVES:12)
Block(5,1,-3,LOG:13)
Block(5,2,-3,LOG:13)
Block(5,3,-3,LOG:13)
Block(5,16,-6,LOG:13)
Block(5,15,-6,LEAVES:12)
Block(5,4,-3,LOG:13)
Block(5,5,-3,LOG:13)
Block(5,18,-6,LEAVES:12)
Block(5,6,-3,LOG:13)
Block(5,17,-6,LEAVES:12)
Block(5,27,-4,LEAVES:12)
Block(5,7,-3,LOG:13)
Block(5,26,-4,LEAVES:12)
Block(5,8,-3,LOG:13)
Block(5,25,-4,LEAVES:12)
Block(5,9,-3,LOG:13)
Block(5,24,-4,LEAVES:12)
Block(5,28,-4,LEAVES:12)
Block(9,18,-4,LEAVES:12)
Block(11,16,-3,LEAVES:12)
Block(9,17,-4,LEAVES:12)
Block(6,12,1,LEAVES:12)
Block(5,22,-4,LOG:13)
Block(5,23,-4,LEAVES:12)
Block(5,20,-4,LOG:13)
Block(5,21,-4,LEAVES:12)
Block(9,20,-8,LEAVES:12)
Block(9,21,-8,LEAVES:12)
Block(9,16,-4,LEAVES:12)
Block(5,-8,-5,LOG:13)
Block(4,17,-9,LEAVES:12)
Block(5,-2,-5,LOG:13)
Block(5,-3,-5,LOG:13)
Block(5,-1,-5,LOG:13)
Block(3,16,-1,LEAVES:12)
Block(5,-6,-5,LOG:13)
Block(3,15,-1,LEAVES:12)
Block(5,19,-2,LEAVES:12)
Block(5,15,-2,LEAVES:12)
Block(5,16,-2,LEAVES:12)
Block(5,17,-2,LEAVES:12)
Block(5,18,-2,LEAVES:12)
Block(12,17,-3,LEAVES:4)
Block(12,16,-3,LEAVES:4)
Block(5,13,-2,LEAVES:12)
Block(5,21,-2,LOG:13)
Block(5,20,-2,LEAVES:12)
Block(12,15,-3,LEAVES:4)
Block(5,12,0,LEAVES:12)
Block(4,19,-7,LEAVES:12)
Block(5,13,0,LEAVES:12)
Block(4,17,-7,LEAVES:12)
Block(4,18,-7,LEAVES:12)
Block(5,18,0,LEAVES:12)
Block(5,19,0,LEAVES:12)
Block(5,22,-2,LEAVES:12)
Block(9,19,-2,LEAVES:12)
Block(2,15,-3,LEAVES:12)
Block(2,16,-3,LEAVES:12)
Block(9,15,-2,LEAVES:12)
Block(9,16,-2,LEAVES:12)
Block(9,13,-2,LEAVES:12)
Block(9,14,-2,LEAVES:12)
Block(6,20,0,LEAVES:12)
Block(7,11,-2,LEAVES:12)
Block(7,12,-2,LEAVES:12)
Block(7,15,-2,LEAVES:12)
Block(5,20,0,LEAVES:12)
Block(7,17,-2,LEAVES:12)
Block(7,18,-2,LEAVES:12)
Block(7,20,0,LEAVES:12)
Block(2,14,-3,LEAVES:12)
Block(6,17,0,LEAVES:12)
Block(6,19,0,LEAVES:12)
Block(2,20,-7,LEAVES:12)
Block(4,19,-3,LEAVES:12)
Block(2,17,-1,LEAVES:12)
Block(4,18,-3,LEAVES:12)
Block(4,15,-3,LOG:13)
Block(4,16,-3,LEAVES:12)
Block(2,16,-1,LEAVES:12)
Block(6,12,0,LEAVES:12)
Block(4,14,-3,LEAVES:12)
Block(6,11,0,LEAVES:12)
Block(7,20,-2,LEAVES:12)
Block(7,24,-4,LEAVES:12)
Block(7,25,-4,LEAVES:12)
Block(7,15,-7,LEAVES:12)
Block(7,23,-4,LEAVES:12)
Block(7,14,-7,LEAVES:12)
Block(4,-2,-5,LOG:13)
Block(4,-7,-5,LOG:13)
Block(10,15,3,LEAVES:4)
Block(4,20,-1,LEAVES:12)
Block(10,20,-8,LEAVES:12)
Block(4,21,-3,LEAVES:12)
Block(7,13,-7,LEAVES:12)
Block(3,18,-8,LEAVES:12)
Block(7,12,-4,LEAVES:12)
Block(7,13,-4,LEAVES:12)
Block(10,20,-7,LEAVES:12)
Block(10,21,-7,LEAVES:12)
Block(8,20,-7,LEAVES:12)
Block(7,15,-4,LEAVES:12)
Block(7,16,-4,LEAVES:12)
Block(7,17,-4,LEAVES:12)
Block(0,19,-6,LEAVES:12)
Block(7,12,0,LEAVES:12)
Block(7,15,-8,LEAVES:12)
Block(10,12,0,LEAVES:12)
Block(10,14,0,LEAVES:12)
Block(7,14,-8,LEAVES:12)
Block(10,15,0,LEAVES:12)
Block(10,17,0,LEAVES:12)
Block(10,17,-1,LEAVES:12)
Block(10,16,-1,LEAVES:12)
Block(6,10,-4,LOG:13)
Block(6,11,-4,LOG:13)
Block(6,17,-4,LOG:13)
Block(6,16,-4,LOG:13)
Block(6,19,-4,LOG:13)
Block(6,18,-4,LOG:13)
Block(6,13,-4,LOG:13)
Block(2,15,-2,LEAVES:12)
Block(10,16,-3,LEAVES:12)
Block(6,12,-4,LEAVES:12)
Block(10,17,-3,LEAVES:12)
Block(6,15,-4,LOG:13)
Block(6,14,-4,LOG:13)
Block(2,16,-2,LEAVES:12)
Block(6,1,-4,LOG:13)
Block(6,2,-4,LOG:13)
Block(6,0,-4,LOG:13)
Block(7,26,-7,LEAVES:12)
Block(6,5,-4,LOG:13)
Block(4,19,-1,LEAVES:12)
Block(6,6,-4,LOG:13)
Block(10,16,-4,LEAVES:12)
Block(6,3,-4,LOG:13)
Block(10,17,-4,LEAVES:12)
Block(6,4,-4,LOG:13)
Block(10,18,-4,LEAVES:12)
Block(6,21,-4,LEAVES:12)
Block(10,19,-3,LEAVES:12)
Block(6,9,-4,LOG:13)
Block(4,16,-1,LEAVES:12)
Block(6,22,-4,LEAVES:12)
Block(10,18,-3,LEAVES:12)
Block(6,7,-4,LOG:13)
Block(4,18,-1,LEAVES:12)
Block(6,20,-4,LEAVES:12)
Block(6,8,-4,LOG:13)
Block(4,17,-1,LEAVES:12)
Block(6,27,-4,LEAVES:12)
Block(6,26,-4,LEAVES:12)
Block(6,24,-4,LEAVES:12)
Block(6,23,-4,LEAVES:12)
Block(10,15,-1,LEAVES:12)
Block(12,15,-1,LEAVES:4)
Block(10,12,-1,LEAVES:12)
Block(12,16,-1,LEAVES:4)
Block(10,13,-1,LEAVES:12)
Block(7,20,-7,LEAVES:12)
Block(5,20,-5,LOG:13)
Block(5,24,-5,LEAVES:12)
Block(5,15,-8,LEAVES:12)
Block(5,23,-5,LEAVES:12)
Block(5,16,-8,LEAVES:12)
Block(5,22,-5,LOG:13)
Block(5,21,-5,LOG:13)
Block(8,11,1,LEAVES:12)
Block(8,12,1,LEAVES:12)
Block(5,25,-5,LEAVES:12)
Block(5,18,-8,LEAVES:12)
Block(5,26,-5,LEAVES:12)
Block(5,17,-8,LEAVES:12)
Block(8,15,-8,LEAVES:12)
Block(11,16,0,LEAVES:12)
Block(11,15,0,LEAVES:12)
Block(11,17,0,LEAVES:12)
Block(5,-5,-3,LOG:13)
Block(5,-4,-3,LOG:13)
Block(5,-1,-3,LOG:13)
Block(5,-6,-3,LOG:13)
Block(7,12,-1,LEAVES:12)
Block(7,15,-1,LEAVES:12)
Block(2,23,-4,LEAVES:12)
Block(7,16,-1,LEAVES:12)
Block(6,14,-3,LOG:13)
Block(6,13,-3,LEAVES:12)
Block(6,12,-3,LEAVES:12)
Block(6,11,-3,LEAVES:12)
Block(6,18,-3,LEAVES:12)
Block(6,17,-3,LEAVES:12)
Block(8,12,0,LEAVES:12)
Block(6,16,-3,LEAVES:12)
Block(6,15,-3,LEAVES:12)
Block(8,11,0,LEAVES:12)
Block(2,19,-4,LEAVES:12)
Block(6,19,-3,LEAVES:12)
Block(11,15,1,LEAVES:12)
Block(1,16,-3,LEAVES:12)
Block(6,10,-3,LEAVES:12)
Block(11,15,2,LEAVES:4)
Block(5,-8,-4,LOG:13)
Block(5,-7,-4,LOG:13)
Block(5,-6,-4,LOG:13)
Block(7,24,-5,LEAVES:12)
Block(5,-5,-4,LOG:13)
Block(7,25,-5,LEAVES:12)
Block(5,-4,-4,LOG:13)
Block(5,-3,-4,LOG:13)
Block(5,-2,-4,LOG:13)
Block(5,-1,-4,LOG:13)
Block(11,15,-1,LEAVES:12)
Block(4,17,-6,LEAVES:12)
Block(11,16,-1,LEAVES:12)
Block(4,18,-6,LEAVES:12)
Block(7,20,-5,LEAVES:12)
Block(9,15,0,LEAVES:12)
Block(9,14,0,LEAVES:12)
Block(9,12,0,LEAVES:12)
Block(3,23,-7,LEAVES:12)
Block(5,18,-9,LEAVES:12)
Block(4,21,-6,LEAVES:12)
Block(5,26,-3,LEAVES:12)
Block(5,24,-3,LEAVES:12)
Block(4,20,-6,LEAVES:12)
Block(5,27,-3,LEAVES:12)
Block(4,23,-6,LEAVES:12)
Block(4,24,-6,LEAVES:12)
Block(5,22,-3,LEAVES:12)
Block(5,21,-3,LEAVES:12)
Block(5,20,-3,LEAVES:12)
Block(10,15,-2,LEAVES:12)
Block(10,16,-2,LEAVES:12)
Block(7,20,-1,LEAVES:12)
Block(5,17,-9,LEAVES:12)
Block(10,19,-2,LEAVES:12)
Block(5,16,-3,LEAVES:12)
Block(5,17,-3,LOG:13)
Block(4,15,-2,LEAVES:12)
Block(5,18,-3,LEAVES:12)
Block(5,19,-3,LEAVES:12)
Block(4,16,-2,LEAVES:12)
Block(4,19,-2,LEAVES:12)
Block(5,15,-3,LEAVES:12)
Block(4,18,-2,LEAVES:12)
Block(5,17,-1,LEAVES:12)
Block(5,10,-3,LOG:13)
Block(4,17,-8,LEAVES:12)
Block(5,13,-1,LEAVES:12)
Block(5,12,-1,LEAVES:12)
Block(3,18,-7,LEAVES:12)
Block(3,19,-7,LEAVES:12)
Block(5,19,-1,LEAVES:12)
Block(12,15,-2,LEAVES:4)
Block(12,16,-2,LEAVES:4)
Block(5,18,-1,LEAVES:12)
Block(5,10,-5,LOG:13)
Block(5,11,-5,LOG:13)
Block(5,12,-5,LOG:13)
Block(5,13,-5,LOG:13)
Block(6,-4,-3,LOG:13)
Block(4,22,-7,LEAVES:12)
Block(1,16,-2,LEAVES:12)
Block(5,19,-5,LOG:13)
Block(11,16,-2,LEAVES:12)
Block(5,18,-5,LOG:13)
Block(5,15,-5,LOG:13)
Block(5,14,-5,LOG:13)
Block(5,17,-5,LOG:13)
Block(5,16,-5,LOG:13)
Block(6,11,-5,LOG:13)
Block(6,12,-5,LOG:13)
Block(6,19,-6,LEAVES:12)
Block(6,15,-6,LEAVES:12)
Block(6,14,-6,LEAVES:12)
Block(6,17,-6,LEAVES:12)
Block(6,16,-6,LEAVES:12)
Block(5,26,-7,LEAVES:12)
Block(10,19,-6,LEAVES:12)
Block(5,22,-7,LEAVES:12)
Block(5,9,-4,LOG:13)
Block(5,8,-4,LOG:13)
Block(5,7,-4,LOG:13)
Block(5,6,-4,LOG:13)
Block(6,14,-5,LEAVES:12)
Block(5,5,-4,LOG:13)
Block(6,13,-5,LEAVES:12)
Block(5,4,-4,LOG:13)
Block(5,3,-4,LOG:13)
Block(11,15,-2,LEAVES:12)
Block(6,16,-5,LOG:13)
Block(6,15,-5,LEAVES:12)
Block(5,2,-4,LOG:13)
Block(5,1,-4,LOG:13)
Block(6,18,-5,LOG:13)
Block(5,0,-4,LOG:13)
Block(6,17,-5,LEAVES:12)
Block(6,19,-5,LEAVES:12)
Block(2,23,-5,LEAVES:12)
Block(2,22,-5,LEAVES:12)
Block(6,25,-6,LEAVES:12)
Block(6,23,-6,LEAVES:12)
Block(8,15,-2,LEAVES:12)
Block(6,24,-6,LEAVES:12)
Block(8,14,-2,LEAVES:12)
Block(6,21,-6,LEAVES:12)
Block(8,13,-2,LEAVES:12)
Block(8,12,-2,LEAVES:12)
Block(6,20,-6,LEAVES:12)
Block(7,24,-3,LEAVES:12)
Block(7,23,-3,LEAVES:12)
Block(7,22,-3,LEAVES:12)
Block(8,17,-2,LEAVES:12)
Block(1,23,-5,LEAVES:12)
Block(8,16,-2,LEAVES:12)
Block(4,25,-4,LEAVES:12)
Block(9,17,-1,LEAVES:12)
Block(9,16,-1,LEAVES:12)
Block(9,15,-1,LEAVES:12)
Block(9,14,-1,LEAVES:12)
Block(2,19,-6,LEAVES:12)
Block(2,18,-6,LEAVES:12)
Block(9,12,-1,LEAVES:12)
Block(2,19,-5,LEAVES:12)
Block(9,18,-5,LEAVES:12)
Block(2,18,-5,LEAVES:12)
Block(9,19,-5,LEAVES:12)
Block(7,11,-3,LEAVES:12)
Block(4,20,-4,LEAVES:12)
Block(7,12,-3,LEAVES:12)
Block(2,17,-6,LEAVES:12)
Block(4,22,-4,LEAVES:12)
Block(7,15,-3,LEAVES:12)
Block(4,21,-4,LEAVES:12)
Block(7,14,-3,LOG:13)
Block(4,24,-4,LEAVES:12)
Block(7,17,-3,LEAVES:12)
Block(7,16,-3,LEAVES:12)
Block(6,22,-5,LOG:13)
Block(6,23,-5,LEAVES:12)
Block(4,17,-4,LEAVES:12)
Block(6,20,-5,LOG:13)
Block(6,21,-5,LOG:13)
Block(4,15,-4,LOG:13)
Block(9,15,-3,LEAVES:12)
Block(4,18,-4,LEAVES:12)
Block(6,22,-7,LEAVES:12)
Block(5,16,-7,LEAVES:12)
Block(5,17,-7,LEAVES:12)
Block(9,18,-3,LEAVES:12)
Block(6,24,-7,LEAVES:12)
Block(9,17,-3,LEAVES:12)
Block(6,25,-7,LEAVES:12)
Block(9,16,-3,LEAVES:12)
Block(5,19,-7,LEAVES:12)
Block(7,17,-5,LEAVES:12)
Block(7,19,-5,LEAVES:12)
Block(7,18,-5,LEAVES:12)
Block(6,26,-7,LEAVES:12)
Block(7,15,-5,LEAVES:12)
Block(5,15,-7,LEAVES:12)
Block(6,28,-5,LOG:13)
Block(6,27,-5,LOG:13)
Block(2,23,-6,LEAVES:12)
Block(10,20,-6,LEAVES:12)
Block(6,26,-5,LOG:13)
Block(10,21,-6,LEAVES:12)
Block(6,25,-5,LEAVES:12)
Block(2,21,-6,LEAVES:12)
Block(6,24,-5,LEAVES:12)
Block(2,22,-6,LEAVES:12)
Block(4,0,-4,LOG:13)
Block(6,21,-3,LEAVES:12)
Block(6,20,-3,LEAVES:12)
Block(6,14,-7,LEAVES:12)
Block(8,19,-6,LEAVES:12)
Block(8,18,-6,LEAVES:12)
Block(9,12,1,LEAVES:12)
Block(1,17,-6,LEAVES:12)
Block(1,18,-6,LEAVES:12)
Block(5,7,-5,LOG:13)
Block(1,20,-7,LEAVES:12)
Block(5,8,-5,LOG:13)
Block(1,19,-6,LEAVES:12)
Block(5,5,-5,LOG:13)
Block(9,15,1,LEAVES:12)
Block(6,-2,-5,LOG:13)
Block(5,6,-5,LOG:13)
Block(9,16,1,LEAVES:12)
Block(5,9,-5,LOG:13)
Block(6,-7,-5,LOG:13)
Block(6,17,-7,LEAVES:12)
Block(5,0,-5,LOG:13)
Block(5,20,1,LEAVES:12)
Block(6,15,-7,LEAVES:12)
Block(6,16,-7,LEAVES:12)
Block(6,24,-3,LEAVES:12)
Block(5,3,-5,LOG:13)
Block(9,19,-6,LEAVES:12)
Block(5,4,-5,LOG:13)
Block(6,22,-3,LEAVES:12)
Block(5,1,-5,LOG:13)
Block(5,2,-5,LOG:13)
Block(3,21,-5,LEAVES:12)
Block(3,22,-5,LEAVES:12)
Block(9,20,-6,LEAVES:12)
Block(3,25,-5,LEAVES:12)
Block(3,23,-5,LEAVES:12)
Block(6,20,-1,LEAVES:12)
Block(8,20,-5,LEAVES:12)
Block(3,24,-5,LEAVES:12)
Block(9,20,-5,LEAVES:12)
Block(8,20,-6,LEAVES:12)
Block(6,19,-1,LEAVES:12)
Block(6,11,-1,LEAVES:12)
Block(1,19,-5,LEAVES:12)
Block(6,12,-1,LEAVES:12)
Block(10,16,2,LEAVES:4)
Block(1,18,-5,LEAVES:12)
Block(10,15,2,LEAVES:4)
Block(6,16,-1,LEAVES:12)
Block(8,18,-5,LEAVES:12)
Block(2,16,0,LEAVES:12)
Block(2,17,0,LEAVES:12)
Block(8,19,-5,LEAVES:12)
Block(4,-2,-4,LOG:13)
Block(4,-1,-4,LOG:13)
Block(4,7,-5,LOG:13)
Block(4,-6,-4,LOG:13)
Block(4,-5,-4,LOG:13)
Block(3,16,-3,LEAVES:12)
Block(3,19,-3,LEAVES:12)

#######################################################################
# +-----------------------------------------------------------------+ #
# |                            BO3 checks                           | #
# +-----------------------------------------------------------------+ #
#######################################################################

# Require a condition at a certain location in order for the BO3 to be spawned.
# BlockCheck(x,y,z,BlockName[,BlockName[,...]]) - one of the blocks must be at the location
# BlockCheckNot(x,y,z,BlockName[,BlockName[,...]]) - all the blocks must not be at the location
# LightCheck(x,y,z,minLightLevel,maxLightLevel) - light must be between min and max (inclusive)

# You can use "Solid" as a BlockName for matching all solid blocks or "All" to match all blocks that aren't air.

# Examples:

#   BlockCheck(0,-1,0,Solid)       Require any solid block just below the object
#   BlockCheck(0,-1,0,WOOL)        Require any type of wool just below the object
#   BlockCheck(0,-1,0,WOOL:0)      Require white wool just below the object
#   BlockCheckNot(0,-1,0,WOOL:0)   Require that there is no white wool below the object
#   LightCheck(0,0,0,0,1)          Require almost complete darkness just below the object
BlockCheck(4,-1,-4,GRASS,DIRT,DIRT:1,DIRT:2)
#######################################################################
# +-----------------------------------------------------------------+ #
# |                             Branches                            | #
# +-----------------------------------------------------------------+ #
#######################################################################

# Branches are objects that will spawn when this object spawns when it is used in
# the CustomStructure resource. Branches can also have branches, making complex
# structures possible. See the wiki for more details.

# Regular Branches spawn each branch with an independent chance of spawning.
# Branch(x,y,z,branchName,rotation,chance[,anotherBranchName,rotation,chance[,...]][IndividualChance])
# branchName - name of the object to spawn.
# rotation - NORTH, SOUTH, EAST or WEST.
# IndividualChance - The chance each branch has to spawn, assumed to be 100 when left blank

# Weighted Branches spawn branches with a dependent chance of spawning.
# WeightedBranch(x,y,z,branchName,rotation,chance[,anotherBranchName,rotation,chance[,...]][MaxChanceOutOf])
# MaxChanceOutOf - The chance all branches have to spawn out of, assumed to be 100 when left blank
