
#######################################################################
# +-----------------------------------------------------------------+ #
# |                            BO3 object                           | #
# +-----------------------------------------------------------------+ #
#######################################################################

# This is the config file of a custom object.
# If you add this object correctly to your BiomeConfigs, it will spawn in the world.

# This is the creator of this BO3 object
Author: NLBlackEagle

# A short description of this BO3 object
Description: Converted version of the BO2 29

# The BO3 version, don't change this! It can be used by external applications to do a version check.
Version: 3

# The settings mode, WriteAll, WriteWithoutComments or WriteDisable. See WorldConfig.
SettingsMode: WriteDisable


#######################################################################
# +-----------------------------------------------------------------+ #
# |                          Main settings                          | #
# +-----------------------------------------------------------------+ #
#######################################################################

# This needs to be set to true to spawn the object in the Tree and Sapling resources.
Tree: true

# The frequency of the BO3 from 1 to 200. Tries this many times to spawn this BO3 when using the CustomObject(...) resource.
# Ignored by Tree(..), Sapling(..) and CustomStructure(..)
Frequency: 1

# The rarity of the BO3 from 0 to 100. Each spawn attempt has rarity% chance to succeed when using the CustomObject(...) resource.
# Ignored by Tree(..), Sapling(..) and CustomStructure(..)
Rarity: 100.0

# If you set this to true, the BO3 will be placed with a random rotation.
RotateRandomly: true

# The spawn height of the BO3 - randomY, highestBlock or highestSolidBlock.
SpawnHeight: highestSolidBlock

# The height limits for the BO3.
MinHeight: 70

MaxHeight: 256

# Objects can have other objects attacthed to it: branches. Branches can also
# have branches attached to it, which can also have branches, etc. This is the
# maximum branch depth for this objects.
MaxBranchDepth: 10

# When spawned with the UseWorld keyword, this BO3 should NOT spawn in the following biomes.
# If you writer.write the BO3 name directly in the BiomeConfigs, this will be ignored.
ExcludedBiomes: 


#######################################################################
# +-----------------------------------------------------------------+ #
# |                      Source block settings                      | #
# +-----------------------------------------------------------------+ #
#######################################################################

# The block(s) the BO3 should spawn in.
SourceBlocks: AIR

# The maximum percentage of the BO3 that can be outside the SourceBlock.
# The BO3 won't be placed on a location with more blocks outside the SourceBlock than this percentage.
MaxPercentageOutsideSourceBlock: 20

# What to do when a block is about to be placed outside the SourceBlock? (dontPlace, placeAnyway)
OutsideSourceBlock: placeAnyway


#######################################################################
# +-----------------------------------------------------------------+ #
# |                              Blocks                             | #
# +-----------------------------------------------------------------+ #
#######################################################################

# All the blocks used in the BO3 are listed here. Possible blocks:
# Block(x,y,z,id[.data][,nbtfile.nbt)
# RandomBlock(x,y,z,id[:data][,nbtfile.nbt],chance[,id[:data][,nbtfile.nbt],chance[,...]])
# So RandomBlock(0,0,0,CHEST,chest.nbt,50,CHEST,anotherchest.nbt,100) will spawn a chest at
# the BO3 origin, and give it a 50% chance to have the contents of chest.nbt, or, if that
# fails, a 100% percent chance to have the contents of anotherchest.nbt.
Block(-19,11,7,LEAVES:12)
Block(-19,10,7,LEAVES:12)
Block(-14,17,8,LEAVES:12)
Block(-11,5,7,LEAVES:12)
Block(-14,18,8,LEAVES:12)
Block(-7,7,4,LEAVES:4)
Block(-14,16,8,LEAVES:12)
Block(-11,6,7,LEAVES:12)
Block(-14,13,8,LEAVES:12)
Block(-13,9,11,LEAVES:12)
Block(-13,8,11,LEAVES:12)
Block(-13,7,11,LOG:13)
Block(-11,7,9,LEAVES:12)
Block(-11,8,9,LEAVES:12)
Block(-11,9,9,LEAVES:12)
Block(-9,8,14,LEAVES:12)
Block(-13,14,4,LEAVES:12)
Block(-13,6,11,LEAVES:12)
Block(-13,-8,8,LOG:13)
Block(-11,8,5,LEAVES:12)
Block(-11,7,5,LEAVES:12)
Block(-12,7,6,LEAVES:12)
Block(-13,-4,8,LOG:13)
Block(-12,9,6,LEAVES:12)
Block(-11,11,6,LEAVES:12)
Block(-12,8,6,LEAVES:12)
Block(-11,10,6,LEAVES:12)
Block(-11,13,6,LEAVES:12)
Block(-13,-1,8,LOG:13)
Block(-13,-2,8,LOG:13)
Block(-11,7,15,LEAVES:12)
Block(-11,8,15,LEAVES:12)
Block(-12,7,13,LEAVES:12)
Block(-15,7,7,LEAVES:12)
Block(-15,6,7,LEAVES:12)
Block(-12,8,13,LEAVES:12)
Block(-15,9,8,LEAVES:12)
Block(-15,8,8,LEAVES:12)
Block(-15,13,12,LEAVES:12)
Block(-15,6,8,LEAVES:12)
Block(-15,14,12,LEAVES:12)
Block(-15,5,8,LEAVES:12)
Block(-15,9,7,LEAVES:12)
Block(-12,8,12,LEAVES:12)
Block(-12,7,12,LEAVES:12)
Block(-14,2,9,LOG:13)
Block(-14,1,9,LOG:13)
Block(-14,8,4,LOG:13)
Block(-15,6,9,LEAVES:12)
Block(-14,0,9,LOG:13)
Block(-8,11,9,LEAVES:12)
Block(-14,6,9,LOG:13)
Block(-12,7,10,LEAVES:12)
Block(-14,5,9,LOG:13)
Block(-12,8,10,LEAVES:12)
Block(-14,4,9,LOG:13)
Block(-14,3,9,LOG:13)
Block(-12,6,11,LEAVES:12)
Block(-12,7,11,LEAVES:12)
Block(-14,9,9,LEAVES:12)
Block(-14,8,9,LOG:13)
Block(-12,8,11,LEAVES:12)
Block(-14,7,9,LOG:13)
Block(-15,5,9,LOG:13)
Block(-12,-3,6,LOG:13)
Block(-16,9,7,LEAVES:12)
Block(-16,5,8,LEAVES:12)
Block(-12,-4,6,LOG:13)
Block(-17,10,9,LEAVES:12)
Block(-12,11,4,LEAVES:12)
Block(-12,-2,6,LOG:13)
Block(-16,8,7,LEAVES:12)
Block(-7,11,10,LEAVES:12)
Block(-13,19,7,LEAVES:12)
Block(-7,10,10,LEAVES:12)
Block(-17,11,9,LEAVES:12)
Block(-12,-5,6,LOG:13)
Block(-12,-6,6,LOG:13)
Block(-13,16,7,LEAVES:12)
Block(-13,15,7,LEAVES:12)
Block(-13,14,7,LEAVES:12)
Block(-13,13,7,LEAVES:12)
Block(-13,12,7,LEAVES:12)
Block(-16,8,8,LEAVES:12)
Block(-13,11,7,LEAVES:12)
Block(-16,9,8,LEAVES:12)
Block(-16,6,8,LEAVES:12)
Block(-13,10,7,LEAVES:12)
Block(-15,8,5,LOG:13)
Block(-12,18,8,LEAVES:12)
Block(-12,19,8,LEAVES:12)
Block(-15,14,10,LEAVES:12)
Block(-15,13,10,LEAVES:12)
Block(-15,15,10,LEAVES:12)
Block(-12,-4,5,LOG:13)
Block(-12,10,8,LOG:13)
Block(-12,11,8,LEAVES:12)
Block(-12,12,8,LEAVES:12)
Block(-12,13,8,LOG:13)
Block(-17,9,6,LEAVES:12)
Block(-12,14,8,LEAVES:12)
Block(-6,7,6,LEAVES:4)
Block(-12,15,8,LEAVES:12)
Block(-17,8,6,LEAVES:12)
Block(-16,14,10,LEAVES:12)
Block(-13,0,8,LOG:13)
Block(-16,13,10,LEAVES:12)
Block(-16,11,10,LEAVES:12)
Block(-13,21,8,LEAVES:12)
Block(-7,7,5,LEAVES:12)
Block(-13,1,7,LOG:13)
Block(-13,0,7,LOG:13)
Block(-7,6,5,LEAVES:12)
Block(-15,10,9,LEAVES:12)
Block(-11,7,8,LEAVES:12)
Block(-16,14,11,LEAVES:12)
Block(-16,13,11,LEAVES:12)
Block(-14,7,13,LEAVES:12)
Block(-11,6,8,LEAVES:12)
Block(-14,8,13,LEAVES:12)
Block(-14,9,13,LEAVES:12)
Block(-14,7,14,LEAVES:12)
Block(-14,8,14,LEAVES:12)
Block(-13,15,8,LEAVES:12)
Block(-12,7,7,LEAVES:12)
Block(-17,7,9,LEAVES:12)
Block(-13,9,9,LOG:13)
Block(-13,14,8,LOG:13)
Block(-17,6,9,LEAVES:12)
Block(-12,8,7,LEAVES:12)
Block(-13,8,9,LOG:13)
Block(-13,17,8,LEAVES:12)
Block(-17,5,9,LOG:13)
Block(-12,9,7,LEAVES:12)
Block(-13,16,8,LEAVES:12)
Block(-15,8,14,LEAVES:12)
Block(-13,11,8,LOG:13)
Block(-11,-4,6,LOG:13)
Block(-13,10,8,LOG:13)
Block(-13,13,8,LOG:13)
Block(-12,5,7,LOG:13)
Block(-13,12,8,LOG:13)
Block(-12,6,7,LEAVES:12)
Block(-11,8,4,LEAVES:12)
Block(-17,14,11,LEAVES:12)
Block(-6,11,10,LEAVES:4)
Block(-13,1,9,LOG:13)
Block(-6,12,10,LEAVES:4)
Block(-13,0,9,LOG:13)
Block(-8,8,5,LEAVES:12)
Block(-13,3,9,LOG:13)
Block(-13,2,9,LOG:13)
Block(-13,5,9,LOG:13)
Block(-13,18,8,LEAVES:12)
Block(-13,4,9,LOG:13)
Block(-15,7,13,LEAVES:12)
Block(-13,7,9,LOG:13)
Block(-13,6,9,LOG:13)
Block(-13,4,7,LOG:13)
Block(-17,9,8,LEAVES:12)
Block(-13,9,8,LOG:13)
Block(-13,7,7,LEAVES:12)
Block(-17,8,8,LEAVES:12)
Block(-13,9,7,LEAVES:12)
Block(-13,5,8,LOG:13)
Block(-13,6,8,LOG:13)
Block(-12,9,5,LEAVES:12)
Block(-17,9,7,LEAVES:12)
Block(-13,7,8,LOG:13)
Block(-13,8,8,LOG:13)
Block(-13,1,8,LOG:13)
Block(-13,2,8,LOG:13)
Block(-13,3,8,LOG:13)
Block(-12,8,5,LEAVES:12)
Block(-13,4,8,LOG:13)
Block(-13,-5,11,LOG:13)
Block(-17,11,10,LEAVES:12)
Block(-18,11,9,LEAVES:12)
Block(-18,10,9,LEAVES:12)
Block(-10,9,11,LEAVES:12)
Block(-8,7,4,LEAVES:12)
Block(-8,8,4,LEAVES:12)
Block(-6,12,8,LEAVES:4)
Block(-6,7,5,LEAVES:4)
Block(-6,6,5,LEAVES:4)
Block(-14,14,4,LEAVES:12)
Block(-11,8,11,LEAVES:12)
Block(-12,-2,8,LOG:13)
Block(-12,-1,8,LOG:13)
Block(-12,-4,8,LOG:13)
Block(-12,11,5,LEAVES:12)
Block(-12,-3,8,LOG:13)
Block(-12,10,5,LEAVES:12)
Block(-9,5,6,LEAVES:12)
Block(-16,5,11,LEAVES:12)
Block(-16,4,11,LEAVES:12)
Block(-16,7,11,LEAVES:12)
Block(-16,6,11,LEAVES:12)
Block(-5,12,10,LEAVES:4)
Block(-12,3,8,LOG:13)
Block(-12,2,8,LOG:13)
Block(-12,5,8,LOG:13)
Block(-12,4,8,LOG:13)
Block(-12,7,8,LOG:13)
Block(-12,6,8,LOG:13)
Block(-14,15,12,LEAVES:12)
Block(-12,9,8,LOG:13)
Block(-14,14,12,LEAVES:12)
Block(-12,8,8,LOG:13)
Block(-12,1,8,LOG:13)
Block(-11,10,4,LEAVES:12)
Block(-11,11,4,LEAVES:12)
Block(-7,7,6,LEAVES:12)
Block(-8,10,10,LEAVES:12)
Block(-11,20,10,LEAVES:12)
Block(-15,15,13,LEAVES:12)
Block(-15,14,13,LEAVES:12)
Block(-11,17,8,LEAVES:12)
Block(-11,16,8,LEAVES:12)
Block(-11,19,8,LEAVES:12)
Block(-8,12,10,LEAVES:12)
Block(-13,20,10,LEAVES:12)
Block(-11,18,8,LEAVES:12)
Block(-8,11,11,LEAVES:12)
Block(-8,11,10,LEAVES:12)
Block(-11,13,8,LEAVES:12)
Block(-11,12,8,LEAVES:12)
Block(-11,15,8,LEAVES:12)
Block(-11,11,8,LEAVES:12)
Block(-12,-1,7,LOG:13)
Block(-13,19,10,LEAVES:12)
Block(-12,19,9,LEAVES:12)
Block(-12,18,9,LOG:13)
Block(-11,11,11,LEAVES:12)
Block(-11,12,11,LEAVES:12)
Block(-11,13,11,LEAVES:12)
Block(-12,15,9,LOG:13)
Block(-13,13,10,LEAVES:12)
Block(-13,14,10,LEAVES:12)
Block(-12,14,9,LOG:13)
Block(-12,17,9,LEAVES:12)
Block(-13,11,10,LEAVES:12)
Block(-8,7,5,LEAVES:12)
Block(-12,16,9,LOG:13)
Block(-13,12,10,LEAVES:12)
Block(-8,6,5,LEAVES:12)
Block(-13,17,10,LEAVES:12)
Block(-12,11,9,LEAVES:12)
Block(-12,-5,7,LOG:13)
Block(-13,18,10,LEAVES:12)
Block(-12,-4,7,LOG:13)
Block(-12,10,9,LOG:13)
Block(-12,13,9,LOG:13)
Block(-12,-3,7,LOG:13)
Block(-12,12,9,LOG:13)
Block(-12,-2,7,LOG:13)
Block(-19,9,5,LEAVES:12)
Block(-11,16,11,LEAVES:12)
Block(-19,9,6,LEAVES:12)
Block(-11,10,5,LEAVES:12)
Block(-11,20,11,LEAVES:12)
Block(-18,9,8,LEAVES:12)
Block(-20,10,9,LEAVES:4)
Block(-9,12,4,LEAVES:12)
Block(-18,9,7,LEAVES:12)
Block(-12,21,9,LOG:13)
Block(-12,20,9,LEAVES:12)
Block(-9,12,8,LEAVES:12)
Block(-19,9,8,LEAVES:12)
Block(-19,10,5,LEAVES:12)
Block(-11,8,10,LEAVES:12)
Block(-18,9,6,LEAVES:12)
Block(-9,8,6,LEAVES:12)
Block(-9,17,8,LEAVES:12)
Block(-9,6,6,LEAVES:12)
Block(-9,7,6,LEAVES:12)
Block(-13,-5,4,LOG:13)
Block(-11,7,16,LEAVES:12)
Block(-10,7,8,LEAVES:12)
Block(-16,6,10,LEAVES:12)
Block(-14,-2,8,LOG:13)
Block(-14,-1,8,LOG:13)
Block(-14,-3,8,LOG:13)
Block(-8,11,12,LEAVES:12)
Block(-11,8,16,LEAVES:12)
Block(-11,9,6,LEAVES:12)
Block(-11,7,6,LEAVES:12)
Block(-11,5,6,LEAVES:12)
Block(-11,6,6,LEAVES:12)
Block(-14,-7,8,LOG:13)
Block(-13,6,10,LEAVES:12)
Block(-14,7,12,LEAVES:12)
Block(-13,7,10,LOG:13)
Block(-14,8,12,LEAVES:12)
Block(-14,6,11,LEAVES:12)
Block(-14,9,12,LEAVES:12)
Block(-15,6,12,LEAVES:12)
Block(-15,5,12,LEAVES:12)
Block(-18,10,6,LEAVES:12)
Block(-15,5,11,LEAVES:12)
Block(-18,11,6,LEAVES:12)
Block(-15,6,11,LEAVES:12)
Block(-8,7,6,LEAVES:12)
Block(-13,8,10,LEAVES:12)
Block(-14,6,12,LEAVES:12)
Block(-11,13,13,LEAVES:12)
Block(-11,13,10,LEAVES:12)
Block(-11,14,10,LEAVES:12)
Block(-11,15,10,LEAVES:12)
Block(-11,16,10,LEAVES:12)
Block(-11,17,10,LEAVES:12)
Block(-13,-4,10,LOG:13)
Block(-11,18,10,LEAVES:12)
Block(-13,-3,10,LOG:13)
Block(-11,19,10,LEAVES:12)
Block(-12,16,7,LEAVES:12)
Block(-13,-8,10,LOG:13)
Block(-12,15,7,LEAVES:12)
Block(-13,-7,10,LOG:13)
Block(-12,12,7,LEAVES:12)
Block(-13,-6,10,LOG:13)
Block(-12,13,7,LEAVES:12)
Block(-13,-5,10,LOG:13)
Block(-17,10,6,LEAVES:12)
Block(-12,10,7,LEAVES:12)
Block(-12,11,7,LEAVES:12)
Block(-8,6,6,LEAVES:12)
Block(-14,14,5,LEAVES:12)
Block(-14,12,5,LEAVES:12)
Block(-14,13,5,LEAVES:12)
Block(-10,8,4,LEAVES:12)
Block(-11,12,10,LEAVES:12)
Block(-11,11,10,LEAVES:12)
Block(-10,7,4,LEAVES:12)
Block(-14,-2,6,LOG:13)
Block(-14,-3,6,LOG:13)
Block(-12,10,6,LEAVES:12)
Block(-10,19,9,LEAVES:12)
Block(-10,18,9,LEAVES:12)
Block(-12,11,6,LEAVES:12)
Block(-10,16,9,LEAVES:12)
Block(-12,13,6,LEAVES:12)
Block(-10,15,9,LEAVES:12)
Block(-10,11,9,LEAVES:12)
Block(-10,10,9,LEAVES:12)
Block(-19,10,8,LEAVES:12)
Block(-9,7,5,LEAVES:12)
Block(-9,8,5,LEAVES:12)
Block(-14,10,9,LEAVES:12)
Block(-14,18,9,LEAVES:12)
Block(-15,10,6,LEAVES:12)
Block(-14,19,9,LEAVES:12)
Block(-14,14,10,LEAVES:12)
Block(-14,14,6,LEAVES:12)
Block(-14,17,9,LEAVES:12)
Block(-14,15,10,LEAVES:12)
Block(-14,13,6,LEAVES:12)
Block(-15,14,6,LEAVES:12)
Block(-14,12,10,LEAVES:12)
Block(-14,12,6,LEAVES:12)
Block(-14,13,10,LEAVES:12)
Block(-14,10,6,LEAVES:12)
Block(-15,-2,8,LOG:13)
Block(-17,10,7,LEAVES:12)
Block(-15,13,11,LEAVES:12)
Block(-17,11,7,LEAVES:12)
Block(-15,14,11,LEAVES:12)
Block(-14,19,10,LEAVES:12)
Block(-13,14,5,LEAVES:12)
Block(-12,-6,9,LOG:13)
Block(-12,8,14,LEAVES:12)
Block(-13,13,5,LEAVES:12)
Block(-12,-7,9,LOG:13)
Block(-12,7,14,LEAVES:12)
Block(-12,-4,9,LOG:13)
Block(-17,6,10,LEAVES:12)
Block(-17,5,10,LEAVES:12)
Block(-11,13,7,LEAVES:12)
Block(-11,11,7,LEAVES:12)
Block(-11,10,7,LEAVES:12)
Block(-12,7,16,LEAVES:12)
Block(-8,12,8,LEAVES:12)
Block(-7,11,11,LEAVES:12)
Block(-20,10,5,LEAVES:4)
Block(-6,12,9,LEAVES:4)
Block(-6,11,9,LEAVES:4)
Block(-10,8,16,LEAVES:12)
Block(-10,6,5,LEAVES:12)
Block(-10,11,10,LEAVES:12)
Block(-10,10,10,LEAVES:12)
Block(-10,7,5,LEAVES:12)
Block(-10,8,5,LEAVES:12)
Block(-16,5,9,LEAVES:12)
Block(-16,6,9,LEAVES:12)
Block(-10,7,7,LEAVES:12)
Block(-10,16,10,LEAVES:12)
Block(-10,17,10,LEAVES:12)
Block(-10,14,10,LEAVES:12)
Block(-10,15,10,LEAVES:12)
Block(-9,7,4,LEAVES:12)
Block(-15,14,7,LEAVES:12)
Block(-14,-6,9,LOG:13)
Block(-14,-5,9,LOG:13)
Block(-15,10,7,LEAVES:12)
Block(-14,-3,9,LOG:13)
Block(-14,-2,9,LOG:13)
Block(-15,18,8,LEAVES:12)
Block(-14,-1,9,LOG:13)
Block(-15,19,8,LEAVES:12)
Block(-14,-7,5,LOG:13)
Block(-11,-4,7,LOG:13)
Block(-16,14,12,LEAVES:12)
Block(-16,15,12,LEAVES:12)
Block(-10,7,15,LEAVES:12)
Block(-10,8,15,LEAVES:12)
Block(-12,20,11,LEAVES:12)
Block(-6,11,11,LEAVES:12)
Block(-15,6,10,LEAVES:12)
Block(-19,10,9,LEAVES:12)
Block(-14,13,11,LEAVES:12)
Block(-19,11,9,LEAVES:12)
Block(-14,14,11,LEAVES:12)
Block(-12,19,11,LEAVES:12)
Block(-12,4,9,LOG:13)
Block(-12,18,11,LEAVES:12)
Block(-12,7,9,LOG:13)
Block(-12,16,11,LEAVES:12)
Block(-12,8,9,LEAVES:12)
Block(-12,5,9,LOG:13)
Block(-12,6,9,LOG:13)
Block(-12,9,9,LOG:13)
Block(-10,6,6,LEAVES:12)
Block(-10,7,6,LEAVES:12)
Block(-10,8,6,LEAVES:12)
Block(-10,9,6,LEAVES:12)
Block(-12,12,11,LEAVES:12)
Block(-12,11,11,LEAVES:12)
Block(-9,6,5,LEAVES:12)
Block(-12,13,12,LEAVES:12)
Block(-13,-3,7,LOG:13)
Block(-13,-4,7,LOG:13)
Block(-18,7,9,LEAVES:12)
Block(-13,-5,7,LOG:13)
Block(-13,-6,7,LOG:13)
Block(-13,-1,7,LOG:13)
Block(-13,-2,7,LOG:13)
Block(-11,8,13,LEAVES:12)
Block(-11,7,13,LEAVES:12)
Block(-10,10,11,LEAVES:12)
Block(-10,11,11,LEAVES:12)
Block(-10,12,11,LEAVES:12)
Block(-10,13,11,LEAVES:12)
Block(-15,-3,9,LOG:13)
Block(-20,10,8,LEAVES:4)
Block(-15,-2,9,LOG:13)
Block(-9,11,13,LEAVES:12)
Block(-10,11,6,LEAVES:12)
Block(-10,10,6,LEAVES:12)
Block(-13,19,11,LOG:13)
Block(-10,12,12,LEAVES:12)
Block(-19,10,4,LEAVES:12)
Block(-13,18,11,LEAVES:12)
Block(-10,13,12,LEAVES:12)
Block(-13,4,6,LOG:13)
Block(-11,12,12,LEAVES:12)
Block(-13,14,11,LEAVES:12)
Block(-11,11,12,LEAVES:12)
Block(-13,13,11,LEAVES:12)
Block(-10,10,12,LEAVES:12)
Block(-11,13,12,LEAVES:12)
Block(-10,11,12,LEAVES:12)
Block(-6,7,4,LEAVES:4)
Block(-5,11,11,LEAVES:12)
Block(-13,12,6,LEAVES:12)
Block(-13,13,6,LEAVES:12)
Block(-18,10,8,LEAVES:12)
Block(-10,12,4,LEAVES:12)
Block(-10,11,4,LEAVES:12)
Block(-18,11,8,LEAVES:12)
Block(-13,11,6,LEAVES:12)
Block(-13,15,9,LOG:13)
Block(-9,10,9,LEAVES:12)
Block(-13,16,9,LOG:13)
Block(-9,11,9,LEAVES:12)
Block(-13,11,9,LOG:13)
Block(-14,19,7,LEAVES:12)
Block(-9,15,9,LEAVES:12)
Block(-13,12,9,LOG:13)
Block(-13,13,9,LOG:13)
Block(-13,14,9,LOG:13)
Block(-14,14,7,LEAVES:12)
Block(-14,15,7,LEAVES:12)
Block(-9,16,9,LEAVES:12)
Block(-14,16,7,LEAVES:12)
Block(-9,17,9,LEAVES:12)
Block(-14,10,7,LEAVES:12)
Block(-14,13,7,LEAVES:12)
Block(-13,20,11,LEAVES:12)
Block(-12,-4,10,LOG:13)
Block(-12,-5,10,LOG:13)
Block(-19,10,6,LEAVES:12)
Block(-13,10,9,LOG:13)
Block(-12,-7,10,LOG:13)
Block(-9,8,15,LEAVES:12)
Block(-11,10,9,LOG:13)
Block(-11,11,9,LEAVES:12)
Block(-11,12,9,LEAVES:12)
Block(-14,-5,10,LOG:13)
Block(-9,17,10,LEAVES:12)
Block(-11,14,9,LEAVES:12)
Block(-14,-4,10,LOG:13)
Block(-11,15,9,LEAVES:12)
Block(-11,16,9,LEAVES:12)
Block(-14,-6,10,LOG:13)
Block(-11,17,9,LEAVES:12)
Block(-11,18,9,LEAVES:12)
Block(-11,8,14,LEAVES:12)
Block(-11,19,9,LEAVES:12)
Block(-14,-3,10,LOG:13)
Block(-11,7,14,LEAVES:12)
Block(-11,6,14,LEAVES:12)
Block(-14,-2,10,LOG:13)
Block(-7,12,9,LEAVES:12)
Block(-7,11,9,LEAVES:12)
Block(-10,12,5,LEAVES:12)
Block(-11,8,12,LEAVES:12)
Block(-11,6,12,LEAVES:12)
Block(-11,7,12,LEAVES:12)
Block(-17,6,11,LEAVES:12)
Block(-9,11,10,LEAVES:12)
Block(-9,10,10,LEAVES:12)
Block(-17,7,11,LEAVES:12)
Block(-10,10,5,LEAVES:12)
Block(-6,11,12,LEAVES:12)
Block(-14,8,6,LOG:13)
Block(-14,8,5,LOG:13)
Block(-9,11,12,LEAVES:12)
Block(-9,10,12,LEAVES:12)
Block(-14,8,7,LOG:13)
Block(-13,-6,5,LOG:13)
Block(-14,7,7,LOG:13)
Block(-9,10,11,LEAVES:12)
Block(-14,9,8,LEAVES:12)
Block(-16,10,8,LEAVES:12)
Block(-14,8,8,LOG:13)
Block(-9,11,11,LEAVES:12)
Block(-13,-4,5,LOG:13)
Block(-14,3,8,LOG:13)
Block(-14,2,8,LOG:13)
Block(-14,1,8,LOG:13)
Block(-14,0,8,LOG:13)
Block(-14,7,8,LOG:13)
Block(-14,6,8,LOG:13)
Block(-14,5,8,LOG:13)
Block(-14,4,8,LOG:13)
Block(-14,9,7,LEAVES:12)
Block(-17,10,8,LEAVES:12)
Block(-16,11,7,LEAVES:12)
Block(-16,10,7,LEAVES:12)
Block(-18,10,7,LEAVES:12)
Block(-18,11,7,LEAVES:12)
Block(-13,-1,6,LOG:13)
Block(-13,-6,6,LOG:13)
Block(-13,-2,6,LOG:13)
Block(-13,-5,6,LOG:13)
Block(-13,-4,6,LOG:13)
Block(-10,16,8,LEAVES:12)
Block(-14,-1,7,LOG:13)
Block(-10,18,8,LEAVES:12)
Block(-14,-3,7,LOG:13)
Block(-10,17,8,LEAVES:12)
Block(-14,-2,7,LOG:13)
Block(-13,-6,9,LOG:13)
Block(-11,20,9,LEAVES:12)
Block(-13,7,13,LEAVES:12)
Block(-13,-7,9,LOG:13)
Block(-12,21,8,LEAVES:12)
Block(-16,11,9,LEAVES:12)
Block(-13,6,12,LEAVES:12)
Block(-13,-2,9,LOG:13)
Block(-12,20,8,LEAVES:12)
Block(-13,-1,9,LOG:13)
Block(-13,7,12,LEAVES:12)
Block(-16,10,9,LEAVES:12)
Block(-13,-4,9,LOG:13)
Block(-13,8,12,LEAVES:12)
Block(-10,12,8,LEAVES:12)
Block(-14,-5,7,LOG:13)
Block(-10,11,8,LEAVES:12)
Block(-18,10,5,LEAVES:12)
Block(-13,7,14,LEAVES:12)
Block(-10,8,13,LEAVES:12)
Block(-13,8,14,LEAVES:12)
Block(-12,17,10,LEAVES:12)
Block(-15,14,5,LEAVES:12)
Block(-12,16,10,LEAVES:12)
Block(-12,19,10,LEAVES:12)
Block(-12,18,10,LEAVES:12)
Block(-12,12,10,LEAVES:12)
Block(-12,15,10,LEAVES:12)
Block(-12,14,10,LEAVES:12)

#######################################################################
# +-----------------------------------------------------------------+ #
# |                            BO3 checks                           | #
# +-----------------------------------------------------------------+ #
#######################################################################

# Require a condition at a certain location in order for the BO3 to be spawned.
# BlockCheck(x,y,z,BlockName[,BlockName[,...]]) - one of the blocks must be at the location
# BlockCheckNot(x,y,z,BlockName[,BlockName[,...]]) - all the blocks must not be at the location
# LightCheck(x,y,z,minLightLevel,maxLightLevel) - light must be between min and max (inclusive)

# You can use "Solid" as a BlockName for matching all solid blocks or "All" to match all blocks that aren't air.

# Examples:

#   BlockCheck(0,-1,0,Solid)       Require any solid block just below the object
#   BlockCheck(0,-1,0,WOOL)        Require any type of wool just below the object
#   BlockCheck(0,-1,0,WOOL:0)      Require white wool just below the object
#   BlockCheckNot(0,-1,0,WOOL:0)   Require that there is no white wool below the object
#   LightCheck(0,0,0,0,1)          Require almost complete darkness just below the object
BlockCheck(0,-1,0,GRASS,DIRT,DIRT:1,DIRT:2)
#######################################################################
# +-----------------------------------------------------------------+ #
# |                             Branches                            | #
# +-----------------------------------------------------------------+ #
#######################################################################

# Branches are objects that will spawn when this object spawns when it is used in
# the CustomStructure resource. Branches can also have branches, making complex
# structures possible. See the wiki for more details.

# Regular Branches spawn each branch with an independent chance of spawning.
# Branch(x,y,z,branchName,rotation,chance[,anotherBranchName,rotation,chance[,...]][IndividualChance])
# branchName - name of the object to spawn.
# rotation - NORTH, SOUTH, EAST or WEST.
# IndividualChance - The chance each branch has to spawn, assumed to be 100 when left blank

# Weighted Branches spawn branches with a dependent chance of spawning.
# WeightedBranch(x,y,z,branchName,rotation,chance[,anotherBranchName,rotation,chance[,...]][MaxChanceOutOf])
# MaxChanceOutOf - The chance all branches have to spawn out of, assumed to be 100 when left blank
