[META]
version=2.0
spawnOnBlockType=2,3,3:1,3:2
spawnSunlight=True
spawnDarkness=True
spawnWater=False
spawnLava=False
underFill=False
randomRotation=True
dig=True
tree=True
branch=False
needsFoundation=True
rarity=100
collisionPercentage=20
spawnElevationMin=0
spawnElevationMax=240
spawnInBiome=Custom
[DATA]
0,-1,-2:17.0
1,-1,-2:17.0
0,0,-2:17.0
1,0,-2:17.0
0,-1,-1:17.0
1,-1,-1:17.0
0,0,-1:17.0
1,0,-1:17.0
0,-1,0:17.0
1,-1,0:17.0
0,0,0:17.0
1,0,0:17.0
0,-1,1:17.0
1,-1,1:17.0
0,0,1:17.0
1,0,1:17.0
0,-1,2:17.0
1,-1,2:17.0
0,0,2:17.0
1,0,2:17.0
0,-1,3:17.0
1,-1,3:17.0
0,0,3:17.0
1,0,3:17.0
0,-1,4:17.0
1,-1,4:17.0
0,0,4:17.0
1,0,4:17.0
0,-1,5:17.0
1,-1,5:17.0
0,0,5:17.0
1,0,5:17.0
0,-1,6:17.0
1,-1,6:17.0
0,0,6:17.0
1,0,6:17.0
0,-1,7:17.0
1,-1,7:17.0
0,0,7:17.0
1,0,7:17.0
0,-1,8:17.0
1,-1,8:17.0
0,0,8:17.0
1,0,8:17.0
0,-2,9:17.0
0,-1,9:17.0
1,-1,9:17.0
0,0,9:17.0
1,0,9:17.0
0,-3,10:17.0
0,-1,10:17.0
1,-1,10:17.0
2,-1,10:17.0
0,0,10:17.0
1,0,10:17.0
0,-4,11:17.0
0,-1,11:17.0
1,-1,11:17.0
3,-1,11:17.0
0,0,11:17.0
1,0,11:17.0
0,1,11:17.0
-1,-7,12:18.0
0,-7,12:18.0
0,-6,12:18.0
-1,-5,12:18.0
0,-5,12:17.0
0,-1,12:17.0
1,-1,12:17.0
4,-1,12:17.0
0,0,12:17.0
1,0,12:17.0
0,2,12:17.0
-2,-7,13:18.0
-1,-7,13:18.0
0,-7,13:18.0
1,-7,13:18.0
-2,-6,13:18.0
-1,-6,13:18.0
0,-6,13:17.0
1,-6,13:18.0
2,-6,13:18.0
-1,-5,13:18.0
0,-5,13:18.0
1,-5,13:18.0
0,-4,13:18.0
6,-2,13:18.0
0,-1,13:17.0
1,-1,13:17.0
5,-1,13:17.0
6,-1,13:18.0
-1,0,13:17.0
0,0,13:17.0
1,0,13:17.0
5,0,13:18.0
6,0,13:18.0
0,3,13:17.0
-1,-6,14:18.0
0,-6,14:18.0
-1,-5,14:18.0
6,-3,14:18.0
0,-2,14:17.0
4,-2,14:18.0
5,-2,14:18.0
6,-2,14:18.0
0,-1,14:17.0
1,-1,14:17.0
2,-1,14:17.0
5,-1,14:18.0
6,-1,14:17.0
7,-1,14:18.0
-2,0,14:17.0
0,0,14:17.0
1,0,14:17.0
4,0,14:18.0
5,0,14:18.0
6,0,14:18.0
-1,4,14:18.0
0,4,14:17.0
1,4,14:18.0
-1,5,14:18.0
0,5,14:18.0
1,5,14:18.0
-1,6,14:18.0
1,6,14:18.0
0,-3,15:17.0
-5,-1,15:18.0
-3,-1,15:18.0
0,-1,15:17.0
1,-1,15:17.0
3,-1,15:17.0
5,-1,15:18.0
6,-1,15:18.0
-5,0,15:18.0
-4,0,15:18.0
-3,0,15:17.0
0,0,15:17.0
1,0,15:17.0
-5,1,15:18.0
-3,1,15:18.0
-1,3,15:18.0
0,3,15:18.0
-2,4,15:18.0
-1,4,15:18.0
0,4,15:18.0
1,4,15:18.0
-1,5,15:18.0
0,5,15:17.0
1,5,15:18.0
0,6,15:18.0
-1,-6,16:18.0
-1,-5,16:18.0
0,-5,16:18.0
1,-5,16:18.0
-1,-4,16:18.0
0,-4,16:17.0
1,-4,16:18.0
-4,-2,16:18.0
-6,-1,16:18.0
-5,-1,16:18.0
-4,-1,16:18.0
-3,-1,16:18.0
-2,-1,16:18.0
-1,-1,16:17.0
0,-1,16:17.0
1,-1,16:17.0
4,-1,16:17.0
-5,0,16:18.0
-4,0,16:17.0
-3,0,16:18.0
0,0,16:17.0
1,0,16:17.0
-6,1,16:18.0
-5,1,16:18.0
-4,1,16:18.0
-3,1,16:18.0
0,1,16:17.0
-5,2,16:18.0
-4,2,16:18.0
-3,2,16:18.0
0,4,16:18.0
-1,5,16:18.0
0,5,16:18.0
0,-7,17:18.0
1,-7,17:18.0
-2,-6,17:18.0
-1,-6,17:18.0
0,-6,17:18.0
1,-6,17:18.0
-1,-5,17:18.0
0,-5,17:17.0
1,-5,17:18.0
2,-5,17:18.0
-1,-4,17:18.0
0,-4,17:18.0
1,-4,17:18.0
2,-4,17:18.0
-1,-3,17:18.0
1,-3,17:18.0
5,-2,17:18.0
-5,-1,17:18.0
-3,-1,17:18.0
-2,-1,17:17.0
0,-1,17:17.0
1,-1,17:17.0
5,-1,17:17.0
6,-1,17:18.0
-5,0,17:18.0
-4,0,17:18.0
0,0,17:17.0
1,0,17:17.0
5,0,17:18.0
6,0,17:18.0
-5,1,17:18.0
-3,1,17:18.0
0,2,17:17.0
-1,-6,18:18.0
1,-6,18:18.0
0,-5,18:18.0
1,-5,18:18.0
1,-4,18:18.0
0,-3,18:18.0
1,-3,18:18.0
5,-3,18:18.0
-2,-2,18:18.0
-1,-2,18:18.0
0,-2,18:18.0
1,-2,18:18.0
2,-2,18:18.0
5,-2,18:18.0
6,-2,18:18.0
-3,-1,18:17.0
-2,-1,18:18.0
-1,-1,18:18.0
0,-1,18:17.0
1,-1,18:17.0
2,-1,18:18.0
4,-1,18:18.0
5,-1,18:18.0
6,-1,18:17.0
7,-1,18:18.0
-2,0,18:18.0
-1,0,18:18.0
0,0,18:17.0
1,0,18:17.0
2,0,18:18.0
3,0,18:18.0
5,0,18:18.0
6,0,18:18.0
-3,1,18:18.0
-2,1,18:18.0
-1,1,18:18.0
0,1,18:18.0
1,1,18:18.0
2,1,18:18.0
3,1,18:18.0
5,1,18:18.0
6,1,18:18.0
-1,2,18:18.0
0,2,18:18.0
1,2,18:18.0
0,3,18:17.0
1,3,18:18.0
0,4,18:18.0
1,4,18:18.0
0,5,18:18.0
1,-3,19:18.0
-4,-2,19:18.0
0,-2,19:18.0
1,-2,19:18.0
2,-2,19:18.0
5,-2,19:18.0
6,-2,19:18.0
-6,-1,19:18.0
-5,-1,19:18.0
-4,-1,19:17.0
-1,-1,19:18.0
0,-1,19:17.0
1,-1,19:17.0
2,-1,19:18.0
3,-1,19:18.0
4,-1,19:18.0
5,-1,19:18.0
6,-1,19:18.0
-6,0,19:18.0
-4,0,19:18.0
-2,0,19:18.0
-1,0,19:18.0
0,0,19:17.0
1,0,19:17.0
2,0,19:18.0
3,0,19:18.0
5,0,19:18.0
6,0,19:18.0
-1,1,19:18.0
0,1,19:18.0
1,1,19:18.0
2,1,19:18.0
3,1,19:18.0
4,1,19:18.0
-1,2,19:18.0
0,2,19:18.0
1,2,19:18.0
2,2,19:18.0
3,2,19:18.0
-1,3,19:18.0
0,3,19:18.0
1,3,19:18.0
2,3,19:18.0
-1,4,19:18.0
0,4,19:17.0
1,4,19:18.0
2,4,19:18.0
-1,5,19:18.0
0,5,19:18.0
1,5,19:18.0
2,5,19:18.0
1,6,19:18.0
-1,-4,20:18.0
0,-4,20:18.0
1,-4,20:18.0
-5,-3,20:18.0
-4,-3,20:18.0
-1,-3,20:18.0
0,-3,20:18.0
1,-3,20:18.0
-6,-2,20:18.0
-5,-2,20:18.0
-4,-2,20:18.0
-3,-2,20:18.0
-2,-2,20:18.0
-1,-2,20:18.0
0,-2,20:18.0
1,-2,20:18.0
2,-2,20:18.0
3,-2,20:18.0
-6,-1,20:18.0
-5,-1,20:17.0
-4,-1,20:18.0
-3,-1,20:18.0
-2,-1,20:18.0
-1,-1,20:18.0
0,-1,20:17.0
1,-1,20:17.0
2,-1,20:18.0
-6,0,20:18.0
-5,0,20:18.0
-4,0,20:18.0
-2,0,20:18.0
-1,0,20:18.0
0,0,20:17.0
1,0,20:17.0
2,0,20:18.0
3,0,20:18.0
-5,1,20:18.0
-2,1,20:18.0
-1,1,20:18.0
0,1,20:18.0
1,1,20:18.0
-1,2,20:18.0
0,2,20:18.0
1,2,20:18.0
-1,3,20:18.0
0,3,20:18.0
1,3,20:18.0
0,4,20:18.0
1,5,20:18.0
0,-4,21:18.0
2,-4,21:18.0
-2,-3,21:18.0
-1,-3,21:18.0
0,-3,21:18.0
1,-3,21:18.0
2,-3,21:18.0
3,-3,21:18.0
4,-3,21:18.0
-5,-2,21:18.0
-4,-2,21:18.0
-1,-2,21:18.0
0,-2,21:18.0
1,-2,21:18.0
2,-2,21:18.0
3,-2,21:18.0
-6,-1,21:18.0
-5,-1,21:18.0
-4,-1,21:18.0
-2,-1,21:18.0
-1,-1,21:18.0
0,-1,21:18.0
1,-1,21:18.0
2,-1,21:18.0
3,-1,21:18.0
4,-1,21:18.0
-6,0,21:18.0
-5,0,21:18.0
-2,0,21:18.0
-1,0,21:18.0
0,0,21:18.0
1,0,21:18.0
2,0,21:18.0
3,0,21:18.0
4,0,21:18.0
0,1,21:18.0
1,1,21:18.0
2,1,21:18.0
4,1,21:18.0
-1,2,21:18.0
2,2,21:18.0
0,-3,22:18.0
1,-3,22:18.0
0,-2,22:18.0
1,-2,22:18.0
2,-2,22:18.0
3,-2,22:18.0
-1,-1,22:18.0
0,-1,22:18.0
1,-1,22:18.0
2,-1,22:18.0
0,0,22:18.0
1,0,22:18.0
2,0,22:18.0
1,1,22:18.0
0,-2,23:18.0
0,-1,23:18.0
-2,0,23:18.0
-1,0,23:18.0
0,0,23:18.0
1,0,23:18.0
2,0,23:18.0
0,1,23:18.0
1,1,23:18.0
0,0,24:18.0
0,1,24:18.0
