[META]
version=2.0
spawnOnBlockType=2,3,3:1,3:2
spawnSunlight=True
spawnDarkness=True
spawnWater=False
spawnLava=False
underFill=False
randomRotation=True
dig=True
tree=True
branch=False
needsFoundation=True
rarity=100
collisionPercentage=20
spawnElevationMin=0
spawnElevationMax=240
spawnInBiome=Custom
[DATA]
0,-3,-5:17.0
1,-3,-5:17.0
0,-2,-5:17.0
1,-2,-5:17.0
0,-3,-4:17.0
1,-3,-4:17.0
0,-2,-4:17.0
1,-2,-4:17.0
0,-3,-3:17.0
1,-3,-3:17.0
0,-2,-3:17.0
1,-2,-3:17.0
0,-3,-2:17.0
1,-3,-2:17.0
0,-2,-2:17.0
1,-2,-2:17.0
0,-3,-1:17.0
1,-3,-1:17.0
0,-2,-1:17.0
1,-2,-1:17.0
0,-3,0:17.0
1,-3,0:17.0
0,-2,0:17.0
1,-2,0:17.0
0,-3,1:17.0
1,-3,1:17.0
0,-2,1:17.0
1,-2,1:17.0
0,-3,2:17.0
1,-3,2:17.0
0,-2,2:17.0
1,-2,2:17.0
0,-3,3:17.0
1,-3,3:17.0
0,-2,3:17.0
1,-2,3:17.0
0,-3,4:17.0
1,-3,4:17.0
0,-2,4:17.0
1,-2,4:17.0
0,-3,5:17.0
1,-3,5:17.0
0,-2,5:17.0
1,-2,5:17.0
0,-3,6:17.0
1,-3,6:17.0
0,-2,6:17.0
1,-2,6:17.0
0,-3,7:17.0
1,-3,7:17.0
0,-2,7:17.0
1,-2,7:17.0
0,-3,8:17.0
1,-3,8:17.0
0,-2,8:17.0
1,-2,8:17.0
0,-3,9:17.0
1,-3,9:17.0
0,-2,9:17.0
1,-2,9:17.0
0,-3,10:17.0
1,-3,10:17.0
0,-2,10:17.0
1,-2,10:17.0
0,-4,11:17.0
0,-3,11:17.0
1,-3,11:17.0
2,-3,11:17.0
0,-2,11:17.0
1,-2,11:17.0
0,-5,12:17.0
0,-3,12:17.0
1,-3,12:17.0
3,-3,12:17.0
0,-2,12:17.0
1,-2,12:17.0
1,-1,12:17.0
1,-8,13:18.0
-1,-7,13:18.0
0,-7,13:18.0
-1,-6,13:18.0
0,-6,13:17.0
1,-6,13:18.0
0,-3,13:17.0
1,-3,13:17.0
4,-3,13:17.0
0,-2,13:17.0
1,-2,13:17.0
1,0,13:17.0
-1,-8,14:18.0
0,-8,14:18.0
1,-8,14:18.0
2,-8,14:18.0
-1,-7,14:18.0
0,-7,14:17.0
1,-7,14:18.0
2,-7,14:18.0
-1,-6,14:18.0
0,-6,14:18.0
1,-6,14:18.0
2,-6,14:18.0
-1,-5,14:18.0
5,-4,14:18.0
6,-4,14:18.0
0,-3,14:17.0
1,-3,14:17.0
5,-3,14:17.0
6,-3,14:18.0
7,-3,14:18.0
-1,-2,14:17.0
0,-2,14:17.0
1,-2,14:17.0
6,-2,14:18.0
7,-2,14:18.0
1,1,14:17.0
-1,-8,15:18.0
0,-8,15:18.0
1,-8,15:18.0
-1,-7,15:18.0
0,-7,15:18.0
0,-6,15:18.0
1,-6,15:18.0
7,-5,15:18.0
0,-4,15:17.0
5,-4,15:18.0
6,-4,15:18.0
7,-4,15:18.0
8,-4,15:18.0
0,-3,15:17.0
1,-3,15:17.0
5,-3,15:18.0
6,-3,15:17.0
7,-3,15:18.0
-2,-2,15:17.0
0,-2,15:17.0
1,-2,15:17.0
2,-2,15:17.0
5,-2,15:18.0
6,-2,15:18.0
7,-2,15:18.0
8,-2,15:18.0
6,-1,15:18.0
7,-1,15:18.0
0,2,15:18.0
1,2,15:17.0
1,3,15:18.0
1,4,15:18.0
0,-5,16:17.0
5,-4,16:18.0
6,-4,16:18.0
-5,-3,16:18.0
-4,-3,16:18.0
-3,-3,16:18.0
0,-3,16:17.0
1,-3,16:17.0
5,-3,16:18.0
6,-3,16:18.0
7,-3,16:18.0
-5,-2,16:18.0
-4,-2,16:18.0
-3,-2,16:17.0
0,-2,16:17.0
1,-2,16:17.0
3,-2,16:17.0
7,-2,16:18.0
-4,-1,16:18.0
0,1,16:18.0
2,1,16:18.0
-1,2,16:18.0
0,2,16:18.0
1,2,16:18.0
2,2,16:18.0
3,2,16:18.0
-1,3,16:18.0
0,3,16:18.0
1,3,16:17.0
2,3,16:18.0
3,3,16:18.0
0,4,16:18.0
1,4,16:18.0
2,4,16:18.0
3,4,16:18.0
1,5,16:18.0
1,-8,17:18.0
0,-7,17:18.0
1,-7,17:18.0
-1,-6,17:18.0
0,-6,17:17.0
1,-6,17:18.0
-5,-3,17:18.0
-4,-3,17:18.0
-3,-3,17:18.0
0,-3,17:17.0
1,-3,17:17.0
-6,-2,17:18.0
-5,-2,17:18.0
-4,-2,17:17.0
-3,-2,17:18.0
-2,-2,17:18.0
-1,-2,17:17.0
0,-2,17:17.0
1,-2,17:17.0
4,-2,17:17.0
-5,-1,17:18.0
-4,-1,17:18.0
-3,-1,17:18.0
1,-1,17:17.0
-5,0,17:18.0
0,2,17:18.0
0,3,17:18.0
1,3,17:18.0
0,4,17:18.0
1,4,17:18.0
2,4,17:18.0
-2,-8,18:18.0
-1,-8,18:18.0
0,-8,18:18.0
1,-8,18:18.0
2,-8,18:18.0
-2,-7,18:18.0
-1,-7,18:18.0
0,-7,18:17.0
1,-7,18:18.0
-1,-6,18:18.0
0,-6,18:18.0
1,-6,18:18.0
2,-6,18:18.0
0,-5,18:18.0
1,-5,18:18.0
-5,-3,18:18.0
-3,-3,18:18.0
0,-3,18:17.0
1,-3,18:17.0
5,-3,18:18.0
-5,-2,18:18.0
-4,-2,18:18.0
-2,-2,18:17.0
0,-2,18:17.0
1,-2,18:17.0
5,-2,18:17.0
6,-2,18:18.0
-5,-1,18:18.0
-4,-1,18:18.0
-3,-1,18:18.0
5,-1,18:18.0
6,-1,18:18.0
1,0,18:17.0
0,-8,19:18.0
0,-7,19:18.0
-1,-6,19:18.0
1,-6,19:18.0
-1,-5,19:18.0
0,-5,19:18.0
1,-5,19:18.0
2,-5,19:18.0
-2,-4,19:18.0
-1,-4,19:18.0
0,-4,19:18.0
1,-4,19:18.0
2,-4,19:18.0
3,-4,19:18.0
4,-4,19:18.0
6,-4,19:18.0
-1,-3,19:18.0
0,-3,19:17.0
1,-3,19:17.0
2,-3,19:18.0
3,-3,19:18.0
4,-3,19:18.0
5,-3,19:18.0
6,-3,19:18.0
7,-3,19:18.0
-3,-2,19:17.0
-2,-2,19:18.0
-1,-2,19:18.0
0,-2,19:17.0
1,-2,19:17.0
2,-2,19:18.0
3,-2,19:18.0
4,-2,19:18.0
5,-2,19:18.0
6,-2,19:17.0
7,-2,19:18.0
8,-2,19:18.0
-1,-1,19:18.0
0,-1,19:18.0
1,-1,19:18.0
2,-1,19:18.0
5,-1,19:18.0
6,-1,19:18.0
7,-1,19:18.0
0,0,19:18.0
1,0,19:18.0
2,0,19:18.0
5,0,19:18.0
6,0,19:18.0
1,1,19:17.0
0,2,19:18.0
1,2,19:18.0
2,3,19:18.0
-1,-5,20:18.0
0,-5,20:18.0
-1,-4,20:18.0
0,-4,20:18.0
1,-4,20:18.0
-5,-3,20:18.0
-2,-3,20:18.0
-1,-3,20:18.0
0,-3,20:17.0
1,-3,20:17.0
2,-3,20:18.0
3,-3,20:18.0
5,-3,20:18.0
-5,-2,20:18.0
-4,-2,20:17.0
-2,-2,20:18.0
-1,-2,20:18.0
0,-2,20:17.0
1,-2,20:17.0
2,-2,20:18.0
5,-2,20:18.0
6,-2,20:18.0
7,-2,20:18.0
-5,-1,20:18.0
-2,-1,20:18.0
-1,-1,20:18.0
0,-1,20:18.0
1,-1,20:18.0
2,-1,20:18.0
3,-1,20:18.0
6,-1,20:18.0
7,-1,20:18.0
-1,0,20:18.0
0,0,20:18.0
1,0,20:18.0
2,0,20:18.0
-1,1,20:18.0
0,1,20:18.0
1,1,20:18.0
2,1,20:18.0
0,2,20:18.0
1,2,20:17.0
2,2,20:18.0
0,3,20:18.0
1,3,20:18.0
2,3,20:18.0
3,3,20:18.0
0,4,20:18.0
1,4,20:18.0
2,4,20:18.0
-1,-5,21:18.0
-5,-4,21:18.0
-2,-4,21:18.0
-1,-4,21:18.0
0,-4,21:18.0
1,-4,21:18.0
-7,-3,21:18.0
-6,-3,21:18.0
-5,-3,21:18.0
-4,-3,21:18.0
-3,-3,21:18.0
-2,-3,21:18.0
-1,-3,21:18.0
0,-3,21:17.0
1,-3,21:17.0
2,-3,21:18.0
-7,-2,21:18.0
-6,-2,21:18.0
-5,-2,21:17.0
-4,-2,21:18.0
-3,-2,21:18.0
-2,-2,21:18.0
-1,-2,21:18.0
0,-2,21:17.0
1,-2,21:17.0
2,-2,21:18.0
3,-2,21:18.0
-7,-1,21:18.0
-6,-1,21:18.0
-5,-1,21:18.0
-4,-1,21:18.0
-3,-1,21:18.0
-2,-1,21:18.0
-1,-1,21:18.0
0,-1,21:18.0
1,-1,21:18.0
2,-1,21:18.0
3,-1,21:18.0
-6,0,21:18.0
-2,0,21:18.0
-1,0,21:18.0
0,0,21:18.0
1,0,21:18.0
0,1,21:18.0
1,2,21:18.0
0,3,21:18.0
-1,-6,22:18.0
0,-6,22:18.0
1,-6,22:18.0
-1,-5,22:18.0
0,-5,22:18.0
1,-5,22:18.0
2,-5,22:18.0
3,-5,22:18.0
-2,-4,22:18.0
-1,-4,22:18.0
0,-4,22:18.0
1,-4,22:18.0
2,-4,22:18.0
3,-4,22:18.0
-2,-3,22:18.0
-1,-3,22:18.0
0,-3,22:18.0
1,-3,22:18.0
2,-3,22:18.0
3,-3,22:18.0
-6,-2,22:18.0
-5,-2,22:18.0
-1,-2,22:18.0
0,-2,22:18.0
1,-2,22:18.0
2,-2,22:18.0
3,-2,22:18.0
4,-2,22:18.0
-2,-1,22:18.0
0,-1,22:18.0
1,-1,22:18.0
2,-1,22:18.0
4,-1,22:18.0
3,0,22:18.0
0,-4,23:18.0
1,-4,23:18.0
2,-4,23:18.0
-1,-3,23:18.0
0,-3,23:18.0
1,-3,23:18.0
2,-3,23:18.0
0,-2,23:18.0
1,-2,23:18.0
2,-2,23:18.0
3,-2,23:18.0
1,-1,23:18.0
2,-1,23:18.0
0,-3,24:18.0
1,-3,24:18.0
-2,-2,24:18.0
-1,-2,24:18.0
0,-2,24:18.0
1,-2,24:18.0
-1,-1,24:18.0
0,-1,24:18.0
0,-3,25:18.0
0,-2,25:18.0
1,-2,25:18.0
