[META]
version=2.0
spawnOnBlockType=2,3,3:1,3:2
spawnSunlight=True
spawnDarkness=True
spawnWater=False
spawnLava=False
underFill=False
randomRotation=True
dig=True
tree=True
branch=False
needsFoundation=True
rarity=100
collisionPercentage=20
spawnElevationMin=0
spawnElevationMax=240
spawnInBiome=Custom
[DATA]
1,-1,-3:17.0
2,-1,-3:17.0
1,0,-3:17.0
2,0,-3:17.0
1,-1,-2:17.0
2,-1,-2:17.0
1,0,-2:17.0
2,0,-2:17.0
1,-1,-1:17.0
2,-1,-1:17.0
1,0,-1:17.0
2,0,-1:17.0
1,-1,0:17.0
2,-1,0:17.0
1,0,0:17.0
2,0,0:17.0
1,-1,1:17.0
2,-1,1:17.0
1,0,1:17.0
2,0,1:17.0
1,-1,2:17.0
2,-1,2:17.0
1,0,2:17.0
2,0,2:17.0
1,-1,3:17.0
2,-1,3:17.0
1,0,3:17.0
2,0,3:17.0
1,-1,4:17.0
2,-1,4:17.0
1,0,4:17.0
2,0,4:17.0
1,-4,5:18.0
0,-3,5:18.0
1,-3,5:17.0
2,-3,5:17.0
-1,-2,5:17.0
1,-2,5:17.0
0,-1,5:17.0
1,-1,5:17.0
2,-1,5:17.0
1,0,5:17.0
2,0,5:17.0
4,0,5:18.0
0,1,5:18.0
1,1,5:17.0
2,1,5:18.0
3,1,5:18.0
4,1,5:18.0
5,1,5:18.0
1,2,5:18.0
4,2,5:18.0
0,-5,6:18.0
1,-5,6:18.0
2,-5,6:18.0
-1,-4,6:18.0
0,-4,6:18.0
1,-4,6:18.0
2,-4,6:17.0
3,-4,6:18.0
-2,-3,6:18.0
-1,-3,6:18.0
0,-3,6:18.0
1,-3,6:18.0
2,-3,6:18.8
3,-3,6:18.0
-3,-2,6:18.0
-2,-2,6:17.0
-1,-2,6:18.0
0,-2,6:17.0
1,-2,6:18.0
2,-2,6:18.0
3,-2,6:18.0
-2,-1,6:18.0
-1,-1,6:17.0
0,-1,6:17.0
1,-1,6:17.0
2,-1,6:17.0
3,-1,6:18.0
4,-1,6:18.0
5,-1,6:18.0
-1,0,6:18.0
0,0,6:18.0
1,0,6:17.0
2,0,6:17.0
3,0,6:17.0
4,0,6:18.0
5,0,6:18.0
6,0,6:18.0
-1,1,6:18.0
0,1,6:18.0
1,1,6:18.0
2,1,6:18.0
3,1,6:18.8
4,1,6:18.0
5,1,6:18.0
6,1,6:18.0
-1,2,6:18.0
0,2,6:18.0
1,2,6:18.0
2,2,6:18.0
3,2,6:18.0
4,2,6:18.0
5,2,6:18.0
6,2,6:18.0
0,3,6:18.8
1,3,6:18.0
2,3,6:18.0
3,3,6:18.0
4,3,6:18.0
5,3,6:18.0
1,-6,7:18.0
2,-6,7:18.0
3,-6,7:18.0
0,-5,7:18.0
1,-5,7:18.0
2,-5,7:18.0
3,-5,7:18.0
4,-5,7:18.0
-3,-4,7:18.0
-2,-4,7:18.0
-1,-4,7:18.0
0,-4,7:18.0
1,-4,7:18.0
2,-4,7:18.0
3,-4,7:18.0
4,-4,7:18.0
-4,-3,7:18.8
-3,-3,7:18.0
-2,-3,7:18.0
-1,-3,7:17.0
0,-3,7:18.0
1,-3,7:18.0
2,-3,7:17.0
3,-3,7:18.0
4,-3,7:18.0
-4,-2,7:18.0
-3,-2,7:18.0
-2,-2,7:18.0
-1,-2,7:17.0
0,-2,7:18.8
1,-2,7:18.0
2,-2,7:17.0
3,-2,7:18.0
-4,-1,7:18.0
-3,-1,7:18.0
-2,-1,7:17.0
-1,-1,7:17.0
0,-1,7:17.0
1,-1,7:17.0
2,-1,7:17.0
3,-1,7:18.0
4,-1,7:18.0
5,-1,7:18.0
-3,0,7:18.0
-2,0,7:18.0
-1,0,7:18.0
0,0,7:18.8
1,0,7:17.0
2,0,7:17.0
3,0,7:18.0
4,0,7:18.0
5,0,7:18.0
6,0,7:18.0
-1,1,7:18.0
0,1,7:18.0
1,1,7:18.0
2,1,7:18.0
3,1,7:17.0
4,1,7:17.0
5,1,7:18.0
6,1,7:18.0
-1,2,7:18.8
0,2,7:18.8
1,2,7:18.0
2,2,7:18.0
3,2,7:18.0
4,2,7:18.0
5,2,7:18.0
6,2,7:18.0
-1,3,7:18.8
0,3,7:18.8
1,3,7:18.0
2,3,7:18.0
3,3,7:18.0
4,3,7:18.0
5,3,7:18.0
0,4,7:18.8
1,4,7:18.8
2,4,7:18.8
1,-6,8:18.0
2,-6,8:18.0
3,-6,8:18.0
-2,-5,8:18.0
-1,-5,8:18.0
0,-5,8:18.0
1,-5,8:18.0
2,-5,8:18.0
3,-5,8:17.0
4,-5,8:18.0
-3,-4,8:18.0
-2,-4,8:18.0
-1,-4,8:18.0
0,-4,8:18.0
1,-4,8:18.0
2,-4,8:18.0
3,-4,8:17.0
4,-4,8:18.0
-4,-3,8:18.0
-3,-3,8:18.0
-2,-3,8:18.0
-1,-3,8:18.0
0,-3,8:18.0
1,-3,8:18.0
2,-3,8:18.0
3,-3,8:18.0
4,-3,8:18.0
-4,-2,8:18.0
-3,-2,8:17.0
-2,-2,8:17.0
-1,-2,8:18.0
0,-2,8:18.0
1,-2,8:18.0
2,-2,8:18.0
3,-2,8:17.0
4,-2,8:18.0
-4,-1,8:18.0
-3,-1,8:18.0
-2,-1,8:18.0
-1,-1,8:18.0
0,-1,8:17.0
1,-1,8:17.0
2,-1,8:17.0
3,-1,8:18.0
4,-1,8:18.0
5,-1,8:18.0
-4,0,8:18.0
-3,0,8:17.0
-2,0,8:17.0
-1,0,8:17.0
0,0,8:18.0
1,0,8:17.0
2,0,8:17.0
3,0,8:18.0
4,0,8:18.0
5,0,8:18.0
6,0,8:18.0
-3,1,8:18.0
-2,1,8:18.0
-1,1,8:18.0
0,1,8:18.0
1,1,8:18.0
2,1,8:18.0
3,1,8:18.0
4,1,8:18.0
5,1,8:18.0
6,1,8:18.0
1,2,8:18.0
2,2,8:18.0
3,2,8:17.0
4,2,8:18.0
5,2,8:18.0
6,2,8:18.0
0,3,8:18.0
1,3,8:18.0
3,3,8:18.0
4,3,8:17.0
5,3,8:18.0
1,4,8:18.8
2,4,8:18.8
4,4,8:18.0
0,5,8:18.8
2,5,8:18.8
0,6,8:18.8
2,-7,9:18.0
3,-7,9:18.0
4,-7,9:18.0
1,-6,9:18.0
2,-6,9:18.0
3,-6,9:18.0
4,-6,9:18.0
5,-6,9:18.0
-2,-5,9:18.0
-1,-5,9:18.0
0,-5,9:18.0
1,-5,9:18.0
2,-5,9:18.0
3,-5,9:18.0
4,-5,9:18.0
5,-5,9:18.0
-5,-4,9:18.0
-3,-4,9:18.0
-2,-4,9:18.0
-1,-4,9:18.0
0,-4,9:18.8
1,-4,9:18.0
2,-4,9:18.0
3,-4,9:18.0
4,-4,9:18.0
5,-4,9:18.0
-6,-3,9:18.0
-5,-3,9:17.0
-4,-3,9:17.0
-3,-3,9:18.0
-2,-3,9:18.0
-1,-3,9:17.0
0,-3,9:18.0
1,-3,9:18.0
2,-3,9:17.0
3,-3,9:18.0
4,-3,9:18.0
5,-3,9:18.0
-5,-2,9:18.0
-4,-2,9:18.8
-3,-2,9:18.0
-2,-2,9:18.0
-1,-2,9:17.0
0,-2,9:17.0
1,-2,9:18.0
2,-2,9:17.0
3,-2,9:18.0
4,-2,9:18.8
5,-2,9:18.0
-5,-1,9:18.0
-4,-1,9:18.0
-3,-1,9:18.0
-2,-1,9:18.0
-1,-1,9:18.0
0,-1,9:17.0
1,-1,9:17.0
2,-1,9:17.0
3,-1,9:17.0
4,-1,9:18.0
5,-1,9:18.0
-6,0,9:18.0
-5,0,9:17.0
-4,0,9:17.0
-3,0,9:17.0
-2,0,9:17.0
-1,0,9:18.0
0,0,9:18.0
1,0,9:17.0
2,0,9:17.0
3,0,9:18.0
4,0,9:18.0
5,0,9:18.0
6,0,9:18.0
-5,1,9:18.0
-3,1,9:18.0
-2,1,9:18.0
-1,1,9:18.0
1,1,9:17.0
2,1,9:18.0
3,1,9:18.0
4,1,9:18.0
5,1,9:18.0
6,1,9:18.0
2,2,9:18.0
3,2,9:18.0
4,2,9:18.0
5,2,9:18.0
6,2,9:18.0
2,3,9:18.0
3,3,9:18.0
4,3,9:18.0
5,3,9:18.0
6,3,9:18.0
2,4,9:18.8
3,4,9:18.0
4,4,9:18.0
5,4,9:18.0
6,4,9:18.0
3,5,9:18.8
4,5,9:18.0
5,5,9:18.0
2,-7,10:18.0
3,-7,10:18.0
4,-7,10:18.0
1,-6,10:18.0
2,-6,10:18.0
3,-6,10:18.0
4,-6,10:18.0
5,-6,10:18.0
-6,-5,10:18.0
-5,-5,10:18.0
-4,-5,10:18.0
1,-5,10:18.0
2,-5,10:18.0
3,-5,10:17.0
4,-5,10:18.0
5,-5,10:18.0
-7,-4,10:18.0
-6,-4,10:18.0
-5,-4,10:18.0
-4,-4,10:18.0
-3,-4,10:17.0
-1,-4,10:18.0
1,-4,10:18.0
2,-4,10:18.0
3,-4,10:17.0
4,-4,10:18.0
5,-4,10:18.0
-7,-3,10:18.0
-6,-3,10:18.8
-5,-3,10:18.0
-4,-3,10:18.0
-3,-3,10:17.0
-2,-3,10:17.0
-1,-3,10:18.8
0,-3,10:18.0
1,-3,10:18.0
2,-3,10:18.0
3,-3,10:18.0
4,-3,10:18.0
5,-3,10:18.0
-7,-2,10:18.0
-6,-2,10:18.0
-5,-2,10:18.0
-4,-2,10:18.0
-3,-2,10:18.0
-2,-2,10:17.0
-1,-2,10:18.0
1,-2,10:18.0
2,-2,10:18.0
3,-2,10:17.0
4,-2,10:18.0
5,-2,10:18.0
-7,-1,10:18.0
-6,-1,10:18.0
-5,-1,10:18.0
-4,-1,10:18.0
-3,-1,10:18.0
-2,-1,10:18.0
-1,-1,10:18.0
1,-1,10:17.0
2,-1,10:17.0
3,-1,10:18.0
4,-1,10:17.0
5,-1,10:17.0
6,-1,10:18.0
-7,0,10:18.0
-6,0,10:18.0
-5,0,10:18.0
-4,0,10:18.0
-3,0,10:18.0
-2,0,10:18.0
-1,0,10:18.0
1,0,10:17.0
2,0,10:17.0
3,0,10:18.0
4,0,10:18.0
5,0,10:18.0
-7,1,10:18.0
-6,1,10:18.0
-5,1,10:18.0
-4,1,10:18.0
-3,1,10:18.0
-2,1,10:18.0
-1,1,10:18.0
3,1,10:18.0
4,1,10:18.0
5,1,10:18.0
-6,2,10:18.0
-5,2,10:18.0
-4,2,10:18.0
-3,2,10:18.0
-2,2,10:18.0
1,2,10:17.0
2,2,10:18.0
3,2,10:18.0
4,2,10:18.0
5,2,10:18.0
6,2,10:18.0
0,3,10:18.8
1,3,10:17.0
2,3,10:18.8
3,3,10:18.0
4,3,10:18.0
5,3,10:18.0
6,3,10:18.0
1,4,10:18.0
2,4,10:18.0
3,4,10:18.0
4,4,10:18.0
5,4,10:18.0
6,4,10:18.0
3,5,10:18.0
4,5,10:18.0
5,5,10:18.0
2,-7,11:18.0
3,-7,11:18.0
4,-7,11:18.0
-4,-6,11:18.0
1,-6,11:18.0
2,-6,11:18.0
3,-6,11:18.0
4,-6,11:18.0
5,-6,11:18.0
-6,-5,11:18.0
-5,-5,11:18.8
-4,-5,11:17.0
-3,-5,11:18.0
1,-5,11:18.0
2,-5,11:18.8
3,-5,11:18.0
4,-5,11:18.0
5,-5,11:18.8
-7,-4,11:18.0
-6,-4,11:18.0
-5,-4,11:18.0
-4,-4,11:18.0
-3,-4,11:18.0
1,-4,11:18.0
2,-4,11:18.0
3,-4,11:18.0
4,-4,11:18.0
5,-4,11:18.0
-7,-3,11:18.0
-6,-3,11:18.0
-5,-3,11:18.0
-4,-3,11:17.0
-3,-3,11:18.0
1,-3,11:17.0
2,-3,11:18.0
3,-3,11:18.0
4,-3,11:18.0
5,-3,11:17.0
6,-3,11:18.0
-7,-2,11:18.0
-6,-2,11:18.0
-5,-2,11:18.0
-4,-2,11:18.0
-3,-2,11:18.0
-2,-2,11:18.0
1,-2,11:17.0
2,-2,11:17.0
3,-2,11:17.0
4,-2,11:17.0
5,-2,11:18.0
6,-2,11:18.0
7,-2,11:18.0
-7,-1,11:18.0
-6,-1,11:18.0
-5,-1,11:18.0
-4,-1,11:18.0
-3,-1,11:18.0
-2,-1,11:18.0
-1,-1,11:18.0
1,-1,11:17.0
2,-1,11:17.0
3,-1,11:18.0
4,-1,11:18.0
5,-1,11:18.0
6,-1,11:18.0
7,-1,11:18.0
-7,0,11:18.0
-6,0,11:18.0
-5,0,11:18.0
-4,0,11:18.0
-3,0,11:18.0
-2,0,11:18.0
-1,0,11:17.0
0,0,11:17.0
1,0,11:17.0
2,0,11:17.0
3,0,11:18.0
4,0,11:18.0
5,0,11:18.0
6,0,11:18.0
7,0,11:18.0
-7,1,11:18.0
-6,1,11:18.0
-5,1,11:18.0
-4,1,11:18.0
-3,1,11:18.0
-2,1,11:18.0
-1,1,11:18.0
0,1,11:18.0
1,1,11:18.0
2,1,11:18.0
4,1,11:18.0
5,1,11:18.0
6,1,11:18.0
-6,2,11:18.0
-5,2,11:18.0
-4,2,11:18.0
-3,2,11:18.0
-2,2,11:18.0
-1,2,11:18.0
0,2,11:18.0
1,2,11:18.0
2,2,11:18.0
3,2,11:18.0
4,2,11:18.0
-1,3,11:18.0
0,3,11:18.0
1,3,11:18.0
2,3,11:18.8
3,3,11:18.0
4,3,11:18.0
5,3,11:18.0
-1,4,11:18.0
0,4,11:18.0
1,4,11:18.0
2,4,11:18.0
3,4,11:18.0
4,4,11:18.0
0,5,11:18.0
1,5,11:18.0
2,5,11:18.0
-5,-7,12:18.0
-4,-7,12:18.0
-3,-7,12:18.0
2,-7,12:18.0
3,-7,12:18.0
4,-7,12:18.0
-6,-6,12:18.0
-5,-6,12:18.0
-4,-6,12:18.0
-3,-6,12:18.0
-2,-6,12:18.0
1,-6,12:18.0
2,-6,12:18.0
3,-6,12:18.0
4,-6,12:18.0
5,-6,12:18.0
-6,-5,12:18.0
-5,-5,12:18.0
-4,-5,12:18.0
-3,-5,12:18.0
-2,-5,12:18.0
0,-5,12:18.0
1,-5,12:17.0
2,-5,12:18.0
3,-5,12:18.0
4,-5,12:18.0
5,-5,12:18.0
-6,-4,12:18.0
-5,-4,12:18.0
-4,-4,12:18.0
-3,-4,12:18.0
-2,-4,12:18.0
1,-4,12:17.0
2,-4,12:18.0
3,-4,12:18.0
4,-4,12:18.8
5,-4,12:17.0
6,-4,12:18.0
-6,-3,12:18.0
-5,-3,12:18.0
-4,-3,12:18.0
-3,-3,12:18.0
-2,-3,12:18.0
1,-3,12:17.0
2,-3,12:18.0
3,-3,12:18.0
4,-3,12:17.0
5,-3,12:18.0
6,-3,12:17.0
7,-3,12:18.0
-6,-2,12:18.0
-5,-2,12:18.0
-4,-2,12:18.0
-3,-2,12:18.0
-2,-2,12:18.0
-1,-2,12:17.0
0,-2,12:18.0
1,-2,12:17.0
3,-2,12:18.0
4,-2,12:18.0
5,-2,12:18.0
6,-2,12:18.0
7,-2,12:18.0
-5,-1,12:18.0
-4,-1,12:18.0
-3,-1,12:18.0
-2,-1,12:18.0
-1,-1,12:18.8
0,-1,12:17.0
1,-1,12:17.0
2,-1,12:17.0
3,-1,12:18.0
4,-1,12:18.0
5,-1,12:18.0
6,-1,12:18.0
7,-1,12:18.0
-6,0,12:18.0
-5,0,12:18.0
-4,0,12:18.0
-3,0,12:18.0
-2,0,12:18.0
-1,0,12:18.0
0,0,12:18.0
1,0,12:17.0
2,0,12:17.0
3,0,12:18.0
4,0,12:18.0
5,0,12:18.0
6,0,12:18.0
7,0,12:18.0
-5,1,12:18.0
-3,1,12:18.0
-2,1,12:18.0
-1,1,12:18.0
0,1,12:18.8
1,1,12:18.0
2,1,12:18.0
3,1,12:17.0
4,1,12:18.0
5,1,12:18.0
6,1,12:18.0
-2,2,12:18.0
-1,2,12:18.0
0,2,12:18.0
1,2,12:18.0
2,2,12:18.0
3,2,12:18.0
-1,3,12:18.0
0,3,12:18.0
1,3,12:18.0
2,3,12:18.0
3,3,12:18.0
-1,4,12:18.0
0,4,12:18.0
1,4,12:18.0
2,4,12:18.0
3,4,12:18.0
0,5,12:18.0
1,5,12:18.0
2,5,12:18.0
-5,-7,13:18.0
-4,-7,13:18.0
-3,-7,13:18.0
0,-7,13:18.0
1,-7,13:18.0
2,-7,13:18.0
-6,-6,13:18.0
-5,-6,13:18.0
-4,-6,13:18.0
-3,-6,13:18.0
-2,-6,13:18.0
-1,-6,13:18.0
0,-6,13:18.0
1,-6,13:17.0
2,-6,13:18.0
3,-6,13:18.0
4,-6,13:18.0
5,-6,13:18.0
6,-6,13:18.0
-6,-5,13:18.0
-5,-5,13:18.0
-4,-5,13:18.0
-3,-5,13:18.0
-2,-5,13:18.0
-1,-5,13:18.0
0,-5,13:18.0
1,-5,13:17.0
2,-5,13:18.0
3,-5,13:18.0
4,-5,13:18.0
5,-5,13:18.0
6,-5,13:18.0
7,-5,13:18.0
-6,-4,13:18.0
-5,-4,13:18.0
-4,-4,13:18.0
-3,-4,13:18.0
-2,-4,13:18.0
-1,-4,13:18.0
0,-4,13:18.0
1,-4,13:17.0
2,-4,13:18.0
3,-4,13:18.0
4,-4,13:18.0
5,-4,13:18.0
6,-4,13:18.0
7,-4,13:18.0
8,-4,13:18.0
-6,-3,13:18.0
-5,-3,13:18.0
-4,-3,13:18.0
-3,-3,13:17.0
-2,-3,13:18.0
0,-3,13:18.0
1,-3,13:18.8
2,-3,13:18.0
3,-3,13:18.0
4,-3,13:18.0
5,-3,13:18.0
6,-3,13:18.0
7,-3,13:18.0
8,-3,13:18.0
-6,-2,13:18.0
-5,-2,13:18.0
-4,-2,13:18.0
-3,-2,13:18.0
-2,-2,13:17.0
-1,-2,13:18.0
0,-2,13:18.0
1,-2,13:17.0
2,-2,13:17.0
3,-2,13:17.0
4,-2,13:18.0
5,-2,13:18.0
6,-2,13:18.0
7,-2,13:18.0
8,-2,13:18.0
-5,-1,13:18.0
-4,-1,13:18.0
-3,-1,13:18.0
-2,-1,13:18.0
-1,-1,13:18.0
0,-1,13:17.0
1,-1,13:17.0
4,-1,13:18.0
5,-1,13:18.0
6,-1,13:18.0
7,-1,13:18.0
-3,0,13:18.0
-2,0,13:18.0
-1,0,13:18.0
0,0,13:18.0
1,0,13:17.0
5,0,13:18.0
-3,1,13:18.0
-2,1,13:18.0
-1,1,13:18.0
0,1,13:18.0
1,1,13:18.0
-2,2,13:18.0
-1,2,13:18.0
0,2,13:18.0
1,2,13:18.0
3,2,13:17.0
4,2,13:18.8
0,3,13:18.0
1,3,13:18.0
2,3,13:18.0
3,3,13:18.0
4,3,13:17.0
5,3,13:18.0
1,4,13:18.0
4,4,13:18.0
0,-8,14:18.0
1,-8,14:18.0
2,-8,14:18.0
-1,-7,14:18.0
0,-7,14:18.0
1,-7,14:18.0
2,-7,14:18.0
3,-7,14:18.0
-4,-6,14:18.0
-1,-6,14:18.0
0,-6,14:18.0
1,-6,14:18.0
2,-6,14:18.0
3,-6,14:18.0
4,-6,14:18.0
5,-6,14:18.0
6,-6,14:18.0
-5,-5,14:18.0
-4,-5,14:18.0
-3,-5,14:18.0
-1,-5,14:18.0
0,-5,14:18.0
1,-5,14:18.0
2,-5,14:18.0
3,-5,14:18.0
4,-5,14:18.0
5,-5,14:18.0
6,-5,14:18.0
7,-5,14:18.0
-4,-4,14:18.0
-1,-4,14:18.0
0,-4,14:18.0
1,-4,14:18.8
2,-4,14:17.0
3,-4,14:18.0
4,-4,14:18.0
5,-4,14:18.0
6,-4,14:18.0
7,-4,14:18.0
8,-4,14:18.0
-5,-3,14:18.0
-4,-3,14:17.0
-3,-3,14:18.0
-1,-3,14:18.0
0,-3,14:18.0
1,-3,14:18.0
2,-3,14:17.0
3,-3,14:18.0
4,-3,14:17.0
5,-3,14:18.0
6,-3,14:18.0
7,-3,14:18.0
8,-3,14:18.0
-4,-2,14:18.0
0,-2,14:18.8
1,-2,14:18.0
2,-2,14:18.0
4,-2,14:18.0
5,-2,14:18.0
6,-2,14:18.0
7,-2,14:18.0
8,-2,14:18.0
-2,-1,14:17.0
-1,-1,14:17.0
1,-1,14:17.0
5,-1,14:18.0
6,-1,14:18.0
7,-1,14:18.0
-2,0,14:18.0
-1,0,14:18.0
0,0,14:18.0
1,0,14:18.0
-1,1,14:18.0
0,1,14:18.0
1,1,14:17.0
2,1,14:18.0
3,1,14:18.0
4,1,14:18.0
5,1,14:18.0
1,2,14:18.0
2,2,14:18.0
3,2,14:18.0
4,2,14:18.0
5,2,14:18.0
6,2,14:18.0
2,3,14:18.0
3,3,14:18.0
4,3,14:18.0
5,3,14:18.0
6,3,14:18.0
2,4,14:18.0
3,4,14:18.0
4,4,14:18.0
5,4,14:18.0
6,4,14:18.0
3,5,14:18.0
4,5,14:18.0
5,5,14:18.0
0,-8,15:18.0
1,-8,15:18.0
2,-8,15:18.0
-1,-7,15:18.0
0,-7,15:18.0
1,-7,15:18.0
2,-7,15:18.0
3,-7,15:18.0
-1,-6,15:18.0
0,-6,15:18.0
1,-6,15:18.0
2,-6,15:18.0
3,-6,15:18.0
-5,-5,15:18.0
-4,-5,15:18.0
-3,-5,15:18.0
-1,-5,15:18.0
0,-5,15:18.0
1,-5,15:18.0
2,-5,15:17.0
3,-5,15:18.0
4,-5,15:18.0
5,-5,15:18.0
-6,-4,15:18.0
-5,-4,15:18.0
-4,-4,15:18.0
-3,-4,15:18.0
-2,-4,15:18.0
-1,-4,15:18.0
0,-4,15:18.0
1,-4,15:18.0
2,-4,15:17.0
3,-4,15:18.0
4,-4,15:18.0
5,-4,15:18.0
6,-4,15:18.0
-6,-3,15:18.0
-5,-3,15:18.0
-4,-3,15:18.0
-3,-3,15:18.0
-2,-3,15:18.0
-1,-3,15:18.0
0,-3,15:18.0
1,-3,15:18.0
2,-3,15:18.0
3,-3,15:18.0
4,-3,15:18.0
5,-3,15:18.0
6,-3,15:18.0
7,-3,15:18.0
-6,-2,15:18.0
-5,-2,15:18.8
-4,-2,15:18.0
-3,-2,15:18.0
-2,-2,15:18.0
0,-2,15:18.0
1,-2,15:18.0
2,-2,15:18.0
3,-2,15:18.0
4,-2,15:18.0
5,-2,15:18.0
6,-2,15:18.0
-5,-1,15:18.0
-4,-1,15:18.0
-3,-1,15:17.0
-2,-1,15:18.0
0,-1,15:18.0
1,-1,15:17.0
2,-1,15:18.0
3,-1,15:18.0
4,-1,15:18.0
5,-1,15:18.0
-3,0,15:18.0
-1,0,15:18.0
0,0,15:18.0
1,0,15:18.0
2,0,15:18.0
3,0,15:18.0
-1,1,15:18.0
0,1,15:18.0
1,1,15:18.0
2,1,15:18.0
3,1,15:18.0
4,1,15:18.0
5,1,15:18.0
-1,2,15:18.0
0,2,15:18.0
1,2,15:18.0
2,2,15:18.0
3,2,15:18.0
4,2,15:18.0
5,2,15:18.0
6,2,15:18.0
0,3,15:18.0
1,3,15:18.0
2,3,15:18.0
3,3,15:18.0
4,3,15:18.0
5,3,15:18.0
6,3,15:18.0
2,4,15:18.0
3,4,15:18.0
4,4,15:18.0
5,4,15:18.0
6,4,15:18.0
3,5,15:18.0
4,5,15:18.0
5,5,15:18.0
1,-7,16:18.0
2,-7,16:18.0
3,-7,16:18.0
0,-6,16:18.0
1,-6,16:18.0
2,-6,16:18.0
3,-6,16:18.0
4,-6,16:18.0
-5,-5,16:18.0
-4,-5,16:18.0
-3,-5,16:18.0
0,-5,16:18.0
1,-5,16:18.0
2,-5,16:18.0
3,-5,16:18.0
4,-5,16:18.0
5,-5,16:18.0
-6,-4,16:18.0
-5,-4,16:18.0
-4,-4,16:18.0
-3,-4,16:18.0
-2,-4,16:18.0
0,-4,16:18.0
1,-4,16:18.0
2,-4,16:18.0
3,-4,16:18.0
4,-4,16:18.0
5,-4,16:18.0
6,-4,16:18.0
-6,-3,16:18.0
-5,-3,16:18.0
-4,-3,16:18.0
-3,-3,16:18.0
-2,-3,16:18.0
0,-3,16:18.0
1,-3,16:18.0
2,-3,16:18.0
3,-3,16:18.0
4,-3,16:18.0
5,-3,16:18.0
6,-3,16:18.0
-6,-2,16:18.0
-5,-2,16:18.0
-4,-2,16:18.0
-3,-2,16:18.0
-2,-2,16:18.0
-1,-2,16:18.0
1,-2,16:18.0
2,-2,16:18.0
3,-2,16:18.0
4,-2,16:18.0
5,-2,16:18.0
6,-2,16:18.0
-5,-1,16:18.0
-4,-1,16:18.0
-3,-1,16:18.0
-2,-1,16:18.0
-1,-1,16:18.0
0,-1,16:18.0
1,-1,16:17.0
2,-1,16:18.0
3,-1,16:18.0
4,-1,16:18.0
5,-1,16:18.0
-5,0,16:18.0
-4,0,16:18.0
-3,0,16:18.8
-2,0,16:18.0
-1,0,16:18.0
0,0,16:18.0
1,0,16:18.0
2,0,16:18.0
3,0,16:18.0
-4,1,16:18.0
-3,1,16:18.0
-2,1,16:18.0
-1,1,16:18.0
0,1,16:18.0
1,1,16:18.0
2,1,16:18.0
3,1,16:18.0
-1,2,16:18.0
0,2,16:18.0
1,2,16:18.0
2,2,16:18.0
3,2,16:18.0
4,2,16:18.0
0,3,16:18.0
1,3,16:18.0
2,3,16:18.0
3,3,16:18.0
4,3,16:18.0
5,3,16:18.0
4,4,16:18.0
1,-7,17:18.0
2,-7,17:18.0
3,-7,17:18.0
0,-6,17:18.0
1,-6,17:18.0
2,-6,17:18.0
3,-6,17:18.0
4,-6,17:18.0
0,-5,17:18.0
1,-5,17:18.0
2,-5,17:18.0
3,-5,17:18.0
4,-5,17:18.0
-4,-4,17:18.0
0,-4,17:18.0
1,-4,17:18.0
2,-4,17:18.0
3,-4,17:18.0
4,-4,17:18.0
-5,-3,17:18.0
-4,-3,17:18.0
-3,-3,17:18.0
-2,-3,17:18.0
0,-3,17:18.0
1,-3,17:18.0
2,-3,17:18.0
3,-3,17:18.0
4,-3,17:18.0
5,-3,17:18.0
-5,-2,17:18.0
-4,-2,17:18.0
-3,-2,17:18.0
-2,-2,17:18.0
-1,-2,17:18.0
0,-2,17:18.0
1,-2,17:18.0
2,-2,17:18.0
3,-2,17:18.0
4,-2,17:18.0
-5,-1,17:18.0
-4,-1,17:18.0
-3,-1,17:18.0
-2,-1,17:18.0
-1,-1,17:18.0
0,-1,17:18.0
1,-1,17:18.0
2,-1,17:18.0
3,-1,17:18.0
-5,0,17:18.0
-4,0,17:18.0
-3,0,17:18.0
-2,0,17:18.0
-1,0,17:18.0
0,0,17:18.0
1,0,17:18.0
2,0,17:18.0
3,0,17:18.0
-4,1,17:18.0
-3,1,17:18.0
-2,1,17:18.0
0,1,17:18.0
1,1,17:18.0
2,1,17:18.0
1,2,17:18.0
2,-6,18:18.0
1,-5,18:18.0
2,-5,18:18.0
3,-5,18:18.0
1,-4,18:18.0
2,-4,18:18.0
3,-4,18:18.0
0,-3,18:18.0
1,-3,18:18.0
2,-3,18:18.0
-3,-2,18:18.0
-1,-2,18:18.0
0,-2,18:18.0
1,-2,18:18.0
2,-2,18:18.0
3,-2,18:18.0
-4,-1,18:18.0
-3,-1,18:18.0
-2,-1,18:18.0
-1,-1,18:18.0
0,-1,18:18.0
1,-1,18:18.0
2,-1,18:18.0
3,-1,18:18.0
-3,0,18:18.0
-1,0,18:18.0
0,0,18:18.0
1,0,18:18.0
2,0,18:18.0
3,0,18:18.0
0,1,18:18.0
1,1,18:18.0
2,1,18:18.0
1,-2,19:18.0
0,-1,19:18.0
1,-1,19:18.0
2,-1,19:18.0
1,0,19:18.0
