[META]
version=2.0
spawnOnBlockType=2,3
spawnSunlight=True
spawnDarkness=True
spawnWater=False
spawnLava=False
underFill=False
randomRotation=True
dig=True
tree=True
branch=False
needsFoundation=True
rarity=100
collisionPercentage=20
spawnElevationMin=0
spawnElevationMax=240
spawnInBiome=Custom
[DATA]
-2,-5,0:17.2
-1,-5,0:17.2
0,-5,0:17.2
1,-5,0:17.2
2,-5,0:17.2
-3,-4,0:17.2
-2,-4,0:17.2
-1,-4,0:17.2
0,-4,0:17.2
1,-4,0:17.2
2,-4,0:17.2
3,-4,0:17.2
-4,-3,0:17.2
-3,-3,0:17.2
-2,-3,0:17.2
-1,-3,0:17.2
0,-3,0:17.2
1,-3,0:17.2
2,-3,0:17.2
3,-3,0:17.2
4,-3,0:17.2
-5,-2,0:17.2
-4,-2,0:17.2
-3,-2,0:17.2
-2,-2,0:17.2
-1,-2,0:17.2
0,-2,0:17.2
1,-2,0:17.2
2,-2,0:17.2
3,-2,0:17.2
4,-2,0:17.2
5,-2,0:17.2
-5,-1,0:17.2
-4,-1,0:17.2
-3,-1,0:17.2
-2,-1,0:17.2
-1,-1,0:17.2
0,-1,0:17.2
1,-1,0:17.2
2,-1,0:17.2
3,-1,0:17.2
4,-1,0:17.2
5,-1,0:17.2
-5,0,0:17.2
-4,0,0:17.2
-3,0,0:17.2
-2,0,0:17.2
-1,0,0:17.2
0,0,0:17.2
1,0,0:17.2
2,0,0:17.2
3,0,0:17.2
4,0,0:17.2
5,0,0:17.2
-5,1,0:17.2
-4,1,0:17.2
-3,1,0:17.2
-2,1,0:17.2
-1,1,0:17.2
0,1,0:17.2
1,1,0:17.2
2,1,0:17.2
3,1,0:17.2
4,1,0:17.2
5,1,0:17.2
-5,2,0:17.2
-4,2,0:17.2
-3,2,0:17.2
-2,2,0:17.2
-1,2,0:17.2
0,2,0:17.2
1,2,0:17.2
2,2,0:17.2
3,2,0:17.2
4,2,0:17.2
5,2,0:17.2
-4,3,0:17.2
-3,3,0:17.2
-2,3,0:17.2
-1,3,0:17.2
0,3,0:17.2
1,3,0:17.2
2,3,0:17.2
3,3,0:17.2
4,3,0:17.2
-3,4,0:17.2
-2,4,0:17.2
-1,4,0:17.2
0,4,0:17.2
1,4,0:17.2
2,4,0:17.2
3,4,0:17.2
-2,5,0:17.2
-1,5,0:17.2
0,5,0:17.2
1,5,0:17.2
2,5,0:17.2
0,-5,1:17.2
-3,-4,1:17.2
-2,-4,1:17.2
-1,-4,1:17.2
0,-4,1:17.2
1,-4,1:17.2
2,-4,1:17.2
3,-4,1:17.2
-4,-3,1:17.2
-3,-3,1:17.2
-2,-3,1:17.2
-1,-3,1:17.2
0,-3,1:17.2
1,-3,1:17.2
2,-3,1:17.2
3,-3,1:17.2
4,-3,1:17.2
-4,-2,1:17.2
-3,-2,1:17.2
-2,-2,1:17.2
-1,-2,1:17.2
0,-2,1:17.2
1,-2,1:17.2
2,-2,1:17.2
3,-2,1:17.2
4,-2,1:17.2
-4,-1,1:17.2
-3,-1,1:17.2
-2,-1,1:17.2
-1,-1,1:17.2
0,-1,1:17.2
1,-1,1:17.2
2,-1,1:17.2
3,-1,1:17.2
4,-1,1:17.2
-5,0,1:17.2
-4,0,1:17.2
-3,0,1:17.2
-2,0,1:17.2
-1,0,1:17.2
0,0,1:17.2
1,0,1:17.2
2,0,1:17.2
3,0,1:17.2
4,0,1:17.2
5,0,1:17.2
-4,1,1:17.2
-3,1,1:17.2
-2,1,1:17.2
-1,1,1:17.2
0,1,1:17.2
1,1,1:17.2
2,1,1:17.2
3,1,1:17.2
4,1,1:17.2
-4,2,1:17.2
-3,2,1:17.2
-2,2,1:17.2
-1,2,1:17.2
0,2,1:17.2
1,2,1:17.2
2,2,1:17.2
3,2,1:17.2
4,2,1:17.2
-4,3,1:17.2
-3,3,1:17.2
-2,3,1:17.2
-1,3,1:17.2
0,3,1:17.2
1,3,1:17.2
2,3,1:17.2
3,3,1:17.2
4,3,1:17.2
-3,4,1:17.2
-2,4,1:17.2
-1,4,1:17.2
0,4,1:17.2
1,4,1:17.2
2,4,1:17.2
3,4,1:17.2
0,5,1:17.2
-2,-4,2:17.2
-1,-4,2:17.2
0,-4,2:17.2
1,-4,2:17.2
2,-4,2:17.2
-3,-3,2:17.2
-2,-3,2:17.2
-1,-3,2:17.2
0,-3,2:17.2
1,-3,2:17.2
2,-3,2:17.2
3,-3,2:17.2
-4,-2,2:17.2
-3,-2,2:17.2
-2,-2,2:17.2
-1,-2,2:17.2
0,-2,2:17.2
1,-2,2:17.2
2,-2,2:17.2
3,-2,2:17.2
4,-2,2:17.2
-4,-1,2:17.2
-3,-1,2:17.2
-2,-1,2:17.2
-1,-1,2:17.2
0,-1,2:17.2
1,-1,2:17.2
2,-1,2:17.2
3,-1,2:17.2
4,-1,2:17.2
-4,0,2:17.2
-3,0,2:17.2
-2,0,2:17.2
-1,0,2:17.2
0,0,2:17.2
1,0,2:17.2
2,0,2:17.2
3,0,2:17.2
4,0,2:17.2
-4,1,2:17.2
-3,1,2:17.2
-2,1,2:17.2
-1,1,2:17.2
0,1,2:17.2
1,1,2:17.2
2,1,2:17.2
3,1,2:17.2
4,1,2:17.2
-4,2,2:17.2
-3,2,2:17.2
-2,2,2:17.2
-1,2,2:17.2
0,2,2:17.2
1,2,2:17.2
2,2,2:17.2
3,2,2:17.2
4,2,2:17.2
-3,3,2:17.2
-2,3,2:17.2
-1,3,2:17.2
0,3,2:17.2
1,3,2:17.2
2,3,2:17.2
3,3,2:17.2
-2,4,2:17.2
-1,4,2:17.2
0,4,2:17.2
1,4,2:17.2
2,4,2:17.2
0,-4,3:17.2
-2,-3,3:17.2
-1,-3,3:17.2
0,-3,3:17.2
1,-3,3:17.2
2,-3,3:17.2
-3,-2,3:17.2
-2,-2,3:17.2
-1,-2,3:17.2
0,-2,3:17.2
1,-2,3:17.2
2,-2,3:17.2
3,-2,3:17.2
-3,-1,3:17.2
-2,-1,3:17.2
-1,-1,3:17.2
0,-1,3:17.2
1,-1,3:17.2
2,-1,3:17.2
3,-1,3:17.2
-4,0,3:17.2
-3,0,3:17.2
-2,0,3:17.2
-1,0,3:17.2
0,0,3:17.2
1,0,3:17.2
2,0,3:17.2
3,0,3:17.2
4,0,3:17.2
-3,1,3:17.2
-2,1,3:17.2
-1,1,3:17.2
0,1,3:17.2
1,1,3:17.2
2,1,3:17.2
3,1,3:17.2
-3,2,3:17.2
-2,2,3:17.2
-1,2,3:17.2
0,2,3:17.2
1,2,3:17.2
2,2,3:17.2
3,2,3:17.2
-2,3,3:17.2
-1,3,3:17.2
0,3,3:17.2
1,3,3:17.2
2,3,3:17.2
0,4,3:17.2
-1,-3,4:17.2
0,-3,4:17.2
1,-3,4:17.2
-2,-2,4:17.2
-1,-2,4:17.2
0,-2,4:17.2
1,-2,4:17.2
2,-2,4:17.2
-3,-1,4:17.2
-2,-1,4:17.2
-1,-1,4:17.2
0,-1,4:17.2
1,-1,4:17.2
2,-1,4:17.2
3,-1,4:17.2
-3,0,4:17.2
-2,0,4:17.2
-1,0,4:17.2
0,0,4:17.2
1,0,4:17.2
2,0,4:17.2
3,0,4:17.2
-3,1,4:17.2
-2,1,4:17.2
-1,1,4:17.2
0,1,4:17.2
1,1,4:17.2
2,1,4:17.2
3,1,4:17.2
-2,2,4:17.2
-1,2,4:17.2
0,2,4:17.2
1,2,4:17.2
2,2,4:17.2
-1,3,4:17.2
0,3,4:17.2
1,3,4:17.2
-1,-3,5:17.2
0,-3,5:17.2
1,-3,5:17.2
-2,-2,5:17.2
-1,-2,5:17.2
0,-2,5:17.2
1,-2,5:17.2
2,-2,5:17.2
-3,-1,5:17.2
-2,-1,5:17.2
-1,-1,5:17.2
0,-1,5:17.2
1,-1,5:17.2
2,-1,5:17.2
3,-1,5:17.2
-3,0,5:17.2
-2,0,5:17.2
-1,0,5:17.2
0,0,5:17.2
1,0,5:17.2
2,0,5:17.2
3,0,5:17.2
-3,1,5:17.2
-2,1,5:17.2
-1,1,5:17.2
0,1,5:17.2
1,1,5:17.2
2,1,5:17.2
3,1,5:17.2
-2,2,5:17.2
-1,2,5:17.2
0,2,5:17.2
1,2,5:17.2
2,2,5:17.2
-1,3,5:17.2
0,3,5:17.2
1,3,5:17.2
-1,-3,6:17.2
0,-3,6:17.2
1,-3,6:17.2
-2,-2,6:17.2
-1,-2,6:17.2
0,-2,6:17.2
1,-2,6:17.2
2,-2,6:17.2
-3,-1,6:17.2
-2,-1,6:17.2
-1,-1,6:17.2
0,-1,6:17.2
1,-1,6:17.2
2,-1,6:17.2
3,-1,6:17.2
-3,0,6:17.2
-2,0,6:17.2
-1,0,6:17.2
0,0,6:17.2
1,0,6:17.2
2,0,6:17.2
3,0,6:17.2
-3,1,6:17.2
-2,1,6:17.2
-1,1,6:17.2
0,1,6:17.2
1,1,6:17.2
2,1,6:17.2
3,1,6:17.2
-2,2,6:17.2
-1,2,6:17.2
0,2,6:17.2
1,2,6:17.2
2,2,6:17.2
-1,3,6:17.2
0,3,6:17.2
1,3,6:17.2
-1,-3,7:17.2
0,-3,7:17.2
1,-3,7:17.2
-2,-2,7:17.2
-1,-2,7:17.2
0,-2,7:17.2
1,-2,7:17.2
2,-2,7:17.2
-3,-1,7:17.2
-2,-1,7:17.2
-1,-1,7:17.2
0,-1,7:17.2
1,-1,7:17.2
2,-1,7:17.2
3,-1,7:17.2
-3,0,7:17.2
-2,0,7:17.2
-1,0,7:17.2
0,0,7:17.2
1,0,7:17.2
2,0,7:17.2
3,0,7:17.2
-3,1,7:17.2
-2,1,7:17.2
-1,1,7:17.2
0,1,7:17.2
1,1,7:17.2
2,1,7:17.2
3,1,7:17.2
-2,2,7:17.2
-1,2,7:17.2
0,2,7:17.2
1,2,7:17.2
2,2,7:17.2
-1,3,7:17.2
0,3,7:17.2
1,3,7:17.2
-1,-3,8:17.2
0,-3,8:17.2
1,-3,8:17.2
-2,-2,8:17.2
-1,-2,8:17.2
0,-2,8:17.2
1,-2,8:17.2
2,-2,8:17.2
-3,-1,8:17.2
-2,-1,8:17.2
-1,-1,8:17.2
0,-1,8:17.2
1,-1,8:17.2
2,-1,8:17.2
3,-1,8:17.2
-3,0,8:17.2
-2,0,8:17.2
-1,0,8:17.2
0,0,8:17.2
1,0,8:17.2
2,0,8:17.2
3,0,8:17.2
-3,1,8:17.2
-2,1,8:17.2
-1,1,8:17.2
0,1,8:17.2
1,1,8:17.2
2,1,8:17.2
3,1,8:17.2
-2,2,8:17.2
-1,2,8:17.2
0,2,8:17.2
1,2,8:17.2
2,2,8:17.2
-1,3,8:17.2
0,3,8:17.2
1,3,8:17.2
-1,-3,9:17.2
0,-3,9:17.2
1,-3,9:17.2
-2,-2,9:17.2
-1,-2,9:17.2
0,-2,9:17.2
1,-2,9:17.2
2,-2,9:17.2
-3,-1,9:17.2
-2,-1,9:17.2
-1,-1,9:17.2
0,-1,9:17.2
1,-1,9:17.2
2,-1,9:17.2
3,-1,9:17.2
-3,0,9:17.2
-2,0,9:17.2
-1,0,9:17.2
0,0,9:17.2
1,0,9:17.2
2,0,9:17.2
3,0,9:17.2
-3,1,9:17.2
-2,1,9:17.2
-1,1,9:17.2
0,1,9:17.2
1,1,9:17.2
2,1,9:17.2
3,1,9:17.2
-2,2,9:17.2
-1,2,9:17.2
0,2,9:17.2
1,2,9:17.2
2,2,9:17.2
-1,3,9:17.2
0,3,9:17.2
1,3,9:17.2
-1,-3,10:17.2
0,-3,10:17.2
1,-3,10:17.2
-2,-2,10:17.2
-1,-2,10:17.2
0,-2,10:17.2
1,-2,10:17.2
2,-2,10:17.2
-3,-1,10:17.2
-2,-1,10:17.2
-1,-1,10:17.2
0,-1,10:17.2
1,-1,10:17.2
2,-1,10:17.2
3,-1,10:17.2
-3,0,10:17.2
-2,0,10:17.2
-1,0,10:17.2
0,0,10:17.2
1,0,10:17.2
2,0,10:17.2
3,0,10:17.2
-3,1,10:17.2
-2,1,10:17.2
-1,1,10:17.2
0,1,10:17.2
1,1,10:17.2
2,1,10:17.2
3,1,10:17.2
-2,2,10:17.2
-1,2,10:17.2
0,2,10:17.2
1,2,10:17.2
2,2,10:17.2
-1,3,10:17.2
0,3,10:17.2
1,3,10:17.2
-1,-3,11:17.2
0,-3,11:17.2
1,-3,11:17.2
-2,-2,11:17.2
-1,-2,11:17.2
0,-2,11:17.2
1,-2,11:17.2
2,-2,11:17.2
-3,-1,11:17.2
-2,-1,11:17.2
-1,-1,11:17.2
0,-1,11:17.2
1,-1,11:17.2
2,-1,11:17.2
3,-1,11:17.2
-3,0,11:17.2
-2,0,11:17.2
-1,0,11:17.2
0,0,11:17.2
1,0,11:17.2
2,0,11:17.2
3,0,11:17.2
-3,1,11:17.2
-2,1,11:17.2
-1,1,11:17.2
0,1,11:17.2
1,1,11:17.2
2,1,11:17.2
3,1,11:17.2
-2,2,11:17.2
-1,2,11:17.2
0,2,11:17.2
1,2,11:17.2
2,2,11:17.2
-1,3,11:17.2
0,3,11:17.2
1,3,11:17.2
1,-5,12:17.2
1,-4,12:17.2
2,-4,12:17.2
-1,-3,12:17.2
0,-3,12:17.2
1,-3,12:17.2
-5,-2,12:17.2
-4,-2,12:17.2
-2,-2,12:17.2
-1,-2,12:17.2
0,-2,12:17.2
1,-2,12:17.2
2,-2,12:17.2
3,-2,12:17.2
4,-2,12:17.2
5,-2,12:17.2
-3,-1,12:17.2
-2,-1,12:17.2
-1,-1,12:17.2
0,-1,12:17.2
1,-1,12:17.2
2,-1,12:17.2
3,-1,12:17.2
4,-1,12:17.2
-3,0,12:17.2
-2,0,12:17.2
-1,0,12:17.2
0,0,12:17.2
1,0,12:17.2
2,0,12:17.2
3,0,12:17.2
-5,1,12:17.2
-4,1,12:17.2
-3,1,12:17.2
-2,1,12:17.2
-1,1,12:17.2
0,1,12:17.2
1,1,12:17.2
2,1,12:17.2
3,1,12:17.2
-4,2,12:17.2
-2,2,12:17.2
-1,2,12:17.2
0,2,12:17.2
1,2,12:17.2
2,2,12:17.2
3,2,12:17.2
-1,3,12:17.2
0,3,12:17.2
1,3,12:17.2
2,3,12:17.2
4,3,12:17.2
0,4,12:17.2
2,4,12:17.2
0,5,12:17.2
0,6,12:17.2
1,-8,13:17.2
1,-7,13:17.2
1,-6,13:17.2
2,-6,13:17.2
-1,-5,13:17.2
1,-5,13:17.2
2,-5,13:17.2
-3,-4,13:17.2
-1,-4,13:17.2
1,-4,13:17.2
-8,-3,13:17.2
-7,-3,13:17.2
-2,-3,13:17.2
-1,-3,13:17.2
0,-3,13:17.2
1,-3,13:17.2
3,-3,13:17.2
5,-3,13:17.2
6,-3,13:17.2
-6,-2,13:17.2
-5,-2,13:17.2
-4,-2,13:17.2
-2,-2,13:17.2
-1,-2,13:17.2
0,-2,13:17.2
1,-2,13:17.2
2,-2,13:17.2
6,-2,13:17.2
7,-2,13:17.2
-3,-1,13:17.2
-2,-1,13:17.2
-1,-1,13:17.2
0,-1,13:17.2
1,-1,13:17.2
2,-1,13:17.2
3,-1,13:17.2
-5,0,13:17.2
-4,0,13:17.2
-3,0,13:17.2
-2,0,13:17.2
-1,0,13:17.2
0,0,13:17.2
1,0,13:17.2
2,0,13:17.2
3,0,13:17.2
4,0,13:17.2
-7,1,13:17.2
-6,1,13:17.2
-3,1,13:17.2
-2,1,13:17.2
-1,1,13:17.2
0,1,13:17.2
1,1,13:17.2
2,1,13:17.2
3,1,13:17.2
5,1,13:17.2
6,1,13:17.2
-6,2,13:17.2
-5,2,13:17.2
-4,2,13:17.2
-3,2,13:17.2
-2,2,13:17.2
-1,2,13:17.2
0,2,13:17.2
1,2,13:17.2
2,2,13:17.2
3,2,13:17.2
-1,3,13:17.2
0,3,13:17.2
1,3,13:17.2
4,3,13:17.2
1,4,13:17.2
5,4,13:17.2
2,5,13:17.2
3,5,13:17.2
6,5,13:17.2
4,6,13:17.2
0,7,13:17.2
0,8,13:17.2
1,-14,14:18.2
0,-13,14:18.2
1,-13,14:18.2
2,-13,14:18.2
8,-13,14:18.2
1,-12,14:18.2
7,-12,14:18.2
8,-12,14:18.2
9,-12,14:18.2
7,-11,14:18.2
8,-11,14:18.2
2,-10,14:17.2
6,-10,14:18.2
7,-10,14:18.2
8,-10,14:18.2
10,-10,14:18.2
2,-9,14:17.2
3,-9,14:18.2
7,-9,14:18.2
9,-9,14:18.2
10,-9,14:18.2
11,-9,14:18.2
-2,-8,14:18.2
1,-8,14:17.2
2,-8,14:18.2
3,-8,14:17.2
4,-8,14:18.2
10,-8,14:18.2
-5,-7,14:18.2
-3,-7,14:18.2
-2,-7,14:17.2
-1,-7,14:18.2
1,-7,14:17.2
3,-7,14:17.2
-6,-6,14:18.2
-5,-6,14:17.2
-4,-6,14:18.2
-2,-6,14:17.2
0,-6,14:18.2
1,-6,14:17.2
2,-6,14:18.2
-5,-5,14:18.2
-4,-5,14:17.2
1,-5,14:17.2
5,-5,14:17.2
8,-5,14:17.2
-10,-4,14:17.2
-9,-4,14:17.2
-1,-4,14:17.2
4,-4,14:17.2
7,-4,14:17.2
-8,-3,14:17.2
-7,-3,14:17.2
-1,-3,14:17.2
0,-3,14:17.2
1,-3,14:17.2
4,-3,14:17.2
8,-3,14:17.2
9,-3,14:17.2
-6,-2,14:17.2
-2,-2,14:17.2
-1,-2,14:17.2
0,-2,14:17.2
1,-2,14:17.2
2,-2,14:17.2
3,-2,14:17.2
5,-2,14:17.2
-7,-1,14:17.2
-6,-1,14:17.2
-5,-1,14:17.2
-3,-1,14:17.2
-2,-1,14:17.2
-1,-1,14:17.2
0,-1,14:17.2
1,-1,14:17.2
2,-1,14:17.2
3,-1,14:17.2
4,-1,14:17.2
-5,0,14:17.2
-4,0,14:17.2
-3,0,14:17.2
-2,0,14:17.2
-1,0,14:17.2
0,0,14:17.2
1,0,14:17.2
2,0,14:17.2
3,0,14:17.2
4,0,14:17.2
5,0,14:17.2
-8,1,14:17.2
-3,1,14:17.2
-2,1,14:17.2
-1,1,14:17.2
0,1,14:17.2
1,1,14:17.2
2,1,14:17.2
3,1,14:17.2
4,1,14:17.2
7,1,14:17.2
8,1,14:17.2
-9,2,14:17.2
-8,2,14:18.2
-6,2,14:17.2
-5,2,14:17.2
-4,2,14:17.2
-2,2,14:17.2
-1,2,14:17.2
0,2,14:17.2
1,2,14:17.2
2,2,14:17.2
-9,3,14:18.2
-8,3,14:17.2
-7,3,14:17.2
-5,3,14:17.2
-3,3,14:17.2
-2,3,14:17.2
-1,3,14:17.2
0,3,14:17.2
1,3,14:17.2
2,3,14:17.2
-8,4,14:18.2
0,4,14:17.2
2,4,14:17.2
3,4,14:17.2
5,4,14:17.2
12,4,14:18.2
2,5,14:17.2
6,5,14:17.2
7,5,14:17.2
8,5,14:18.2
11,5,14:18.2
12,5,14:18.2
13,5,14:18.2
2,6,14:17.2
7,6,14:18.2
8,6,14:17.2
9,6,14:18.2
12,6,14:18.2
2,7,14:17.2
4,7,14:17.2
8,7,14:18.2
5,8,14:17.2
-5,9,14:18.2
0,9,14:17.2
-6,10,14:18.2
-5,10,14:18.2
-4,10,14:18.2
-1,10,14:18.2
0,10,14:17.2
1,10,14:18.2
9,10,14:18.2
-5,11,14:18.2
0,11,14:18.2
8,11,14:18.2
9,11,14:18.2
10,11,14:18.2
9,12,14:18.2
-3,13,14:18.2
5,13,14:18.2
-4,14,14:18.2
-3,14,14:18.2
-2,14,14:18.2
4,14,14:18.2
5,14,14:18.2
6,14,14:18.2
-3,15,14:18.2
5,15,14:18.2
0,-15,15:18.2
1,-15,15:18.2
2,-15,15:18.2
-1,-14,15:18.2
0,-14,15:18.2
1,-14,15:18.2
2,-14,15:18.2
3,-14,15:18.2
7,-14,15:18.2
8,-14,15:18.2
9,-14,15:18.2
-1,-13,15:18.2
0,-13,15:18.2
1,-13,15:18.2
2,-13,15:18.2
3,-13,15:18.2
6,-13,15:18.2
7,-13,15:18.2
8,-13,15:18.2
9,-13,15:18.2
10,-13,15:18.2
-1,-12,15:18.2
0,-12,15:18.2
1,-12,15:18.2
2,-12,15:17.2
3,-12,15:18.2
5,-12,15:18.2
6,-12,15:18.2
7,-12,15:18.2
8,-12,15:18.2
9,-12,15:18.2
10,-12,15:18.2
0,-11,15:18.2
1,-11,15:18.2
2,-11,15:17.2
5,-11,15:18.2
6,-11,15:18.2
7,-11,15:18.2
8,-11,15:18.2
9,-11,15:18.2
10,-11,15:18.2
11,-11,15:18.2
2,-10,15:17.2
3,-10,15:18.2
4,-10,15:18.2
5,-10,15:18.2
6,-10,15:18.2
7,-10,15:18.2
8,-10,15:18.2
9,-10,15:18.2
10,-10,15:18.2
11,-10,15:18.2
12,-10,15:18.2
-3,-9,15:18.2
-2,-9,15:18.2
-1,-9,15:18.2
1,-9,15:18.2
2,-9,15:17.2
3,-9,15:18.2
4,-9,15:18.2
5,-9,15:18.2
6,-9,15:18.2
7,-9,15:18.2
8,-9,15:18.2
9,-9,15:18.2
10,-9,15:18.2
11,-9,15:18.2
12,-9,15:18.2
-6,-8,15:18.2
-5,-8,15:18.2
-4,-8,15:18.2
-3,-8,15:18.2
-2,-8,15:18.2
-1,-8,15:18.2
0,-8,15:18.2
1,-8,15:18.2
2,-8,15:18.2
3,-8,15:18.2
4,-8,15:18.2
5,-8,15:18.2
6,-8,15:18.2
7,-8,15:18.2
8,-8,15:18.2
9,-8,15:18.2
10,-8,15:18.2
11,-8,15:18.2
12,-8,15:18.2
-7,-7,15:18.2
-6,-7,15:18.2
-5,-7,15:18.2
-4,-7,15:18.2
-3,-7,15:18.2
-2,-7,15:18.2
-1,-7,15:18.2
0,-7,15:18.2
1,-7,15:18.2
2,-7,15:18.2
3,-7,15:18.2
4,-7,15:18.2
5,-7,15:18.2
7,-7,15:17.2
9,-7,15:18.2
10,-7,15:18.2
11,-7,15:18.2
-12,-6,15:18.2
-7,-6,15:18.2
-6,-6,15:18.2
-5,-6,15:18.2
-4,-6,15:18.2
-3,-6,15:18.2
-2,-6,15:18.2
-1,-6,15:17.2
0,-6,15:17.2
1,-6,15:18.2
2,-6,15:18.2
3,-6,15:18.2
4,-6,15:18.2
6,-6,15:17.2
10,-6,15:17.2
-13,-5,15:18.2
-12,-5,15:17.2
-11,-5,15:17.2
-7,-5,15:18.2
-6,-5,15:18.2
-5,-5,15:18.2
-4,-5,15:18.2
-3,-5,15:18.2
-2,-5,15:18.2
-1,-5,15:17.2
0,-5,15:17.2
1,-5,15:18.2
2,-5,15:18.2
3,-5,15:18.2
5,-5,15:18.2
6,-5,15:17.2
9,-5,15:17.2
-12,-4,15:18.2
-10,-4,15:17.2
-9,-4,15:17.2
-6,-4,15:18.2
-5,-4,15:18.2
-4,-4,15:18.2
-1,-4,15:17.2
0,-4,15:17.2
1,-4,15:18.2
2,-4,15:18.2
4,-4,15:18.2
5,-4,15:17.2
6,-4,15:18.2
11,-4,15:17.2
-3,-3,15:17.2
-1,-3,15:17.2
0,-3,15:17.2
1,-3,15:17.2
5,-3,15:18.2
10,-3,15:17.2
-4,-2,15:17.2
-3,-2,15:17.2
-2,-2,15:17.2
-1,-2,15:17.2
0,-2,15:17.2
1,-2,15:17.2
2,-2,15:17.2
6,-2,15:17.2
7,-2,15:17.2
-9,-1,15:17.2
-8,-1,15:17.2
-7,-1,15:17.2
-6,-1,15:17.2
-3,-1,15:17.2
-2,-1,15:17.2
-1,-1,15:17.2
0,-1,15:17.2
1,-1,15:17.2
2,-1,15:17.2
3,-1,15:17.2
-3,0,15:17.2
-2,0,15:17.2
-1,0,15:17.2
0,0,15:17.2
1,0,15:17.2
2,0,15:17.2
3,0,15:17.2
4,0,15:17.2
5,0,15:17.2
6,0,15:17.2
7,0,15:17.2
10,0,15:18.2
-11,1,15:18.2
-9,1,15:18.2
-8,1,15:18.2
-7,1,15:18.2
-3,1,15:17.2
-2,1,15:17.2
-1,1,15:17.2
0,1,15:17.2
1,1,15:17.2
2,1,15:17.2
3,1,15:17.2
4,1,15:17.2
6,1,15:18.2
9,1,15:17.2
10,1,15:17.2
11,1,15:18.2
-12,2,15:18.2
-11,2,15:17.2
-10,2,15:17.2
-9,2,15:18.2
-8,2,15:18.2
-7,2,15:18.2
-6,2,15:17.2
-2,2,15:17.2
-1,2,15:17.2
0,2,15:17.2
1,2,15:17.2
2,2,15:17.2
3,2,15:17.2
4,2,15:17.2
5,2,15:17.2
6,2,15:17.2
7,2,15:18.2
10,2,15:18.2
-11,3,15:18.2
-10,3,15:18.2
-9,3,15:17.2
-8,3,15:17.2
-7,3,15:17.2
-6,3,15:17.2
-3,3,15:17.2
-1,3,15:17.2
0,3,15:17.2
1,3,15:17.2
2,3,15:17.2
3,3,15:18.2
4,3,15:17.2
5,3,15:18.2
6,3,15:18.2
11,3,15:18.2
12,3,15:18.2
13,3,15:18.2
-10,4,15:18.2
-9,4,15:18.2
-8,4,15:18.2
-7,4,15:17.2
-6,4,15:18.2
-3,4,15:17.2
-2,4,15:17.2
0,4,15:17.2
1,4,15:17.2
3,4,15:17.2
4,4,15:18.2
7,4,15:18.2
8,4,15:18.2
9,4,15:18.2
10,4,15:18.2
11,4,15:18.2
12,4,15:18.2
13,4,15:18.2
14,4,15:18.2
-9,5,15:18.2
-8,5,15:18.2
-7,5,15:18.2
-4,5,15:17.2
-3,5,15:17.2
-1,5,15:17.2
0,5,15:17.2
1,5,15:17.2
4,5,15:17.2
6,5,15:18.2
7,5,15:17.2
8,5,15:18.2
9,5,15:18.2
10,5,15:18.2
11,5,15:18.2
12,5,15:18.2
13,5,15:18.2
14,5,15:18.2
-1,6,15:18.2
0,6,15:17.2
1,6,15:17.2
3,6,15:17.2
5,6,15:17.2
6,6,15:18.2
7,6,15:18.2
8,6,15:17.2
9,6,15:18.2
10,6,15:18.2
11,6,15:18.2
12,6,15:18.2
13,6,15:18.2
14,6,15:18.2
0,7,15:18.2
3,7,15:17.2
6,7,15:18.2
7,7,15:18.2
8,7,15:18.2
9,7,15:18.2
10,7,15:18.2
11,7,15:18.2
12,7,15:18.2
13,7,15:18.2
-6,8,15:18.2
-5,8,15:18.2
-4,8,15:18.2
-1,8,15:18.2
0,8,15:18.2
1,8,15:18.2
3,8,15:17.2
7,8,15:18.2
8,8,15:18.2
9,8,15:18.2
-7,9,15:18.2
-6,9,15:18.2
-5,9,15:18.2
-4,9,15:18.2
-3,9,15:18.2
-2,9,15:18.2
-1,9,15:18.2
0,9,15:18.2
1,9,15:18.2
2,9,15:18.2
3,9,15:17.2
4,9,15:18.2
5,9,15:17.2
6,9,15:18.2
8,9,15:18.2
9,9,15:18.2
10,9,15:18.2
-7,10,15:18.2
-6,10,15:18.2
-5,10,15:18.2
-4,10,15:18.2
-3,10,15:18.2
-2,10,15:18.2
-1,10,15:18.2
0,10,15:18.2
1,10,15:18.2
2,10,15:18.2
3,10,15:18.2
5,10,15:18.2
6,10,15:17.2
7,10,15:18.2
8,10,15:18.2
9,10,15:18.2
10,10,15:18.2
11,10,15:18.2
-7,11,15:18.2
-6,11,15:18.2
-5,11,15:18.2
-4,11,15:18.2
-3,11,15:18.2
-2,11,15:18.2
-1,11,15:18.2
0,11,15:18.2
1,11,15:18.2
2,11,15:18.2
6,11,15:18.2
7,11,15:18.2
8,11,15:18.2
9,11,15:18.2
10,11,15:18.2
11,11,15:18.2
-6,12,15:18.2
-5,12,15:18.2
-4,12,15:18.2
-3,12,15:18.2
-2,12,15:18.2
-1,12,15:18.2
0,12,15:18.2
1,12,15:18.2
4,12,15:18.2
5,12,15:18.2
6,12,15:18.2
7,12,15:18.2
8,12,15:18.2
9,12,15:18.2
10,12,15:18.2
11,12,15:18.2
-6,13,15:18.2
-5,13,15:18.2
-4,13,15:18.2
-3,13,15:18.2
-2,13,15:18.2
-1,13,15:18.2
3,13,15:18.2
4,13,15:18.2
5,13,15:18.2
6,13,15:18.2
7,13,15:18.2
8,13,15:18.2
9,13,15:18.2
10,13,15:18.2
-5,14,15:18.2
-4,14,15:18.2
-3,14,15:18.2
-2,14,15:18.2
-1,14,15:18.2
3,14,15:18.2
4,14,15:18.2
5,14,15:18.2
6,14,15:18.2
7,14,15:18.2
-5,15,15:18.2
-4,15,15:18.2
-3,15,15:18.2
-2,15,15:18.2
-1,15,15:18.2
3,15,15:18.2
4,15,15:18.2
5,15,15:18.2
6,15,15:18.2
7,15,15:18.2
-4,16,15:18.2
-3,16,15:18.2
-2,16,15:18.2
4,16,15:18.2
5,16,15:18.2
6,16,15:18.2
0,-15,16:18.2
1,-15,16:18.2
2,-15,16:18.2
-1,-14,16:18.2
0,-14,16:18.2
1,-14,16:18.2
2,-14,16:18.2
3,-14,16:18.2
5,-14,16:18.2
6,-14,16:18.2
7,-14,16:18.2
8,-14,16:18.2
9,-14,16:18.2
-1,-13,16:18.2
0,-13,16:18.2
1,-13,16:18.2
2,-13,16:18.2
3,-13,16:18.2
4,-13,16:18.2
5,-13,16:18.2
6,-13,16:18.2
7,-13,16:18.2
8,-13,16:18.2
9,-13,16:18.2
10,-13,16:18.2
-1,-12,16:18.2
0,-12,16:18.2
1,-12,16:18.2
2,-12,16:17.2
3,-12,16:18.2
4,-12,16:18.2
5,-12,16:18.2
6,-12,16:18.2
7,-12,16:18.2
8,-12,16:18.2
9,-12,16:18.2
10,-12,16:18.2
11,-12,16:18.2
0,-11,16:18.2
1,-11,16:18.2
2,-11,16:17.2
3,-11,16:18.2
4,-11,16:18.2
5,-11,16:18.2
6,-11,16:18.2
7,-11,16:18.2
8,-11,16:18.2
9,-11,16:18.2
10,-11,16:18.2
11,-11,16:18.2
12,-11,16:18.2
1,-10,16:18.2
2,-10,16:18.2
3,-10,16:18.2
4,-10,16:18.2
5,-10,16:18.2
6,-10,16:18.2
7,-10,16:18.2
8,-10,16:18.2
9,-10,16:18.2
10,-10,16:18.2
11,-10,16:18.2
12,-10,16:18.2
-3,-9,16:18.2
-2,-9,16:18.2
-1,-9,16:18.2
1,-9,16:18.2
2,-9,16:18.2
3,-9,16:18.2
4,-9,16:18.2
5,-9,16:18.2
6,-9,16:18.2
7,-9,16:18.2
8,-9,16:18.2
9,-9,16:18.2
10,-9,16:18.2
11,-9,16:18.2
12,-9,16:18.2
-6,-8,16:18.2
-5,-8,16:18.2
-4,-8,16:18.2
-3,-8,16:18.2
-2,-8,16:17.2
-1,-8,16:17.2
0,-8,16:18.2
1,-8,16:18.2
2,-8,16:18.2
3,-8,16:18.2
4,-8,16:18.2
5,-8,16:18.2
6,-8,16:18.2
7,-8,16:18.2
8,-8,16:17.2
9,-8,16:18.2
10,-8,16:18.2
11,-8,16:18.2
12,-8,16:18.2
-13,-7,16:18.2
-12,-7,16:18.2
-11,-7,16:18.2
-7,-7,16:18.2
-6,-7,16:18.2
-5,-7,16:18.2
-4,-7,16:18.2
-3,-7,16:18.2
-2,-7,16:17.2
-1,-7,16:17.2
0,-7,16:17.2
1,-7,16:18.2
2,-7,16:18.2
3,-7,16:18.2
4,-7,16:18.2
5,-7,16:18.2
8,-7,16:18.2
9,-7,16:18.2
10,-7,16:18.2
11,-7,16:18.2
12,-7,16:17.2
13,-7,16:18.2
-14,-6,16:18.2
-13,-6,16:18.2
-12,-6,16:18.2
-11,-6,16:18.2
-10,-6,16:18.2
-7,-6,16:18.2
-6,-6,16:18.2
-5,-6,16:18.2
-4,-6,16:18.2
-3,-6,16:18.2
-2,-6,16:18.2
-1,-6,16:17.2
0,-6,16:17.2
1,-6,16:18.2
2,-6,16:18.2
3,-6,16:18.2
4,-6,16:18.2
5,-6,16:18.2
6,-6,16:18.2
7,-6,16:17.2
8,-6,16:17.2
11,-6,16:17.2
12,-6,16:18.2
-14,-5,16:18.2
-13,-5,16:18.2
-12,-5,16:17.2
-11,-5,16:17.2
-10,-5,16:18.2
-7,-5,16:18.2
-6,-5,16:18.2
-5,-5,16:17.2
-4,-5,16:18.2
-3,-5,16:18.2
-2,-5,16:18.2
-1,-5,16:18.2
0,-5,16:18.2
1,-5,16:18.2
2,-5,16:18.2
3,-5,16:18.2
4,-5,16:18.2
5,-5,16:18.2
6,-5,16:18.2
7,-5,16:18.2
-14,-4,16:18.2
-13,-4,16:18.2
-12,-4,16:18.2
-11,-4,16:18.2
-10,-4,16:18.2
-6,-4,16:18.2
-5,-4,16:18.2
-4,-4,16:17.2
-2,-4,16:17.2
-1,-4,16:17.2
0,-4,16:18.2
1,-4,16:18.2
2,-4,16:18.2
3,-4,16:18.2
4,-4,16:18.2
5,-4,16:18.2
6,-4,16:18.2
7,-4,16:18.2
9,-4,16:18.2
12,-4,16:17.2
13,-4,16:17.2
-13,-3,16:18.2
-12,-3,16:18.2
-11,-3,16:18.2
-6,-3,16:18.2
-5,-3,16:17.2
-4,-3,16:18.2
-3,-3,16:17.2
-2,-3,16:17.2
-1,-3,16:17.2
0,-3,16:17.2
1,-3,16:17.2
3,-3,16:18.2
4,-3,16:17.2
5,-3,16:18.2
6,-3,16:18.2
7,-3,16:18.2
8,-3,16:17.2
9,-3,16:17.2
10,-3,16:18.2
-11,-2,16:18.2
-9,-2,16:18.2
-5,-2,16:18.2
-4,-2,16:17.2
-3,-2,16:17.2
-2,-2,16:17.2
-1,-2,16:17.2
0,-2,16:17.2
1,-2,16:17.2
2,-2,16:17.2
3,-2,16:17.2
4,-2,16:17.2
5,-2,16:18.2
6,-2,16:18.2
9,-2,16:18.2
-12,-1,16:18.2
-11,-1,16:17.2
-10,-1,16:17.2
-9,-1,16:17.2
-8,-1,16:17.2
-3,-1,16:17.2
-2,-1,16:17.2
-1,-1,16:17.2
0,-1,16:17.2
1,-1,16:17.2
2,-1,16:17.2
3,-1,16:17.2
9,-1,16:18.2
10,-1,16:18.2
11,-1,16:18.2
-12,0,16:18.2
-11,0,16:18.2
-10,0,16:18.2
-9,0,16:18.2
-5,0,16:17.2
-4,0,16:17.2
-3,0,16:17.2
-2,0,16:17.2
-1,0,16:17.2
0,0,16:17.2
1,0,16:17.2
2,0,16:17.2
3,0,16:17.2
4,0,16:17.2
5,0,16:17.2
6,0,16:17.2
7,0,16:17.2
8,0,16:17.2
9,0,16:17.2
10,0,16:18.2
11,0,16:18.2
12,0,16:18.2
-13,1,16:18.2
-12,1,16:18.2
-11,1,16:18.2
-10,1,16:18.2
-9,1,16:18.2
-8,1,16:18.2
-7,1,16:18.2
-5,1,16:17.2
-4,1,16:17.2
-3,1,16:17.2
-2,1,16:17.2
-1,1,16:17.2
0,1,16:17.2
1,1,16:17.2
2,1,16:17.2
3,1,16:17.2
4,1,16:18.2
5,1,16:18.2
6,1,16:18.2
7,1,16:17.2
8,1,16:17.2
9,1,16:17.2
10,1,16:18.2
11,1,16:18.2
12,1,16:18.2
-13,2,16:18.2
-12,2,16:18.2
-11,2,16:18.2
-10,2,16:18.2
-9,2,16:18.2
-8,2,16:18.2
-7,2,16:18.2
-6,2,16:18.2
-2,2,16:17.2
-1,2,16:17.2
0,2,16:17.2
1,2,16:17.2
2,2,16:17.2
3,2,16:18.2
4,2,16:18.2
5,2,16:18.2
6,2,16:17.2
7,2,16:18.2
8,2,16:18.2
9,2,16:18.2
10,2,16:18.2
11,2,16:18.2
12,2,16:18.2
-13,3,16:18.2
-12,3,16:18.2
-11,3,16:18.2
-10,3,16:18.2
-9,3,16:18.2
-8,3,16:17.2
-7,3,16:18.2
-6,3,16:18.2
-4,3,16:18.2
-3,3,16:18.2
-2,3,16:17.2
-1,3,16:17.2
0,3,16:17.2
1,3,16:17.2
2,3,16:18.2
3,3,16:18.2
4,3,16:18.2
5,3,16:18.2
6,3,16:18.2
7,3,16:17.2
8,3,16:18.2
9,3,16:18.2
10,3,16:18.2
11,3,16:18.2
12,3,16:18.2
13,3,16:18.2
-12,4,16:18.2
-11,4,16:17.2
-10,4,16:17.2
-9,4,16:17.2
-8,4,16:17.2
-7,4,16:18.2
-6,4,16:18.2
-5,4,16:18.2
-4,4,16:17.2
-3,4,16:17.2
-2,4,16:17.2
-1,4,16:18.2
0,4,16:17.2
1,4,16:18.2
2,4,16:18.2
3,4,16:18.2
4,4,16:18.2
5,4,16:18.2
6,4,16:18.2
7,4,16:18.2
8,4,16:18.2
9,4,16:18.2
10,4,16:18.2
11,4,16:18.2
12,4,16:18.2
13,4,16:18.2
14,4,16:18.2
-9,5,16:17.2
-8,5,16:18.2
-7,5,16:18.2
-4,5,16:18.2
-3,5,16:18.2
-2,5,16:17.2
-1,5,16:17.2
0,5,16:17.2
1,5,16:18.2
2,5,16:18.2
3,5,16:18.2
4,5,16:17.2
5,5,16:18.2
6,5,16:18.2
7,5,16:18.2
8,5,16:18.2
9,5,16:18.2
10,5,16:18.2
11,5,16:18.2
12,5,16:18.2
13,5,16:18.2
14,5,16:18.2
-5,6,16:17.2
-4,6,16:18.2
-3,6,16:17.2
-2,6,16:18.2
-1,6,16:17.2
0,6,16:17.2
1,6,16:18.2
2,6,16:18.2
4,6,16:18.2
6,6,16:18.2
7,6,16:18.2
8,6,16:18.2
9,6,16:18.2
10,6,16:18.2
11,6,16:18.2
12,6,16:18.2
13,6,16:18.2
14,6,16:18.2
-6,7,16:17.2
-4,7,16:17.2
-3,7,16:18.2
-2,7,16:18.2
-1,7,16:17.2
0,7,16:18.2
1,7,16:17.2
2,7,16:18.2
3,7,16:18.2
4,7,16:18.2
5,7,16:17.2
6,7,16:18.2
7,7,16:18.2
8,7,16:18.2
9,7,16:17.2
10,7,16:18.2
11,7,16:18.2
12,7,16:18.2
13,7,16:18.2
-6,8,16:18.2
-5,8,16:18.2
-4,8,16:18.2
-1,8,16:18.2
0,8,16:18.2
1,8,16:18.2
2,8,16:17.2
3,8,16:18.2
4,8,16:18.2
5,8,16:18.2
6,8,16:17.2
7,8,16:18.2
8,8,16:18.2
9,8,16:18.2
-7,9,16:18.2
-6,9,16:18.2
-5,9,16:18.2
-4,9,16:18.2
-3,9,16:18.2
-2,9,16:18.2
-1,9,16:18.2
0,9,16:18.2
1,9,16:18.2
2,9,16:18.2
3,9,16:18.2
4,9,16:17.2
5,9,16:18.2
6,9,16:18.2
7,9,16:18.2
8,9,16:18.2
9,9,16:18.2
10,9,16:18.2
-7,10,16:18.2
-6,10,16:18.2
-5,10,16:18.2
-4,10,16:18.2
-3,10,16:18.2
-2,10,16:18.2
-1,10,16:18.2
0,10,16:18.2
1,10,16:18.2
2,10,16:18.2
3,10,16:18.2
4,10,16:17.2
5,10,16:18.2
6,10,16:18.2
7,10,16:18.2
8,10,16:18.2
9,10,16:18.2
10,10,16:18.2
11,10,16:18.2
-7,11,16:18.2
-6,11,16:18.2
-5,11,16:18.2
-4,11,16:18.2
-3,11,16:18.2
-2,11,16:18.2
-1,11,16:18.2
0,11,16:18.2
1,11,16:18.2
2,11,16:18.2
3,11,16:18.2
4,11,16:18.2
5,11,16:18.2
6,11,16:18.2
7,11,16:18.2
8,11,16:18.2
9,11,16:18.2
10,11,16:18.2
11,11,16:18.2
-7,12,16:18.2
-6,12,16:18.2
-5,12,16:18.2
-4,12,16:18.2
-3,12,16:18.2
-2,12,16:18.2
-1,12,16:18.2
0,12,16:18.2
1,12,16:18.2
4,12,16:18.2
5,12,16:18.2
6,12,16:18.2
7,12,16:18.2
8,12,16:18.2
9,12,16:18.2
10,12,16:18.2
11,12,16:18.2
-7,13,16:18.2
-6,13,16:18.2
-5,13,16:18.2
-4,13,16:18.2
-3,13,16:18.2
-2,13,16:18.2
-1,13,16:18.2
3,13,16:18.2
4,13,16:18.2
5,13,16:18.2
6,13,16:18.2
7,13,16:18.2
8,13,16:18.2
9,13,16:18.2
10,13,16:18.2
-7,14,16:18.2
-6,14,16:18.2
-5,14,16:18.2
-4,14,16:18.2
-3,14,16:18.2
-2,14,16:18.2
-1,14,16:18.2
3,14,16:18.2
4,14,16:18.2
5,14,16:18.2
6,14,16:18.2
7,14,16:18.2
-6,15,16:18.2
-5,15,16:18.2
-4,15,16:18.2
-3,15,16:18.2
-2,15,16:18.2
-1,15,16:18.2
3,15,16:18.2
4,15,16:18.2
5,15,16:18.2
6,15,16:18.2
7,15,16:18.2
-4,16,16:18.2
-3,16,16:18.2
-2,16,16:18.2
4,16,16:18.2
5,16,16:18.2
6,16,16:18.2
1,-14,17:18.2
2,-14,17:18.2
3,-14,17:18.2
5,-14,17:18.2
6,-14,17:18.2
7,-14,17:18.2
0,-13,17:18.2
1,-13,17:18.2
2,-13,17:18.2
3,-13,17:18.2
4,-13,17:18.2
5,-13,17:18.2
6,-13,17:18.2
7,-13,17:18.2
8,-13,17:18.2
0,-12,17:18.2
1,-12,17:18.2
2,-12,17:18.2
3,-12,17:18.2
4,-12,17:18.2
5,-12,17:18.2
6,-12,17:18.2
7,-12,17:18.2
8,-12,17:18.2
9,-12,17:18.2
10,-12,17:18.2
11,-12,17:18.2
-1,-11,17:17.2
0,-11,17:18.2
1,-11,17:18.2
2,-11,17:18.2
3,-11,17:18.2
4,-11,17:18.2
5,-11,17:18.2
6,-11,17:18.2
7,-11,17:18.2
8,-11,17:18.2
9,-11,17:18.2
10,-11,17:18.2
11,-11,17:18.2
12,-11,17:18.2
-3,-10,17:18.2
-2,-10,17:18.2
-1,-10,17:17.2
1,-10,17:18.2
2,-10,17:18.2
3,-10,17:18.2
5,-10,17:18.2
6,-10,17:18.2
7,-10,17:18.2
8,-10,17:18.2
9,-10,17:18.2
10,-10,17:18.2
11,-10,17:18.2
12,-10,17:18.2
-4,-9,17:18.2
-3,-9,17:18.2
-2,-9,17:17.2
-1,-9,17:17.2
0,-9,17:18.2
1,-9,17:18.2
3,-9,17:18.2
6,-9,17:18.2
7,-9,17:18.2
8,-9,17:18.2
9,-9,17:18.2
10,-9,17:18.2
11,-9,17:18.2
12,-9,17:18.2
13,-9,17:18.2
-4,-8,17:18.2
-3,-8,17:18.2
-2,-8,17:17.2
-1,-8,17:18.2
0,-8,17:18.2
1,-8,17:18.2
2,-8,17:18.2
3,-8,17:18.2
4,-8,17:18.2
6,-8,17:18.2
7,-8,17:18.2
8,-8,17:18.2
9,-8,17:18.2
10,-8,17:17.2
11,-8,17:18.2
12,-8,17:18.2
13,-8,17:18.2
14,-8,17:18.2
-13,-7,17:18.2
-12,-7,17:18.2
-11,-7,17:18.2
-6,-7,17:18.2
-5,-7,17:18.2
-4,-7,17:18.2
-3,-7,17:18.2
-2,-7,17:18.2
-1,-7,17:18.2
0,-7,17:18.2
1,-7,17:18.2
2,-7,17:18.2
3,-7,17:18.2
6,-7,17:18.2
7,-7,17:18.2
8,-7,17:18.2
9,-7,17:17.2
10,-7,17:18.2
11,-7,17:18.2
12,-7,17:18.2
13,-7,17:18.2
14,-7,17:18.2
-14,-6,17:18.2
-13,-6,17:18.2
-12,-6,17:18.2
-11,-6,17:18.2
-10,-6,17:18.2
-7,-6,17:18.2
-6,-6,17:17.2
-5,-6,17:18.2
-4,-6,17:17.2
-3,-6,17:18.2
-2,-6,17:17.2
-1,-6,17:18.2
0,-6,17:18.2
1,-6,17:18.2
2,-6,17:18.2
4,-6,17:18.2
5,-6,17:18.2
6,-6,17:18.2
7,-6,17:18.2
8,-6,17:18.2
9,-6,17:18.2
10,-6,17:18.2
11,-6,17:18.2
12,-6,17:18.2
13,-6,17:18.2
14,-6,17:18.2
15,-6,17:18.2
-14,-5,17:18.2
-13,-5,17:18.2
-12,-5,17:18.2
-11,-5,17:18.2
-10,-5,17:18.2
-6,-5,17:18.2
-5,-5,17:18.2
-4,-5,17:17.2
-3,-5,17:17.2
-2,-5,17:17.2
-1,-5,17:18.2
0,-5,17:18.2
1,-5,17:18.2
3,-5,17:18.2
4,-5,17:18.2
5,-5,17:18.2
6,-5,17:17.2
7,-5,17:18.2
8,-5,17:18.2
9,-5,17:18.2
10,-5,17:18.2
11,-5,17:18.2
12,-5,17:18.2
13,-5,17:18.2
14,-5,17:17.2
15,-5,17:17.2
16,-5,17:18.2
-14,-4,17:18.2
-13,-4,17:18.2
-12,-4,17:18.2
-11,-4,17:18.2
-10,-4,17:18.2
-7,-4,17:18.2
-6,-4,17:18.2
-5,-4,17:18.2
-4,-4,17:18.2
-3,-4,17:18.2
3,-4,17:17.2
4,-4,17:18.2
5,-4,17:17.2
6,-4,17:18.2
7,-4,17:18.2
8,-4,17:18.2
9,-4,17:18.2
10,-4,17:18.2
11,-4,17:18.2
15,-4,17:18.2
-13,-3,17:18.2
-12,-3,17:18.2
-11,-3,17:18.2
-10,-3,17:18.2
-9,-3,17:18.2
-8,-3,17:18.2
-7,-3,17:18.2
-6,-3,17:18.2
-5,-3,17:17.2
-4,-3,17:17.2
-3,-3,17:18.2
-1,-3,17:17.2
0,-3,17:17.2
1,-3,17:17.2
2,-3,17:17.2
3,-3,17:18.2
4,-3,17:18.2
5,-3,17:18.2
6,-3,17:17.2
7,-3,17:18.2
8,-3,17:18.2
9,-3,17:18.2
10,-3,17:18.2
11,-3,17:18.2
-13,-2,17:18.2
-12,-2,17:18.2
-11,-2,17:18.2
-10,-2,17:18.2
-9,-2,17:18.2
-8,-2,17:18.2
-7,-2,17:18.2
-6,-2,17:18.2
-5,-2,17:17.2
-4,-2,17:18.2
-3,-2,17:17.2
-2,-2,17:17.2
-1,-2,17:17.2
0,-2,17:17.2
1,-2,17:17.2
2,-2,17:17.2
4,-2,17:18.2
5,-2,17:17.2
6,-2,17:18.2
7,-2,17:18.2
8,-2,17:18.2
9,-2,17:18.2
10,-2,17:18.2
11,-2,17:18.2
-13,-1,17:18.2
-12,-1,17:18.2
-11,-1,17:17.2
-10,-1,17:17.2
-9,-1,17:18.2
-8,-1,17:18.2
-7,-1,17:17.2
-6,-1,17:17.2
-5,-1,17:18.2
-4,-1,17:17.2
-3,-1,17:17.2
-2,-1,17:17.2
-1,-1,17:17.2
0,-1,17:17.2
1,-1,17:17.2
2,-1,17:17.2
3,-1,17:17.2
4,-1,17:17.2
5,-1,17:17.2
6,-1,17:17.2
8,-1,17:18.2
9,-1,17:18.2
10,-1,17:18.2
11,-1,17:18.2
-13,0,17:18.2
-12,0,17:18.2
-11,0,17:18.2
-10,0,17:18.2
-9,0,17:18.2
-8,0,17:18.2
-7,0,17:18.2
-3,0,17:17.2
-2,0,17:17.2
-1,0,17:17.2
0,0,17:17.2
1,0,17:17.2
2,0,17:17.2
3,0,17:17.2
4,0,17:18.2
5,0,17:18.2
6,0,17:18.2
7,0,17:18.2
8,0,17:17.2
9,0,17:17.2
10,0,17:17.2
11,0,17:17.2
12,0,17:18.2
-13,1,17:18.2
-12,1,17:18.2
-11,1,17:18.2
-10,1,17:18.2
-9,1,17:18.2
-8,1,17:18.2
-7,1,17:17.2
-6,1,17:17.2
-4,1,17:18.2
-3,1,17:17.2
-2,1,17:17.2
-1,1,17:17.2
0,1,17:17.2
1,1,17:17.2
2,1,17:17.2
3,1,17:17.2
4,1,17:17.2
5,1,17:17.2
6,1,17:17.2
7,1,17:17.2
8,1,17:17.2
9,1,17:18.2
10,1,17:17.2
11,1,17:17.2
12,1,17:18.2
-13,2,17:18.2
-12,2,17:18.2
-11,2,17:18.2
-10,2,17:18.2
-9,2,17:18.2
-8,2,17:18.2
-7,2,17:18.2
-5,2,17:17.2
-4,2,17:17.2
-3,2,17:17.2
-2,2,17:17.2
-1,2,17:17.2
0,2,17:17.2
1,2,17:17.2
2,2,17:17.2
3,2,17:17.2
4,2,17:17.2
5,2,17:17.2
6,2,17:18.2
7,2,17:18.2
8,2,17:18.2
9,2,17:18.2
10,2,17:18.2
11,2,17:18.2
12,2,17:18.2
-13,3,17:18.2
-12,3,17:18.2
-11,3,17:18.2
-10,3,17:18.2
-9,3,17:18.2
-8,3,17:18.2
-7,3,17:18.2
-6,3,17:18.2
-5,3,17:18.2
-4,3,17:18.2
-3,3,17:18.2
-2,3,17:17.2
-1,3,17:17.2
0,3,17:17.2
1,3,17:17.2
2,3,17:17.2
3,3,17:17.2
4,3,17:17.2
5,3,17:18.2
6,3,17:18.2
7,3,17:18.2
8,3,17:17.2
9,3,17:17.2
10,3,17:18.2
11,3,17:18.2
-13,4,17:18.2
-12,4,17:18.2
-11,4,17:17.2
-10,4,17:17.2
-8,4,17:18.2
-6,4,17:18.2
-5,4,17:18.2
-4,4,17:18.2
-3,4,17:17.2
-2,4,17:17.2
-1,4,17:18.2
0,4,17:18.2
1,4,17:18.2
2,4,17:17.2
3,4,17:17.2
4,4,17:18.2
5,4,17:18.2
6,4,17:18.2
7,4,17:18.2
12,4,17:18.2
-14,5,17:18.2
-13,5,17:17.2
-12,5,17:17.2
-10,5,17:17.2
-6,5,17:18.2
-5,5,17:18.2
-4,5,17:18.2
-3,5,17:17.2
-2,5,17:18.2
-1,5,17:18.2
0,5,17:18.2
1,5,17:18.2
2,5,17:18.2
3,5,17:18.2
4,5,17:18.2
5,5,17:18.2
6,5,17:18.2
8,5,17:18.2
9,5,17:18.2
10,5,17:18.2
11,5,17:18.2
12,5,17:18.2
13,5,17:18.2
-13,6,17:18.2
-11,6,17:17.2
-5,6,17:18.2
-4,6,17:18.2
-3,6,17:18.2
-2,6,17:18.2
-1,6,17:17.2
0,6,17:18.2
1,6,17:18.2
2,6,17:18.2
3,6,17:18.2
4,6,17:18.2
5,6,17:18.2
6,6,17:18.2
7,6,17:18.2
8,6,17:18.2
9,6,17:18.2
10,6,17:18.2
11,6,17:18.2
12,6,17:18.2
-7,7,17:18.2
-5,7,17:18.2
-4,7,17:18.2
-3,7,17:18.2
-2,7,17:18.2
-1,7,17:17.2
0,7,17:17.2
1,7,17:18.2
2,7,17:18.2
3,7,17:18.2
4,7,17:18.2
5,7,17:18.2
6,7,17:18.2
7,7,17:18.2
8,7,17:18.2
9,7,17:18.2
10,7,17:18.2
11,7,17:18.2
-8,8,17:18.2
-7,8,17:17.2
-6,8,17:18.2
-4,8,17:17.2
-3,8,17:18.2
-2,8,17:18.2
-1,8,17:17.2
0,8,17:18.2
1,8,17:17.2
2,8,17:18.2
3,8,17:18.2
4,8,17:18.2
5,8,17:18.2
6,8,17:18.2
7,8,17:18.2
8,8,17:18.2
9,8,17:18.2
10,8,17:18.2
11,8,17:18.2
-7,9,17:18.2
-5,9,17:17.2
-1,9,17:17.2
0,9,17:18.2
1,9,17:18.2
2,9,17:17.2
3,9,17:18.2
4,9,17:18.2
5,9,17:18.2
6,9,17:18.2
7,9,17:18.2
8,9,17:18.2
9,9,17:18.2
10,9,17:18.2
-6,10,17:18.2
-5,10,17:18.2
-4,10,17:18.2
-1,10,17:17.2
0,10,17:18.2
1,10,17:18.2
2,10,17:17.2
3,10,17:18.2
4,10,17:18.2
5,10,17:18.2
6,10,17:18.2
7,10,17:18.2
8,10,17:18.2
9,10,17:18.2
-6,11,17:18.2
-5,11,17:18.2
-4,11,17:18.2
0,11,17:18.2
2,11,17:17.2
3,11,17:18.2
4,11,17:18.2
5,11,17:17.2
6,11,17:18.2
7,11,17:18.2
8,11,17:18.2
9,11,17:18.2
10,11,17:18.2
-7,12,17:18.2
-6,12,17:18.2
-5,12,17:18.2
-4,12,17:18.2
-3,12,17:18.2
5,12,17:17.2
6,12,17:18.2
7,12,17:18.2
9,12,17:18.2
-7,13,17:18.2
-6,13,17:18.2
-5,13,17:18.2
-4,13,17:18.2
-3,13,17:18.2
5,13,17:18.2
-7,14,17:18.2
-6,14,17:18.2
-5,14,17:18.2
-4,14,17:18.2
-3,14,17:18.2
-2,14,17:18.2
4,14,17:18.2
5,14,17:18.2
6,14,17:18.2
-6,15,17:18.2
-5,15,17:18.2
-4,15,17:18.2
-3,15,17:18.2
5,15,17:18.2
1,-14,18:18.2
2,-14,18:18.2
3,-14,18:18.2
-2,-13,18:17.2
-1,-13,18:17.2
0,-13,18:18.2
1,-13,18:18.2
2,-13,18:18.2
3,-13,18:18.2
4,-13,18:18.2
6,-13,18:18.2
-2,-12,18:17.2
-1,-12,18:17.2
0,-12,18:18.2
1,-12,18:18.2
2,-12,18:18.2
3,-12,18:18.2
4,-12,18:18.2
5,-12,18:18.2
6,-12,18:18.2
7,-12,18:18.2
-3,-11,18:18.2
-2,-11,18:18.2
-1,-11,18:18.2
0,-11,18:18.2
1,-11,18:18.2
2,-11,18:18.2
3,-11,18:18.2
4,-11,18:18.2
6,-11,18:18.2
10,-11,18:18.2
-4,-10,18:18.2
-3,-10,18:18.2
-2,-10,18:18.2
-1,-10,18:18.2
0,-10,18:18.2
1,-10,18:18.2
2,-10,18:18.2
3,-10,18:18.2
7,-10,18:18.2
8,-10,18:18.2
9,-10,18:18.2
10,-10,18:18.2
11,-10,18:18.2
-5,-9,18:18.2
-4,-9,18:18.2
-3,-9,18:18.2
-2,-9,18:18.2
-1,-9,18:18.2
0,-9,18:18.2
1,-9,18:18.2
6,-9,18:18.2
7,-9,18:18.2
8,-9,18:18.2
9,-9,18:18.2
10,-9,18:18.2
11,-9,18:18.2
12,-9,18:18.2
13,-9,18:18.2
-7,-8,18:18.2
-6,-8,18:18.2
-5,-8,18:17.2
-4,-8,18:18.2
-3,-8,18:17.2
-2,-8,18:18.2
-1,-8,18:18.2
0,-8,18:18.2
1,-8,18:18.2
2,-8,18:18.2
6,-8,18:18.2
7,-8,18:18.2
8,-8,18:18.2
9,-8,18:18.2
10,-8,18:18.2
11,-8,18:18.2
12,-8,18:18.2
13,-8,18:18.2
14,-8,18:18.2
-13,-7,18:18.2
-12,-7,18:18.2
-11,-7,18:18.2
-8,-7,18:18.2
-7,-7,18:18.2
-6,-7,18:17.2
-5,-7,18:18.2
-4,-7,18:17.2
-3,-7,18:17.2
-2,-7,18:18.2
-1,-7,18:18.2
0,-7,18:18.2
1,-7,18:18.2
2,-7,18:18.2
6,-7,18:18.2
7,-7,18:18.2
8,-7,18:17.2
9,-7,18:18.2
10,-7,18:18.2
11,-7,18:18.2
12,-7,18:18.2
13,-7,18:18.2
14,-7,18:18.2
15,-7,18:18.2
16,-7,18:18.2
-14,-6,18:18.2
-13,-6,18:18.2
-12,-6,18:18.2
-11,-6,18:18.2
-10,-6,18:18.2
-8,-6,18:18.2
-7,-6,18:18.2
-6,-6,18:18.2
-5,-6,18:17.2
-4,-6,18:18.2
-3,-6,18:18.2
-2,-6,18:18.2
-1,-6,18:18.2
0,-6,18:18.2
1,-6,18:17.2
2,-6,18:18.2
5,-6,18:17.2
7,-6,18:17.2
8,-6,18:18.2
9,-6,18:18.2
10,-6,18:18.2
11,-6,18:18.2
12,-6,18:18.2
13,-6,18:18.2
14,-6,18:18.2
15,-6,18:18.2
16,-6,18:18.2
17,-6,18:18.2
-14,-5,18:18.2
-13,-5,18:18.2
-12,-5,18:18.2
-11,-5,18:18.2
-10,-5,18:18.2
-8,-5,18:18.2
-7,-5,18:18.2
-6,-5,18:17.2
-5,-5,18:18.2
-4,-5,18:18.2
-2,-5,18:17.2
-1,-5,18:17.2
0,-5,18:17.2
1,-5,18:17.2
4,-5,18:17.2
5,-5,18:18.2
8,-5,18:18.2
9,-5,18:18.2
10,-5,18:18.2
11,-5,18:18.2
12,-5,18:18.2
13,-5,18:18.2
14,-5,18:18.2
15,-5,18:18.2
16,-5,18:18.2
17,-5,18:18.2
-14,-4,18:18.2
-13,-4,18:18.2
-12,-4,18:18.2
-11,-4,18:18.2
-10,-4,18:18.2
-7,-4,18:18.2
-6,-4,18:18.2
-5,-4,18:17.2
-4,-4,18:18.2
-3,-4,18:18.2
-1,-4,18:17.2
0,-4,18:17.2
1,-4,18:17.2
2,-4,18:18.2
4,-4,18:18.2
5,-4,18:18.2
6,-4,18:18.2
7,-4,18:18.2
8,-4,18:17.2
9,-4,18:18.2
10,-4,18:18.2
11,-4,18:18.2
13,-4,18:18.2
14,-4,18:18.2
15,-4,18:18.2
16,-4,18:18.2
17,-4,18:18.2
-13,-3,18:18.2
-12,-3,18:18.2
-11,-3,18:18.2
-10,-3,18:18.2
-9,-3,18:18.2
-8,-3,18:18.2
-7,-3,18:17.2
-6,-3,18:18.2
-5,-3,18:18.2
-4,-3,18:18.2
-3,-3,18:17.2
-2,-3,18:18.2
-1,-3,18:17.2
0,-3,18:17.2
1,-3,18:17.2
2,-3,18:17.2
4,-3,18:18.2
5,-3,18:18.2
6,-3,18:18.2
7,-3,18:17.2
8,-3,18:18.2
9,-3,18:18.2
10,-3,18:18.2
11,-3,18:18.2
14,-3,18:18.2
15,-3,18:18.2
16,-3,18:18.2
-13,-2,18:18.2
-12,-2,18:18.2
-11,-2,18:18.2
-10,-2,18:18.2
-9,-2,18:18.2
-8,-2,18:18.2
-7,-2,18:18.2
-6,-2,18:17.2
-5,-2,18:18.2
-4,-2,18:18.2
-3,-2,18:18.2
-2,-2,18:17.2
-1,-2,18:17.2
0,-2,18:17.2
1,-2,18:17.2
2,-2,18:17.2
3,-2,18:18.2
4,-2,18:18.2
5,-2,18:18.2
6,-2,18:18.2
7,-2,18:18.2
8,-2,18:18.2
9,-2,18:18.2
10,-2,18:18.2
11,-2,18:18.2
12,-2,18:18.2
-13,-1,18:18.2
-12,-1,18:18.2
-11,-1,18:18.2
-10,-1,18:18.2
-9,-1,18:17.2
-8,-1,18:17.2
-7,-1,18:18.2
-6,-1,18:18.2
-5,-1,18:17.2
-4,-1,18:17.2
-3,-1,18:17.2
-2,-1,18:17.2
-1,-1,18:17.2
0,-1,18:17.2
1,-1,18:17.2
2,-1,18:17.2
3,-1,18:17.2
4,-1,18:17.2
5,-1,18:17.2
6,-1,18:18.2
7,-1,18:17.2
8,-1,18:17.2
9,-1,18:18.2
10,-1,18:18.2
11,-1,18:18.2
12,-1,18:18.2
13,-1,18:18.2
-13,0,18:18.2
-12,0,18:18.2
-11,0,18:18.2
-10,0,18:18.2
-9,0,18:18.2
-8,0,18:18.2
-7,0,18:18.2
-6,0,18:18.2
-5,0,18:18.2
-4,0,18:18.2
-3,0,18:17.2
-2,0,18:17.2
-1,0,18:17.2
0,0,18:17.2
1,0,18:17.2
2,0,18:17.2
3,0,18:17.2
4,0,18:17.2
5,0,18:17.2
6,0,18:18.2
7,0,18:18.2
8,0,18:18.2
9,0,18:18.2
10,0,18:18.2
11,0,18:18.2
12,0,18:18.2
13,0,18:18.2
-12,1,18:18.2
-11,1,18:18.2
-10,1,18:18.2
-9,1,18:18.2
-8,1,18:18.2
-7,1,18:18.2
-6,1,18:18.2
-5,1,18:18.2
-4,1,18:17.2
-3,1,18:17.2
-2,1,18:17.2
-1,1,18:17.2
0,1,18:17.2
1,1,18:17.2
2,1,18:17.2
3,1,18:17.2
4,1,18:17.2
5,1,18:17.2
6,1,18:17.2
7,1,18:17.2
8,1,18:18.2
9,1,18:17.2
10,1,18:17.2
11,1,18:18.2
12,1,18:17.2
13,1,18:17.2
14,1,18:18.2
-12,2,18:18.2
-11,2,18:18.2
-10,2,18:18.2
-9,2,18:18.2
-8,2,18:18.2
-7,2,18:18.2
-6,2,18:17.2
-5,2,18:17.2
-4,2,18:18.2
-3,2,18:17.2
-2,2,18:17.2
-1,2,18:17.2
0,2,18:17.2
1,2,18:17.2
2,2,18:17.2
3,2,18:17.2
4,2,18:18.2
5,2,18:18.2
6,2,18:17.2
7,2,18:17.2
8,2,18:17.2
9,2,18:18.2
10,2,18:18.2
11,2,18:18.2
12,2,18:18.2
13,2,18:18.2
-14,3,18:18.2
-13,3,18:18.2
-12,3,18:18.2
-11,3,18:18.2
-8,3,18:17.2
-7,3,18:17.2
-6,3,18:17.2
-5,3,18:18.2
-4,3,18:17.2
-3,3,18:18.2
-2,3,18:17.2
-1,3,18:17.2
0,3,18:17.2
1,3,18:17.2
3,3,18:17.2
4,3,18:17.2
5,3,18:18.2
6,3,18:18.2
7,3,18:17.2
11,3,18:18.2
-15,4,18:18.2
-14,4,18:18.2
-13,4,18:18.2
-12,4,18:18.2
-11,4,18:18.2
-6,4,18:18.2
-5,4,18:18.2
-4,4,18:18.2
-3,4,18:17.2
-2,4,18:17.2
-1,4,18:17.2
0,4,18:18.2
1,4,18:17.2
2,4,18:18.2
3,4,18:18.2
4,4,18:17.2
5,4,18:17.2
6,4,18:18.2
10,4,18:17.2
11,4,18:17.2
12,4,18:18.2
-15,5,18:18.2
-14,5,18:18.2
-13,5,18:17.2
-12,5,18:17.2
-11,5,18:18.2
-6,5,18:18.2
-5,5,18:18.2
-4,5,18:17.2
-3,5,18:18.2
-2,5,18:18.2
-1,5,18:17.2
0,5,18:18.2
1,5,18:17.2
2,5,18:18.2
3,5,18:17.2
4,5,18:17.2
5,5,18:17.2
6,5,18:17.2
8,5,18:18.2
9,5,18:18.2
10,5,18:18.2
11,5,18:18.2
-15,6,18:18.2
-14,6,18:18.2
-13,6,18:18.2
-12,6,18:17.2
-11,6,18:18.2
-8,6,18:18.2
-7,6,18:18.2
-6,6,18:18.2
-5,6,18:17.2
-4,6,18:18.2
-3,6,18:18.2
-2,6,18:18.2
-1,6,18:18.2
0,6,18:18.2
1,6,18:18.2
2,6,18:18.2
3,6,18:17.2
4,6,18:18.2
5,6,18:18.2
6,6,18:18.2
7,6,18:18.2
8,6,18:18.2
9,6,18:18.2
10,6,18:18.2
11,6,18:18.2
-14,7,18:18.2
-13,7,18:17.2
-12,7,18:18.2
-9,7,18:18.2
-8,7,18:18.2
-7,7,18:18.2
-6,7,18:18.2
-5,7,18:18.2
-4,7,18:18.2
-3,7,18:18.2
-2,7,18:18.2
-1,7,18:18.2
0,7,18:18.2
3,7,18:18.2
4,7,18:18.2
5,7,18:18.2
6,7,18:18.2
7,7,18:18.2
8,7,18:18.2
9,7,18:18.2
10,7,18:18.2
11,7,18:18.2
-13,8,18:18.2
-9,8,18:18.2
-8,8,18:18.2
-7,8,18:18.2
-6,8,18:18.2
-5,8,18:18.2
-4,8,18:18.2
-3,8,18:18.2
-2,8,18:18.2
-1,8,18:17.2
3,8,18:18.2
4,8,18:18.2
5,8,18:18.2
6,8,18:18.2
7,8,18:18.2
8,8,18:18.2
9,8,18:18.2
10,8,18:18.2
11,8,18:18.2
-9,9,18:18.2
-8,9,18:18.2
-7,9,18:18.2
-6,9,18:18.2
-5,9,18:18.2
-1,9,18:17.2
1,9,18:17.2
2,9,18:18.2
3,9,18:18.2
4,9,18:18.2
5,9,18:18.2
6,9,18:18.2
7,9,18:18.2
8,9,18:18.2
9,9,18:18.2
10,9,18:18.2
-8,10,18:18.2
-7,10,18:18.2
-6,10,18:18.2
-5,10,18:17.2
-1,10,18:17.2
1,10,18:17.2
3,10,18:18.2
5,10,18:18.2
6,10,18:18.2
7,10,18:18.2
-6,11,18:17.2
-1,11,18:17.2
1,11,18:17.2
6,11,18:18.2
-5,12,18:18.2
-1,12,18:17.2
2,12,18:17.2
-6,13,18:18.2
-5,13,18:18.2
-4,13,18:18.2
3,13,18:17.2
6,13,18:17.2
-5,14,18:18.2
5,14,18:18.2
6,14,18:17.2
7,14,18:18.2
6,15,18:18.2
-2,-16,19:18.2
-1,-16,19:18.2
-3,-15,19:18.2
-2,-15,19:17.2
-1,-15,19:17.2
0,-15,19:18.2
-2,-14,19:17.2
-1,-14,19:17.2
2,-13,19:18.2
1,-12,19:18.2
2,-12,19:18.2
3,-12,19:18.2
-3,-11,19:18.2
-2,-11,19:18.2
-1,-11,19:18.2
2,-11,19:18.2
-6,-10,19:18.2
-5,-10,19:18.2
-4,-10,19:18.2
-3,-10,19:18.2
-2,-10,19:18.2
-1,-10,19:18.2
0,-10,19:18.2
9,-10,19:18.2
10,-10,19:18.2
11,-10,19:18.2
-8,-9,19:17.2
-7,-9,19:18.2
-6,-9,19:18.2
-5,-9,19:18.2
-4,-9,19:18.2
-3,-9,19:18.2
-2,-9,19:18.2
-1,-9,19:18.2
0,-9,19:18.2
8,-9,19:18.2
9,-9,19:18.2
10,-9,19:18.2
11,-9,19:18.2
12,-9,19:18.2
-7,-8,19:17.2
-6,-8,19:18.2
-5,-8,19:18.2
-4,-8,19:18.2
-3,-8,19:18.2
-2,-8,19:18.2
-1,-8,19:17.2
0,-8,19:18.2
1,-8,19:17.2
6,-8,19:17.2
7,-8,19:18.2
8,-8,19:18.2
9,-8,19:18.2
10,-8,19:17.2
11,-8,19:18.2
12,-8,19:18.2
-8,-7,19:18.2
-7,-7,19:18.2
-6,-7,19:18.2
-5,-7,19:18.2
-4,-7,19:18.2
-3,-7,19:18.2
-2,-7,19:17.2
-1,-7,19:17.2
0,-7,19:17.2
1,-7,19:17.2
5,-7,19:17.2
8,-7,19:18.2
9,-7,19:17.2
10,-7,19:18.2
11,-7,19:18.2
12,-7,19:18.2
13,-7,19:18.2
14,-7,19:18.2
15,-7,19:18.2
16,-7,19:18.2
-12,-6,19:18.2
-8,-6,19:17.2
-7,-6,19:18.2
-6,-6,19:18.2
-5,-6,19:18.2
-4,-6,19:18.2
-3,-6,19:18.2
-2,-6,19:17.2
-1,-6,19:17.2
0,-6,19:17.2
1,-6,19:18.2
2,-6,19:18.2
9,-6,19:18.2
10,-6,19:18.2
11,-6,19:18.2
12,-6,19:18.2
13,-6,19:18.2
14,-6,19:18.2
15,-6,19:18.2
16,-6,19:18.2
17,-6,19:18.2
-13,-5,19:18.2
-12,-5,19:18.2
-11,-5,19:18.2
-8,-5,19:18.2
-7,-5,19:17.2
-6,-5,19:18.2
-5,-5,19:18.2
-4,-5,19:18.2
-3,-5,19:18.2
-2,-5,19:18.2
-1,-5,19:18.2
0,-5,19:17.2
1,-5,19:17.2
2,-5,19:18.2
3,-5,19:17.2
9,-5,19:18.2
10,-5,19:17.2
11,-5,19:18.2
13,-5,19:18.2
14,-5,19:18.2
15,-5,19:18.2
16,-5,19:18.2
17,-5,19:18.2
-12,-4,19:18.2
-7,-4,19:18.2
-6,-4,19:18.2
-5,-4,19:18.2
-4,-4,19:18.2
-3,-4,19:17.2
-2,-4,19:18.2
-1,-4,19:18.2
0,-4,19:17.2
1,-4,19:17.2
2,-4,19:18.2
3,-4,19:17.2
9,-4,19:17.2
10,-4,19:18.2
13,-4,19:18.2
14,-4,19:18.2
15,-4,19:18.2
16,-4,19:18.2
17,-4,19:18.2
-12,-3,19:18.2
-11,-3,19:18.2
-10,-3,19:18.2
-9,-3,19:17.2
-8,-3,19:17.2
-7,-3,19:18.2
-6,-3,19:18.2
-5,-3,19:18.2
-4,-3,19:18.2
-3,-3,19:18.2
-2,-3,19:17.2
-1,-3,19:17.2
0,-3,19:17.2
1,-3,19:17.2
2,-3,19:18.2
3,-3,19:18.2
4,-3,19:18.2
5,-3,19:18.2
6,-3,19:18.2
7,-3,19:18.2
8,-3,19:18.2
9,-3,19:18.2
10,-3,19:18.2
14,-3,19:18.2
15,-3,19:18.2
16,-3,19:18.2
-13,-2,19:18.2
-12,-2,19:18.2
-11,-2,19:18.2
-10,-2,19:18.2
-9,-2,19:18.2
-7,-2,19:18.2
-6,-2,19:18.2
-5,-2,19:18.2
-4,-2,19:17.2
-3,-2,19:17.2
-2,-2,19:17.2
-1,-2,19:17.2
0,-2,19:17.2
1,-2,19:17.2
2,-2,19:17.2
3,-2,19:18.2
4,-2,19:17.2
5,-2,19:17.2
6,-2,19:17.2
7,-2,19:17.2
8,-2,19:18.2
9,-2,19:18.2
10,-2,19:18.2
11,-2,19:18.2
12,-2,19:18.2
-13,-1,19:18.2
-12,-1,19:18.2
-11,-1,19:17.2
-10,-1,19:17.2
-9,-1,19:18.2
-8,-1,19:18.2
-7,-1,19:18.2
-6,-1,19:18.2
-5,-1,19:18.2
-4,-1,19:18.2
-3,-1,19:17.2
-2,-1,19:17.2
-1,-1,19:17.2
0,-1,19:17.2
1,-1,19:17.2
2,-1,19:17.2
3,-1,19:17.2
4,-1,19:18.2
5,-1,19:18.2
6,-1,19:17.2
7,-1,19:17.2
8,-1,19:18.2
9,-1,19:18.2
10,-1,19:18.2
11,-1,19:18.2
12,-1,19:18.2
13,-1,19:18.2
14,-1,19:18.2
-13,0,19:18.2
-12,0,19:18.2
-11,0,19:18.2
-10,0,19:18.2
-9,0,19:18.2
-8,0,19:18.2
-7,0,19:18.2
-6,0,19:18.2
-5,0,19:18.2
-4,0,19:18.2
-3,0,19:17.2
-2,0,19:17.2
-1,0,19:17.2
0,0,19:17.2
1,0,19:17.2
2,0,19:17.2
3,0,19:17.2
4,0,19:18.2
5,0,19:18.2
6,0,19:17.2
7,0,19:17.2
8,0,19:18.2
9,0,19:18.2
10,0,19:18.2
11,0,19:18.2
12,0,19:18.2
13,0,19:18.2
14,0,19:18.2
15,0,19:18.2
-12,1,19:18.2
-11,1,19:18.2
-10,1,19:18.2
-9,1,19:18.2
-8,1,19:18.2
-7,1,19:18.2
-6,1,19:18.2
-5,1,19:18.2
-4,1,19:17.2
-3,1,19:17.2
-2,1,19:17.2
-1,1,19:17.2
0,1,19:17.2
1,1,19:17.2
2,1,19:17.2
3,1,19:17.2
4,1,19:18.2
5,1,19:18.2
6,1,19:18.2
7,1,19:18.2
8,1,19:17.2
9,1,19:17.2
10,1,19:17.2
11,1,19:17.2
12,1,19:17.2
13,1,19:18.2
14,1,19:18.2
15,1,19:18.2
-9,2,19:18.2
-8,2,19:17.2
-7,2,19:17.2
-6,2,19:18.2
-5,2,19:17.2
-4,2,19:17.2
-3,2,19:18.2
-2,2,19:17.2
-1,2,19:17.2
0,2,19:17.2
1,2,19:17.2
2,2,19:17.2
3,2,19:17.2
4,2,19:18.2
5,2,19:18.2
6,2,19:17.2
7,2,19:17.2
8,2,19:18.2
9,2,19:17.2
10,2,19:17.2
11,2,19:18.2
12,2,19:18.2
13,2,19:18.2
14,2,19:18.2
15,2,19:18.2
-14,3,19:18.2
-13,3,19:18.2
-12,3,19:18.2
-8,3,19:18.2
-7,3,19:18.2
-6,3,19:18.2
-5,3,19:18.2
-4,3,19:18.2
-3,3,19:18.2
-2,3,19:17.2
-1,3,19:17.2
0,3,19:17.2
1,3,19:17.2
3,3,19:18.2
4,3,19:17.2
5,3,19:18.2
6,3,19:18.2
7,3,19:18.2
8,3,19:17.2
9,3,19:17.2
10,3,19:18.2
11,3,19:18.2
12,3,19:18.2
13,3,19:18.2
14,3,19:18.2
-15,4,19:18.2
-14,4,19:18.2
-13,4,19:18.2
-12,4,19:18.2
-11,4,19:18.2
-10,4,19:17.2
-9,4,19:17.2
-6,4,19:18.2
-5,4,19:18.2
-4,4,19:18.2
-3,4,19:18.2
-2,4,19:17.2
-1,4,19:17.2
0,4,19:18.2
1,4,19:17.2
2,4,19:17.2
3,4,19:18.2
4,4,19:17.2
5,4,19:17.2
6,4,19:17.2
7,4,19:18.2
8,4,19:18.2
9,4,19:18.2
10,4,19:18.2
11,4,19:18.2
12,4,19:18.2
13,4,19:18.2
-15,5,19:18.2
-14,5,19:18.2
-13,5,19:18.2
-12,5,19:18.2
-11,5,19:18.2
-5,5,19:18.2
-4,5,19:17.2
-3,5,19:18.2
-2,5,19:17.2
-1,5,19:17.2
0,5,19:18.2
1,5,19:17.2
2,5,19:17.2
3,5,19:18.2
4,5,19:18.2
5,5,19:17.2
6,5,19:18.2
7,5,19:17.2
9,5,19:18.2
10,5,19:18.2
11,5,19:18.2
12,5,19:18.2
13,5,19:18.2
-16,6,19:18.2
-15,6,19:17.2
-14,6,19:17.2
-13,6,19:18.2
-12,6,19:18.2
-11,6,19:18.2
-8,6,19:18.2
-7,6,19:18.2
-6,6,19:18.2
-5,6,19:17.2
-4,6,19:18.2
-3,6,19:18.2
-2,6,19:18.2
-1,6,19:18.2
0,6,19:18.2
1,6,19:17.2
2,6,19:18.2
3,6,19:18.2
4,6,19:18.2
5,6,19:18.2
6,6,19:17.2
7,6,19:18.2
8,6,19:17.2
9,6,19:18.2
10,6,19:18.2
11,6,19:18.2
12,6,19:18.2
-15,7,19:18.2
-14,7,19:18.2
-13,7,19:18.2
-12,7,19:18.2
-11,7,19:18.2
-9,7,19:18.2
-8,7,19:18.2
-7,7,19:18.2
-6,7,19:18.2
-5,7,19:17.2
-4,7,19:18.2
-3,7,19:18.2
-2,7,19:18.2
-1,7,19:18.2
0,7,19:18.2
1,7,19:17.2
3,7,19:18.2
4,7,19:17.2
5,7,19:18.2
6,7,19:18.2
8,7,19:18.2
9,7,19:18.2
10,7,19:18.2
-15,8,19:18.2
-14,8,19:18.2
-13,8,19:18.2
-12,8,19:18.2
-11,8,19:18.2
-9,8,19:18.2
-8,8,19:18.2
-7,8,19:18.2
-6,8,19:17.2
-5,8,19:18.2
1,8,19:17.2
3,8,19:18.2
4,8,19:17.2
5,8,19:18.2
6,8,19:18.2
7,8,19:18.2
9,8,19:18.2
-14,9,19:18.2
-13,9,19:18.2
-12,9,19:18.2
-9,9,19:18.2
-8,9,19:18.2
-7,9,19:18.2
-6,9,19:18.2
-5,9,19:18.2
4,9,19:18.2
6,9,19:18.2
-8,10,19:18.2
-7,10,19:18.2
-6,10,19:18.2
-1,11,19:17.2
-7,12,19:18.2
-6,12,19:17.2
-1,12,19:17.2
1,12,19:17.2
5,12,19:18.2
6,12,19:18.2
7,12,19:18.2
-8,13,19:18.2
-7,13,19:17.2
-6,13,19:18.2
-2,13,19:17.2
1,13,19:17.2
4,13,19:18.2
5,13,19:18.2
6,13,19:18.2
7,13,19:18.2
8,13,19:18.2
-7,14,19:18.2
-2,14,19:17.2
3,14,19:17.2
4,14,19:18.2
5,14,19:18.2
6,14,19:18.2
7,14,19:18.2
8,14,19:18.2
2,15,19:18.2
3,15,19:17.2
4,15,19:18.2
5,15,19:18.2
6,15,19:18.2
7,15,19:18.2
8,15,19:18.2
3,16,19:18.2
5,16,19:18.2
6,16,19:18.2
7,16,19:18.2
-3,-17,20:18.2
-2,-17,20:18.2
-1,-17,20:18.2
0,-17,20:18.2
-4,-16,20:18.2
-3,-16,20:18.2
-2,-16,20:18.2
-1,-16,20:18.2
0,-16,20:18.2
1,-16,20:18.2
-4,-15,20:18.2
-3,-15,20:18.2
-2,-15,20:18.2
-1,-15,20:18.2
0,-15,20:18.2
1,-15,20:18.2
-4,-14,20:18.2
-3,-14,20:18.2
-2,-14,20:18.2
-1,-14,20:18.2
0,-14,20:18.2
1,-14,20:18.2
-3,-13,20:18.2
-2,-13,20:18.2
-1,-13,20:18.2
0,-13,20:18.2
-9,-11,20:18.2
1,-11,20:18.2
12,-11,20:18.2
-10,-10,20:18.2
-9,-10,20:17.2
-8,-10,20:18.2
-6,-10,20:18.2
-5,-10,20:18.2
-4,-10,20:18.2
-3,-10,20:18.2
-2,-10,20:18.2
-1,-10,20:17.2
0,-10,20:18.2
1,-10,20:17.2
2,-10,20:18.2
8,-10,20:17.2
11,-10,20:18.2
12,-10,20:17.2
13,-10,20:18.2
-9,-9,20:18.2
-7,-9,20:18.2
-6,-9,20:18.2
-5,-9,20:18.2
-4,-9,20:18.2
-3,-9,20:17.2
-2,-9,20:18.2
-1,-9,20:17.2
0,-9,20:18.2
1,-9,20:17.2
7,-9,20:17.2
10,-9,20:18.2
11,-9,20:17.2
12,-9,20:18.2
-9,-8,20:18.2
-7,-8,20:18.2
-6,-8,20:18.2
-5,-8,20:18.2
-4,-8,20:18.2
-3,-8,20:18.2
-2,-8,20:17.2
-1,-8,20:18.2
0,-8,20:18.2
1,-8,20:18.2
2,-8,20:18.2
9,-8,20:18.2
10,-8,20:18.2
11,-8,20:18.2
-10,-7,20:18.2
-9,-7,20:17.2
-8,-7,20:18.2
-7,-7,20:18.2
-6,-7,20:18.2
-5,-7,20:18.2
-4,-7,20:18.2
-3,-7,20:18.2
-2,-7,20:18.2
-1,-7,20:18.2
0,-7,20:18.2
1,-7,20:17.2
2,-7,20:18.2
4,-7,20:17.2
9,-7,20:18.2
10,-7,20:18.2
11,-7,20:18.2
-9,-6,20:18.2
-7,-6,20:18.2
-6,-6,20:18.2
-5,-6,20:18.2
-4,-6,20:17.2
-3,-6,20:18.2
-2,-6,20:18.2
-1,-6,20:18.2
0,-6,20:18.2
1,-6,20:17.2
2,-6,20:18.2
4,-6,20:17.2
8,-6,20:18.2
9,-6,20:18.2
10,-6,20:18.2
11,-6,20:18.2
12,-6,20:18.2
15,-6,20:18.2
-11,-5,20:18.2
-6,-5,20:18.2
-4,-5,20:17.2
-3,-5,20:18.2
-2,-5,20:18.2
-1,-5,20:17.2
0,-5,20:18.2
1,-5,20:18.2
2,-5,20:18.2
3,-5,20:18.2
8,-5,20:18.2
9,-5,20:18.2
10,-5,20:18.2
11,-5,20:18.2
12,-5,20:18.2
14,-5,20:18.2
15,-5,20:18.2
16,-5,20:18.2
-12,-4,20:18.2
-11,-4,20:17.2
-10,-4,20:17.2
-6,-4,20:17.2
-5,-4,20:18.2
-4,-4,20:17.2
-3,-4,20:17.2
-2,-4,20:18.2
-1,-4,20:17.2
0,-4,20:18.2
1,-4,20:18.2
2,-4,20:17.2
3,-4,20:17.2
6,-4,20:18.2
7,-4,20:18.2
8,-4,20:18.2
9,-4,20:18.2
10,-4,20:18.2
11,-4,20:18.2
12,-4,20:18.2
15,-4,20:18.2
-12,-3,20:18.2
-11,-3,20:18.2
-10,-3,20:18.2
-6,-3,20:18.2
-5,-3,20:17.2
-4,-3,20:18.2
-3,-3,20:17.2
-2,-3,20:17.2
-1,-3,20:17.2
0,-3,20:17.2
1,-3,20:17.2
2,-3,20:17.2
3,-3,20:17.2
5,-3,20:18.2
6,-3,20:17.2
7,-3,20:17.2
8,-3,20:18.2
9,-3,20:18.2
10,-3,20:18.2
11,-3,20:18.2
-13,-2,20:18.2
-12,-2,20:18.2
-11,-2,20:18.2
-10,-2,20:18.2
-9,-2,20:18.2
-7,-2,20:18.2
-6,-2,20:18.2
-5,-2,20:18.2
-4,-2,20:18.2
-3,-2,20:18.2
-2,-2,20:17.2
-1,-2,20:17.2
0,-2,20:17.2
1,-2,20:17.2
2,-2,20:17.2
4,-2,20:17.2
5,-2,20:17.2
6,-2,20:17.2
7,-2,20:18.2
8,-2,20:18.2
9,-2,20:17.2
10,-2,20:17.2
-13,-1,20:18.2
-12,-1,20:18.2
-11,-1,20:18.2
-10,-1,20:18.2
-9,-1,20:18.2
-7,-1,20:18.2
-6,-1,20:18.2
-5,-1,20:18.2
-4,-1,20:18.2
-3,-1,20:17.2
-2,-1,20:17.2
-1,-1,20:17.2
0,-1,20:17.2
1,-1,20:17.2
2,-1,20:17.2
3,-1,20:17.2
4,-1,20:17.2
5,-1,20:18.2
6,-1,20:18.2
7,-1,20:18.2
8,-1,20:17.2
9,-1,20:18.2
10,-1,20:18.2
11,-1,20:18.2
12,-1,20:18.2
13,-1,20:18.2
14,-1,20:18.2
-13,0,20:18.2
-12,0,20:18.2
-11,0,20:18.2
-10,0,20:18.2
-9,0,20:18.2
-7,0,20:18.2
-6,0,20:18.2
-5,0,20:18.2
-4,0,20:18.2
-3,0,20:17.2
-2,0,20:17.2
-1,0,20:17.2
0,0,20:17.2
1,0,20:17.2
2,0,20:17.2
3,0,20:17.2
5,0,20:18.2
6,0,20:18.2
7,0,20:18.2
8,0,20:17.2
9,0,20:17.2
10,0,20:18.2
11,0,20:18.2
12,0,20:18.2
13,0,20:18.2
14,0,20:18.2
15,0,20:18.2
-12,1,20:18.2
-11,1,20:18.2
-10,1,20:18.2
-8,1,20:18.2
-7,1,20:18.2
-6,1,20:18.2
-5,1,20:18.2
-4,1,20:18.2
-3,1,20:17.2
-2,1,20:17.2
-1,1,20:17.2
0,1,20:17.2
1,1,20:17.2
2,1,20:17.2
3,1,20:17.2
5,1,20:18.2
6,1,20:18.2
7,1,20:18.2
8,1,20:18.2
9,1,20:18.2
10,1,20:18.2
11,1,20:17.2
12,1,20:18.2
13,1,20:18.2
14,1,20:18.2
15,1,20:18.2
-10,2,20:18.2
-7,2,20:17.2
-6,2,20:17.2
-5,2,20:18.2
-4,2,20:18.2
-3,2,20:18.2
-2,2,20:17.2
-1,2,20:17.2
0,2,20:17.2
1,2,20:17.2
2,2,20:17.2
3,2,20:17.2
4,2,20:18.2
5,2,20:18.2
6,2,20:18.2
7,2,20:18.2
8,2,20:18.2
9,2,20:18.2
10,2,20:18.2
11,2,20:18.2
12,2,20:17.2
13,2,20:18.2
14,2,20:18.2
15,2,20:18.2
-11,3,20:18.2
-10,3,20:17.2
-9,3,20:17.2
-8,3,20:17.2
-7,3,20:17.2
-6,3,20:17.2
-5,3,20:18.2
-4,3,20:18.2
-3,3,20:17.2
-2,3,20:18.2
-1,3,20:17.2
0,3,20:17.2
1,3,20:17.2
3,3,20:18.2
4,3,20:17.2
5,3,20:17.2
6,3,20:18.2
7,3,20:18.2
8,3,20:18.2
9,3,20:18.2
10,3,20:18.2
11,3,20:18.2
12,3,20:18.2
13,3,20:18.2
14,3,20:18.2
-16,4,20:18.2
-15,4,20:18.2
-14,4,20:18.2
-13,4,20:18.2
-10,4,20:18.2
-6,4,20:18.2
-5,4,20:18.2
-4,4,20:17.2
-3,4,20:18.2
-2,4,20:18.2
-1,4,20:17.2
0,4,20:17.2
1,4,20:18.2
2,4,20:18.2
3,4,20:18.2
4,4,20:18.2
5,4,20:18.2
6,4,20:17.2
7,4,20:18.2
8,4,20:18.2
9,4,20:18.2
10,4,20:17.2
11,4,20:17.2
12,4,20:18.2
13,4,20:18.2
-17,5,20:18.2
-16,5,20:18.2
-15,5,20:18.2
-14,5,20:18.2
-13,5,20:18.2
-12,5,20:17.2
-11,5,20:17.2
-7,5,20:18.2
-6,5,20:18.2
-5,5,20:18.2
-4,5,20:18.2
-3,5,20:17.2
-2,5,20:18.2
-1,5,20:17.2
0,5,20:17.2
1,5,20:18.2
2,5,20:18.2
3,5,20:18.2
4,5,20:18.2
5,5,20:18.2
6,5,20:18.2
7,5,20:17.2
8,5,20:18.2
9,5,20:18.2
10,5,20:18.2
11,5,20:18.2
12,5,20:18.2
13,5,20:18.2
-17,6,20:18.2
-16,6,20:18.2
-15,6,20:18.2
-14,6,20:18.2
-13,6,20:18.2
-12,6,20:18.2
-11,6,20:18.2
-7,6,20:18.2
-6,6,20:18.2
-5,6,20:18.2
-4,6,20:18.2
-3,6,20:17.2
-2,6,20:17.2
-1,6,20:17.2
0,6,20:18.2
1,6,20:18.2
2,6,20:18.2
3,6,20:17.2
4,6,20:18.2
5,6,20:18.2
6,6,20:17.2
7,6,20:18.2
8,6,20:17.2
9,6,20:18.2
10,6,20:18.2
11,6,20:18.2
12,6,20:18.2
-17,7,20:18.2
-16,7,20:18.2
-15,7,20:18.2
-14,7,20:18.2
-13,7,20:18.2
-12,7,20:18.2
-11,7,20:18.2
-7,7,20:18.2
-6,7,20:18.2
-5,7,20:18.2
-4,7,20:18.2
-3,7,20:18.2
-2,7,20:17.2
-1,7,20:18.2
0,7,20:18.2
1,7,20:17.2
2,7,20:18.2
3,7,20:17.2
4,7,20:18.2
5,7,20:18.2
6,7,20:18.2
7,7,20:18.2
8,7,20:18.2
9,7,20:17.2
10,7,20:18.2
-16,8,20:18.2
-15,8,20:18.2
-14,8,20:18.2
-13,8,20:18.2
-12,8,20:18.2
-11,8,20:18.2
-8,8,20:18.2
-7,8,20:18.2
-6,8,20:18.2
-5,8,20:18.2
-4,8,20:18.2
-3,8,20:17.2
1,8,20:17.2
2,8,20:17.2
3,8,20:18.2
4,8,20:18.2
5,8,20:18.2
6,8,20:18.2
7,8,20:18.2
9,8,20:18.2
-14,9,20:18.2
-13,9,20:18.2
-12,9,20:18.2
-8,9,20:18.2
-7,9,20:17.2
-6,9,20:18.2
1,9,20:17.2
2,9,20:18.2
3,9,20:18.2
4,9,20:18.2
5,9,20:18.2
6,9,20:18.2
-7,10,20:18.2
1,10,20:17.2
3,10,20:18.2
4,10,20:18.2
5,10,20:18.2
-8,11,20:18.2
-7,11,20:18.2
-6,11,20:18.2
-9,12,20:18.2
-8,12,20:18.2
-7,12,20:18.2
-6,12,20:18.2
-5,12,20:18.2
5,12,20:18.2
6,12,20:18.2
7,12,20:18.2
-9,13,20:18.2
-8,13,20:18.2
-7,13,20:18.2
-6,13,20:18.2
-5,13,20:18.2
-2,13,20:17.2
2,13,20:18.2
3,13,20:18.2
4,13,20:18.2
5,13,20:18.2
6,13,20:18.2
7,13,20:18.2
8,13,20:18.2
-9,14,20:18.2
-8,14,20:18.2
-7,14,20:18.2
-6,14,20:18.2
-5,14,20:18.2
-2,14,20:17.2
1,14,20:17.2
2,14,20:18.2
3,14,20:18.2
4,14,20:18.2
5,14,20:18.2
6,14,20:18.2
7,14,20:18.2
8,14,20:18.2
-8,15,20:18.2
-7,15,20:18.2
-6,15,20:18.2
-2,15,20:17.2
0,15,20:18.2
1,15,20:17.2
2,15,20:18.2
3,15,20:18.2
4,15,20:18.2
5,15,20:18.2
6,15,20:18.2
7,15,20:18.2
8,15,20:18.2
-3,16,20:18.2
-2,16,20:17.2
-1,16,20:18.2
1,16,20:18.2
2,16,20:18.2
3,16,20:18.2
4,16,20:18.2
5,16,20:18.2
6,16,20:18.2
7,16,20:18.2
-2,17,20:18.2
2,17,20:18.2
3,17,20:18.2
4,17,20:18.2
-3,-17,21:18.2
-2,-17,21:18.2
-1,-17,21:18.2
0,-17,21:18.2
-4,-16,21:18.2
-3,-16,21:18.2
-2,-16,21:18.2
-1,-16,21:18.2
0,-16,21:18.2
1,-16,21:18.2
-4,-15,21:18.2
-3,-15,21:18.2
-2,-15,21:18.2
-1,-15,21:18.2
0,-15,21:18.2
1,-15,21:18.2
-4,-14,21:18.2
-3,-14,21:18.2
-2,-14,21:18.2
-1,-14,21:18.2
0,-14,21:18.2
1,-14,21:18.2
-3,-13,21:18.2
-2,-13,21:18.2
-1,-13,21:18.2
0,-13,21:18.2
9,-13,21:18.2
-10,-12,21:18.2
-9,-12,21:18.2
-8,-12,21:18.2
-2,-12,21:17.2
0,-12,21:18.2
1,-12,21:18.2
2,-12,21:18.2
8,-12,21:18.2
9,-12,21:17.2
10,-12,21:18.2
11,-12,21:18.2
12,-12,21:18.2
13,-12,21:18.2
-11,-11,21:18.2
-10,-11,21:18.2
-9,-11,21:18.2
-8,-11,21:18.2
-7,-11,21:18.2
-3,-11,21:17.2
-2,-11,21:17.2
-1,-11,21:18.2
0,-11,21:18.2
1,-11,21:18.2
2,-11,21:18.2
3,-11,21:18.2
8,-11,21:17.2
9,-11,21:18.2
10,-11,21:18.2
11,-11,21:18.2
12,-11,21:18.2
13,-11,21:18.2
14,-11,21:18.2
-11,-10,21:18.2
-10,-10,21:18.2
-9,-10,21:18.2
-8,-10,21:18.2
-7,-10,21:18.2
-3,-10,21:17.2
-1,-10,21:18.2
0,-10,21:18.2
1,-10,21:18.2
2,-10,21:18.2
3,-10,21:18.2
10,-10,21:18.2
11,-10,21:18.2
12,-10,21:18.2
13,-10,21:18.2
14,-10,21:18.2
-11,-9,21:18.2
-10,-9,21:18.2
-9,-9,21:18.2
-8,-9,21:18.2
-7,-9,21:18.2
-6,-9,21:18.2
-5,-9,21:18.2
-3,-9,21:18.2
-1,-9,21:18.2
0,-9,21:18.2
1,-9,21:17.2
2,-9,21:18.2
3,-9,21:18.2
6,-9,21:17.2
10,-9,21:18.2
11,-9,21:18.2
12,-9,21:18.2
13,-9,21:18.2
14,-9,21:18.2
-11,-8,21:18.2
-10,-8,21:18.2
-9,-8,21:18.2
-8,-8,21:18.2
-7,-8,21:18.2
-6,-8,21:17.2
-5,-8,21:18.2
-4,-8,21:18.2
-3,-8,21:18.2
-2,-8,21:18.2
-1,-8,21:18.2
0,-8,21:18.2
1,-8,21:17.2
2,-8,21:18.2
3,-8,21:18.2
5,-8,21:17.2
11,-8,21:18.2
12,-8,21:18.2
13,-8,21:18.2
-11,-7,21:18.2
-10,-7,21:18.2
-9,-7,21:18.2
-8,-7,21:18.2
-7,-7,21:18.2
-6,-7,21:18.2
-5,-7,21:17.2
-3,-7,21:18.2
-2,-7,21:18.2
-1,-7,21:18.2
0,-7,21:18.2
1,-7,21:18.2
2,-7,21:18.2
3,-7,21:18.2
5,-7,21:18.2
9,-7,21:18.2
10,-7,21:18.2
11,-7,21:18.2
-12,-6,21:18.2
-11,-6,21:18.2
-10,-6,21:18.2
-9,-6,21:18.2
-8,-6,21:18.2
-7,-6,21:18.2
-5,-6,21:18.2
-4,-6,21:18.2
-3,-6,21:18.2
-2,-6,21:18.2
-1,-6,21:17.2
0,-6,21:18.2
1,-6,21:18.2
2,-6,21:18.2
3,-6,21:18.2
4,-6,21:18.2
5,-6,21:17.2
6,-6,21:18.2
8,-6,21:18.2
9,-6,21:18.2
10,-6,21:18.2
11,-6,21:18.2
12,-6,21:18.2
-13,-5,21:18.2
-12,-5,21:18.2
-11,-5,21:18.2
-10,-5,21:18.2
-9,-5,21:18.2
-8,-5,21:17.2
-6,-5,21:18.2
-5,-5,21:17.2
-4,-5,21:18.2
-3,-5,21:18.2
-2,-5,21:18.2
-1,-5,21:17.2
0,-5,21:18.2
1,-5,21:18.2
2,-5,21:18.2
3,-5,21:18.2
4,-5,21:17.2
5,-5,21:18.2
8,-5,21:18.2
9,-5,21:18.2
10,-5,21:18.2
11,-5,21:18.2
12,-5,21:18.2
-13,-4,21:18.2
-12,-4,21:18.2
-11,-4,21:18.2
-10,-4,21:18.2
-9,-4,21:18.2
-7,-4,21:17.2
-5,-4,21:18.2
-4,-4,21:18.2
-3,-4,21:18.2
-2,-4,21:18.2
-1,-4,21:18.2
0,-4,21:18.2
1,-4,21:18.2
2,-4,21:18.2
3,-4,21:18.2
4,-4,21:17.2
6,-4,21:18.2
7,-4,21:18.2
8,-4,21:17.2
9,-4,21:17.2
10,-4,21:18.2
11,-4,21:18.2
12,-4,21:18.2
-13,-3,21:18.2
-12,-3,21:18.2
-11,-3,21:18.2
-10,-3,21:18.2
-9,-3,21:18.2
-5,-3,21:18.2
-4,-3,21:18.2
-3,-3,21:17.2
-2,-3,21:18.2
-1,-3,21:17.2
0,-3,21:17.2
1,-3,21:17.2
2,-3,21:18.2
3,-3,21:17.2
4,-3,21:18.2
5,-3,21:18.2
6,-3,21:17.2
7,-3,21:17.2
8,-3,21:17.2
9,-3,21:18.2
10,-3,21:18.2
11,-3,21:18.2
-13,-2,21:18.2
-12,-2,21:18.2
-11,-2,21:18.2
-10,-2,21:18.2
-9,-2,21:18.2
-5,-2,21:18.2
-4,-2,21:18.2
-3,-2,21:18.2
-2,-2,21:17.2
-1,-2,21:17.2
0,-2,21:17.2
1,-2,21:17.2
2,-2,21:17.2
3,-2,21:18.2
5,-2,21:17.2
6,-2,21:18.2
7,-2,21:18.2
8,-2,21:18.2
9,-2,21:18.2
10,-2,21:18.2
11,-2,21:17.2
12,-2,21:17.2
-13,-1,21:18.2
-12,-1,21:18.2
-11,-1,21:18.2
-10,-1,21:18.2
-9,-1,21:18.2
-6,-1,21:18.2
-5,-1,21:18.2
-4,-1,21:18.2
-3,-1,21:17.2
-2,-1,21:17.2
-1,-1,21:17.2
0,-1,21:17.2
1,-1,21:17.2
2,-1,21:17.2
3,-1,21:17.2
4,-1,21:17.2
5,-1,21:17.2
6,-1,21:17.2
7,-1,21:18.2
8,-1,21:18.2
9,-1,21:18.2
10,-1,21:18.2
11,-1,21:18.2
12,-1,21:18.2
13,-1,21:18.2
-13,0,21:18.2
-12,0,21:18.2
-11,0,21:18.2
-10,0,21:18.2
-9,0,21:18.2
-5,0,21:18.2
-3,0,21:17.2
-2,0,21:17.2
-1,0,21:17.2
0,0,21:17.2
1,0,21:17.2
2,0,21:17.2
3,0,21:17.2
4,0,21:17.2
5,0,21:18.2
6,0,21:18.2
7,0,21:18.2
8,0,21:18.2
9,0,21:18.2
10,0,21:18.2
11,0,21:18.2
12,0,21:18.2
13,0,21:18.2
14,0,21:18.2
-12,1,21:18.2
-11,1,21:18.2
-10,1,21:18.2
-9,1,21:18.2
-5,1,21:17.2
-4,1,21:17.2
-3,1,21:17.2
-2,1,21:17.2
-1,1,21:17.2
0,1,21:17.2
1,1,21:17.2
2,1,21:17.2
3,1,21:17.2
4,1,21:17.2
5,1,21:17.2
6,1,21:18.2
7,1,21:18.2
8,1,21:18.2
9,1,21:18.2
10,1,21:18.2
11,1,21:18.2
12,1,21:18.2
13,1,21:18.2
14,1,21:18.2
-12,2,21:18.2
-11,2,21:18.2
-10,2,21:18.2
-9,2,21:18.2
-8,2,21:18.2
-4,2,21:17.2
-2,2,21:17.2
-1,2,21:17.2
0,2,21:17.2
1,2,21:17.2
2,2,21:17.2
5,2,21:17.2
6,2,21:18.2
7,2,21:18.2
8,2,21:18.2
9,2,21:18.2
10,2,21:18.2
11,2,21:18.2
12,2,21:18.2
13,2,21:17.2
14,2,21:17.2
-12,3,21:18.2
-11,3,21:18.2
-10,3,21:18.2
-9,3,21:17.2
-8,3,21:17.2
-5,3,21:18.2
-4,3,21:18.2
-3,3,21:18.2
-2,3,21:18.2
-1,3,21:17.2
0,3,21:17.2
1,3,21:17.2
2,3,21:17.2
5,3,21:18.2
6,3,21:18.2
7,3,21:18.2
8,3,21:18.2
9,3,21:18.2
10,3,21:18.2
11,3,21:18.2
12,3,21:18.2
13,3,21:18.2
-16,4,21:18.2
-15,4,21:18.2
-14,4,21:18.2
-12,4,21:18.2
-11,4,21:18.2
-10,4,21:17.2
-9,4,21:17.2
-8,4,21:18.2
-6,4,21:18.2
-5,4,21:18.2
-4,4,21:18.2
-3,4,21:18.2
-2,4,21:17.2
-1,4,21:18.2
0,4,21:17.2
1,4,21:17.2
3,4,21:17.2
4,4,21:18.2
5,4,21:17.2
6,4,21:18.2
7,4,21:18.2
8,4,21:18.2
9,4,21:18.2
10,4,21:18.2
11,4,21:18.2
12,4,21:18.2
13,4,21:18.2
-17,5,21:18.2
-16,5,21:18.2
-15,5,21:18.2
-14,5,21:18.2
-13,5,21:18.2
-11,5,21:18.2
-10,5,21:18.2
-9,5,21:18.2
-7,5,21:18.2
-6,5,21:18.2
-5,5,21:17.2
-4,5,21:18.2
-3,5,21:18.2
-2,5,21:18.2
-1,5,21:18.2
0,5,21:17.2
1,5,21:17.2
3,5,21:18.2
4,5,21:18.2
5,5,21:18.2
6,5,21:17.2
7,5,21:17.2
8,5,21:17.2
9,5,21:18.2
10,5,21:18.2
11,5,21:18.2
12,5,21:17.2
13,5,21:17.2
14,5,21:18.2
-17,6,21:18.2
-16,6,21:18.2
-15,6,21:18.2
-14,6,21:17.2
-13,6,21:17.2
-7,6,21:18.2
-6,6,21:18.2
-5,6,21:18.2
-4,6,21:18.2
-3,6,21:18.2
-1,6,21:17.2
0,6,21:17.2
1,6,21:17.2
2,6,21:18.2
3,6,21:18.2
4,6,21:18.2
5,6,21:18.2
6,6,21:18.2
7,6,21:18.2
8,6,21:18.2
9,6,21:17.2
10,6,21:18.2
11,6,21:18.2
13,6,21:18.2
-17,7,21:18.2
-16,7,21:18.2
-15,7,21:18.2
-14,7,21:18.2
-13,7,21:18.2
-12,7,21:18.2
-8,7,21:18.2
-7,7,21:18.2
-6,7,21:18.2
-5,7,21:18.2
-4,7,21:17.2
-3,7,21:18.2
-2,7,21:17.2
-1,7,21:17.2
0,7,21:17.2
2,7,21:18.2
3,7,21:18.2
4,7,21:18.2
5,7,21:18.2
6,7,21:18.2
7,7,21:18.2
8,7,21:18.2
9,7,21:18.2
10,7,21:17.2
11,7,21:18.2
-16,8,21:18.2
-15,8,21:18.2
-14,8,21:18.2
-13,8,21:18.2
-9,8,21:18.2
-8,8,21:18.2
-7,8,21:18.2
-6,8,21:18.2
-5,8,21:17.2
-4,8,21:18.2
-3,8,21:18.2
-2,8,21:17.2
-1,8,21:17.2
0,8,21:17.2
2,8,21:18.2
3,8,21:18.2
4,8,21:17.2
5,8,21:18.2
6,8,21:18.2
7,8,21:18.2
8,8,21:18.2
9,8,21:18.2
10,8,21:18.2
11,8,21:18.2
-9,9,21:18.2
-8,9,21:18.2
-7,9,21:18.2
-6,9,21:18.2
-5,9,21:18.2
-3,9,21:17.2
-2,9,21:17.2
-1,9,21:18.2
1,9,21:17.2
2,9,21:17.2
3,9,21:18.2
4,9,21:17.2
5,9,21:18.2
6,9,21:18.2
8,9,21:18.2
9,9,21:18.2
10,9,21:18.2
-9,10,21:18.2
-8,10,21:18.2
-7,10,21:18.2
-6,10,21:18.2
-5,10,21:18.2
-3,10,21:17.2
-2,10,21:18.2
1,10,21:17.2
2,10,21:17.2
3,10,21:18.2
4,10,21:18.2
5,10,21:18.2
-8,11,21:18.2
-7,11,21:18.2
-6,11,21:18.2
1,11,21:17.2
2,11,21:17.2
-9,12,21:18.2
-8,12,21:18.2
-7,12,21:18.2
-6,12,21:18.2
-5,12,21:18.2
2,12,21:17.2
-9,13,21:18.2
-8,13,21:18.2
-7,13,21:18.2
-6,13,21:18.2
-5,13,21:18.2
0,13,21:18.2
1,13,21:18.2
2,13,21:18.2
3,13,21:18.2
4,13,21:18.2
6,13,21:18.2
-9,14,21:18.2
-8,14,21:18.2
-7,14,21:18.2
-6,14,21:18.2
-5,14,21:18.2
-3,14,21:18.2
-2,14,21:18.2
-1,14,21:18.2
0,14,21:18.2
1,14,21:18.2
2,14,21:18.2
3,14,21:18.2
4,14,21:18.2
5,14,21:18.2
6,14,21:18.2
7,14,21:18.2
-8,15,21:18.2
-7,15,21:18.2
-6,15,21:18.2
-4,15,21:18.2
-3,15,21:18.2
-2,15,21:17.2
-1,15,21:18.2
0,15,21:18.2
1,15,21:18.2
2,15,21:18.2
3,15,21:18.2
4,15,21:18.2
5,15,21:18.2
6,15,21:18.2
-4,16,21:18.2
-3,16,21:18.2
-2,16,21:17.2
-1,16,21:18.2
0,16,21:18.2
1,16,21:18.2
2,16,21:18.2
3,16,21:18.2
4,16,21:18.2
5,16,21:18.2
-4,17,21:18.2
-3,17,21:18.2
-2,17,21:18.2
-1,17,21:18.2
0,17,21:18.2
1,17,21:18.2
2,17,21:18.2
3,17,21:18.2
4,17,21:18.2
-3,18,21:18.2
-2,18,21:18.2
-1,18,21:18.2
-2,-16,22:18.2
-1,-16,22:18.2
-3,-15,22:18.2
-2,-15,22:18.2
-1,-15,22:18.2
0,-15,22:18.2
-4,-14,22:18.2
-3,-14,22:18.2
-2,-14,22:17.2
-1,-14,22:18.2
8,-14,22:18.2
9,-14,22:18.2
10,-14,22:18.2
-5,-13,22:18.2
-4,-13,22:17.2
-3,-13,22:18.2
-2,-13,22:17.2
7,-13,22:18.2
8,-13,22:18.2
9,-13,22:18.2
10,-13,22:18.2
11,-13,22:18.2
-10,-12,22:18.2
-9,-12,22:18.2
-8,-12,22:18.2
-4,-12,22:17.2
0,-12,22:18.2
1,-12,22:18.2
2,-12,22:18.2
7,-12,22:18.2
8,-12,22:18.2
9,-12,22:18.2
10,-12,22:18.2
11,-12,22:18.2
12,-12,22:18.2
13,-12,22:18.2
-11,-11,22:18.2
-10,-11,22:18.2
-9,-11,22:18.2
-8,-11,22:18.2
-7,-11,22:18.2
-1,-11,22:18.2
0,-11,22:18.2
1,-11,22:17.2
2,-11,22:18.2
3,-11,22:18.2
6,-11,22:18.2
7,-11,22:17.2
8,-11,22:18.2
9,-11,22:18.2
10,-11,22:18.2
11,-11,22:18.2
12,-11,22:18.2
13,-11,22:18.2
14,-11,22:18.2
-11,-10,22:18.2
-10,-10,22:18.2
-9,-10,22:18.2
-8,-10,22:18.2
-7,-10,22:18.2
-6,-10,22:18.2
-5,-10,22:18.2
-1,-10,22:18.2
0,-10,22:18.2
1,-10,22:17.2
2,-10,22:18.2
3,-10,22:18.2
6,-10,22:17.2
7,-10,22:18.2
8,-10,22:18.2
9,-10,22:18.2
10,-10,22:18.2
11,-10,22:18.2
12,-10,22:18.2
13,-10,22:18.2
14,-10,22:18.2
-11,-9,22:18.2
-10,-9,22:18.2
-9,-9,22:18.2
-8,-9,22:18.2
-7,-9,22:18.2
-6,-9,22:18.2
-5,-9,22:18.2
-4,-9,22:18.2
-1,-9,22:18.2
0,-9,22:18.2
1,-9,22:18.2
2,-9,22:18.2
3,-9,22:18.2
10,-9,22:18.2
11,-9,22:18.2
12,-9,22:18.2
13,-9,22:18.2
14,-9,22:18.2
-11,-8,22:18.2
-10,-8,22:18.2
-9,-8,22:18.2
-8,-8,22:18.2
-7,-8,22:18.2
-6,-8,22:18.2
-5,-8,22:18.2
-4,-8,22:18.2
-2,-8,22:18.2
-1,-8,22:18.2
0,-8,22:18.2
1,-8,22:18.2
2,-8,22:18.2
3,-8,22:18.2
4,-8,22:18.2
5,-8,22:18.2
6,-8,22:18.2
11,-8,22:18.2
12,-8,22:18.2
13,-8,22:18.2
-11,-7,22:18.2
-10,-7,22:18.2
-9,-7,22:18.2
-8,-7,22:18.2
-7,-7,22:18.2
-6,-7,22:18.2
-5,-7,22:18.2
-4,-7,22:18.2
-3,-7,22:18.2
-2,-7,22:18.2
-1,-7,22:18.2
0,-7,22:18.2
1,-7,22:18.2
2,-7,22:18.2
3,-7,22:18.2
4,-7,22:18.2
5,-7,22:18.2
6,-7,22:18.2
7,-7,22:18.2
-12,-6,22:18.2
-11,-6,22:18.2
-10,-6,22:17.2
-9,-6,22:18.2
-8,-6,22:18.2
-7,-6,22:18.2
-6,-6,22:18.2
-5,-6,22:18.2
-4,-6,22:18.2
-3,-6,22:18.2
-2,-6,22:18.2
-1,-6,22:17.2
0,-6,22:18.2
1,-6,22:18.2
2,-6,22:18.2
3,-6,22:18.2
4,-6,22:18.2
5,-6,22:18.2
6,-6,22:18.2
7,-6,22:18.2
10,-6,22:18.2
-13,-5,22:18.2
-12,-5,22:18.2
-11,-5,22:18.2
-10,-5,22:18.2
-9,-5,22:17.2
-8,-5,22:18.2
-7,-5,22:18.2
-6,-5,22:18.2
-5,-5,22:17.2
-4,-5,22:18.2
-3,-5,22:18.2
-2,-5,22:18.2
-1,-5,22:17.2
0,-5,22:17.2
1,-5,22:18.2
2,-5,22:18.2
3,-5,22:18.2
4,-5,22:18.2
5,-5,22:17.2
6,-5,22:18.2
7,-5,22:18.2
9,-5,22:18.2
10,-5,22:17.2
11,-5,22:17.2
-13,-4,22:18.2
-12,-4,22:18.2
-11,-4,22:18.2
-10,-4,22:18.2
-9,-4,22:18.2
-7,-4,22:18.2
-6,-4,22:18.2
-5,-4,22:18.2
-4,-4,22:17.2
-3,-4,22:17.2
-2,-4,22:17.2
-1,-4,22:17.2
0,-4,22:17.2
1,-4,22:18.2
2,-4,22:18.2
3,-4,22:18.2
4,-4,22:18.2
5,-4,22:18.2
6,-4,22:18.2
8,-4,22:17.2
9,-4,22:17.2
10,-4,22:17.2
11,-4,22:18.2
-13,-3,22:18.2
-12,-3,22:18.2
-11,-3,22:18.2
-10,-3,22:18.2
-9,-3,22:18.2
-6,-3,22:18.2
-5,-3,22:18.2
-4,-3,22:17.2
-3,-3,22:18.2
-2,-3,22:17.2
-1,-3,22:17.2
0,-3,22:17.2
1,-3,22:17.2
2,-3,22:18.2
3,-3,22:18.2
4,-3,22:18.2
5,-3,22:18.2
6,-3,22:18.2
7,-3,22:17.2
8,-3,22:18.2
10,-3,22:18.2
14,-3,22:17.2
-12,-2,22:18.2
-11,-2,22:18.2
-10,-2,22:18.2
-4,-2,22:18.2
-3,-2,22:17.2
-2,-2,22:17.2
-1,-2,22:17.2
0,-2,22:17.2
1,-2,22:17.2
2,-2,22:17.2
3,-2,22:17.2
4,-2,22:17.2
5,-2,22:17.2
6,-2,22:17.2
7,-2,22:17.2
8,-2,22:17.2
9,-2,22:18.2
10,-2,22:18.2
13,-2,22:17.2
-12,-1,22:18.2
-11,-1,22:18.2
-10,-1,22:18.2
-6,-1,22:17.2
-5,-1,22:17.2
-4,-1,22:17.2
-3,-1,22:17.2
-2,-1,22:17.2
-1,-1,22:17.2
0,-1,22:17.2
1,-1,22:17.2
2,-1,22:17.2
3,-1,22:17.2
4,-1,22:18.2
5,-1,22:18.2
6,-1,22:17.2
7,-1,22:17.2
8,-1,22:18.2
9,-1,22:18.2
10,-1,22:18.2
11,-1,22:18.2
-11,0,22:18.2
-5,0,22:17.2
-4,0,22:17.2
-3,0,22:17.2
-2,0,22:17.2
-1,0,22:17.2
0,0,22:17.2
1,0,22:17.2
2,0,22:17.2
3,0,22:17.2
4,0,22:18.2
5,0,22:18.2
6,0,22:18.2
7,0,22:18.2
8,0,22:18.2
9,0,22:18.2
10,0,22:18.2
11,0,22:18.2
12,0,22:18.2
-11,1,22:18.2
-10,1,22:18.2
-9,1,22:18.2
-8,1,22:18.2
-6,1,22:17.2
-5,1,22:17.2
-4,1,22:17.2
-3,1,22:17.2
-2,1,22:17.2
-1,1,22:17.2
0,1,22:17.2
1,1,22:17.2
2,1,22:17.2
3,1,22:17.2
4,1,22:18.2
5,1,22:18.2
6,1,22:18.2
7,1,22:18.2
8,1,22:18.2
9,1,22:18.2
10,1,22:18.2
11,1,22:18.2
12,1,22:18.2
13,1,22:18.2
16,1,22:18.2
-12,2,22:18.2
-11,2,22:18.2
-10,2,22:18.2
-9,2,22:18.2
-8,2,22:18.2
-7,2,22:17.2
-6,2,22:17.2
-5,2,22:17.2
-4,2,22:17.2
-3,2,22:17.2
-2,2,22:17.2
-1,2,22:17.2
0,2,22:17.2
1,2,22:17.2
2,2,22:17.2
3,2,22:17.2
4,2,22:18.2
5,2,22:18.2
6,2,22:17.2
7,2,22:18.2
8,2,22:18.2
9,2,22:18.2
10,2,22:18.2
11,2,22:18.2
12,2,22:18.2
15,2,22:17.2
16,2,22:17.2
17,2,22:18.2
-12,3,22:18.2
-11,3,22:18.2
-10,3,22:18.2
-9,3,22:18.2
-8,3,22:18.2
-7,3,22:18.2
-4,3,22:17.2
-2,3,22:17.2
-1,3,22:17.2
0,3,22:17.2
1,3,22:17.2
4,3,22:17.2
5,3,22:18.2
6,3,22:18.2
7,3,22:17.2
8,3,22:17.2
10,3,22:18.2
12,3,22:18.2
13,3,22:18.2
14,3,22:18.2
16,3,22:18.2
-15,4,22:18.2
-14,4,22:18.2
-13,4,22:18.2
-12,4,22:18.2
-11,4,22:18.2
-10,4,22:18.2
-9,4,22:18.2
-8,4,22:18.2
-7,4,22:18.2
-3,4,22:17.2
-2,4,22:18.2
-1,4,22:18.2
0,4,22:18.2
1,4,22:17.2
2,4,22:17.2
5,4,22:18.2
6,4,22:18.2
7,4,22:18.2
11,4,22:18.2
12,4,22:18.2
13,4,22:18.2
14,4,22:18.2
15,4,22:18.2
-16,5,22:18.2
-15,5,22:18.2
-14,5,22:18.2
-13,5,22:18.2
-12,5,22:17.2
-11,5,22:17.2
-10,5,22:18.2
-9,5,22:18.2
-8,5,22:18.2
-6,5,22:17.2
-5,5,22:18.2
-3,5,22:18.2
-2,5,22:17.2
-1,5,22:18.2
0,5,22:17.2
1,5,22:17.2
2,5,22:17.2
4,5,22:17.2
5,5,22:18.2
6,5,22:18.2
7,5,22:18.2
8,5,22:18.2
9,5,22:18.2
10,5,22:18.2
11,5,22:18.2
12,5,22:18.2
13,5,22:18.2
14,5,22:18.2
15,5,22:18.2
-16,6,22:18.2
-15,6,22:18.2
-14,6,22:18.2
-13,6,22:18.2
-12,6,22:18.2
-7,6,22:17.2
-6,6,22:18.2
-5,6,22:18.2
-4,6,22:18.2
-3,6,22:17.2
-2,6,22:18.2
-1,6,22:18.2
0,6,22:17.2
1,6,22:17.2
2,6,22:18.2
4,6,22:18.2
5,6,22:17.2
6,6,22:18.2
7,6,22:17.2
8,6,22:18.2
9,6,22:17.2
10,6,22:18.2
11,6,22:18.2
12,6,22:18.2
13,6,22:18.2
14,6,22:18.2
15,6,22:18.2
-16,7,22:18.2
-15,7,22:18.2
-14,7,22:18.2
-13,7,22:18.2
-12,7,22:18.2
-8,7,22:18.2
-7,7,22:18.2
-6,7,22:18.2
-5,7,22:18.2
-4,7,22:18.2
-3,7,22:18.2
-2,7,22:18.2
-1,7,22:18.2
0,7,22:18.2
1,7,22:17.2
2,7,22:18.2
3,7,22:18.2
4,7,22:18.2
5,7,22:18.2
6,7,22:18.2
7,7,22:18.2
8,7,22:17.2
9,7,22:18.2
10,7,22:17.2
11,7,22:18.2
12,7,22:18.2
13,7,22:18.2
14,7,22:18.2
-15,8,22:18.2
-14,8,22:18.2
-13,8,22:18.2
-9,8,22:18.2
-8,8,22:18.2
-7,8,22:18.2
-6,8,22:18.2
-5,8,22:18.2
-4,8,22:18.2
-3,8,22:18.2
-2,8,22:18.2
-1,8,22:18.2
0,8,22:18.2
1,8,22:17.2
2,8,22:18.2
3,8,22:18.2
4,8,22:18.2
5,8,22:18.2
6,8,22:18.2
7,8,22:18.2
8,8,22:18.2
9,8,22:18.2
10,8,22:18.2
11,8,22:18.2
12,8,22:18.2
-9,9,22:18.2
-8,9,22:18.2
-7,9,22:18.2
-6,9,22:18.2
-5,9,22:17.2
-4,9,22:18.2
-3,9,22:18.2
-2,9,22:18.2
-1,9,22:17.2
0,9,22:17.2
2,9,22:18.2
3,9,22:18.2
4,9,22:18.2
5,9,22:18.2
6,9,22:18.2
8,9,22:18.2
9,9,22:18.2
10,9,22:18.2
11,9,22:18.2
-9,10,22:18.2
-8,10,22:18.2
-7,10,22:18.2
-6,10,22:17.2
-5,10,22:18.2
-4,10,22:18.2
-3,10,22:18.2
-2,10,22:17.2
-1,10,22:18.2
0,10,22:17.2
2,10,22:18.2
3,10,22:18.2
4,10,22:18.2
5,10,22:18.2
6,10,22:18.2
-8,11,22:18.2
-7,11,22:18.2
-6,11,22:18.2
-4,11,22:17.2
-3,11,22:18.2
-2,11,22:18.2
-1,11,22:18.2
3,11,22:18.2
4,11,22:18.2
5,11,22:18.2
-7,12,22:18.2
-5,12,22:18.2
-4,12,22:17.2
-3,12,22:18.2
2,12,22:17.2
-8,13,22:18.2
-7,13,22:18.2
-6,13,22:18.2
-4,13,22:18.2
0,13,22:18.2
1,13,22:18.2
2,13,22:17.2
3,13,22:17.2
-7,14,22:18.2
-3,14,22:18.2
-2,14,22:18.2
-1,14,22:18.2
0,14,22:18.2
1,14,22:18.2
2,14,22:17.2
3,14,22:18.2
-4,15,22:18.2
-3,15,22:18.2
-2,15,22:18.2
-1,15,22:18.2
0,15,22:18.2
1,15,22:18.2
2,15,22:18.2
3,15,22:18.2
4,15,22:18.2
-4,16,22:18.2
-3,16,22:18.2
-2,16,22:18.2
-1,16,22:18.2
0,16,22:18.2
1,16,22:18.2
2,16,22:18.2
3,16,22:18.2
-4,17,22:18.2
-3,17,22:18.2
-2,17,22:18.2
-1,17,22:18.2
0,17,22:18.2
1,17,22:18.2
2,17,22:18.2
-3,18,22:18.2
-2,18,22:18.2
-1,18,22:18.2
-3,-16,23:18.2
-2,-16,23:18.2
-1,-16,23:18.2
-5,-15,23:18.2
-4,-15,23:18.2
-3,-15,23:18.2
-2,-15,23:18.2
-1,-15,23:18.2
0,-15,23:18.2
-6,-14,23:18.2
-5,-14,23:18.2
-4,-14,23:18.2
-3,-14,23:18.2
-2,-14,23:18.2
-1,-14,23:18.2
0,-14,23:18.2
8,-14,23:18.2
9,-14,23:18.2
10,-14,23:18.2
-6,-13,23:18.2
-5,-13,23:18.2
-4,-13,23:18.2
-3,-13,23:18.2
-2,-13,23:18.2
-1,-13,23:18.2
0,-13,23:18.2
1,-13,23:18.2
2,-13,23:18.2
6,-13,23:18.2
7,-13,23:18.2
8,-13,23:18.2
9,-13,23:18.2
10,-13,23:18.2
11,-13,23:18.2
-6,-12,23:18.2
-5,-12,23:18.2
-4,-12,23:18.2
-3,-12,23:18.2
-2,-12,23:18.2
-1,-12,23:18.2
0,-12,23:18.2
1,-12,23:18.2
2,-12,23:18.2
3,-12,23:18.2
5,-12,23:18.2
6,-12,23:18.2
7,-12,23:18.2
8,-12,23:18.2
9,-12,23:18.2
10,-12,23:18.2
11,-12,23:18.2
-9,-11,23:18.2
-5,-11,23:18.2
-4,-11,23:18.2
-3,-11,23:18.2
-1,-11,23:18.2
0,-11,23:18.2
1,-11,23:18.2
2,-11,23:18.2
3,-11,23:18.2
5,-11,23:18.2
6,-11,23:18.2
7,-11,23:18.2
8,-11,23:18.2
9,-11,23:18.2
10,-11,23:18.2
11,-11,23:18.2
12,-11,23:18.2
-10,-10,23:18.2
-9,-10,23:18.2
-8,-10,23:18.2
-7,-10,23:18.2
-6,-10,23:18.2
-5,-10,23:18.2
-1,-10,23:18.2
0,-10,23:18.2
1,-10,23:18.2
2,-10,23:18.2
3,-10,23:18.2
5,-10,23:18.2
6,-10,23:18.2
7,-10,23:18.2
8,-10,23:18.2
9,-10,23:18.2
10,-10,23:18.2
11,-10,23:18.2
12,-10,23:18.2
13,-10,23:18.2
-9,-9,23:18.2
-8,-9,23:18.2
-7,-9,23:18.2
-6,-9,23:18.2
-5,-9,23:18.2
-4,-9,23:18.2
0,-9,23:18.2
1,-9,23:18.2
2,-9,23:18.2
6,-9,23:18.2
7,-9,23:18.2
8,-9,23:18.2
12,-9,23:18.2
-11,-8,23:18.2
-10,-8,23:18.2
-9,-8,23:18.2
-8,-8,23:18.2
-7,-8,23:18.2
-6,-8,23:18.2
-5,-8,23:18.2
-4,-8,23:18.2
-2,-8,23:17.2
-1,-8,23:18.2
0,-8,23:18.2
1,-8,23:18.2
4,-8,23:18.2
5,-8,23:18.2
6,-8,23:18.2
-12,-7,23:18.2
-11,-7,23:18.2
-10,-7,23:18.2
-9,-7,23:18.2
-8,-7,23:18.2
-7,-7,23:17.2
-6,-7,23:18.2
-5,-7,23:18.2
-4,-7,23:18.2
-3,-7,23:18.2
-2,-7,23:18.2
-1,-7,23:17.2
0,-7,23:17.2
1,-7,23:18.2
2,-7,23:18.2
3,-7,23:18.2
4,-7,23:18.2
5,-7,23:18.2
6,-7,23:18.2
7,-7,23:18.2
-12,-6,23:18.2
-11,-6,23:18.2
-10,-6,23:18.2
-9,-6,23:18.2
-8,-6,23:18.2
-7,-6,23:18.2
-6,-6,23:17.2
-5,-6,23:17.2
-4,-6,23:17.2
-3,-6,23:18.2
-2,-6,23:18.2
-1,-6,23:17.2
0,-6,23:17.2
1,-6,23:18.2
3,-6,23:18.2
4,-6,23:18.2
5,-6,23:18.2
6,-6,23:18.2
7,-6,23:18.2
9,-6,23:18.2
10,-6,23:18.2
11,-6,23:18.2
12,-6,23:17.2
13,-6,23:17.2
-12,-5,23:18.2
-11,-5,23:18.2
-10,-5,23:18.2
-9,-5,23:18.2
-8,-5,23:18.2
-7,-5,23:18.2
-6,-5,23:18.2
-5,-5,23:18.2
-4,-5,23:17.2
-3,-5,23:17.2
-2,-5,23:17.2
-1,-5,23:18.2
0,-5,23:18.2
1,-5,23:18.2
2,-5,23:18.2
3,-5,23:18.2
4,-5,23:18.2
5,-5,23:18.2
6,-5,23:18.2
7,-5,23:18.2
8,-5,23:18.2
9,-5,23:18.2
10,-5,23:17.2
11,-5,23:18.2
12,-5,23:18.2
-12,-4,23:18.2
-11,-4,23:18.2
-10,-4,23:18.2
-9,-4,23:18.2
-7,-4,23:18.2
-6,-4,23:17.2
-5,-4,23:18.2
-4,-4,23:18.2
-3,-4,23:18.2
-2,-4,23:17.2
-1,-4,23:18.2
0,-4,23:18.2
1,-4,23:18.2
2,-4,23:18.2
3,-4,23:18.2
4,-4,23:18.2
5,-4,23:18.2
6,-4,23:18.2
7,-4,23:18.2
8,-4,23:18.2
9,-4,23:17.2
10,-4,23:18.2
11,-4,23:18.2
12,-4,23:18.2
16,-4,23:18.2
-11,-3,23:18.2
-6,-3,23:18.2
-5,-3,23:17.2
-4,-3,23:18.2
-3,-3,23:18.2
-1,-3,23:17.2
0,-3,23:17.2
1,-3,23:17.2
2,-3,23:18.2
3,-3,23:17.2
4,-3,23:17.2
5,-3,23:17.2
6,-3,23:18.2
7,-3,23:17.2
8,-3,23:17.2
9,-3,23:18.2
10,-3,23:18.2
11,-3,23:18.2
12,-3,23:18.2
15,-3,23:17.2
16,-3,23:17.2
17,-3,23:18.2
-8,-2,23:17.2
-4,-2,23:18.2
-2,-2,23:17.2
-1,-2,23:17.2
0,-2,23:17.2
1,-2,23:17.2
2,-2,23:17.2
3,-2,23:17.2
4,-2,23:18.2
5,-2,23:18.2
6,-2,23:18.2
7,-2,23:18.2
8,-2,23:18.2
9,-2,23:18.2
10,-2,23:18.2
11,-2,23:18.2
16,-2,23:18.2
-8,-1,23:17.2
-7,-1,23:17.2
-6,-1,23:18.2
-5,-1,23:17.2
-4,-1,23:17.2
-3,-1,23:17.2
-2,-1,23:17.2
-1,-1,23:17.2
0,-1,23:17.2
1,-1,23:17.2
2,-1,23:17.2
3,-1,23:17.2
4,-1,23:17.2
5,-1,23:17.2
6,-1,23:18.2
7,-1,23:18.2
8,-1,23:17.2
9,-1,23:17.2
10,-1,23:18.2
-7,0,23:18.2
-6,0,23:17.2
-5,0,23:17.2
-4,0,23:17.2
-3,0,23:17.2
-2,0,23:17.2
-1,0,23:17.2
0,0,23:17.2
1,0,23:17.2
2,0,23:17.2
3,0,23:17.2
4,0,23:17.2
5,0,23:17.2
6,0,23:17.2
7,0,23:18.2
8,0,23:18.2
9,0,23:18.2
10,0,23:18.2
15,0,23:18.2
16,0,23:18.2
17,0,23:18.2
-10,1,23:18.2
-9,1,23:18.2
-8,1,23:18.2
-7,1,23:18.2
-6,1,23:18.2
-5,1,23:18.2
-4,1,23:18.2
-3,1,23:17.2
-2,1,23:17.2
-1,1,23:17.2
0,1,23:17.2
1,1,23:17.2
2,1,23:17.2
3,1,23:17.2
4,1,23:18.2
5,1,23:18.2
6,1,23:18.2
7,1,23:18.2
9,1,23:18.2
14,1,23:18.2
15,1,23:18.2
16,1,23:18.2
17,1,23:18.2
18,1,23:18.2
-11,2,23:18.2
-10,2,23:18.2
-9,2,23:17.2
-8,2,23:17.2
-7,2,23:17.2
-6,2,23:17.2
-5,2,23:17.2
-4,2,23:17.2
-3,2,23:18.2
-2,2,23:17.2
-1,2,23:17.2
0,2,23:17.2
1,2,23:17.2
2,2,23:17.2
3,2,23:17.2
4,2,23:17.2
5,2,23:18.2
6,2,23:18.2
7,2,23:18.2
14,2,23:18.2
15,2,23:18.2
16,2,23:18.2
17,2,23:18.2
18,2,23:18.2
-11,3,23:18.2
-10,3,23:18.2
-9,3,23:18.2
-8,3,23:17.2
-7,3,23:17.2
-6,3,23:18.2
-5,3,23:17.2
-4,3,23:18.2
-3,3,23:18.2
-2,3,23:18.2
-1,3,23:17.2
0,3,23:17.2
1,3,23:17.2
2,3,23:18.2
3,3,23:18.2
4,3,23:18.2
5,3,23:18.2
6,3,23:18.2
9,3,23:17.2
12,3,23:18.2
13,3,23:18.2
14,3,23:18.2
15,3,23:18.2
16,3,23:18.2
17,3,23:18.2
18,3,23:18.2
-15,4,23:18.2
-14,4,23:18.2
-13,4,23:18.2
-11,4,23:18.2
-10,4,23:18.2
-9,4,23:18.2
-8,4,23:18.2
-7,4,23:18.2
-6,4,23:17.2
-5,4,23:17.2
-4,4,23:18.2
-3,4,23:18.2
-2,4,23:18.2
-1,4,23:18.2
0,4,23:17.2
1,4,23:17.2
2,4,23:18.2
3,4,23:18.2
5,4,23:17.2
10,4,23:17.2
11,4,23:18.2
12,4,23:18.2
13,4,23:18.2
14,4,23:18.2
15,4,23:18.2
16,4,23:18.2
17,4,23:18.2
-16,5,23:18.2
-15,5,23:18.2
-14,5,23:18.2
-13,5,23:18.2
-12,5,23:18.2
-10,5,23:18.2
-9,5,23:18.2
-8,5,23:18.2
-6,5,23:17.2
-5,5,23:18.2
-4,5,23:18.2
-3,5,23:17.2
-2,5,23:18.2
-1,5,23:18.2
0,5,23:17.2
1,5,23:17.2
2,5,23:17.2
3,5,23:18.2
6,5,23:17.2
9,5,23:18.2
10,5,23:18.2
11,5,23:18.2
12,5,23:18.2
13,5,23:18.2
14,5,23:18.2
15,5,23:18.2
-16,6,23:18.2
-15,6,23:18.2
-14,6,23:17.2
-13,6,23:17.2
-12,6,23:18.2
-5,6,23:18.2
-4,6,23:17.2
-3,6,23:18.2
-2,6,23:18.2
-1,6,23:18.2
0,6,23:17.2
1,6,23:17.2
2,6,23:17.2
5,6,23:18.2
6,6,23:18.2
7,6,23:18.2
8,6,23:18.2
9,6,23:18.2
10,6,23:18.2
11,6,23:18.2
12,6,23:18.2
13,6,23:18.2
14,6,23:18.2
15,6,23:18.2
-16,7,23:18.2
-15,7,23:18.2
-14,7,23:18.2
-13,7,23:18.2
-12,7,23:18.2
-8,7,23:17.2
-5,7,23:18.2
-4,7,23:18.2
-3,7,23:18.2
-2,7,23:18.2
-1,7,23:18.2
0,7,23:18.2
1,7,23:17.2
2,7,23:17.2
3,7,23:17.2
4,7,23:18.2
5,7,23:18.2
6,7,23:17.2
8,7,23:18.2
9,7,23:17.2
10,7,23:18.2
11,7,23:17.2
12,7,23:18.2
13,7,23:18.2
14,7,23:18.2
-15,8,23:18.2
-14,8,23:18.2
-13,8,23:18.2
-9,8,23:17.2
-7,8,23:18.2
-4,8,23:18.2
-3,8,23:18.2
-2,8,23:18.2
-1,8,23:18.2
0,8,23:18.2
1,8,23:18.2
2,8,23:17.2
3,8,23:18.2
4,8,23:18.2
5,8,23:18.2
6,8,23:17.2
8,8,23:18.2
9,8,23:18.2
10,8,23:17.2
11,8,23:18.2
12,8,23:17.2
13,8,23:18.2
-8,9,23:18.2
-7,9,23:18.2
-6,9,23:18.2
-4,9,23:18.2
-3,9,23:18.2
-2,9,23:18.2
-1,9,23:18.2
0,9,23:18.2
1,9,23:17.2
2,9,23:18.2
3,9,23:18.2
4,9,23:18.2
5,9,23:18.2
6,9,23:18.2
9,9,23:18.2
10,9,23:18.2
11,9,23:18.2
12,9,23:18.2
-7,10,23:18.2
-5,10,23:18.2
-4,10,23:18.2
-3,10,23:18.2
-2,10,23:18.2
-1,10,23:18.2
0,10,23:18.2
1,10,23:17.2
2,10,23:18.2
3,10,23:18.2
4,10,23:18.2
5,10,23:18.2
6,10,23:18.2
-6,11,23:17.2
-5,11,23:18.2
-4,11,23:18.2
-3,11,23:18.2
-2,11,23:17.2
-1,11,23:18.2
0,11,23:17.2
1,11,23:17.2
3,11,23:18.2
4,11,23:18.2
5,11,23:18.2
-7,12,23:17.2
-6,12,23:18.2
-5,12,23:18.2
-4,12,23:18.2
-3,12,23:18.2
-2,12,23:17.2
-1,12,23:18.2
0,12,23:17.2
1,12,23:18.2
2,12,23:18.2
3,12,23:18.2
-6,13,23:18.2
-5,13,23:18.2
-4,13,23:18.2
-3,13,23:18.2
-2,13,23:18.2
0,13,23:18.2
1,13,23:18.2
2,13,23:18.2
3,13,23:18.2
4,13,23:18.2
-5,14,23:18.2
-4,14,23:18.2
-3,14,23:18.2
-2,14,23:18.2
-1,14,23:18.2
0,14,23:18.2
1,14,23:18.2
2,14,23:17.2
3,14,23:17.2
4,14,23:18.2
-4,15,23:18.2
-3,15,23:18.2
-2,15,23:18.2
-1,15,23:18.2
0,15,23:18.2
1,15,23:18.2
2,15,23:17.2
3,15,23:17.2
4,15,23:18.2
-4,16,23:18.2
-3,16,23:18.2
-2,16,23:18.2
-1,16,23:18.2
0,16,23:18.2
1,16,23:18.2
2,16,23:18.2
3,16,23:18.2
-4,17,23:18.2
-3,17,23:18.2
-2,17,23:18.2
-1,17,23:18.2
0,17,23:18.2
-3,18,23:18.2
-2,18,23:18.2
-1,18,23:18.2
-3,-16,24:18.2
-2,-16,24:18.2
-1,-16,24:18.2
-5,-15,24:18.2
-4,-15,24:18.2
-3,-15,24:18.2
-2,-15,24:18.2
-1,-15,24:18.2
0,-15,24:18.2
-6,-14,24:18.2
-5,-14,24:18.2
-4,-14,24:18.2
-3,-14,24:18.2
-2,-14,24:18.2
-1,-14,24:18.2
0,-14,24:18.2
-6,-13,24:18.2
-5,-13,24:18.2
-4,-13,24:18.2
-3,-13,24:18.2
-2,-13,24:18.2
-1,-13,24:18.2
0,-13,24:18.2
1,-13,24:18.2
2,-13,24:18.2
6,-13,24:18.2
7,-13,24:18.2
8,-13,24:18.2
9,-13,24:18.2
-6,-12,24:18.2
-5,-12,24:18.2
-4,-12,24:18.2
-3,-12,24:18.2
-2,-12,24:18.2
-1,-12,24:18.2
0,-12,24:18.2
1,-12,24:18.2
2,-12,24:18.2
3,-12,24:18.2
5,-12,24:18.2
6,-12,24:18.2
7,-12,24:18.2
8,-12,24:18.2
9,-12,24:18.2
10,-12,24:18.2
-5,-11,24:18.2
-4,-11,24:18.2
-3,-11,24:18.2
-2,-11,24:18.2
-1,-11,24:18.2
0,-11,24:18.2
1,-11,24:18.2
2,-11,24:18.2
3,-11,24:18.2
5,-11,24:18.2
6,-11,24:18.2
7,-11,24:18.2
8,-11,24:18.2
9,-11,24:18.2
-3,-10,24:18.2
-2,-10,24:17.2
-1,-10,24:17.2
0,-10,24:18.2
1,-10,24:18.2
2,-10,24:18.2
3,-10,24:18.2
5,-10,24:18.2
6,-10,24:18.2
7,-10,24:18.2
8,-10,24:18.2
9,-10,24:18.2
-8,-9,24:18.2
-6,-9,24:18.2
-2,-9,24:17.2
-1,-9,24:17.2
0,-9,24:17.2
1,-9,24:18.2
2,-9,24:18.2
6,-9,24:18.2
7,-9,24:18.2
8,-9,24:18.2
-11,-8,24:18.2
-10,-8,24:18.2
-9,-8,24:18.2
-8,-8,24:17.2
-7,-8,24:18.2
-6,-8,24:17.2
-5,-8,24:18.2
-4,-8,24:17.2
-3,-8,24:18.2
-1,-8,24:17.2
0,-8,24:17.2
15,-8,24:18.2
-12,-7,24:18.2
-11,-7,24:18.2
-10,-7,24:18.2
-9,-7,24:18.2
-8,-7,24:18.2
-6,-7,24:18.2
-5,-7,24:17.2
-4,-7,24:18.2
-3,-7,24:17.2
-2,-7,24:18.2
-1,-7,24:18.2
4,-7,24:18.2
5,-7,24:18.2
6,-7,24:18.2
12,-7,24:18.2
14,-7,24:17.2
15,-7,24:17.2
16,-7,24:18.2
-12,-6,24:18.2
-11,-6,24:18.2
-10,-6,24:18.2
-9,-6,24:18.2
-8,-6,24:18.2
-6,-6,24:18.2
-5,-6,24:18.2
-4,-6,24:18.2
-3,-6,24:17.2
-2,-6,24:17.2
-1,-6,24:18.2
0,-6,24:18.2
3,-6,24:18.2
4,-6,24:18.2
5,-6,24:18.2
6,-6,24:18.2
7,-6,24:18.2
9,-6,24:18.2
10,-6,24:18.2
11,-6,24:18.2
12,-6,24:17.2
13,-6,24:18.2
15,-6,24:18.2
-12,-5,24:18.2
-11,-5,24:18.2
-10,-5,24:18.2
-9,-5,24:18.2
-8,-5,24:17.2
-7,-5,24:17.2
-6,-5,24:18.2
-5,-5,24:18.2
-4,-5,24:18.2
-3,-5,24:18.2
-2,-5,24:17.2
-1,-5,24:18.2
3,-5,24:18.2
4,-5,24:18.2
5,-5,24:17.2
6,-5,24:18.2
7,-5,24:18.2
8,-5,24:18.2
9,-5,24:18.2
10,-5,24:18.2
11,-5,24:17.2
12,-5,24:18.2
15,-5,24:18.2
16,-5,24:18.2
17,-5,24:18.2
-11,-4,24:18.2
-10,-4,24:18.2
-9,-4,24:18.2
-5,-4,24:18.2
-4,-4,24:18.2
-3,-4,24:17.2
-2,-4,24:18.2
-1,-4,24:18.2
2,-4,24:17.2
3,-4,24:18.2
4,-4,24:17.2
5,-4,24:18.2
6,-4,24:17.2
7,-4,24:18.2
8,-4,24:18.2
9,-4,24:18.2
10,-4,24:18.2
11,-4,24:18.2
12,-4,24:18.2
14,-4,24:18.2
15,-4,24:18.2
16,-4,24:18.2
17,-4,24:18.2
18,-4,24:18.2
-10,-3,24:18.2
-5,-3,24:18.2
-4,-3,24:17.2
-3,-3,24:18.2
-2,-3,24:17.2
-1,-3,24:17.2
0,-3,24:17.2
1,-3,24:17.2
2,-3,24:17.2
3,-3,24:18.2
4,-3,24:18.2
5,-3,24:17.2
6,-3,24:18.2
7,-3,24:18.2
8,-3,24:18.2
9,-3,24:18.2
10,-3,24:18.2
11,-3,24:18.2
12,-3,24:18.2
14,-3,24:18.2
15,-3,24:18.2
16,-3,24:18.2
17,-3,24:18.2
18,-3,24:18.2
-11,-2,24:18.2
-10,-2,24:17.2
-9,-2,24:17.2
-6,-2,24:18.2
-5,-2,24:18.2
-4,-2,24:18.2
-3,-2,24:17.2
-2,-2,24:17.2
-1,-2,24:17.2
0,-2,24:17.2
1,-2,24:17.2
2,-2,24:17.2
3,-2,24:18.2
4,-2,24:18.2
5,-2,24:18.2
6,-2,24:18.2
7,-2,24:18.2
8,-2,24:18.2
9,-2,24:18.2
10,-2,24:18.2
11,-2,24:18.2
14,-2,24:18.2
15,-2,24:18.2
16,-2,24:18.2
17,-2,24:18.2
18,-2,24:18.2
-11,-1,24:18.2
-10,-1,24:17.2
-9,-1,24:17.2
-8,-1,24:17.2
-7,-1,24:17.2
-6,-1,24:17.2
-5,-1,24:17.2
-4,-1,24:17.2
-3,-1,24:17.2
-2,-1,24:17.2
-1,-1,24:17.2
0,-1,24:17.2
1,-1,24:17.2
2,-1,24:17.2
3,-1,24:17.2
4,-1,24:18.2
5,-1,24:18.2
6,-1,24:17.2
7,-1,24:17.2
8,-1,24:18.2
9,-1,24:18.2
10,-1,24:18.2
11,-1,24:18.2
15,-1,24:18.2
16,-1,24:18.2
17,-1,24:18.2
-10,0,24:18.2
-9,0,24:18.2
-8,0,24:18.2
-7,0,24:17.2
-6,0,24:17.2
-5,0,24:17.2
-4,0,24:17.2
-3,0,24:17.2
-2,0,24:17.2
-1,0,24:17.2
0,0,24:17.2
1,0,24:17.2
2,0,24:17.2
3,0,24:17.2
4,0,24:17.2
5,0,24:17.2
7,0,24:17.2
8,0,24:17.2
9,0,24:17.2
10,0,24:18.2
11,0,24:18.2
15,0,24:18.2
16,0,24:18.2
17,0,24:18.2
-11,1,24:18.2
-10,1,24:18.2
-9,1,24:18.2
-8,1,24:18.2
-7,1,24:18.2
-6,1,24:18.2
-5,1,24:18.2
-4,1,24:17.2
-3,1,24:17.2
-2,1,24:17.2
-1,1,24:17.2
0,1,24:17.2
1,1,24:17.2
2,1,24:17.2
3,1,24:17.2
4,1,24:18.2
5,1,24:18.2
6,1,24:18.2
8,1,24:18.2
9,1,24:18.2
10,1,24:18.2
14,1,24:18.2
15,1,24:18.2
16,1,24:18.2
17,1,24:18.2
18,1,24:18.2
-11,2,24:18.2
-10,2,24:18.2
-9,2,24:18.2
-8,2,24:18.2
-7,2,24:18.2
-6,2,24:18.2
-5,2,24:17.2
-4,2,24:18.2
-3,2,24:18.2
-2,2,24:17.2
-1,2,24:17.2
0,2,24:17.2
1,2,24:17.2
2,2,24:17.2
5,2,24:18.2
14,2,24:18.2
15,2,24:18.2
16,2,24:18.2
17,2,24:18.2
18,2,24:18.2
-11,3,24:18.2
-10,3,24:17.2
-9,3,24:17.2
-8,3,24:17.2
-7,3,24:17.2
-6,3,24:17.2
-5,3,24:18.2
-4,3,24:18.2
-3,3,24:17.2
-2,3,24:17.2
-1,3,24:17.2
0,3,24:17.2
1,3,24:17.2
2,3,24:18.2
3,3,24:17.2
5,3,24:17.2
14,3,24:18.2
15,3,24:18.2
16,3,24:18.2
17,3,24:18.2
18,3,24:18.2
-15,4,24:18.2
-14,4,24:18.2
-13,4,24:18.2
-10,4,24:18.2
-9,4,24:18.2
-8,4,24:18.2
-7,4,24:18.2
-6,4,24:18.2
-4,4,24:17.2
-3,4,24:17.2
-2,4,24:18.2
-1,4,24:17.2
0,4,24:18.2
1,4,24:18.2
2,4,24:17.2
3,4,24:18.2
4,4,24:17.2
6,4,24:17.2
11,4,24:17.2
12,4,24:17.2
13,4,24:18.2
15,4,24:18.2
16,4,24:18.2
17,4,24:18.2
-16,5,24:18.2
-15,5,24:18.2
-14,5,24:18.2
-13,5,24:18.2
-12,5,24:18.2
-9,5,24:18.2
-8,5,24:17.2
-7,5,24:17.2
-5,5,24:18.2
-4,5,24:18.2
-3,5,24:18.2
-2,5,24:18.2
-1,5,24:17.2
0,5,24:18.2
1,5,24:18.2
2,5,24:17.2
3,5,24:18.2
12,5,24:18.2
13,5,24:18.2
14,5,24:18.2
-16,6,24:18.2
-15,6,24:18.2
-14,6,24:18.2
-13,6,24:18.2
-12,6,24:18.2
-7,6,24:17.2
-5,6,24:18.2
-4,6,24:18.2
-3,6,24:18.2
-2,6,24:18.2
-1,6,24:18.2
0,6,24:18.2
1,6,24:18.2
2,6,24:17.2
7,6,24:17.2
8,6,24:17.2
10,6,24:18.2
11,6,24:18.2
12,6,24:18.2
13,6,24:18.2
-16,7,24:18.2
-15,7,24:18.2
-14,7,24:18.2
-13,7,24:18.2
-12,7,24:18.2
-8,7,24:17.2
-5,7,24:17.2
-4,7,24:18.2
-3,7,24:18.2
-2,7,24:18.2
-1,7,24:18.2
0,7,24:17.2
1,7,24:18.2
2,7,24:17.2
9,7,24:18.2
10,7,24:18.2
11,7,24:18.2
12,7,24:18.2
13,7,24:18.2
14,7,24:18.2
-15,8,24:18.2
-14,8,24:18.2
-13,8,24:18.2
-10,8,24:18.2
-6,8,24:17.2
-4,8,24:18.2
-3,8,24:18.2
-2,8,24:18.2
-1,8,24:17.2
0,8,24:18.2
1,8,24:18.2
2,8,24:17.2
3,8,24:17.2
4,8,24:18.2
10,8,24:18.2
11,8,24:18.2
12,8,24:18.2
13,8,24:18.2
14,8,24:18.2
-11,9,24:18.2
-10,9,24:17.2
-9,9,24:18.2
-3,9,24:18.2
-2,9,24:18.2
-1,9,24:18.2
1,9,24:18.2
2,9,24:17.2
3,9,24:17.2
4,9,24:18.2
5,9,24:18.2
7,9,24:17.2
8,9,24:18.2
10,9,24:18.2
11,9,24:17.2
12,9,24:18.2
13,9,24:18.2
14,9,24:18.2
-10,10,24:18.2
-5,10,24:18.2
-4,10,24:18.2
-3,10,24:18.2
-2,10,24:18.2
-1,10,24:18.2
0,10,24:18.2
1,10,24:18.2
2,10,24:17.2
3,10,24:18.2
4,10,24:18.2
7,10,24:18.2
8,10,24:17.2
9,10,24:18.2
11,10,24:18.2
12,10,24:18.2
13,10,24:18.2
-6,11,24:18.2
-5,11,24:18.2
-4,11,24:18.2
-3,11,24:18.2
-2,11,24:18.2
-1,11,24:18.2
0,11,24:18.2
1,11,24:18.2
2,11,24:18.2
8,11,24:18.2
-6,12,24:18.2
-5,12,24:18.2
-4,12,24:18.2
-3,12,24:18.2
-2,12,24:18.2
-1,12,24:18.2
0,12,24:18.2
1,12,24:18.2
2,12,24:17.2
3,12,24:18.2
-8,13,24:18.2
-7,13,24:17.2
-6,13,24:18.2
-5,13,24:18.2
-4,13,24:18.2
-3,13,24:18.2
-2,13,24:18.2
-1,13,24:18.2
0,13,24:18.2
1,13,24:18.2
2,13,24:17.2
3,13,24:18.2
4,13,24:18.2
-9,14,24:18.2
-8,14,24:17.2
-7,14,24:18.2
-5,14,24:18.2
-4,14,24:18.2
-3,14,24:18.2
-2,14,24:18.2
-1,14,24:18.2
0,14,24:18.2
1,14,24:18.2
2,14,24:18.2
3,14,24:18.2
4,14,24:18.2
5,14,24:18.2
-8,15,24:18.2
-2,15,24:18.2
0,15,24:18.2
1,15,24:18.2
2,15,24:18.2
3,15,24:18.2
4,15,24:18.2
5,15,24:18.2
-3,16,24:18.2
-2,16,24:18.2
-1,16,24:18.2
0,16,24:18.2
1,16,24:18.2
2,16,24:18.2
3,16,24:18.2
4,16,24:18.2
5,16,24:18.2
-2,17,24:18.2
1,17,24:18.2
2,17,24:18.2
3,17,24:18.2
4,17,24:18.2
-2,-15,25:18.2
-4,-14,25:18.2
-3,-14,25:18.2
-2,-14,25:18.2
-1,-14,25:18.2
-5,-13,25:18.2
-4,-13,25:18.2
-3,-13,25:18.2
-2,-13,25:18.2
-4,-12,25:18.2
-3,-12,25:18.2
-2,-12,25:18.2
-1,-12,25:17.2
0,-12,25:18.2
1,-12,25:18.2
7,-12,25:18.2
-4,-11,25:18.2
-3,-11,25:18.2
-2,-11,25:18.2
-1,-11,25:17.2
0,-11,25:17.2
1,-11,25:18.2
2,-11,25:18.2
6,-11,25:18.2
7,-11,25:18.2
8,-11,25:18.2
-9,-10,25:18.2
-8,-10,25:18.2
-7,-10,25:18.2
-5,-10,25:17.2
-4,-10,25:18.2
-3,-10,25:18.2
-2,-10,25:18.2
-1,-10,25:18.2
0,-10,25:17.2
1,-10,25:18.2
7,-10,25:18.2
-10,-9,25:18.2
-9,-9,25:18.2
-8,-9,25:18.2
-7,-9,25:17.2
-6,-9,25:18.2
-4,-9,25:17.2
-3,-9,25:18.2
-2,-9,25:18.2
-1,-9,25:18.2
0,-9,25:18.2
14,-9,25:18.2
15,-9,25:18.2
16,-9,25:18.2
-10,-8,25:18.2
-9,-8,25:18.2
-8,-8,25:18.2
-7,-8,25:18.2
-6,-8,25:18.2
-5,-8,25:18.2
-4,-8,25:18.2
-3,-8,25:17.2
-2,-8,25:18.2
-1,-8,25:18.2
11,-8,25:18.2
12,-8,25:18.2
13,-8,25:18.2
14,-8,25:18.2
15,-8,25:18.2
16,-8,25:18.2
17,-8,25:18.2
-10,-7,25:18.2
-9,-7,25:18.2
-8,-7,25:18.2
-7,-7,25:18.2
-6,-7,25:18.2
-5,-7,25:18.2
-4,-7,25:18.2
-3,-7,25:17.2
-2,-7,25:18.2
6,-7,25:18.2
10,-7,25:18.2
11,-7,25:18.2
12,-7,25:18.2
13,-7,25:18.2
14,-7,25:18.2
15,-7,25:18.2
16,-7,25:18.2
17,-7,25:18.2
-11,-6,25:18.2
-10,-6,25:18.2
-9,-6,25:17.2
-8,-6,25:18.2
-7,-6,25:18.2
-6,-6,25:18.2
-5,-6,25:18.2
-4,-6,25:17.2
-3,-6,25:18.2
-2,-6,25:18.2
-1,-6,25:18.2
2,-6,25:17.2
5,-6,25:18.2
6,-6,25:17.2
7,-6,25:18.2
10,-6,25:18.2
11,-6,25:18.2
12,-6,25:18.2
13,-6,25:18.2
14,-6,25:18.2
15,-6,25:18.2
16,-6,25:18.2
17,-6,25:18.2
-10,-5,25:18.2
-9,-5,25:18.2
-6,-5,25:18.2
-5,-5,25:18.2
-4,-5,25:18.2
-3,-5,25:17.2
-2,-5,25:18.2
-1,-5,25:18.2
2,-5,25:17.2
3,-5,25:17.2
4,-5,25:18.2
5,-5,25:18.2
6,-5,25:18.2
7,-5,25:18.2
8,-5,25:18.2
9,-5,25:18.2
10,-5,25:18.2
11,-5,25:18.2
12,-5,25:18.2
13,-5,25:18.2
14,-5,25:18.2
15,-5,25:18.2
16,-5,25:18.2
17,-5,25:18.2
-11,-4,25:18.2
-10,-4,25:18.2
-9,-4,25:18.2
-6,-4,25:17.2
-5,-4,25:18.2
-4,-4,25:17.2
-3,-4,25:18.2
-2,-4,25:18.2
-1,-4,25:18.2
2,-4,25:17.2
3,-4,25:18.2
4,-4,25:18.2
5,-4,25:18.2
6,-4,25:18.2
7,-4,25:18.2
8,-4,25:18.2
9,-4,25:18.2
10,-4,25:18.2
11,-4,25:18.2
12,-4,25:18.2
13,-4,25:18.2
14,-4,25:18.2
15,-4,25:18.2
16,-4,25:18.2
17,-4,25:18.2
18,-4,25:18.2
-12,-3,25:18.2
-11,-3,25:18.2
-10,-3,25:18.2
-9,-3,25:18.2
-8,-3,25:18.2
-6,-3,25:18.2
-5,-3,25:17.2
-4,-3,25:17.2
-3,-3,25:17.2
-2,-3,25:18.2
-1,-3,25:17.2
0,-3,25:17.2
1,-3,25:17.2
3,-3,25:18.2
4,-3,25:18.2
5,-3,25:18.2
6,-3,25:18.2
7,-3,25:18.2
8,-3,25:18.2
9,-3,25:18.2
10,-3,25:18.2
14,-3,25:18.2
15,-3,25:18.2
16,-3,25:18.2
17,-3,25:18.2
18,-3,25:18.2
-12,-2,25:18.2
-11,-2,25:18.2
-10,-2,25:18.2
-9,-2,25:18.2
-8,-2,25:18.2
-7,-2,25:18.2
-6,-2,25:18.2
-5,-2,25:18.2
-4,-2,25:17.2
-3,-2,25:17.2
-2,-2,25:18.2
-1,-2,25:17.2
0,-2,25:17.2
3,-2,25:18.2
4,-2,25:18.2
5,-2,25:18.2
6,-2,25:18.2
7,-2,25:18.2
8,-2,25:18.2
9,-2,25:17.2
10,-2,25:18.2
11,-2,25:18.2
14,-2,25:18.2
15,-2,25:18.2
16,-2,25:18.2
17,-2,25:18.2
18,-2,25:18.2
-12,-1,25:18.2
-11,-1,25:17.2
-10,-1,25:17.2
-9,-1,25:17.2
-8,-1,25:17.2
-7,-1,25:18.2
-6,-1,25:17.2
-5,-1,25:17.2
-4,-1,25:17.2
-3,-1,25:18.2
-2,-1,25:17.2
0,-1,25:17.2
4,-1,25:18.2
5,-1,25:18.2
6,-1,25:18.2
7,-1,25:17.2
8,-1,25:17.2
9,-1,25:18.2
10,-1,25:18.2
11,-1,25:18.2
15,-1,25:18.2
16,-1,25:18.2
17,-1,25:18.2
-12,0,25:18.2
-11,0,25:18.2
-10,0,25:18.2
-9,0,25:18.2
-8,0,25:17.2
-7,0,25:17.2
-6,0,25:17.2
-5,0,25:18.2
-4,0,25:17.2
-3,0,25:17.2
-2,0,25:18.2
-1,0,25:17.2
0,0,25:17.2
1,0,25:17.2
7,0,25:18.2
8,0,25:18.2
9,0,25:18.2
10,0,25:17.2
11,0,25:17.2
-11,1,25:18.2
-10,1,25:18.2
-9,1,25:18.2
-8,1,25:18.2
-7,1,25:18.2
-6,1,25:18.2
-5,1,25:17.2
-4,1,25:17.2
-3,1,25:17.2
-2,1,25:18.2
0,1,25:17.2
1,1,25:17.2
8,1,25:18.2
9,1,25:18.2
10,1,25:18.2
16,1,25:18.2
-12,2,25:18.2
-11,2,25:18.2
-10,2,25:18.2
-9,2,25:18.2
-8,2,25:18.2
-7,2,25:18.2
-6,2,25:17.2
-5,2,25:18.2
-4,2,25:17.2
-3,2,25:17.2
-1,2,25:17.2
0,2,25:17.2
1,2,25:17.2
15,2,25:18.2
16,2,25:18.2
17,2,25:18.2
-12,3,25:18.2
-11,3,25:18.2
-10,3,25:18.2
-9,3,25:18.2
-8,3,25:17.2
-7,3,25:17.2
-6,3,25:18.2
-4,3,25:18.2
-3,3,25:18.2
-2,3,25:17.2
1,3,25:17.2
2,3,25:17.2
3,3,25:17.2
16,3,25:18.2
-15,4,25:18.2
-14,4,25:18.2
-13,4,25:18.2
-12,4,25:18.2
-11,4,25:18.2
-10,4,25:17.2
-9,4,25:17.2
-8,4,25:17.2
-7,4,25:18.2
-6,4,25:18.2
-4,4,25:18.2
-3,4,25:17.2
-2,4,25:18.2
-1,4,25:17.2
0,4,25:18.2
1,4,25:18.2
2,4,25:17.2
3,4,25:17.2
7,4,25:17.2
14,4,25:18.2
-16,5,25:18.2
-15,5,25:18.2
-14,5,25:18.2
-13,5,25:18.2
-12,5,25:18.2
-11,5,25:18.2
-10,5,25:18.2
-9,5,25:18.2
-8,5,25:18.2
-7,5,25:18.2
-5,5,25:17.2
-4,5,25:17.2
-3,5,25:18.2
-2,5,25:18.2
-1,5,25:17.2
0,5,25:18.2
1,5,25:18.2
2,5,25:17.2
5,5,25:17.2
8,5,25:17.2
13,5,25:17.2
14,5,25:17.2
15,5,25:18.2
-16,6,25:18.2
-15,6,25:18.2
-14,6,25:18.2
-13,6,25:18.2
-12,6,25:18.2
-9,6,25:17.2
-6,6,25:17.2
-5,6,25:17.2
-4,6,25:18.2
-3,6,25:18.2
-2,6,25:18.2
-1,6,25:17.2
0,6,25:18.2
1,6,25:18.2
3,6,25:17.2
6,6,25:17.2
11,6,25:18.2
12,6,25:18.2
13,6,25:18.2
14,6,25:18.2
-16,7,25:18.2
-15,7,25:18.2
-14,7,25:18.2
-13,7,25:18.2
-12,7,25:18.2
-11,7,25:18.2
-10,7,25:17.2
-9,7,25:17.2
-3,7,25:18.2
-1,7,25:17.2
0,7,25:18.2
1,7,25:18.2
2,7,25:18.2
3,7,25:17.2
9,7,25:17.2
10,7,25:18.2
11,7,25:18.2
12,7,25:18.2
13,7,25:18.2
14,7,25:18.2
-15,8,25:18.2
-14,8,25:18.2
-13,8,25:18.2
-12,8,25:18.2
-11,8,25:18.2
-10,8,25:17.2
-9,8,25:18.2
-8,8,25:18.2
0,8,25:18.2
1,8,25:18.2
2,8,25:17.2
3,8,25:17.2
4,8,25:18.2
7,8,25:18.2
8,8,25:18.2
9,8,25:18.2
10,8,25:17.2
11,8,25:18.2
12,8,25:18.2
13,8,25:18.2
14,8,25:18.2
-12,9,25:18.2
-11,9,25:18.2
-10,9,25:18.2
-9,9,25:18.2
-8,9,25:18.2
-7,9,25:18.2
-6,9,25:17.2
-1,9,25:17.2
0,9,25:18.2
1,9,25:18.2
2,9,25:17.2
3,9,25:17.2
4,9,25:18.2
6,9,25:18.2
7,9,25:18.2
8,9,25:18.2
9,9,25:18.2
10,9,25:18.2
11,9,25:18.2
12,9,25:18.2
13,9,25:18.2
14,9,25:18.2
-12,10,25:18.2
-11,10,25:18.2
-10,10,25:18.2
-9,10,25:18.2
-8,10,25:18.2
-7,10,25:17.2
-6,10,25:18.2
-3,10,25:18.2
-2,10,25:18.2
-1,10,25:17.2
0,10,25:18.2
1,10,25:18.2
2,10,25:18.2
3,10,25:18.2
4,10,25:17.2
6,10,25:18.2
7,10,25:18.2
8,10,25:18.2
9,10,25:18.2
10,10,25:18.2
11,10,25:18.2
12,10,25:18.2
13,10,25:18.2
-11,11,25:18.2
-10,11,25:18.2
-9,11,25:18.2
-7,11,25:18.2
-4,11,25:18.2
-3,11,25:18.2
-2,11,25:18.2
-1,11,25:17.2
0,11,25:18.2
1,11,25:18.2
2,11,25:18.2
3,11,25:18.2
4,11,25:17.2
6,11,25:18.2
7,11,25:18.2
8,11,25:18.2
9,11,25:18.2
10,11,25:18.2
11,11,25:18.2
12,11,25:18.2
-9,12,25:18.2
-8,12,25:18.2
-7,12,25:18.2
-5,12,25:18.2
-4,12,25:18.2
-3,12,25:18.2
-2,12,25:18.2
-1,12,25:18.2
0,12,25:18.2
1,12,25:18.2
2,12,25:18.2
3,12,25:18.2
7,12,25:18.2
8,12,25:18.2
9,12,25:18.2
-10,13,25:18.2
-9,13,25:18.2
-8,13,25:18.2
-7,13,25:18.2
-6,13,25:18.2
-4,13,25:18.2
-3,13,25:18.2
-2,13,25:18.2
-1,13,25:18.2
0,13,25:18.2
1,13,25:18.2
2,13,25:18.2
3,13,25:18.2
4,13,25:18.2
-10,14,25:18.2
-9,14,25:18.2
-8,14,25:18.2
-7,14,25:18.2
-6,14,25:18.2
-3,14,25:18.2
-2,14,25:18.2
-1,14,25:18.2
0,14,25:18.2
1,14,25:18.2
2,14,25:17.2
3,14,25:18.2
4,14,25:18.2
5,14,25:18.2
-10,15,25:18.2
-9,15,25:18.2
-8,15,25:18.2
-7,15,25:18.2
-6,15,25:18.2
0,15,25:18.2
1,15,25:18.2
2,15,25:17.2
3,15,25:18.2
4,15,25:18.2
5,15,25:18.2
-9,16,25:18.2
-8,16,25:18.2
-7,16,25:18.2
0,16,25:18.2
1,16,25:18.2
2,16,25:18.2
3,16,25:18.2
4,16,25:18.2
5,16,25:18.2
1,17,25:18.2
2,17,25:18.2
3,17,25:18.2
4,17,25:18.2
-2,-14,26:17.2
-2,-13,26:17.2
-1,-13,26:18.2
0,-13,26:18.2
1,-13,26:18.2
-6,-12,26:17.2
-3,-12,26:18.2
-2,-12,26:18.2
-1,-12,26:18.2
0,-12,26:18.2
1,-12,26:18.2
2,-12,26:18.2
-8,-11,26:18.2
-7,-11,26:18.2
-6,-11,26:18.2
-5,-11,26:17.2
-4,-11,26:18.2
-3,-11,26:18.2
-2,-11,26:18.2
-1,-11,26:18.2
0,-11,26:18.2
1,-11,26:18.2
2,-11,26:18.2
-9,-10,26:18.2
-8,-10,26:18.2
-7,-10,26:18.2
-6,-10,26:18.2
-5,-10,26:18.2
-4,-10,26:17.2
-3,-10,26:18.2
-2,-10,26:18.2
-1,-10,26:18.2
0,-10,26:18.2
1,-10,26:18.2
2,-10,26:18.2
-10,-9,26:18.2
-9,-9,26:18.2
-8,-9,26:18.2
-7,-9,26:18.2
-6,-9,26:18.2
-5,-9,26:18.2
-4,-9,26:17.2
-3,-9,26:18.2
-2,-9,26:18.2
-1,-9,26:18.2
0,-9,26:18.2
1,-9,26:18.2
14,-9,26:18.2
15,-9,26:18.2
16,-9,26:18.2
-10,-8,26:18.2
-9,-8,26:18.2
-8,-8,26:18.2
-7,-8,26:18.2
-6,-8,26:18.2
-5,-8,26:18.2
-4,-8,26:18.2
-3,-8,26:18.2
-2,-8,26:18.2
-1,-8,26:18.2
3,-8,26:17.2
5,-8,26:18.2
6,-8,26:18.2
7,-8,26:18.2
11,-8,26:18.2
12,-8,26:18.2
13,-8,26:18.2
14,-8,26:18.2
15,-8,26:18.2
16,-8,26:18.2
17,-8,26:18.2
-11,-7,26:18.2
-10,-7,26:18.2
-9,-7,26:18.2
-8,-7,26:18.2
-7,-7,26:18.2
-6,-7,26:18.2
-5,-7,26:18.2
-4,-7,26:18.2
-3,-7,26:18.2
-2,-7,26:18.2
3,-7,26:17.2
4,-7,26:17.2
5,-7,26:18.2
6,-7,26:18.2
7,-7,26:18.2
8,-7,26:18.2
10,-7,26:18.2
11,-7,26:18.2
12,-7,26:18.2
13,-7,26:18.2
14,-7,26:18.2
15,-7,26:18.2
16,-7,26:18.2
17,-7,26:18.2
-11,-6,26:18.2
-10,-6,26:18.2
-9,-6,26:18.2
-8,-6,26:17.2
-7,-6,26:18.2
-6,-6,26:17.2
-5,-6,26:18.2
-4,-6,26:18.2
-3,-6,26:18.2
-2,-6,26:17.2
3,-6,26:17.2
4,-6,26:17.2
5,-6,26:18.2
6,-6,26:18.2
7,-6,26:18.2
8,-6,26:18.2
10,-6,26:18.2
11,-6,26:18.2
12,-6,26:18.2
13,-6,26:18.2
14,-6,26:18.2
15,-6,26:18.2
16,-6,26:18.2
17,-6,26:18.2
-11,-5,26:18.2
-10,-5,26:18.2
-9,-5,26:18.2
-8,-5,26:18.2
-7,-5,26:17.2
-6,-5,26:18.2
-5,-5,26:17.2
-4,-5,26:18.2
-3,-5,26:18.2
-2,-5,26:17.2
-1,-5,26:17.2
1,-5,26:17.2
4,-5,26:18.2
5,-5,26:18.2
6,-5,26:18.2
7,-5,26:18.2
8,-5,26:18.2
10,-5,26:18.2
11,-5,26:18.2
12,-5,26:18.2
13,-5,26:18.2
14,-5,26:18.2
15,-5,26:18.2
16,-5,26:18.2
-11,-4,26:18.2
-10,-4,26:18.2
-9,-4,26:18.2
-8,-4,26:18.2
-7,-4,26:17.2
-6,-4,26:18.2
-5,-4,26:18.2
-4,-4,26:18.2
-3,-4,26:18.2
-2,-4,26:18.2
-1,-4,26:17.2
0,-4,26:17.2
1,-4,26:17.2
4,-4,26:18.2
5,-4,26:18.2
6,-4,26:18.2
7,-4,26:18.2
8,-4,26:18.2
11,-4,26:18.2
12,-4,26:18.2
13,-4,26:18.2
16,-4,26:18.2
-12,-3,26:18.2
-11,-3,26:18.2
-10,-3,26:18.2
-9,-3,26:18.2
-8,-3,26:18.2
-6,-3,26:17.2
-5,-3,26:18.2
-4,-3,26:18.2
-3,-3,26:18.2
-2,-3,26:18.2
-1,-3,26:17.2
0,-3,26:17.2
1,-3,26:17.2
4,-3,26:18.2
5,-3,26:18.2
6,-3,26:18.2
7,-3,26:18.2
8,-3,26:18.2
9,-3,26:18.2
11,-3,26:18.2
15,-3,26:18.2
16,-3,26:18.2
17,-3,26:18.2
-12,-2,26:18.2
-11,-2,26:18.2
-10,-2,26:18.2
-9,-2,26:18.2
-8,-2,26:18.2
-7,-2,26:18.2
-6,-2,26:18.2
-5,-2,26:18.2
-4,-2,26:18.2
-3,-2,26:18.2
-2,-2,26:18.2
-1,-2,26:17.2
0,-2,26:17.2
1,-2,26:17.2
5,-2,26:18.2
6,-2,26:18.2
7,-2,26:18.2
8,-2,26:18.2
9,-2,26:18.2
10,-2,26:17.2
11,-2,26:17.2
12,-2,26:18.2
16,-2,26:18.2
-13,-1,26:17.2
-12,-1,26:17.2
-11,-1,26:17.2
-10,-1,26:18.2
-9,-1,26:18.2
-8,-1,26:17.2
