
#######################################################################
# +-----------------------------------------------------------------+ #
# |                            BO3 object                           | #
# +-----------------------------------------------------------------+ #
#######################################################################

# This is the config file of a custom object.
# If you add this object correctly to your BiomeConfigs, it will spawn in the world.

# This is the creator of this BO3 object
Author: NLBlackEagle

# A short description of this BO3 object
Description: Converted version of the BO2 44

# The BO3 version, don't change this! It can be used by external applications to do a version check.
Version: 3

# The settings mode, WriteAll, WriteWithoutComments or WriteDisable. See WorldConfig.
SettingsMode: WriteDisable


#######################################################################
# +-----------------------------------------------------------------+ #
# |                          Main settings                          | #
# +-----------------------------------------------------------------+ #
#######################################################################

# This needs to be set to true to spawn the object in the Tree and Sapling resources.
Tree: true

# The frequency of the BO3 from 1 to 200. Tries this many times to spawn this BO3 when using the CustomObject(...) resource.
# Ignored by Tree(..), Sapling(..) and CustomStructure(..)
Frequency: 1

# The rarity of the BO3 from 0 to 100. Each spawn attempt has rarity% chance to succeed when using the CustomObject(...) resource.
# Ignored by Tree(..), Sapling(..) and CustomStructure(..)
Rarity: 100.0

# If you set this to true, the BO3 will be placed with a random rotation.
RotateRandomly: true

# The spawn height of the BO3 - randomY, highestBlock or highestSolidBlock.
SpawnHeight: highestSolidBlock

# The height limits for the BO3.
MinHeight: 0

MaxHeight: 199

# Objects can have other objects attacthed to it: branches. Branches can also
# have branches attached to it, which can also have branches, etc. This is the
# maximum branch depth for this objects.
MaxBranchDepth: 10

# When spawned with the UseWorld keyword, this BO3 should NOT spawn in the following biomes.
# If you writer.write the BO3 name directly in the BiomeConfigs, this will be ignored.
ExcludedBiomes: 


#######################################################################
# +-----------------------------------------------------------------+ #
# |                      Source block settings                      | #
# +-----------------------------------------------------------------+ #
#######################################################################

# The block(s) the BO3 should spawn in.
SourceBlocks: AIR

# The maximum percentage of the BO3 that can be outside the SourceBlock.
# The BO3 won't be placed on a location with more blocks outside the SourceBlock than this percentage.
MaxPercentageOutsideSourceBlock: 20

# What to do when a block is about to be placed outside the SourceBlock? (dontPlace, placeAnyway)
OutsideSourceBlock: placeAnyway


#######################################################################
# +-----------------------------------------------------------------+ #
# |                              Blocks                             | #
# +-----------------------------------------------------------------+ #
#######################################################################

# All the blocks used in the BO3 are listed here. Possible blocks:
# Block(x,y,z,id[.data][,nbtfile.nbt)
# RandomBlock(x,y,z,id[:data][,nbtfile.nbt],chance[,id[:data][,nbtfile.nbt],chance[,...]])
# So RandomBlock(0,0,0,CHEST,chest.nbt,50,CHEST,anotherchest.nbt,100) will spawn a chest at
# the BO3 origin, and give it a 50% chance to have the contents of chest.nbt, or, if that
# fails, a 100% percent chance to have the contents of anotherchest.nbt.
Block(15,16,-9,LEAVES:14)
Block(11,17,-12,LEAVES:14)
Block(11,7,-6,LEAVES:14)
Block(11,8,-6,LEAVES:14)
Block(9,8,-7,LEAVES:14)
Block(15,13,-9,LEAVES:14)
Block(9,17,-7,LEAVES:14)
Block(8,5,-14,LEAVES:6)
Block(9,19,-7,LEAVES:14)
Block(8,4,-14,LEAVES:6)
Block(9,1,-7,LOG:12)
Block(9,0,-7,LOG:12)
Block(9,14,-7,LEAVES:14)
Block(9,7,-5,LEAVES:14)
Block(9,6,-5,LEAVES:14)
Block(9,11,-7,LEAVES:14)
Block(12,20,-5,LEAVES:6)
Block(4,3,-11,LEAVES:6)
Block(11,12,-12,LEAVES:14)
Block(14,9,-3,LEAVES:6)
Block(11,16,-12,LEAVES:14)
Block(11,13,-12,LEAVES:14)
Block(12,4,-13,LEAVES:6)
Block(8,18,-4,LEAVES:14)
Block(12,12,-5,LEAVES:14)
Block(15,6,-9,LEAVES:6)
Block(11,20,-12,LEAVES:6)
Block(15,5,-9,LEAVES:14)
Block(12,11,-5,LEAVES:14)
Block(12,17,-5,LEAVES:14)
Block(8,12,-4,LEAVES:14)
Block(12,14,-5,LEAVES:14)
Block(12,15,-5,LEAVES:14)
Block(8,17,-7,LEAVES:14)
Block(8,18,-7,LEAVES:14)
Block(8,19,-7,LEAVES:14)
Block(13,17,-12,LEAVES:14)
Block(14,14,-4,LEAVES:14)
Block(13,11,-12,LEAVES:14)
Block(8,16,-7,LEAVES:14)
Block(10,9,-7,LEAVES:14)
Block(10,8,-7,LEAVES:14)
Block(10,7,-7,LOG:12)
Block(16,3,-4,LEAVES:6)
Block(10,6,-7,LOG:12)
Block(15,3,-13,LEAVES:6)
Block(10,5,-7,LOG:12)
Block(10,3,-15,LEAVES:6)
Block(6,9,-10,LEAVES:14)
Block(10,7,-5,LEAVES:14)
Block(16,4,-6,LEAVES:6)
Block(8,11,-7,LEAVES:14)
Block(6,4,-10,LEAVES:14)
Block(9,24,-7,LEAVES:6)
Block(10,6,-5,LEAVES:14)
Block(9,23,-7,LEAVES:6)
Block(10,1,-7,LOG:12)
Block(10,2,-7,LOG:12)
Block(10,3,-7,LOG:12)
Block(10,4,-7,LOG:12)
Block(9,21,-7,LEAVES:6)
Block(10,0,-7,LOG:12)
Block(9,20,-7,LEAVES:6)
Block(7,23,-6,LEAVES:6)
Block(8,6,-4,LEAVES:14)
Block(8,5,-4,LEAVES:14)
Block(8,9,-4,LEAVES:14)
Block(10,10,-5,LEAVES:14)
Block(6,6,-7,LEAVES:14)
Block(10,15,-5,LEAVES:14)
Block(10,14,-5,LEAVES:14)
Block(10,13,-5,LEAVES:14)
Block(6,5,-7,LEAVES:14)
Block(14,17,-12,LEAVES:14)
Block(10,18,-5,LEAVES:14)
Block(8,5,-2,LEAVES:6)
Block(7,10,-6,LEAVES:14)
Block(10,20,-5,LEAVES:6)
Block(10,22,-5,LEAVES:6)
Block(10,21,-5,LEAVES:6)
Block(7,17,-6,LEAVES:14)
Block(7,15,-6,LEAVES:14)
Block(7,16,-6,LEAVES:14)
Block(6,14,-12,LEAVES:14)
Block(6,4,-13,LEAVES:6)
Block(16,5,-9,LEAVES:6)
Block(5,15,-6,LEAVES:6)
Block(7,5,-7,LEAVES:14)
Block(7,6,-7,LEAVES:14)
Block(11,6,-4,LEAVES:14)
Block(11,5,-4,LEAVES:14)
Block(15,14,-5,LEAVES:14)
Block(7,5,-5,LEAVES:14)
Block(5,5,-7,LEAVES:14)
Block(13,11,0,LEAVES:6)
Block(7,9,-5,LEAVES:14)
Block(5,10,-6,LEAVES:14)
Block(7,4,-12,LEAVES:14)
Block(7,5,-12,LEAVES:14)
Block(18,5,-9,LEAVES:6)
Block(14,4,-12,LEAVES:14)
Block(7,5,-10,LEAVES:14)
Block(7,9,-10,LEAVES:14)
Block(7,12,-12,LEAVES:14)
Block(7,15,-12,LEAVES:14)
Block(7,11,-12,LEAVES:14)
Block(8,12,-12,LEAVES:14)
Block(12,12,-3,LEAVES:6)
Block(15,5,-7,LEAVES:14)
Block(11,-7,-7,LOG:12)
Block(9,11,-2,LEAVES:6)
Block(6,16,-10,LEAVES:14)
Block(6,15,-10,LEAVES:14)
Block(7,20,-9,LEAVES:6)
Block(12,3,-2,LEAVES:6)
Block(10,12,-14,LEAVES:6)
Block(12,6,-4,LEAVES:14)
Block(12,4,-4,LEAVES:14)
Block(12,5,-4,LEAVES:14)
Block(11,-4,-7,LOG:12)
Block(11,-5,-7,LOG:12)
Block(13,9,-4,LEAVES:14)
Block(13,5,-4,LEAVES:14)
Block(13,4,-4,LEAVES:14)
Block(14,5,-10,LEAVES:14)
Block(10,24,-8,LEAVES:6)
Block(10,25,-8,LOG)
Block(10,22,-8,LEAVES:6)
Block(10,23,-8,LOG)
Block(10,20,-8,LOG)
Block(10,21,-8,LEAVES:6)
Block(9,6,-11,LEAVES:14)
Block(13,5,-6,LEAVES:14)
Block(13,6,-6,LEAVES:14)
Block(10,28,-8,LEAVES:6)
Block(10,26,-8,LOG)
Block(10,27,-8,LOG)
Block(8,20,-7,LEAVES:6)
Block(7,17,-4,LEAVES:14)
Block(8,23,-7,LEAVES:6)
Block(13,24,-8,LEAVES:6)
Block(7,17,-9,LEAVES:14)
Block(7,16,-9,LEAVES:14)
Block(7,19,-9,LEAVES:14)
Block(7,13,-9,LEAVES:14)
Block(7,10,-9,LEAVES:14)
Block(9,4,-15,LEAVES:6)
Block(9,3,-15,LEAVES:6)
Block(12,11,-1,LEAVES:6)
Block(13,18,-8,LEAVES:14)
Block(13,17,-8,LEAVES:14)
Block(13,15,-8,LEAVES:14)
Block(11,4,-2,LEAVES:6)
Block(11,3,-2,LEAVES:6)
Block(11,27,-7,LEAVES:6)
Block(5,9,-9,LEAVES:14)
Block(11,26,-7,LEAVES:6)
Block(11,23,-7,LEAVES:6)
Block(11,21,-7,LEAVES:6)
Block(13,9,-6,LEAVES:14)
Block(11,6,-6,LEAVES:14)
Block(6,4,-4,LEAVES:14)
Block(6,9,-4,LEAVES:14)
Block(12,16,-13,LEAVES:6)
Block(6,8,-4,LEAVES:14)
Block(12,11,-13,LEAVES:6)
Block(12,12,-13,LEAVES:6)
Block(11,19,-7,LEAVES:14)
Block(11,14,-7,LEAVES:14)
Block(11,13,-7,LEAVES:14)
Block(11,16,-7,LEAVES:14)
Block(6,4,-2,LEAVES:6)
Block(11,12,-7,LEAVES:14)
Block(5,15,-11,LEAVES:6)
Block(12,10,-7,LEAVES:14)
Block(8,11,-8,LEAVES:14)
Block(12,11,-7,LEAVES:14)
Block(12,15,-9,LEAVES:14)
Block(12,18,-9,LEAVES:14)
Block(12,19,-9,LEAVES:14)
Block(12,16,-7,LEAVES:14)
Block(9,7,-9,LEAVES:14)
Block(12,18,-7,LEAVES:14)
Block(5,15,-8,LEAVES:6)
Block(12,13,-9,LEAVES:14)
Block(5,16,-8,LEAVES:6)
Block(11,21,-6,LEAVES:6)
Block(4,15,-10,LEAVES:6)
Block(4,16,-10,LEAVES:6)
Block(8,18,-8,LEAVES:14)
Block(12,20,-6,LEAVES:6)
Block(8,17,-8,LEAVES:14)
Block(11,23,-6,LEAVES:6)
Block(10,4,-2,LEAVES:6)
Block(12,25,-9,LEAVES:6)
Block(12,21,-7,LEAVES:6)
Block(8,23,-8,LEAVES:6)
Block(10,6,-11,LEAVES:14)
Block(8,20,-8,LEAVES:6)
Block(5,3,-10,LEAVES:14)
Block(12,27,-7,LEAVES:6)
Block(12,20,-9,LEAVES:6)
Block(12,21,-9,LEAVES:6)
Block(12,26,-7,LEAVES:6)
Block(12,24,-9,LEAVES:6)
Block(5,16,-10,LEAVES:6)
Block(5,15,-10,LEAVES:6)
Block(3,9,-7,LEAVES:6)
Block(12,5,-11,LEAVES:14)
Block(10,4,-13,LEAVES:6)
Block(10,5,-13,LEAVES:6)
Block(10,13,-12,LEAVES:14)
Block(12,6,-11,LEAVES:14)
Block(10,-1,-9,LOG:12)
Block(10,-6,-9,LOG:12)
Block(14,14,-5,LEAVES:14)
Block(10,-8,-9,LOG:12)
Block(13,5,-12,LEAVES:14)
Block(13,4,-12,LEAVES:14)
Block(10,-2,-9,LOG:12)
Block(10,-3,-9,LOG:12)
Block(10,-4,-9,LOG:12)
Block(10,-5,-9,LOG:12)
Block(13,6,-10,LEAVES:14)
Block(14,14,-9,LEAVES:14)
Block(8,20,-11,LEAVES:6)
Block(14,17,-9,LEAVES:14)
Block(10,20,-12,LEAVES:6)
Block(11,11,-14,LEAVES:6)
Block(11,12,-14,LEAVES:6)
Block(11,9,-8,LEAVES:14)
Block(8,19,-11,LEAVES:14)
Block(12,11,-6,LEAVES:14)
Block(8,16,-11,LEAVES:14)
Block(12,12,-6,LEAVES:14)
Block(12,18,-6,LEAVES:14)
Block(12,15,-6,LEAVES:14)
Block(8,6,-10,LEAVES:14)
Block(12,10,-6,LEAVES:14)
Block(8,15,-11,LEAVES:14)
Block(8,12,-11,LEAVES:14)
Block(8,5,-10,LEAVES:14)
Block(8,13,-11,LEAVES:14)
Block(11,12,-8,LEAVES:14)
Block(15,15,-6,LEAVES:14)
Block(9,21,-9,LEAVES:6)
Block(11,13,-8,LEAVES:14)
Block(15,14,-6,LEAVES:14)
Block(9,23,-9,LEAVES:6)
Block(11,10,-8,LEAVES:14)
Block(8,7,-6,LEAVES:14)
Block(11,5,-12,LEAVES:14)
Block(11,11,-8,LEAVES:14)
Block(11,6,-12,LEAVES:14)
Block(11,7,-12,LEAVES:14)
Block(9,20,-9,LEAVES:6)
Block(11,18,-8,LOG)
Block(11,19,-8,LEAVES:14)
Block(8,6,-6,LEAVES:14)
Block(7,5,-9,LEAVES:14)
Block(11,16,-8,LEAVES:14)
Block(11,17,-8,LOG)
Block(11,14,-8,LOG:12)
Block(11,15,-8,LOG:12)
Block(10,18,-10,LEAVES:14)
Block(10,14,-10,LEAVES:14)
Block(10,17,-10,LEAVES:14)
Block(10,16,-10,LEAVES:14)
Block(8,7,-8,LEAVES:14)
Block(11,3,-14,LEAVES:6)
Block(8,6,-8,LEAVES:14)
Block(11,0,-8,LOG:12)
Block(11,1,-8,LOG:12)
Block(11,4,-14,LEAVES:6)
Block(9,28,-9,LEAVES:6)
Block(12,8,-9,LEAVES:14)
Block(12,7,-9,LEAVES:14)
Block(12,12,-2,LEAVES:6)
Block(12,11,-2,LEAVES:6)
Block(11,6,-10,LEAVES:14)
Block(11,7,-10,LEAVES:14)
Block(11,13,-4,LEAVES:14)
Block(11,17,-4,LEAVES:14)
Block(11,8,-10,LEAVES:14)
Block(11,14,-4,LEAVES:14)
Block(11,11,-1,LEAVES:6)
Block(9,5,-13,LEAVES:6)
Block(10,11,-2,LEAVES:6)
Block(11,30,-8,LOG)
Block(7,12,-10,LEAVES:14)
Block(11,31,-8,LOG)
Block(7,10,-10,LEAVES:14)
Block(16,14,-5,LEAVES:6)
Block(7,19,-10,LEAVES:14)
Block(7,16,-10,LEAVES:14)
Block(11,2,-16,LEAVES:6)
Block(4,9,-7,LEAVES:6)
Block(7,4,-1,LEAVES:6)
Block(7,5,-1,LEAVES:6)
Block(11,20,-8,LOG)
Block(11,21,-8,LEAVES:6)
Block(11,22,-8,LEAVES:6)
Block(11,23,-8,LOG)
Block(11,24,-8,LOG)
Block(11,25,-8,LEAVES:6)
Block(11,26,-8,LOG)
Block(11,27,-8,LEAVES:6)
Block(11,28,-8,LOG)
Block(11,29,-8,LOG)
Block(11,13,-6,LEAVES:14)
Block(11,12,-6,LEAVES:14)
Block(11,15,-6,LEAVES:14)
Block(11,14,-6,LEAVES:14)
Block(11,19,-6,LEAVES:14)
Block(11,18,-6,LEAVES:14)
Block(7,5,-3,LEAVES:14)
Block(7,8,-3,LEAVES:6)
Block(6,10,-5,LEAVES:14)
Block(11,17,-11,LEAVES:14)
Block(6,15,-6,LEAVES:14)
Block(5,4,-6,LEAVES:14)
Block(5,5,-6,LEAVES:14)
Block(6,10,-6,LEAVES:14)
Block(11,-5,-8,LOG:12)
Block(11,-4,-8,LOG:12)
Block(11,-7,-8,LOG:12)
Block(10,5,-4,LEAVES:14)
Block(5,9,-4,LEAVES:14)
Block(11,-1,-8,LOG:12)
Block(5,8,-4,LEAVES:14)
Block(8,12,-13,LEAVES:6)
Block(11,-3,-8,LOG:12)
Block(11,-2,-8,LOG:12)
Block(10,20,-13,LEAVES:6)
Block(5,4,-4,LEAVES:14)
Block(11,13,-11,LEAVES:14)
Block(16,4,-11,LEAVES:6)
Block(6,17,-5,LEAVES:14)
Block(13,10,-3,LEAVES:6)
Block(8,3,-16,LEAVES:6)
Block(13,11,-3,LEAVES:6)
Block(8,4,-16,LEAVES:6)
Block(13,13,-3,LEAVES:6)
Block(13,18,-11,LEAVES:14)
Block(5,3,-12,LEAVES:14)
Block(6,4,-12,LEAVES:14)
Block(13,12,-11,LEAVES:14)
Block(13,17,-11,LEAVES:14)
Block(10,12,-13,LEAVES:6)
Block(10,13,-13,LEAVES:6)
Block(15,5,-6,LEAVES:14)
Block(15,4,-6,LEAVES:14)
Block(9,11,-1,LEAVES:6)
Block(9,10,-1,LEAVES:6)
Block(15,3,-4,LEAVES:14)
Block(15,4,-4,LEAVES:14)
Block(14,6,-9,LEAVES:14)
Block(9,18,-5,LEAVES:14)
Block(9,19,-5,LEAVES:14)
Block(12,7,-8,LEAVES:14)
Block(12,8,-8,LEAVES:14)
Block(9,13,-5,LEAVES:14)
Block(9,10,-5,LEAVES:14)
Block(7,17,-3,LEAVES:6)
Block(14,5,-5,LEAVES:14)
Block(9,11,-3,LEAVES:6)
Block(9,14,-9,LEAVES:14)
Block(14,4,-5,LEAVES:14)
Block(9,17,-9,LEAVES:14)
Block(7,5,-14,LEAVES:6)
Block(9,12,-3,LEAVES:6)
Block(9,18,-3,LEAVES:6)
Block(11,-8,-8,LOG:12)
Block(9,17,-3,LEAVES:6)
Block(10,28,-10,LEAVES:6)
Block(17,4,-7,LEAVES:6)
Block(13,11,-4,LEAVES:14)
Block(10,20,-10,LEAVES:6)
Block(13,10,-4,LEAVES:14)
Block(13,13,-4,LEAVES:14)
Block(10,21,-10,LEAVES:6)
Block(10,24,-10,LEAVES:6)
Block(9,4,-2,LEAVES:6)
Block(8,5,-12,LEAVES:14)
Block(9,5,-2,LEAVES:6)
Block(13,14,-4,LEAVES:14)
Block(11,20,-11,LEAVES:6)
Block(11,24,-11,LEAVES:6)
Block(12,6,-6,LEAVES:14)
Block(7,4,-16,LEAVES:6)
Block(9,11,-9,LEAVES:14)
Block(12,7,-6,LEAVES:14)
Block(10,3,-8,LOG:12)
Block(10,2,-8,LOG:12)
Block(8,16,-6,LEAVES:14)
Block(10,1,-8,LOG:12)
Block(9,20,-12,LEAVES:6)
Block(10,0,-8,LOG:12)
Block(8,18,-6,LEAVES:14)
Block(8,13,-6,LEAVES:14)
Block(8,10,-6,LEAVES:14)
Block(8,11,-6,LEAVES:14)
Block(13,6,-8,LEAVES:14)
Block(16,5,-7,LEAVES:6)
Block(16,4,-7,LEAVES:6)
Block(15,17,-12,LEAVES:14)
Block(8,23,-6,LEAVES:6)
Block(9,20,-5,LEAVES:6)
Block(9,22,-5,LEAVES:6)
Block(10,8,-8,LOG:12)
Block(10,9,-8,LOG:12)
Block(9,-1,-7,LOG:12)
Block(10,4,-8,LOG:12)
Block(10,5,-8,LOG:12)
Block(9,13,-12,LEAVES:14)
Block(10,6,-8,LOG:12)
Block(9,-2,-7,LOG:12)
Block(10,7,-8,LOG:12)
Block(9,-3,-7,LOG:12)
Block(15,4,-12,LEAVES:14)
Block(15,3,-12,LEAVES:14)
Block(4,8,-9,LEAVES:6)
Block(9,21,-10,LEAVES:6)
Block(9,20,-10,LEAVES:6)
Block(9,17,-10,LEAVES:14)
Block(9,16,-10,LEAVES:14)
Block(9,19,-10,LEAVES:14)
Block(4,3,-5,LEAVES:6)
Block(9,-1,-9,LOG:12)
Block(9,13,-10,LEAVES:14)
Block(9,-3,-9,LOG:12)
Block(9,-2,-9,LOG:12)
Block(9,14,-10,LEAVES:14)
Block(4,9,-5,LEAVES:6)
Block(9,10,-10,LEAVES:14)
Block(13,7,-8,LEAVES:14)
Block(11,19,-9,LEAVES:14)
Block(6,6,-8,LEAVES:14)
Block(11,18,-9,LEAVES:14)
Block(11,16,-9,LEAVES:14)
Block(11,14,-9,LEAVES:14)
Block(11,8,-5,LEAVES:14)
Block(11,25,-10,LEAVES:6)
Block(11,24,-10,LEAVES:6)
Block(4,3,-12,LEAVES:6)
Block(17,5,-9,LEAVES:6)
Block(11,21,-10,LEAVES:6)
Block(11,20,-10,LEAVES:6)
Block(6,5,-6,LEAVES:14)
Block(11,28,-9,LEAVES:6)
Block(9,7,-10,LEAVES:14)
Block(11,25,-9,LEAVES:6)
Block(9,6,-10,LEAVES:14)
Block(11,18,-10,LEAVES:14)
Block(11,21,-9,LEAVES:6)
Block(11,14,-10,LEAVES:14)
Block(11,13,-10,LEAVES:14)
Block(9,-7,-8,LOG:12)
Block(9,-8,-8,LOG:12)
Block(15,5,-10,LEAVES:14)
Block(9,-5,-8,LOG:12)
Block(9,-6,-8,LOG:12)
Block(9,-3,-8,LOG:12)
Block(6,4,-14,LEAVES:6)
Block(9,-1,-8,LOG:12)
Block(9,-2,-8,LOG:12)
Block(9,3,-16,LEAVES:6)
Block(11,4,-3,LEAVES:14)
Block(11,5,-5,LEAVES:14)
Block(11,7,-5,LEAVES:14)
Block(6,5,-5,LEAVES:14)
Block(11,6,-5,LEAVES:14)
Block(6,4,-5,LEAVES:14)
Block(6,9,-5,LEAVES:14)
Block(8,9,-5,LEAVES:14)
Block(9,8,-6,LEAVES:14)
Block(6,10,-8,LEAVES:14)
Block(11,-7,-9,LOG:12)
Block(9,7,-6,LEAVES:14)
Block(8,6,-5,LEAVES:14)
Block(8,5,-3,LEAVES:14)
Block(14,8,-4,LEAVES:14)
Block(14,4,-4,LEAVES:14)
Block(6,16,-8,LEAVES:14)
Block(13,24,-11,LEAVES:6)
Block(15,6,-8,LEAVES:6)
Block(15,5,-8,LEAVES:14)
Block(12,3,-14,LEAVES:6)
Block(9,19,-8,LEAVES:14)
Block(9,18,-8,LEAVES:14)
Block(9,17,-8,LEAVES:14)
Block(13,11,-13,LEAVES:6)
Block(9,14,-8,LEAVES:14)
Block(16,3,-5,LEAVES:6)
Block(15,14,-8,LEAVES:14)
Block(15,13,-8,LEAVES:14)
Block(11,17,-3,LEAVES:6)
Block(10,8,-6,LEAVES:14)
Block(10,7,-6,LEAVES:14)
Block(10,3,-16,LEAVES:6)
Block(9,11,-8,LEAVES:14)
Block(9,12,-8,LEAVES:14)
Block(13,10,-6,LEAVES:14)
Block(7,5,-6,LEAVES:14)
Block(13,15,-6,LEAVES:14)
Block(7,6,-6,LEAVES:14)
Block(9,18,-4,LEAVES:14)
Block(11,16,-3,LEAVES:6)
Block(7,9,-4,LEAVES:14)
Block(7,8,-4,LEAVES:14)
Block(13,16,-7,LEAVES:14)
Block(11,12,-3,LEAVES:6)
Block(13,15,-7,LEAVES:14)
Block(13,18,-7,LEAVES:14)
Block(13,17,-7,LEAVES:14)
Block(9,20,-8,LEAVES:6)
Block(9,21,-8,LEAVES:6)
Block(9,12,-4,LEAVES:14)
Block(9,23,-8,LEAVES:6)
Block(5,9,-8,LEAVES:14)
Block(7,5,-4,LEAVES:14)
Block(10,-3,-7,LOG:12)
Block(10,-2,-7,LOG:12)
Block(10,20,-4,LEAVES:6)
Block(10,-1,-7,LOG:12)
Block(18,4,-8,LEAVES:6)
Block(14,17,-11,LEAVES:14)
Block(10,-7,-7,LOG:12)
Block(10,-5,-7,LOG:12)
Block(4,16,-9,LEAVES:6)
Block(10,-4,-7,LOG:12)
Block(8,12,-14,LEAVES:6)
Block(11,3,-15,LEAVES:6)
Block(10,-8,-7,LOG:12)
Block(13,11,-2,LEAVES:6)
Block(13,10,-2,LEAVES:6)
Block(8,11,-3,LEAVES:6)
Block(8,18,-3,LEAVES:6)
Block(8,17,-3,LEAVES:6)
Block(6,4,-16,LEAVES:6)
Block(6,8,-3,LEAVES:6)
Block(12,4,-3,LEAVES:14)
Block(6,4,-3,LEAVES:14)
Block(7,17,-7,LEAVES:14)
Block(7,16,-7,LEAVES:14)
Block(9,20,-11,LEAVES:6)
Block(9,5,-4,LEAVES:14)
Block(9,6,-4,LEAVES:14)
Block(7,19,-7,LEAVES:14)
Block(10,11,-7,LEAVES:14)
Block(7,18,-7,LEAVES:14)
Block(10,16,-7,LEAVES:14)
Block(12,4,-12,LEAVES:14)
Block(14,4,-11,LEAVES:14)
Block(10,14,-7,LEAVES:14)
Block(13,4,-3,LEAVES:14)
Block(14,5,-11,LEAVES:14)
Block(10,15,-7,LEAVES:14)
Block(7,5,-11,LEAVES:14)
Block(7,4,-11,LEAVES:14)
Block(12,5,-12,LEAVES:14)
Block(13,9,-3,LEAVES:6)
Block(10,19,-7,LEAVES:14)
Block(10,20,-9,LEAVES:6)
Block(13,5,-5,LEAVES:14)
Block(14,4,-13,LEAVES:6)
Block(10,22,-9,LEAVES:6)
Block(7,20,-8,LEAVES:6)
Block(10,21,-9,LEAVES:6)
Block(13,8,-5,LEAVES:14)
Block(13,9,-5,LEAVES:14)
Block(13,6,-5,LEAVES:14)
Block(10,25,-9,LEAVES:6)
Block(10,28,-9,LEAVES:6)
Block(7,11,-7,LEAVES:14)
Block(10,20,-7,LEAVES:6)
Block(10,21,-7,LEAVES:6)
Block(10,22,-7,LEAVES:6)
Block(10,23,-7,LEAVES:6)
Block(10,24,-7,LEAVES:6)
Block(7,17,-8,LEAVES:14)
Block(7,18,-8,LEAVES:14)
Block(7,16,-8,LEAVES:14)
Block(7,19,-8,LEAVES:14)
Block(7,10,-8,LEAVES:14)
Block(9,1,-8,LOG:12)
Block(9,0,-8,LOG:12)
Block(9,5,-8,LOG:12)
Block(10,15,-9,LEAVES:14)
Block(9,4,-8,LOG:12)
Block(10,14,-9,LEAVES:14)
Block(9,3,-8,LOG:12)
Block(9,2,-8,LOG:12)
Block(7,11,-8,LEAVES:14)
Block(10,19,-9,LEAVES:14)
Block(9,8,-8,LOG:12)
Block(10,18,-9,LEAVES:14)
Block(9,7,-8,LEAVES:14)
Block(10,17,-9,LEAVES:14)
Block(9,6,-8,LOG:12)
Block(15,16,-10,LEAVES:14)
Block(15,17,-10,LEAVES:14)
Block(12,12,-11,LEAVES:14)
Block(12,13,-11,LEAVES:14)
Block(10,12,-3,LEAVES:6)
Block(7,12,-11,LEAVES:14)
Block(10,17,-3,LEAVES:6)
Block(12,18,-11,LEAVES:14)
Block(12,17,-11,LEAVES:14)
Block(12,19,-11,LEAVES:14)
Block(7,15,-11,LEAVES:14)
Block(10,12,-4,LEAVES:14)
Block(10,13,-4,LEAVES:14)
Block(12,20,-11,LEAVES:6)
Block(15,17,-11,LEAVES:14)
Block(15,16,-11,LEAVES:14)
Block(12,24,-11,LEAVES:6)
Block(10,17,-4,LEAVES:14)
Block(10,18,-4,LEAVES:14)
Block(9,13,-13,LEAVES:6)
Block(9,12,-13,LEAVES:6)
Block(7,22,-7,LEAVES:6)
Block(9,12,-14,LEAVES:6)
Block(12,10,-8,LEAVES:14)
Block(11,4,-13,LEAVES:6)
Block(12,16,-8,LEAVES:14)
Block(6,15,-11,LEAVES:14)
Block(12,15,-8,LEAVES:14)
Block(12,19,-8,LEAVES:14)
Block(14,17,-10,LEAVES:14)
Block(12,18,-8,LEAVES:14)
Block(16,3,-12,LEAVES:6)
Block(9,5,-12,LEAVES:14)
Block(9,6,-12,LEAVES:14)
Block(5,3,-11,LEAVES:14)
Block(14,14,-8,LEAVES:14)
Block(14,17,-8,LEAVES:14)
Block(14,15,-6,LEAVES:14)
Block(9,4,-14,LEAVES:6)
Block(13,24,-9,LEAVES:6)
Block(9,16,-11,LEAVES:14)
Block(9,15,-11,LEAVES:14)
Block(9,13,-11,LEAVES:14)
Block(11,8,-7,LEAVES:14)
Block(13,14,-9,LEAVES:14)
Block(11,9,-7,LEAVES:14)
Block(13,13,-9,LEAVES:14)
Block(13,15,-9,LEAVES:14)
Block(13,18,-9,LEAVES:14)
Block(13,12,-9,LEAVES:14)
Block(11,7,-9,LEAVES:14)
Block(11,9,-9,LEAVES:14)
Block(11,8,-9,LEAVES:14)
Block(7,6,-8,LEAVES:14)
Block(7,7,-8,LEAVES:14)
Block(10,4,-3,LEAVES:14)
Block(7,5,-8,LEAVES:14)
Block(10,5,-3,LEAVES:14)
Block(13,12,-10,LEAVES:14)
Block(12,17,-4,LEAVES:14)
Block(4,10,-6,LEAVES:6)
Block(8,10,-9,LEAVES:14)
Block(8,11,-9,LEAVES:14)
Block(8,7,-7,LEAVES:14)
Block(17,4,-10,LEAVES:6)
Block(8,13,-9,LEAVES:14)
Block(8,17,-9,LEAVES:14)
Block(8,6,-9,LEAVES:14)
Block(6,10,-9,LEAVES:14)
Block(13,18,-10,LEAVES:14)
Block(6,16,-9,LEAVES:14)
Block(10,5,-12,LEAVES:14)
Block(13,24,-10,LEAVES:6)
Block(12,7,-10,LEAVES:14)
Block(12,6,-10,LEAVES:14)
Block(7,11,-13,LEAVES:6)
Block(12,20,-10,LEAVES:6)
Block(5,16,-9,LEAVES:6)
Block(12,24,-10,LEAVES:6)
Block(12,25,-10,LEAVES:6)
Block(12,18,-10,LEAVES:14)
Block(13,6,-11,LEAVES:14)
Block(4,15,-8,LEAVES:6)
Block(13,5,-11,LEAVES:14)
Block(12,15,-10,LEAVES:14)
Block(12,13,-10,LEAVES:14)
Block(16,13,-8,LEAVES:6)
Block(12,24,-8,LEAVES:6)
Block(12,25,-8,LEAVES:6)
Block(12,26,-8,LEAVES:6)
Block(12,21,-8,LEAVES:6)
Block(14,6,-8,LEAVES:14)
Block(8,20,-9,LEAVES:6)
Block(7,5,-13,LEAVES:6)
Block(7,4,-13,LEAVES:6)
Block(7,5,-2,LEAVES:6)
Block(14,5,-6,LEAVES:14)
Block(7,4,-2,LEAVES:6)
Block(8,5,-1,LEAVES:6)
Block(10,14,-11,LEAVES:14)
Block(10,13,-11,LEAVES:14)
Block(13,11,-1,LEAVES:6)
Block(10,19,-6,LEAVES:14)
Block(16,4,-10,LEAVES:6)
Block(10,15,-6,LEAVES:14)
Block(16,5,-10,LEAVES:6)
Block(10,14,-6,LEAVES:14)
Block(10,11,-6,LEAVES:14)
Block(11,12,-2,LEAVES:6)
Block(10,10,-6,LEAVES:14)
Block(10,17,-11,LEAVES:14)
Block(11,11,-2,LEAVES:6)
Block(6,4,-11,LEAVES:14)
Block(10,16,-11,LEAVES:14)
Block(5,3,-13,LEAVES:14)
Block(10,21,-11,LEAVES:6)
Block(10,20,-11,LEAVES:6)
Block(10,-8,-8,LOG:12)
Block(10,-7,-8,LOG:12)
Block(10,-6,-8,LOG:12)
Block(10,-5,-8,LOG:12)
Block(10,-4,-8,LOG:12)
Block(10,-3,-8,LOG:12)
Block(10,-2,-8,LOG:12)
Block(10,-1,-8,LOG:12)
Block(11,7,-11,LEAVES:14)
Block(11,6,-11,LEAVES:14)
Block(8,17,-2,LEAVES:6)
Block(11,5,-11,LEAVES:14)
Block(11,18,-5,LEAVES:14)
Block(11,15,-5,LEAVES:14)
Block(11,14,-5,LEAVES:14)
Block(11,13,-5,LEAVES:14)
Block(12,7,-7,LEAVES:14)
Block(12,8,-7,LEAVES:14)
Block(4,9,-8,LEAVES:6)
Block(12,12,-4,LEAVES:14)
Block(12,11,-4,LEAVES:14)
Block(12,16,-12,LEAVES:14)
Block(12,17,-12,LEAVES:14)
Block(12,12,-12,LEAVES:14)
Block(12,14,-4,LEAVES:14)
Block(12,13,-4,LEAVES:14)
Block(11,21,-5,LEAVES:6)
Block(7,10,-5,LEAVES:14)
Block(4,9,-6,LEAVES:6)
Block(11,20,-5,LEAVES:6)
Block(12,7,-5,LEAVES:14)
Block(7,17,-5,LEAVES:14)
Block(13,7,-9,LEAVES:14)
Block(12,5,-5,LEAVES:14)
Block(5,10,-7,LEAVES:14)
Block(12,6,-5,LEAVES:14)
Block(13,6,-9,LEAVES:14)
Block(7,12,-5,LEAVES:14)
Block(5,15,-7,LEAVES:6)
Block(4,3,-4,LEAVES:6)
Block(12,19,-12,LEAVES:14)
Block(10,21,-6,LEAVES:6)
Block(10,23,-6,LEAVES:6)
Block(6,10,-7,LEAVES:14)
Block(10,1,-9,LOG:12)
Block(10,0,-9,LOG:12)
Block(9,10,-6,LEAVES:14)
Block(9,16,-6,LEAVES:14)
Block(9,4,-1,LEAVES:6)
Block(9,18,-6,LEAVES:14)
Block(9,11,-6,LEAVES:14)
Block(5,9,-5,LEAVES:14)
Block(9,13,-6,LEAVES:14)
Block(9,14,-6,LEAVES:14)
Block(10,7,-10,LEAVES:14)
Block(13,6,-7,LEAVES:14)
Block(6,15,-7,LEAVES:14)
Block(13,7,-7,LEAVES:14)
Block(6,16,-7,LEAVES:14)
Block(9,19,-6,LEAVES:14)
Block(5,4,-5,LEAVES:14)
Block(8,10,-10,LEAVES:14)
Block(8,13,-10,LEAVES:14)
Block(9,21,-6,LEAVES:6)
Block(9,20,-6,LEAVES:6)
Block(10,4,-14,LEAVES:6)
Block(8,16,-10,LEAVES:14)
Block(16,5,-8,LEAVES:6)
Block(8,19,-10,LEAVES:14)
Block(10,13,-8,LOG:12)
Block(10,12,-15,LEAVES:6)
Block(10,14,-8,LOG:12)
Block(10,11,-8,LOG:12)
Block(15,4,-11,LEAVES:14)
Block(10,12,-8,LOG:12)
Block(10,10,-8,LOG:12)
Block(9,23,-6,LEAVES:6)
Block(8,4,-15,LEAVES:6)
Block(13,10,-5,LEAVES:14)
Block(10,19,-8,LOG)
Block(10,7,-9,LEAVES:14)
Block(10,17,-8,LOG)
Block(10,8,-9,LEAVES:14)
Block(10,18,-8,LOG)
Block(11,12,-13,LEAVES:6)
Block(13,14,-5,LEAVES:14)
Block(10,15,-8,LOG:12)
Block(10,16,-8,LOG)
Block(15,4,-5,LEAVES:14)
Block(8,20,-10,LEAVES:6)
Block(8,10,-5,LEAVES:14)
Block(8,18,-5,LEAVES:14)
Block(8,13,-5,LEAVES:14)
Block(8,12,-5,LEAVES:14)
Block(13,4,-13,LEAVES:6)
Block(8,5,-11,LEAVES:14)
Block(17,5,-8,LEAVES:6)
Block(17,4,-8,LEAVES:6)
Block(9,5,-3,LEAVES:14)
Block(8,5,-13,LEAVES:6)
Block(7,4,-15,LEAVES:6)
Block(17,4,-6,LEAVES:6)
Block(7,5,-15,LEAVES:6)
Block(15,14,-7,LEAVES:14)
Block(6,9,-9,LEAVES:14)
Block(6,4,-9,LEAVES:14)

#######################################################################
# +-----------------------------------------------------------------+ #
# |                            BO3 checks                           | #
# +-----------------------------------------------------------------+ #
#######################################################################

# Require a condition at a certain location in order for the BO3 to be spawned.
# BlockCheck(x,y,z,BlockName[,BlockName[,...]]) - one of the blocks must be at the location
# BlockCheckNot(x,y,z,BlockName[,BlockName[,...]]) - all the blocks must not be at the location
# LightCheck(x,y,z,minLightLevel,maxLightLevel) - light must be between min and max (inclusive)

# You can use "Solid" as a BlockName for matching all solid blocks or "All" to match all blocks that aren't air.

# Examples:
BlockCheck(0,-1,0,Solid)
BlockCheck(0,-1,0,GRASS,DIRT)
BlockCheck(0,-1,2,GRASS,DIRT)
BlockCheck(1,-1,0,GRASS,DIRT)
BlockCheck(-1,-1,0,GRASS,DIRT)
BlockCheck(0,-1,-1,GRASS,DIRT)
BlockCheck(0,-1,0,Solid)
BlockCheckNot(0,-1,0,AIR)
#   BlockCheck(0,-1,0,Solid)       Require any solid block just below the object
#   BlockCheck(0,-1,0,WOOL)        Require any type of wool just below the object
#   BlockCheck(0,-1,0,WOOL:0)      Require white wool just below the object
#   BlockCheckNot(0,-1,0,WOOL:0)   Require that there is no white wool below the object
#   LightCheck(0,0,0,0,1)          Require almost complete darkness just below the object

#######################################################################
# +-----------------------------------------------------------------+ #
# |                             Branches                            | #
# +-----------------------------------------------------------------+ #
#######################################################################

# Branches are objects that will spawn when this object spawns when it is used in
# the CustomStructure resource. Branches can also have branches, making complex
# structures possible. See the wiki for more details.

# Regular Branches spawn each branch with an independent chance of spawning.
# Branch(x,y,z,branchName,rotation,chance[,anotherBranchName,rotation,chance[,...]][IndividualChance])
# branchName - name of the object to spawn.
# rotation - NORTH, SOUTH, EAST or WEST.
# IndividualChance - The chance each branch has to spawn, assumed to be 100 when left blank

# Weighted Branches spawn branches with a dependent chance of spawning.
# WeightedBranch(x,y,z,branchName,rotation,chance[,anotherBranchName,rotation,chance[,...]][MaxChanceOutOf])
# MaxChanceOutOf - The chance all branches have to spawn out of, assumed to be 100 when left blank
