
#######################################################################
# +-----------------------------------------------------------------+ #
# |                            BO3 object                           | #
# +-----------------------------------------------------------------+ #
#######################################################################

# This is the config file of a custom object.
# If you add this object correctly to your BiomeConfigs, it will spawn in the world.

# This is the creator of this BO3 object
Author: NLBlackEagle

# A short description of this BO3 object
Description: Converted version of the BO2 48

# The BO3 version, don't change this! It can be used by external applications to do a version check.
Version: 3

# The settings mode, WriteAll, WriteWithoutComments or WriteDisable. See WorldConfig.
SettingsMode: WriteDisable


#######################################################################
# +-----------------------------------------------------------------+ #
# |                          Main settings                          | #
# +-----------------------------------------------------------------+ #
#######################################################################

# This needs to be set to true to spawn the object in the Tree and Sapling resources.
Tree: true

# The frequency of the BO3 from 1 to 200. Tries this many times to spawn this BO3 when using the CustomObject(...) resource.
# Ignored by Tree(..), Sapling(..) and CustomStructure(..)
Frequency: 5

# The rarity of the BO3 from 0 to 100. Each spawn attempt has rarity% chance to succeed when using the CustomObject(...) resource.
# Ignored by Tree(..), Sapling(..) and CustomStructure(..)
Rarity: 25.0

# If you set this to true, the BO3 will be placed with a random rotation.
RotateRandomly: true

# The spawn height of the BO3 - randomY, highestBlock or highestSolidBlock.
SpawnHeight: highestSolidBlock

# The height limits for the BO3.
MinHeight: 0

MaxHeight: 199

# Objects can have other objects attacthed to it: branches. Branches can also
# have branches attached to it, which can also have branches, etc. This is the
# maximum branch depth for this objects.
MaxBranchDepth: 10

# When spawned with the UseWorld keyword, this BO3 should NOT spawn in the following biomes.
# If you writer.write the BO3 name directly in the BiomeConfigs, this will be ignored.
ExcludedBiomes: 


#######################################################################
# +-----------------------------------------------------------------+ #
# |                      Source block settings                      | #
# +-----------------------------------------------------------------+ #
#######################################################################

# The block(s) the BO3 should spawn in.
SourceBlocks: AIR

# The maximum percentage of the BO3 that can be outside the SourceBlock.
# The BO3 won't be placed on a location with more blocks outside the SourceBlock than this percentage.
MaxPercentageOutsideSourceBlock: 20

# What to do when a block is about to be placed outside the SourceBlock? (dontPlace, placeAnyway)
OutsideSourceBlock: placeAnyway


#######################################################################
# +-----------------------------------------------------------------+ #
# |                              Blocks                             | #
# +-----------------------------------------------------------------+ #
#######################################################################

# All the blocks used in the BO3 are listed here. Possible blocks:
# Block(x,y,z,id[.data][,nbtfile.nbt)
# RandomBlock(x,y,z,id[:data][,nbtfile.nbt],chance[,id[:data][,nbtfile.nbt],chance[,...]])
# So RandomBlock(0,0,0,CHEST,chest.nbt,50,CHEST,anotherchest.nbt,100) will spawn a chest at
# the BO3 origin, and give it a 50% chance to have the contents of chest.nbt, or, if that
# fails, a 100% percent chance to have the contents of anotherchest.nbt.
Block(-1,9,4,LEAVES:13)
Block(-6,8,7,LEAVES:13)
Block(-6,9,7,LEAVES:13)
Block(-1,5,4,LEAVES:13)
Block(-2,46,10,LEAVES:5)
Block(1,6,5,LEAVES:5)
Block(-2,47,10,LEAVES:5)
Block(-2,48,10,LOG)
Block(-2,49,10,LOG)
Block(1,9,5,LEAVES:5)
Block(-3,1,8,LEAVES:13)
Block(-3,0,8,LEAVES:13)
Block(-7,9,11,LEAVES:13)
Block(-6,-6,6,LOG:12)
Block(-2,14,9,LEAVES:5)
Block(-2,40,10,LEAVES:5)
Block(-3,3,8,LEAVES:13)
Block(-3,2,8,LEAVES:13)
Block(-10,8,9,LEAVES:5)
Block(-3,9,8,LEAVES:13)
Block(-2,43,10,LEAVES:5)
Block(-3,8,8,LEAVES:13)
Block(-2,44,10,LOG)
Block(-2,45,10,LEAVES:5)
Block(-10,9,9,LEAVES:5)
Block(-12,6,6,LEAVES:5)
Block(-2,18,9,LEAVES:5)
Block(-3,8,4,LEAVES:13)
Block(-2,19,9,LEAVES:5)
Block(-2,38,10,LEAVES:5)
Block(-2,35,10,LEAVES:5)
Block(-4,-7,6,LOG:12)
Block(-2,36,10,LEAVES:5)
Block(-2,23,9,LEAVES:5)
Block(-4,-6,6,LOG:12)
Block(-2,24,9,LEAVES:5)
Block(-4,-5,6,LOG:12)
Block(-2,39,10,LEAVES:5)
Block(-5,-1,9,LOG:12)
Block(-2,30,10,LEAVES:5)
Block(-2,33,10,LEAVES:5)
Block(-5,-5,9,LOG:12)
Block(-2,34,10,LEAVES:5)
Block(-5,-4,9,LOG:12)
Block(-2,31,10,LEAVES:5)
Block(-5,-3,9,LOG:12)
Block(-2,32,10,LEAVES:5)
Block(-5,-2,9,LOG:12)
Block(-7,1,8,LEAVES:14)
Block(1,20,10,LEAVES:5)
Block(-7,9,8,LEAVES:13)
Block(1,21,10,LEAVES:5)
Block(-7,8,8,LEAVES:13)
Block(-7,26,10,LEAVES:5)
Block(-7,20,10,LEAVES:5)
Block(-2,37,9,LEAVES:5)
Block(-1,23,10,LEAVES:5)
Block(-2,38,9,LEAVES:5)
Block(-2,29,10,LEAVES:5)
Block(-2,35,9,LEAVES:5)
Block(-1,21,10,LEAVES:5)
Block(-2,36,9,LEAVES:5)
Block(-1,22,10,LEAVES:5)
Block(-1,8,10,LEAVES:13)
Block(-8,10,9,LEAVES:13)
Block(-2,33,9,LEAVES:5)
Block(-1,9,10,LEAVES:13)
Block(-8,11,9,LEAVES:13)
Block(-2,31,9,LEAVES:5)
Block(-2,26,10,LEAVES:5)
Block(-2,32,9,LEAVES:5)
Block(-2,27,10,LEAVES:5)
Block(-2,20,10,LEAVES:5)
Block(-8,15,9,LEAVES:5)
Block(-2,30,9,LEAVES:5)
Block(-1,29,10,LEAVES:5)
Block(-2,23,10,LEAVES:5)
Block(-8,18,9,LEAVES:5)
Block(-7,27,10,LEAVES:5)
Block(-8,19,9,LEAVES:5)
Block(-1,28,10,LEAVES:5)
Block(-7,15,10,LEAVES:5)
Block(1,16,10,LEAVES:5)
Block(-7,10,10,LEAVES:13)
Block(-6,13,6,LEAVES:13)
Block(-6,12,6,LEAVES:13)
Block(-6,11,6,LEAVES:13)
Block(-6,17,6,LEAVES:5)
Block(-2,39,9,LEAVES:5)
Block(-6,16,6,LEAVES:5)
Block(-6,10,15,LEAVES:5)
Block(-6,11,15,LEAVES:5)
Block(-2,46,9,LEAVES:5)
Block(-3,6,13,LEAVES:13)
Block(-2,42,9,LEAVES:5)
Block(-2,43,9,LEAVES:5)
Block(-8,25,9,LEAVES:5)
Block(-2,16,10,LEAVES:5)
Block(-3,9,13,LEAVES:13)
Block(-2,45,9,LEAVES:5)
Block(-2,40,9,LEAVES:5)
Block(-2,41,9,LEAVES:5)
Block(-2,10,10,LEAVES:13)
Block(-7,19,10,LEAVES:5)
Block(-1,7,7,LEAVES:13)
Block(-4,6,9,LOG:12)
Block(-4,7,9,LOG:12)
Block(-6,27,6,LEAVES:5)
Block(-4,4,9,LOG:12)
Block(-4,5,9,LOG:12)
Block(-4,2,9,LOG:12)
Block(-6,22,6,LEAVES:5)
Block(-4,3,9,LOG:12)
Block(-4,0,9,LOG:12)
Block(-4,1,9,LOG:12)
Block(-6,20,10,LEAVES:5)
Block(-6,21,10,LEAVES:5)
Block(-2,31,12,LEAVES:5)
Block(-2,32,12,LEAVES:5)
Block(-6,27,10,LEAVES:5)
Block(-11,8,8,LEAVES:5)
Block(-6,28,10,LEAVES:5)
Block(-11,9,8,LEAVES:5)
Block(-1,2,9,LEAVES:13)
Block(-1,1,9,LEAVES:13)
Block(-11,6,8,LEAVES:5)
Block(-1,0,9,LEAVES:13)
Block(-11,5,8,LEAVES:5)
Block(-11,6,4,LEAVES:5)
Block(-6,18,6,LEAVES:5)
Block(-1,8,9,LEAVES:13)
Block(-8,9,9,LEAVES:13)
Block(-5,6,8,LOG:12)
Block(-5,7,8,LOG:12)
Block(-5,4,8,LOG:12)
Block(-5,5,8,LOG:12)
Block(-5,2,8,LOG:12)
Block(-5,3,8,LOG:12)
Block(-5,0,8,LOG:12)
Block(-5,1,8,LOG:12)
Block(-7,31,10,LEAVES:5)
Block(-6,10,10,LEAVES:13)
Block(-6,16,10,LEAVES:5)
Block(-5,14,9,LEAVES:5)
Block(-5,15,9,LEAVES:5)
Block(-5,12,9,LEAVES:13)
Block(-5,13,9,LEAVES:13)
Block(-5,18,9,LOG)
Block(-5,19,9,LOG)
Block(-5,16,9,LOG)
Block(-5,17,9,LEAVES:5)
Block(-5,10,9,LEAVES:13)
Block(-5,11,9,LEAVES:13)
Block(-5,33,6,LEAVES:5)
Block(-5,8,1,LEAVES:5)
Block(-8,7,13,LEAVES:13)
Block(-5,-6,9,LOG:12)
Block(1,11,5,LEAVES:5)
Block(1,10,5,LEAVES:5)
Block(-5,9,8,LEAVES:13)
Block(-5,8,8,LOG:12)
Block(-10,8,11,LEAVES:5)
Block(-5,28,6,LEAVES:5)
Block(-10,7,11,LEAVES:5)
Block(-4,8,1,LEAVES:5)
Block(-6,8,5,LEAVES:13)
Block(-6,4,5,LEAVES:14)
Block(-6,2,5,LEAVES:14)
Block(-5,8,3,LEAVES:5)
Block(-3,1,10,LEAVES:13)
Block(-3,0,10,LEAVES:13)
Block(-6,32,10,LEAVES:5)
Block(-5,9,3,LEAVES:5)
Block(-3,9,10,LEAVES:13)
Block(-2,54,10,LOG)
Block(-5,3,5,LEAVES:14)
Block(-2,53,10,LOG)
Block(-5,4,5,LEAVES:14)
Block(-2,52,10,LOG)
Block(-5,9,5,LEAVES:13)
Block(-2,51,10,LOG)
Block(-2,50,10,LOG)
Block(-1,-2,10,LEAVES:13)
Block(-6,6,7,LEAVES:14)
Block(-6,4,7,LEAVES:14)
Block(-4,9,3,LEAVES:5)
Block(-4,8,3,LEAVES:5)
Block(-6,5,7,LEAVES:14)
Block(-6,2,7,LEAVES:14)
Block(-5,2,5,LEAVES:14)
Block(-6,3,7,LEAVES:14)
Block(-6,0,7,LOG:12)
Block(-6,1,7,LEAVES:14)
Block(-2,24,14,LEAVES:5)
Block(-2,25,14,LEAVES:5)
Block(-3,4,6,LEAVES:14)
Block(-3,5,6,LEAVES:14)
Block(-4,-2,10,LEAVES:13)
Block(-3,25,12,LEAVES:5)
Block(-3,26,12,LEAVES:5)
Block(-3,9,6,LEAVES:13)
Block(-5,16,6,LEAVES:5)
Block(-3,24,12,LEAVES:5)
Block(-5,10,6,LEAVES:13)
Block(-11,12,4,LEAVES:5)
Block(1,9,7,LEAVES:5)
Block(-5,17,6,LEAVES:5)
Block(-2,18,14,LEAVES:5)
Block(-5,18,6,LEAVES:5)
Block(1,5,7,LEAVES:5)
Block(-8,15,10,LEAVES:5)
Block(-12,6,4,LEAVES:5)
Block(-12,7,4,LEAVES:5)
Block(-2,14,14,LEAVES:5)
Block(-8,19,10,LEAVES:5)
Block(-7,7,6,LEAVES:13)
Block(-3,-6,7,LOG:12)
Block(-7,5,6,LEAVES:14)
Block(-3,19,12,LEAVES:5)
Block(-7,4,6,LEAVES:14)
Block(-3,16,12,LEAVES:5)
Block(2,7,12,LEAVES:5)
Block(-3,-2,7,LEAVES:13)
Block(-7,3,6,LEAVES:14)
Block(-8,14,10,LEAVES:5)
Block(-7,2,6,LEAVES:14)
Block(2,12,7,LEAVES:5)
Block(-3,-4,7,LOG:12)
Block(-7,1,6,LEAVES:14)
Block(-3,15,12,LEAVES:5)
Block(-5,27,6,LEAVES:5)
Block(-3,10,12,LEAVES:13)
Block(-3,11,12,LEAVES:13)
Block(-5,23,6,LEAVES:5)
Block(-5,22,6,LEAVES:5)
Block(-7,8,6,LEAVES:13)
Block(-8,7,5,LEAVES:13)
Block(-8,6,5,LEAVES:13)
Block(-8,1,5,LEAVES:14)
Block(-3,15,7,LEAVES:5)
Block(-3,12,7,LEAVES:13)
Block(-5,37,10,LEAVES:5)
Block(-4,16,13,LEAVES:5)
Block(-7,16,12,LEAVES:5)
Block(-2,10,12,LEAVES:13)
Block(-5,38,10,LEAVES:5)
Block(-5,33,10,LEAVES:5)
Block(-5,34,10,LEAVES:5)
Block(-8,1,7,LEAVES:14)
Block(-2,16,12,LEAVES:5)
Block(-2,15,12,LEAVES:5)
Block(-5,30,10,LEAVES:5)
Block(-4,13,13,LEAVES:13)
Block(-2,19,12,LEAVES:5)
Block(-4,12,13,LEAVES:13)
Block(-4,10,13,LEAVES:13)
Block(0,5,4,LEAVES:13)
Block(0,9,4,LEAVES:13)
Block(-9,11,4,LEAVES:5)
Block(-1,7,12,LEAVES:13)
Block(-4,12,14,LEAVES:5)
Block(-1,8,12,LEAVES:13)
Block(-4,11,14,LEAVES:5)
Block(-7,27,12,LEAVES:5)
Block(-9,11,8,LEAVES:13)
Block(-2,20,12,LEAVES:5)
Block(-9,14,8,LEAVES:5)
Block(-2,25,12,LEAVES:5)
Block(-9,10,8,LEAVES:13)
Block(-5,42,10,LEAVES:5)
Block(-5,41,10,LEAVES:5)
Block(-3,31,12,LEAVES:5)
Block(-2,27,12,LEAVES:5)
Block(-2,26,12,LEAVES:5)
Block(-3,5,15,LEAVES:5)
Block(-3,34,12,LEAVES:5)
Block(-3,6,15,LEAVES:5)
Block(-9,8,6,LEAVES:13)
Block(-3,35,12,LEAVES:5)
Block(-3,32,12,LEAVES:5)
Block(-3,8,15,LEAVES:5)
Block(-9,7,6,LEAVES:13)
Block(-4,19,10,LEAVES:5)
Block(-5,16,14,LEAVES:5)
Block(-5,12,14,LEAVES:5)
Block(-1,44,10,LEAVES:5)
Block(-5,8,10,LEAVES:13)
Block(-9,8,13,LEAVES:13)
Block(-1,45,10,LEAVES:5)
Block(-9,7,13,LEAVES:13)
Block(-4,10,10,LEAVES:13)
Block(-3,14,14,LEAVES:5)
Block(-5,-1,6,LOG:12)
Block(-5,9,10,LEAVES:13)
Block(-5,-2,6,LOG:12)
Block(-3,13,14,LEAVES:5)
Block(-3,10,14,LEAVES:5)
Block(-3,11,14,LEAVES:5)
Block(-9,8,11,LEAVES:13)
Block(-4,15,10,LEAVES:5)
Block(-11,7,6,LEAVES:5)
Block(-4,14,10,LEAVES:5)
Block(-11,8,6,LEAVES:5)
Block(-4,13,10,LEAVES:13)
Block(-4,12,10,LEAVES:13)
Block(-11,6,6,LEAVES:5)
Block(-4,11,10,LEAVES:13)
Block(-5,6,14,LEAVES:5)
Block(-8,8,7,LEAVES:13)
Block(-1,38,10,LEAVES:5)
Block(-5,5,14,LEAVES:5)
Block(-8,9,7,LEAVES:13)
Block(-1,37,10,LEAVES:5)
Block(-5,8,14,LEAVES:5)
Block(-1,31,12,LEAVES:5)
Block(-1,30,10,LEAVES:5)
Block(-5,-7,6,LOG:12)
Block(-1,35,10,LEAVES:5)
Block(-5,-6,6,LOG:12)
Block(-1,34,10,LEAVES:5)
Block(-1,33,10,LEAVES:5)
Block(-1,32,10,LEAVES:5)
Block(1,7,13,LEAVES:5)
Block(-4,21,10,LEAVES:5)
Block(-4,20,10,LEAVES:5)
Block(-4,27,10,LOG)
Block(-5,7,12,LEAVES:13)
Block(-4,26,10,LEAVES:5)
Block(-4,29,10,LOG)
Block(-4,28,10,LOG)
Block(-4,23,10,LEAVES:5)
Block(-4,22,10,LEAVES:5)
Block(-4,25,10,LEAVES:5)
Block(-4,24,10,LEAVES:5)
Block(-1,26,12,LEAVES:5)
Block(-1,25,12,LEAVES:5)
Block(-3,-1,7,LEAVES:13)
Block(-1,24,12,LEAVES:5)
Block(-1,27,12,LEAVES:5)
Block(-2,7,6,LEAVES:13)
Block(-4,32,10,LEAVES:5)
Block(-1,14,14,LEAVES:5)
Block(-4,31,10,LEAVES:5)
Block(-4,30,10,LEAVES:5)
Block(-4,36,10,LEAVES:5)
Block(-1,18,14,LEAVES:5)
Block(-4,35,10,LEAVES:5)
Block(-4,34,10,LEAVES:5)
Block(-8,25,7,LEAVES:5)
Block(-4,39,10,LEAVES:5)
Block(-4,38,10,LEAVES:5)
Block(-1,15,12,LEAVES:5)
Block(-1,14,12,LEAVES:5)
Block(-1,19,12,LEAVES:5)
Block(3,11,8,LEAVES:5)
Block(-4,40,10,LEAVES:5)
Block(-8,10,7,LEAVES:13)
Block(-4,43,10,LEAVES:5)
Block(-4,42,10,LEAVES:5)
Block(-8,12,7,LEAVES:13)
Block(-4,45,10,LEAVES:5)
Block(-8,13,7,LEAVES:13)
Block(-4,44,10,LEAVES:5)
Block(-8,14,7,LEAVES:5)
Block(-10,14,9,LEAVES:5)
Block(-8,16,7,LEAVES:5)
Block(-9,8,9,LEAVES:13)
Block(1,12,6,LEAVES:5)
Block(-4,8,15,LEAVES:5)
Block(1,11,6,LEAVES:5)
Block(-9,9,9,LEAVES:13)
Block(-4,6,15,LEAVES:5)
Block(-6,32,11,LEAVES:5)
Block(-2,18,13,LEAVES:5)
Block(-2,19,13,LEAVES:5)
Block(-7,26,11,LEAVES:5)
Block(-7,27,11,LEAVES:5)
Block(0,13,13,LEAVES:13)
Block(-2,14,13,LEAVES:5)
Block(-2,15,13,LEAVES:5)
Block(0,18,13,LEAVES:5)
Block(-8,15,8,LEAVES:5)
Block(-8,14,8,LEAVES:5)
Block(-6,28,11,LEAVES:5)
Block(-6,27,11,LEAVES:5)
Block(-6,22,11,LEAVES:5)
Block(-11,10,7,LEAVES:5)
Block(-6,21,11,LEAVES:5)
Block(-8,18,8,LEAVES:5)
Block(-7,11,14,LEAVES:5)
Block(0,7,13,LEAVES:13)
Block(-5,-7,7,LOG:12)
Block(-5,-6,7,LOG:12)
Block(-3,-2,10,LEAVES:13)
Block(-5,-4,7,LOG:12)
Block(-4,-3,8,LOG:12)
Block(-8,11,8,LEAVES:13)
Block(-4,-2,8,LOG:12)
Block(-4,-1,8,LOG:12)
Block(-3,-1,10,LEAVES:13)
Block(-8,12,8,LEAVES:13)
Block(-1,7,14,LEAVES:5)
Block(-5,-1,7,LOG:12)
Block(-5,-2,7,LOG:12)
Block(-3,20,5,LEAVES:5)
Block(-5,-3,7,LOG:12)
Block(1,7,12,LEAVES:5)
Block(-2,24,13,LEAVES:5)
Block(-2,25,13,LEAVES:5)
Block(-2,26,13,LEAVES:5)
Block(-7,19,11,LEAVES:5)
Block(-7,18,11,LEAVES:5)
Block(-10,6,5,LEAVES:13)
Block(-3,15,5,LEAVES:5)
Block(-3,16,5,LEAVES:5)
Block(-3,19,5,LEAVES:5)
Block(1,7,10,LEAVES:5)
Block(1,6,10,LEAVES:5)
Block(-10,7,5,LEAVES:5)
Block(-2,31,13,LEAVES:5)
Block(-6,5,14,LEAVES:5)
Block(-10,6,7,LEAVES:13)
Block(-10,7,7,LEAVES:5)
Block(-10,9,7,LEAVES:5)
Block(-7,31,8,LEAVES:5)
Block(-7,32,8,LEAVES:5)
Block(-9,6,4,LEAVES:5)
Block(-4,0,7,LOG:12)
Block(-4,1,7,LEAVES:14)
Block(-4,2,7,LEAVES:14)
Block(-4,3,7,LEAVES:14)
Block(-4,4,7,LEAVES:14)
Block(-1,14,2,LEAVES:5)
Block(-4,7,7,LEAVES:13)
Block(-4,8,7,LEAVES:13)
Block(-6,2,9,LOG:12)
Block(-6,0,9,LOG:12)
Block(-4,9,5,LEAVES:13)
Block(-6,1,9,LOG:12)
Block(-8,9,11,LEAVES:13)
Block(-8,8,11,LEAVES:13)
Block(-2,3,9,LEAVES:13)
Block(-4,12,8,LEAVES:13)
Block(-2,2,9,LEAVES:13)
Block(-4,13,8,LEAVES:13)
Block(-2,5,9,LEAVES:13)
Block(-4,10,8,LEAVES:13)
Block(-2,4,9,LEAVES:13)
Block(-4,11,8,LEAVES:13)
Block(-4,16,8,LOG)
Block(-2,7,3,LEAVES:5)
Block(-4,17,8,LEAVES:5)
Block(-2,9,9,LEAVES:13)
Block(-4,14,8,LEAVES:5)
Block(0,18,11,LEAVES:5)
Block(-4,15,8,LEAVES:5)
Block(-2,1,9,LEAVES:13)
Block(-2,0,9,LEAVES:13)
Block(-2,9,10,LEAVES:13)
Block(-4,-5,8,LOG:12)
Block(-4,-4,8,LOG:12)
Block(-4,-7,8,LOG:12)
Block(-4,-6,8,LOG:12)
Block(1,5,8,LEAVES:5)
Block(0,27,11,LEAVES:5)
Block(-2,7,12,LEAVES:13)
Block(-2,1,10,LEAVES:13)
Block(-2,0,10,LEAVES:13)
Block(-6,17,11,LEAVES:5)
Block(-8,25,8,LEAVES:5)
Block(-2,9,12,LEAVES:13)
Block(-2,8,12,LEAVES:13)
Block(-6,7,3,LEAVES:5)
Block(-6,8,3,LEAVES:5)
Block(-2,5,14,LEAVES:5)
Block(3,5,4,LEAVES:5)
Block(-2,9,14,LEAVES:5)
Block(-2,8,14,LEAVES:5)
Block(-6,11,13,LEAVES:13)
Block(0,8,11,LEAVES:13)
Block(-3,15,13,LEAVES:5)
Block(-2,23,8,LEAVES:5)
Block(-8,17,5,LEAVES:5)
Block(-4,45,8,LEAVES:5)
Block(-1,25,6,LEAVES:5)
Block(-3,10,13,LEAVES:13)
Block(-1,26,6,LEAVES:5)
Block(-3,9,11,LEAVES:13)
Block(-6,16,13,LEAVES:5)
Block(-8,16,5,LEAVES:5)
Block(-3,8,11,LEAVES:13)
Block(-8,13,5,LEAVES:13)
Block(-3,14,13,LEAVES:5)
Block(0,7,11,LEAVES:13)
Block(-8,11,5,LEAVES:13)
Block(-3,11,13,LEAVES:13)
Block(-8,12,5,LEAVES:13)
Block(-6,12,13,LEAVES:13)
Block(-3,12,13,LEAVES:13)
Block(-1,31,6,LEAVES:5)
Block(-9,13,6,LEAVES:5)
Block(-4,8,11,LEAVES:13)
Block(-2,18,8,LEAVES:5)
Block(-9,12,6,LEAVES:5)
Block(-7,-6,8,LOG:12)
Block(-2,33,8,LEAVES:5)
Block(-5,41,9,LEAVES:5)
Block(-2,32,8,LEAVES:5)
Block(1,16,7,LEAVES:5)
Block(-3,51,10,LOG)
Block(1,13,7,LEAVES:5)
Block(-3,50,10,LOG)
Block(-2,37,8,LEAVES:5)
Block(1,12,7,LEAVES:5)
Block(-2,27,8,LEAVES:5)
Block(-2,28,8,LEAVES:5)
Block(-10,12,6,LEAVES:5)
Block(-10,11,6,LEAVES:5)
Block(-4,20,8,LEAVES:5)
Block(-3,40,10,LEAVES:5)
Block(-3,42,10,LOG)
Block(-3,41,10,LEAVES:5)
Block(-5,30,9,LEAVES:5)
Block(-3,44,10,LOG)
Block(-5,33,9,LEAVES:5)
Block(-4,8,9,LOG:12)
Block(-3,43,10,LEAVES:5)
Block(-4,9,9,LOG:12)
Block(-3,46,10,LEAVES:5)
Block(-3,45,10,LOG)
Block(-3,48,10,LOG)
Block(-4,26,8,LEAVES:5)
Block(-3,47,10,LEAVES:5)
Block(-5,36,9,LEAVES:5)
Block(-4,25,8,LEAVES:5)
Block(-4,24,8,LEAVES:5)
Block(-3,8,1,LEAVES:5)
Block(-3,49,10,LOG)
Block(-4,23,8,LEAVES:5)
Block(-4,22,8,LEAVES:5)
Block(-4,21,8,LEAVES:5)
Block(-4,18,8,LOG)
Block(-4,19,8,LOG)
Block(-3,-1,8,LEAVES:13)
Block(-3,-2,8,LEAVES:13)
Block(-2,13,8,LEAVES:13)
Block(-2,12,8,LEAVES:13)
Block(-4,31,8,LEAVES:5)
Block(-2,15,8,LEAVES:5)
Block(-4,30,8,LEAVES:5)
Block(-2,14,8,LEAVES:5)
Block(-3,33,10,LEAVES:5)
Block(-5,22,9,LEAVES:5)
Block(-3,-4,8,LOG:12)
Block(-3,32,10,LEAVES:5)
Block(-5,21,9,LEAVES:5)
Block(-3,-3,8,LOG:12)
Block(-3,31,10,LEAVES:5)
Block(-6,22,13,LEAVES:5)
Block(-5,20,9,LEAVES:5)
Block(-3,-6,8,LOG:12)
Block(-2,11,8,LEAVES:13)
Block(-3,30,10,LOG)
Block(-6,21,13,LEAVES:5)
Block(-3,-5,8,LOG:12)
Block(-3,37,10,LEAVES:5)
Block(-3,36,10,LOG)
Block(-4,36,8,LEAVES:5)
Block(-4,39,8,LEAVES:5)
Block(-3,35,10,LOG)
Block(-4,38,8,LEAVES:5)
Block(-3,34,10,LOG)
Block(-5,23,9,LEAVES:5)
Block(-4,32,8,LEAVES:5)
Block(-5,29,9,LEAVES:5)
Block(-3,39,10,LEAVES:5)
Block(-4,35,8,LEAVES:5)
Block(-5,28,9,LEAVES:5)
Block(-3,38,10,LEAVES:5)
Block(-5,27,9,LEAVES:5)
Block(2,5,4,LEAVES:5)
Block(-6,9,9,LEAVES:13)
Block(-9,11,7,LEAVES:13)
Block(-9,10,7,LEAVES:13)
Block(2,6,4,LEAVES:5)
Block(-9,12,7,LEAVES:5)
Block(-1,7,6,LEAVES:13)
Block(-1,6,6,LEAVES:13)
Block(-3,27,10,LEAVES:5)
Block(-7,25,6,LEAVES:5)
Block(-2,15,4,LEAVES:5)
Block(-3,28,10,LEAVES:5)
Block(-2,14,4,LEAVES:5)
Block(-3,29,10,LOG)
Block(-5,29,7,LEAVES:5)
Block(-3,23,10,LEAVES:5)
Block(-2,19,4,LEAVES:5)
Block(-3,24,10,LEAVES:5)
Block(-2,18,4,LEAVES:5)
Block(-3,25,10,LEAVES:5)
Block(-5,1,6,LEAVES:14)
Block(-5,3,6,LEAVES:14)
Block(-3,20,10,LEAVES:5)
Block(-5,2,6,LEAVES:14)
Block(-3,21,10,LEAVES:5)
Block(-5,5,6,LEAVES:14)
Block(-3,22,10,LEAVES:5)
Block(-5,4,6,LEAVES:14)
Block(-5,7,6,LEAVES:14)
Block(-5,6,6,LEAVES:14)
Block(-5,9,6,LEAVES:13)
Block(-7,26,8,LEAVES:5)
Block(-2,-5,8,LOG:12)
Block(-10,12,5,LEAVES:5)
Block(-2,-3,8,LOG:12)
Block(-11,8,12,LEAVES:5)
Block(0,7,9,LEAVES:13)
Block(-2,-2,8,LEAVES:13)
Block(-2,-6,8,LOG:12)
Block(-5,34,7,LEAVES:5)
Block(-10,11,5,LEAVES:5)
Block(-5,18,7,LEAVES:5)
Block(-7,12,6,LEAVES:13)
Block(-7,12,8,LEAVES:13)
Block(-5,19,7,LEAVES:5)
Block(-7,11,8,LEAVES:13)
Block(-7,14,6,LEAVES:5)
Block(-3,17,10,LEAVES:5)
Block(-7,13,6,LEAVES:13)
Block(-7,18,6,LEAVES:5)
Block(0,10,5,LEAVES:13)
Block(-3,12,10,LEAVES:13)
Block(-7,17,6,LEAVES:5)
Block(-3,10,10,LEAVES:13)
Block(-7,19,8,LEAVES:5)
Block(-3,11,10,LEAVES:13)
Block(-7,17,8,LEAVES:5)
Block(-7,16,8,LEAVES:5)
Block(2,11,8,LEAVES:5)
Block(2,12,8,LEAVES:5)
Block(-7,15,8,LEAVES:5)
Block(-7,13,8,LEAVES:13)
Block(-3,18,4,LEAVES:5)
Block(-3,19,4,LEAVES:5)
Block(-3,14,4,LEAVES:5)
Block(-3,15,4,LEAVES:5)
Block(-5,23,7,LEAVES:5)
Block(-5,28,7,LEAVES:5)
Block(-1,13,4,LEAVES:5)
Block(-1,14,4,LEAVES:5)
Block(-1,24,13,LEAVES:5)
Block(-1,25,13,LEAVES:5)
Block(-2,-2,10,LEAVES:13)
Block(-2,-1,10,LEAVES:13)
Block(2,11,6,LEAVES:5)
Block(-5,17,7,LEAVES:5)
Block(-1,10,6,LEAVES:13)
Block(-1,11,6,LEAVES:13)
Block(-5,14,7,LEAVES:5)
Block(-5,13,7,LEAVES:13)
Block(-5,12,7,LEAVES:13)
Block(-5,11,7,LEAVES:13)
Block(-5,10,7,LEAVES:13)
Block(-4,27,5,LEAVES:5)
Block(-10,10,8,LEAVES:5)
Block(-2,-1,8,LEAVES:13)
Block(-10,14,8,LEAVES:5)
Block(-10,8,13,LEAVES:5)
Block(-1,8,3,LEAVES:5)
Block(-11,6,7,LEAVES:5)
Block(-11,9,7,LEAVES:5)
Block(0,17,8,LEAVES:5)
Block(-1,0,8,LEAVES:13)
Block(-1,1,8,LEAVES:13)
Block(0,32,9,LEAVES:5)
Block(0,13,8,LEAVES:13)
Block(0,33,9,LEAVES:5)
Block(-11,8,9,LEAVES:5)
Block(-7,8,12,LEAVES:13)
Block(1,5,4,LEAVES:5)
Block(-6,21,5,LEAVES:5)
Block(-1,6,8,LEAVES:13)
Block(-1,7,8,LEAVES:13)
Block(1,8,4,LEAVES:5)
Block(1,9,4,LEAVES:5)
Block(-5,2,9,LOG:12)
Block(-5,1,9,LOG:12)
Block(-11,7,5,LEAVES:5)
Block(-5,0,9,LOG:12)
Block(-5,6,9,LOG:12)
Block(-5,5,9,LOG:12)
Block(-5,4,9,LOG:12)
Block(-5,3,9,LOG:12)
Block(-4,21,4,LEAVES:5)
Block(0,21,8,LEAVES:5)
Block(-9,7,10,LEAVES:13)
Block(0,27,9,LEAVES:5)
Block(-9,8,10,LEAVES:13)
Block(-5,8,11,LEAVES:13)
Block(-4,18,4,LEAVES:5)
Block(-4,14,4,LEAVES:5)
Block(-5,0,7,LOG:12)
Block(0,21,9,LEAVES:5)
Block(0,22,9,LEAVES:5)
Block(-6,16,5,LEAVES:5)
Block(-5,3,7,LEAVES:14)
Block(-5,4,7,LEAVES:14)
Block(-5,1,7,LEAVES:14)
Block(-5,2,7,LEAVES:14)
Block(-5,7,7,LEAVES:14)
Block(-5,8,7,LEAVES:13)
Block(-6,11,5,LEAVES:13)
Block(-5,5,7,LEAVES:14)
Block(-6,10,5,LEAVES:13)
Block(-5,6,7,LEAVES:14)
Block(-4,22,12,LEAVES:5)
Block(-4,-7,7,LOG:12)
Block(-3,46,8,LEAVES:5)
Block(-4,20,12,LEAVES:5)
Block(-4,21,12,LEAVES:5)
Block(-4,-4,7,LOG:12)
Block(-10,8,12,LEAVES:5)
Block(-3,45,8,LEAVES:5)
Block(-4,-3,7,LOG:12)
Block(-4,-6,7,LOG:12)
Block(-4,-5,7,LOG:12)
Block(-3,41,8,LEAVES:5)
Block(-4,-6,9,LOG:12)
Block(-4,-5,9,LOG:12)
Block(-7,9,9,LEAVES:13)
Block(0,8,3,LEAVES:5)
Block(-1,8,11,LEAVES:13)
Block(-1,9,11,LEAVES:13)
Block(-10,7,10,LEAVES:5)
Block(-10,8,10,LEAVES:5)
Block(-3,39,8,LEAVES:5)
Block(-3,35,8,LEAVES:5)
Block(0,6,7,LEAVES:13)
Block(-4,10,12,LEAVES:13)
Block(-7,17,5,LEAVES:5)
Block(-4,11,12,LEAVES:13)
Block(-3,38,8,LEAVES:5)
Block(-1,24,5,LEAVES:5)
Block(-7,16,5,LEAVES:5)
Block(-3,31,8,LEAVES:5)
Block(-7,11,5,LEAVES:13)
Block(-3,32,8,LEAVES:5)
Block(-3,33,8,LEAVES:5)
Block(-3,34,8,LEAVES:5)
Block(-7,12,5,LEAVES:13)
Block(-4,17,12,LEAVES:5)
Block(-3,9,9,LEAVES:13)
Block(-2,13,6,LEAVES:13)
Block(-2,11,6,LEAVES:13)
Block(-3,30,8,LEAVES:5)
Block(-4,13,12,LEAVES:13)
Block(-4,14,12,LEAVES:5)
Block(-4,16,12,LEAVES:5)
Block(-5,9,4,LEAVES:13)
Block(-5,8,4,LEAVES:13)
Block(-4,-1,9,LOG:12)
Block(-4,-2,9,LOG:12)
Block(-4,-3,9,LOG:12)
Block(-4,-4,9,LOG:12)
Block(-6,4,6,LEAVES:14)
Block(-4,-1,7,LOG:12)
Block(-4,-2,7,LOG:12)
Block(-6,3,6,LEAVES:14)
Block(-1,-1,9,LEAVES:13)
Block(-6,2,6,LEAVES:14)
Block(-6,1,6,LEAVES:14)
Block(-3,29,8,LEAVES:5)
Block(-3,28,8,LEAVES:5)
Block(-4,8,2,LEAVES:5)
Block(-6,7,6,LEAVES:14)
Block(-6,6,6,LEAVES:14)
Block(-4,9,2,LEAVES:5)
Block(-6,5,6,LEAVES:14)
Block(2,5,6,LEAVES:5)
Block(-3,8,7,LEAVES:13)
Block(-3,4,7,LEAVES:14)
Block(-3,23,8,LEAVES:5)
Block(-3,22,8,LEAVES:5)
Block(-7,4,5,LEAVES:14)
Block(-3,21,8,LEAVES:5)
Block(-3,0,7,LEAVES:13)
Block(-3,20,8,LEAVES:5)
Block(-3,27,8,LEAVES:5)
Block(-3,26,8,LOG)
Block(2,8,6,LEAVES:5)
Block(-3,25,8,LEAVES:5)
Block(-3,24,8,LEAVES:5)
Block(-3,19,8,LEAVES:5)
Block(-3,0,9,LEAVES:13)
Block(-3,17,8,LEAVES:5)
Block(-8,7,8,LEAVES:13)
Block(-6,32,8,LEAVES:5)
Block(-8,8,8,LEAVES:13)
Block(-6,31,8,LEAVES:5)
Block(-3,8,9,LEAVES:13)
Block(-6,35,8,LEAVES:5)
Block(-6,34,8,LEAVES:5)
Block(-3,3,9,LEAVES:13)
Block(-3,1,9,LEAVES:13)
Block(-3,2,9,LEAVES:13)
Block(-7,1,7,LEAVES:14)
Block(-12,9,7,LEAVES:5)
Block(-7,2,7,LEAVES:14)
Block(-7,4,7,LEAVES:14)
Block(-12,6,7,LEAVES:5)
Block(-3,10,8,LEAVES:13)
Block(-2,38,8,LEAVES:5)
Block(-3,9,5,LEAVES:13)
Block(-3,12,8,LEAVES:13)
Block(-4,29,7,LEAVES:5)
Block(-3,11,8,LEAVES:13)
Block(-3,14,8,LEAVES:5)
Block(-3,13,8,LEAVES:13)
Block(-4,34,12,LEAVES:5)
Block(-3,16,8,LEAVES:5)
Block(-3,8,5,LEAVES:13)
Block(-3,15,8,LEAVES:5)
Block(-4,34,7,LEAVES:5)
Block(-4,33,7,LEAVES:5)
Block(-2,45,8,LEAVES:5)
Block(-4,38,7,LEAVES:5)
Block(-3,7,3,LEAVES:5)
Block(-4,37,7,LEAVES:5)
Block(-3,8,3,LEAVES:5)
Block(-6,26,8,LEAVES:5)
Block(-4,30,7,LEAVES:5)
Block(-6,27,8,LEAVES:5)
Block(-2,40,8,LEAVES:5)
Block(-12,7,5,LEAVES:5)
Block(-3,6,16,LEAVES:5)
Block(-3,5,16,LEAVES:5)
Block(-3,8,16,LEAVES:5)
Block(-10,11,7,LEAVES:5)
Block(0,17,9,LEAVES:5)
Block(-10,10,7,LEAVES:5)
Block(-4,13,4,LEAVES:5)
Block(0,13,9,LEAVES:13)
Block(-4,17,7,LEAVES:5)
Block(-4,19,7,LEAVES:5)
Block(-6,11,8,LEAVES:13)
Block(-4,24,7,LEAVES:5)
Block(-4,21,7,LEAVES:5)
Block(-5,8,9,LEAVES:13)
Block(-4,20,7,LEAVES:5)
Block(-5,7,9,LOG:12)
Block(-4,23,7,LEAVES:5)
Block(-5,9,9,LEAVES:13)
Block(-4,14,5,LEAVES:5)
Block(-6,18,8,LEAVES:5)
Block(-6,17,8,LEAVES:5)
Block(-6,16,8,LEAVES:5)
Block(-6,15,8,LEAVES:5)
Block(-7,9,10,LEAVES:13)
Block(-6,14,8,LEAVES:5)
Block(-8,6,4,LEAVES:13)
Block(-6,12,8,LEAVES:13)
Block(-4,19,5,LEAVES:5)
Block(-4,15,5,LEAVES:5)
Block(-4,18,5,LEAVES:5)
Block(-3,9,14,LEAVES:5)
Block(-3,42,11,LEAVES:5)
Block(-3,6,14,LEAVES:5)
Block(-3,41,11,LEAVES:5)
Block(-4,16,7,LEAVES:5)
Block(-3,7,12,LEAVES:13)
Block(-4,12,7,LEAVES:13)
Block(-4,11,7,LEAVES:13)
Block(-4,10,7,LEAVES:13)
Block(-4,22,5,LEAVES:5)
Block(-5,15,8,LEAVES:5)
Block(-5,16,8,LEAVES:5)
Block(-5,28,5,LEAVES:5)
Block(-5,27,5,LEAVES:5)
Block(-5,18,8,LEAVES:5)
Block(-5,11,8,LEAVES:13)
Block(-5,12,8,LEAVES:13)
Block(-5,11,15,LEAVES:5)
Block(-5,13,8,LEAVES:13)
Block(-5,14,8,LEAVES:5)
Block(-4,41,9,LEAVES:5)
Block(-4,42,9,LEAVES:5)
Block(-1,22,9,LEAVES:5)
Block(-4,43,9,LEAVES:5)
Block(-5,10,8,LEAVES:13)
Block(-5,18,10,LEAVES:5)
Block(-1,23,9,LEAVES:5)
Block(-5,22,12,LEAVES:5)
Block(-5,21,12,LEAVES:5)
Block(-5,14,10,LEAVES:5)
Block(-1,18,9,LEAVES:5)
Block(-6,13,7,LEAVES:13)
Block(-9,8,12,LEAVES:13)
Block(-6,14,7,LEAVES:5)
Block(-1,10,7,LEAVES:13)
Block(-5,11,10,LEAVES:13)
Block(-6,15,7,LEAVES:5)
Block(-5,10,10,LEAVES:13)
Block(-1,11,7,LEAVES:13)
Block(-5,13,10,LEAVES:13)
Block(-6,18,7,LEAVES:5)
Block(-5,12,10,LEAVES:13)
Block(-1,13,7,LEAVES:13)
Block(-5,27,12,LEAVES:5)
Block(-5,23,12,LEAVES:5)
Block(-6,10,7,LEAVES:13)
Block(-4,39,9,LEAVES:5)
Block(-5,28,8,LEAVES:5)
Block(-5,29,8,LEAVES:5)
Block(-4,37,9,LEAVES:5)
Block(-4,38,9,LEAVES:5)
Block(-5,27,8,LEAVES:5)
Block(-5,18,5,LEAVES:5)
Block(-4,35,9,LOG)
Block(-5,24,8,LEAVES:5)
Block(-5,6,13,LEAVES:13)
Block(1,5,6,LEAVES:5)
Block(-4,36,9,LEAVES:5)
Block(-5,7,13,LEAVES:13)
Block(1,6,6,LEAVES:5)
Block(-4,33,9,LOG)
Block(-5,22,8,LEAVES:5)
Block(-5,8,13,LEAVES:13)
Block(-4,34,9,LOG)
Block(-5,23,8,LEAVES:5)
Block(-5,9,13,LEAVES:13)
Block(-1,33,9,LEAVES:5)
Block(-4,31,9,LEAVES:5)
Block(-5,20,8,LEAVES:5)
Block(1,9,6,LEAVES:5)
Block(-4,32,9,LOG)
Block(-4,30,9,LOG)
Block(-1,36,9,LEAVES:5)
Block(-1,35,9,LEAVES:5)
Block(-5,29,10,LEAVES:5)
Block(-1,34,9,LEAVES:5)
Block(-8,18,11,LEAVES:5)
Block(-5,10,12,LEAVES:13)
Block(-5,24,10,LEAVES:5)
Block(-5,23,10,LEAVES:5)
Block(-6,26,7,LEAVES:5)
Block(-5,22,10,LEAVES:5)
Block(-6,27,7,LEAVES:5)
Block(-5,21,10,LEAVES:5)
Block(-5,20,10,LEAVES:5)
Block(-5,17,12,LEAVES:5)
Block(-5,22,5,LEAVES:5)
Block(-5,18,12,LEAVES:5)
Block(-5,13,12,LEAVES:13)
Block(-5,19,8,LEAVES:5)
Block(-5,34,8,LEAVES:5)
Block(-5,35,8,LEAVES:5)
Block(-7,8,7,LEAVES:13)
Block(-7,9,7,LEAVES:13)
Block(-1,26,7,LEAVES:5)
Block(-2,6,5,LEAVES:13)
Block(-1,25,7,LEAVES:5)
Block(-5,32,8,LEAVES:5)
Block(-2,8,7,LEAVES:13)
Block(-2,7,7,LEAVES:13)
Block(-1,31,7,LEAVES:5)
Block(-2,0,7,LEAVES:13)
Block(-1,7,13,LEAVES:13)
Block(-1,8,13,LEAVES:13)
Block(0,9,5,LEAVES:13)
Block(0,6,5,LEAVES:13)
Block(-1,14,7,LEAVES:5)
Block(-9,7,7,LEAVES:13)
Block(-9,8,7,LEAVES:13)
Block(-5,33,12,LEAVES:5)
Block(-9,9,7,LEAVES:13)
Block(-5,32,12,LEAVES:5)
Block(-5,8,2,LEAVES:5)
Block(-1,28,11,LEAVES:5)
Block(-5,-5,10,LOG:12)
Block(-5,-7,10,LOG:12)
Block(-1,27,11,LEAVES:5)
Block(-1,24,11,LEAVES:5)
Block(-1,25,11,LEAVES:5)
Block(-5,-4,8,LOG:12)
Block(-2,15,6,LEAVES:5)
Block(-5,-3,8,LOG:12)
Block(-10,9,8,LEAVES:5)
Block(-2,14,6,LEAVES:5)
Block(-10,6,8,LEAVES:13)
Block(-1,21,11,LEAVES:5)
Block(-2,19,6,LEAVES:5)
Block(-2,18,6,LEAVES:5)
Block(-8,13,6,LEAVES:13)
Block(-8,14,6,LEAVES:5)
Block(-8,17,6,LEAVES:5)
Block(-8,16,6,LEAVES:5)
Block(-1,-2,9,LEAVES:13)
Block(-5,-2,10,LOG:12)
Block(-5,-3,10,LOG:12)
Block(-6,-2,7,LOG:12)
Block(-6,-1,7,LOG:12)
Block(-6,-3,7,LOG:12)
Block(-5,5,16,LEAVES:5)
Block(-2,26,6,LEAVES:5)
Block(-2,25,6,LEAVES:5)
Block(-1,31,11,LEAVES:5)
Block(-8,7,6,LEAVES:13)
Block(-1,32,11,LEAVES:5)
Block(-8,8,6,LEAVES:13)
Block(2,7,13,LEAVES:5)
Block(-2,31,6,LEAVES:5)
Block(-5,-7,8,LOG:12)
Block(-5,-8,8,LOG:12)
Block(-5,-5,8,LOG:12)
Block(-5,-6,8,LOG:12)
Block(-4,21,9,LOG)
Block(-4,20,9,LOG)
Block(-4,23,9,LEAVES:5)
Block(-4,22,9,LEAVES:5)
Block(-4,25,9,LEAVES:5)
Block(-4,24,9,LEAVES:5)
Block(-4,27,9,LOG)
Block(-4,26,9,LOG)
Block(-4,29,9,LOG)
Block(-4,28,9,LOG)
Block(-4,19,9,LOG)
Block(-8,2,6,LEAVES:14)
Block(-5,13,5,LEAVES:13)
Block(-6,16,14,LEAVES:5)
Block(-6,11,14,LEAVES:5)
Block(-1,14,9,LEAVES:5)
Block(-4,6,13,LEAVES:13)
Block(-4,7,13,LEAVES:13)
Block(-1,13,9,LEAVES:13)
Block(-1,14,13,LEAVES:5)
Block(-1,19,11,LEAVES:5)
Block(-4,9,13,LEAVES:13)
Block(-4,10,9,LEAVES:13)
Block(-10,6,4,LEAVES:5)
Block(-4,14,9,LEAVES:5)
Block(-4,13,9,LEAVES:13)
Block(-4,12,9,LEAVES:13)
Block(-4,11,9,LEAVES:13)
Block(-1,19,13,LEAVES:5)
Block(-4,18,9,LOG)
Block(-4,17,9,LEAVES:5)
Block(-4,16,9,LEAVES:5)
Block(-1,18,13,LEAVES:5)
Block(-4,15,9,LEAVES:5)
Block(-4,5,16,LEAVES:5)
Block(-4,2,6,LEAVES:14)
Block(-4,1,6,LEAVES:14)
Block(-4,6,16,LEAVES:5)
Block(-1,22,8,LEAVES:5)
Block(-6,32,9,LEAVES:5)
Block(-1,25,8,LEAVES:5)
Block(-4,9,6,LEAVES:13)
Block(-5,21,13,LEAVES:5)
Block(-4,4,6,LEAVES:14)
Block(-5,20,13,LEAVES:5)
Block(-4,3,6,LEAVES:14)
Block(-4,5,6,LEAVES:14)
Block(-3,40,9,LEAVES:5)
Block(-3,41,9,LEAVES:5)
Block(-3,42,9,LOG)
Block(-7,21,13,LEAVES:5)
Block(-1,17,8,LEAVES:5)
Block(-1,18,8,LEAVES:5)
Block(-3,47,9,LEAVES:5)
Block(1,13,8,LEAVES:5)
Block(-4,6,14,LEAVES:5)
Block(1,12,8,LEAVES:5)
Block(-3,43,9,LEAVES:5)
Block(1,17,8,LEAVES:5)
Block(-3,44,9,LOG)
Block(1,16,8,LEAVES:5)
Block(-3,45,9,LOG)
Block(-4,9,14,LEAVES:5)
Block(-3,46,9,LEAVES:5)
Block(-4,8,14,LEAVES:5)
Block(-1,14,8,LEAVES:5)
Block(-8,9,10,LEAVES:13)
Block(-8,8,10,LEAVES:13)
Block(-6,16,9,LEAVES:5)
Block(-6,14,9,LEAVES:5)
Block(-2,9,11,LEAVES:13)
Block(-2,8,11,LEAVES:13)
Block(-6,17,9,LEAVES:5)
Block(-3,21,7,LEAVES:5)
Block(-3,20,7,LEAVES:5)
Block(-6,12,9,LEAVES:13)
Block(-6,11,9,LEAVES:13)
Block(-6,10,9,LEAVES:13)
Block(-3,19,7,LEAVES:5)
Block(-3,17,7,LEAVES:5)
Block(-3,16,7,LEAVES:5)
Block(3,11,7,LEAVES:5)
Block(-5,6,15,LEAVES:5)
Block(-2,13,7,LEAVES:13)
Block(-2,14,7,LEAVES:5)
Block(-2,11,7,LEAVES:13)
Block(-5,5,15,LEAVES:5)
Block(-2,12,7,LEAVES:13)
Block(-2,15,7,LEAVES:5)
Block(-6,27,9,LEAVES:5)
Block(-2,18,7,LEAVES:5)
Block(-6,26,9,LEAVES:5)
Block(-2,17,7,LEAVES:5)
Block(-6,6,13,LEAVES:13)
Block(-2,19,7,LEAVES:5)
Block(-1,31,8,LEAVES:5)
Block(-3,31,7,LEAVES:5)
Block(-1,30,8,LEAVES:5)
Block(-3,33,7,LEAVES:5)
Block(-1,36,8,LEAVES:5)
Block(-3,34,7,LEAVES:5)
Block(-6,21,9,LEAVES:5)
Block(-1,35,8,LEAVES:5)
Block(-6,20,9,LEAVES:5)
Block(-6,7,2,LEAVES:5)
Block(3,5,5,LEAVES:5)
Block(-3,37,7,LEAVES:5)
Block(-6,8,2,LEAVES:5)
Block(-3,28,7,LEAVES:5)
Block(-2,5,15,LEAVES:5)
Block(-3,27,7,LEAVES:5)
Block(-1,26,8,LEAVES:5)
Block(-3,29,7,LEAVES:5)
Block(-5,21,4,LEAVES:5)
Block(-2,8,15,LEAVES:5)
Block(-5,22,4,LEAVES:5)
Block(0,26,10,LEAVES:5)
Block(0,27,10,LEAVES:5)
Block(-9,7,8,LEAVES:13)
Block(0,21,10,LEAVES:5)
Block(0,22,10,LEAVES:5)
Block(-2,26,7,LEAVES:5)
Block(-2,27,7,LEAVES:5)
Block(-4,38,11,LEAVES:5)
Block(-4,35,11,LEAVES:5)
Block(-2,32,7,LEAVES:5)
Block(-4,34,11,LEAVES:5)
Block(-2,31,7,LEAVES:5)
Block(-4,36,11,LEAVES:5)
Block(0,16,10,LEAVES:5)
Block(-4,29,11,LEAVES:5)
Block(-4,25,11,LEAVES:5)
Block(-4,24,11,LEAVES:5)
Block(-4,23,11,LEAVES:5)
Block(-2,7,4,LEAVES:13)
Block(-4,22,11,LEAVES:5)
Block(-2,5,4,LEAVES:13)
Block(-6,-1,9,LOG:12)
Block(-6,-2,9,LOG:12)
Block(-6,-5,9,LOG:12)
Block(-6,-6,9,LOG:12)
Block(-6,-3,9,LOG:12)
Block(-9,12,5,LEAVES:5)
Block(-9,13,5,LEAVES:5)
Block(1,7,11,LEAVES:5)
Block(-6,31,7,LEAVES:5)
Block(-4,45,11,LEAVES:5)
Block(-7,11,13,LEAVES:13)
Block(-10,7,6,LEAVES:5)
Block(-10,8,6,LEAVES:5)
Block(-9,6,5,LEAVES:13)
Block(-4,44,11,LEAVES:5)
Block(-6,0,8,LOG:12)
Block(-3,27,6,LEAVES:5)
Block(-6,2,8,LEAVES:14)
Block(-4,9,4,LEAVES:13)
Block(-6,1,8,LOG:12)
Block(-4,8,4,LEAVES:13)
Block(-6,3,8,LEAVES:14)
Block(-2,18,5,LEAVES:5)
Block(-2,19,5,LEAVES:5)
Block(-2,14,5,LEAVES:5)
Block(-2,16,5,LEAVES:5)
Block(-2,15,5,LEAVES:5)
Block(-5,33,11,LEAVES:5)
Block(-2,32,11,LEAVES:5)
Block(-5,34,11,LEAVES:5)
Block(-2,33,11,LEAVES:5)
Block(-3,20,11,LEAVES:5)
Block(-5,37,11,LEAVES:5)
Block(-5,38,11,LEAVES:5)
Block(-2,30,11,LEAVES:5)
Block(-3,28,11,LEAVES:5)
Block(-3,25,11,LEAVES:5)
Block(-2,37,11,LEAVES:5)
Block(-3,33,6,LEAVES:5)
Block(-5,30,11,LEAVES:5)
Block(-6,-8,8,LOG:12)
Block(-2,38,11,LEAVES:5)
Block(-3,27,11,LEAVES:5)
Block(-6,-7,8,LOG:12)
Block(-3,26,11,LEAVES:5)
Block(-6,-6,8,LOG:12)
Block(2,11,9,LEAVES:5)
Block(-3,14,3,LEAVES:5)
Block(-2,7,8,LEAVES:13)
Block(-3,13,3,LEAVES:5)
Block(-2,8,8,LEAVES:13)
Block(-2,5,8,LEAVES:13)
Block(-3,18,3,LEAVES:5)
Block(-2,3,8,LEAVES:13)
Block(-2,4,8,LEAVES:13)
Block(-2,1,8,LEAVES:13)
Block(-3,-1,9,LEAVES:13)
Block(-2,2,8,LEAVES:13)
Block(-3,-2,9,LEAVES:13)
Block(-3,-3,9,LOG:12)
Block(-2,0,8,LEAVES:13)
Block(-5,24,11,LEAVES:5)
Block(-4,6,8,LOG:12)
Block(0,12,7,LEAVES:13)
Block(-3,33,11,LEAVES:5)
Block(-4,5,8,LOG:12)
Block(0,13,7,LEAVES:13)
Block(-3,32,11,LEAVES:5)
Block(-5,22,11,LEAVES:5)
Block(-7,16,7,LEAVES:5)
Block(-4,8,8,LOG:12)
Block(0,10,7,LEAVES:13)
Block(-3,31,11,LEAVES:5)
Block(-5,23,11,LEAVES:5)
Block(-7,17,7,LEAVES:5)
Block(-4,7,8,LOG:12)
Block(-2,10,5,LEAVES:13)
Block(-5,28,11,LEAVES:5)
Block(0,16,7,LEAVES:5)
Block(-4,2,8,LOG:12)
Block(-7,14,7,LEAVES:5)
Block(-5,29,11,LEAVES:5)
Block(-2,20,11,LEAVES:5)
Block(0,17,7,LEAVES:5)
Block(-4,1,8,LOG:12)
Block(-4,4,8,LOG:12)
Block(-4,3,8,LOG:12)
Block(-7,13,7,LEAVES:13)
Block(-7,10,7,LEAVES:13)
Block(-2,29,11,LEAVES:5)
Block(-4,0,8,LOG:12)
Block(-8,8,12,LEAVES:13)
Block(-2,27,11,LEAVES:5)
Block(-3,37,11,LEAVES:5)
Block(-2,28,11,LEAVES:5)
Block(-3,36,11,LEAVES:5)
Block(-3,35,11,LEAVES:5)
Block(-2,26,11,LEAVES:5)
Block(2,16,9,LEAVES:5)
Block(-6,9,11,LEAVES:13)
Block(-4,11,11,LEAVES:13)
Block(-2,7,13,LEAVES:13)
Block(-7,-7,7,LOG:12)
Block(-4,14,11,LEAVES:5)
Block(-2,8,13,LEAVES:13)
Block(-4,9,8,LEAVES:13)
Block(-2,9,13,LEAVES:13)
Block(-4,12,11,LEAVES:13)
Block(-4,18,11,LEAVES:5)
Block(-2,5,13,LEAVES:13)
Block(-2,-3,9,LOG:12)
Block(-3,8,2,LEAVES:5)
Block(-2,6,13,LEAVES:13)
Block(0,25,7,LEAVES:5)
Block(-6,8,4,LEAVES:13)
Block(-5,17,11,LEAVES:5)
Block(-5,18,11,LEAVES:5)
Block(-3,-4,9,LOG:12)
Block(-1,14,3,LEAVES:5)
Block(-5,13,11,LEAVES:13)
Block(0,24,7,LEAVES:5)
Block(-5,14,11,LEAVES:5)
Block(-10,12,4,LEAVES:5)
Block(-10,11,4,LEAVES:5)
Block(-9,10,9,LEAVES:13)
Block(-3,19,6,LEAVES:5)
Block(-6,-1,8,LOG:12)
Block(-6,-2,8,LOG:12)
Block(-9,14,9,LEAVES:5)
Block(-9,15,9,LEAVES:5)
Block(-6,-3,8,LOG:12)
Block(-6,-4,8,LOG:12)
Block(-3,16,6,LEAVES:5)
Block(-6,-5,8,LOG:12)
Block(-9,18,9,LEAVES:5)
Block(-2,24,5,LEAVES:5)
Block(-2,41,11,LEAVES:5)
Block(-2,42,11,LEAVES:5)
Block(-2,-2,9,LEAVES:13)
Block(-2,-1,9,LEAVES:13)
Block(-3,11,11,LEAVES:13)
Block(2,9,5,LEAVES:5)
Block(-2,44,11,LEAVES:5)
Block(-3,16,11,LEAVES:5)
Block(2,8,5,LEAVES:5)
Block(-1,6,5,LEAVES:13)
Block(2,5,5,LEAVES:5)
Block(2,6,5,LEAVES:5)
Block(-1,5,5,LEAVES:13)
Block(-6,9,8,LEAVES:13)
Block(-3,20,6,LEAVES:5)
Block(-6,7,8,LEAVES:13)
Block(-6,8,8,LEAVES:13)
Block(-7,16,9,LEAVES:5)
Block(-9,18,10,LEAVES:5)
Block(-6,22,12,LEAVES:5)
Block(-9,19,10,LEAVES:5)
Block(-7,15,9,LEAVES:5)
Block(0,7,12,LEAVES:13)
Block(0,8,12,LEAVES:13)
Block(-6,27,12,LEAVES:5)
Block(-1,10,5,LEAVES:13)
Block(-9,14,10,LEAVES:5)
Block(-6,26,12,LEAVES:5)
Block(-7,19,9,LEAVES:5)
Block(-4,8,10,LEAVES:13)
Block(-4,9,10,LEAVES:13)
Block(-6,21,12,LEAVES:5)
Block(-1,-2,8,LEAVES:13)
Block(-7,10,9,LEAVES:13)
Block(-1,-1,8,LEAVES:13)
Block(-7,11,9,LEAVES:13)
Block(0,6,8,LEAVES:13)
Block(-4,8,12,LEAVES:13)
Block(-4,7,12,LEAVES:13)
Block(0,5,8,LEAVES:13)
Block(0,8,10,LEAVES:13)
Block(0,7,10,LEAVES:13)
Block(0,18,12,LEAVES:5)
Block(0,13,12,LEAVES:13)
Block(-3,15,9,LEAVES:5)
Block(-6,12,12,LEAVES:13)
Block(-3,14,9,LEAVES:5)
Block(-3,17,9,LOG)
Block(-3,16,9,LEAVES:5)
Block(-6,13,12,LEAVES:13)
Block(-6,16,12,LEAVES:5)
Block(-3,11,9,LEAVES:13)
Block(-3,10,9,LEAVES:13)
Block(-3,13,9,LEAVES:13)
Block(-6,17,12,LEAVES:5)
Block(-3,12,9,LEAVES:13)
Block(-4,15,6,LEAVES:5)
Block(0,26,12,LEAVES:5)
Block(-4,10,6,LEAVES:13)
Block(-3,24,9,LEAVES:5)
Block(-3,23,9,LEAVES:5)
Block(-3,22,9,LEAVES:5)
Block(-3,21,9,LEAVES:5)
Block(-4,19,6,LEAVES:5)
Block(-3,28,9,LOG)
Block(-3,27,9,LOG)
Block(-3,26,9,LEAVES:5)
Block(-3,25,9,LEAVES:5)
Block(1,21,9,LEAVES:5)
Block(1,20,9,LEAVES:5)
Block(-3,20,9,LEAVES:5)
Block(-7,31,9,LEAVES:5)
Block(-2,15,11,LEAVES:5)
Block(-2,16,11,LEAVES:5)
Block(-2,19,3,LEAVES:5)
Block(-4,20,6,LEAVES:5)
Block(-2,18,3,LEAVES:5)
Block(-7,26,7,LEAVES:5)
Block(-3,18,9,LOG)
Block(-7,25,7,LEAVES:5)
Block(-3,19,9,LOG)
Block(-2,15,3,LEAVES:5)
Block(-2,14,3,LEAVES:5)
Block(-4,23,6,LEAVES:5)
Block(-3,33,9,LOG)
Block(-4,29,6,LEAVES:5)
Block(-3,32,9,LOG)
Block(-3,35,9,LOG)
Block(-4,27,6,LEAVES:5)
Block(-3,34,9,LOG)
Block(-4,28,6,LEAVES:5)
Block(-3,37,9,LOG)
Block(-7,25,9,LEAVES:5)
Block(-3,36,9,LOG)
Block(-7,26,9,LEAVES:5)
Block(-3,39,9,LOG)
Block(-3,38,9,LOG)
Block(1,12,9,LEAVES:5)
Block(1,11,9,LEAVES:5)
Block(-4,11,15,LEAVES:5)
Block(-4,10,15,LEAVES:5)
Block(-3,31,9,LOG)
Block(-3,30,9,LOG)
Block(-7,20,9,LEAVES:5)
Block(1,17,9,LEAVES:5)
Block(-5,12,13,LEAVES:13)
Block(1,16,9,LEAVES:5)
Block(-4,33,6,LEAVES:5)
Block(-3,29,9,LOG)
Block(-5,17,13,LEAVES:5)
Block(-2,-1,7,LEAVES:13)
Block(-2,-2,7,LEAVES:13)
Block(-5,13,13,LEAVES:13)
Block(-5,16,13,LEAVES:5)

#######################################################################
# +-----------------------------------------------------------------+ #
# |                            BO3 checks                           | #
# +-----------------------------------------------------------------+ #
#######################################################################

# Require a condition at a certain location in order for the BO3 to be spawned.
# BlockCheck(x,y,z,BlockName[,BlockName[,...]]) - one of the blocks must be at the location
# BlockCheckNot(x,y,z,BlockName[,BlockName[,...]]) - all the blocks must not be at the location
# LightCheck(x,y,z,minLightLevel,maxLightLevel) - light must be between min and max (inclusive)

# You can use "Solid" as a BlockName for matching all solid blocks or "All" to match all blocks that aren't air.

# Examples:
BlockCheck(0,-1,0,Solid)
BlockCheck(0,-1,0,GRASS,DIRT)
BlockCheck(0,-1,2,GRASS,DIRT)
BlockCheck(1,-1,0,GRASS,DIRT)
BlockCheck(-1,-1,0,GRASS,DIRT)
BlockCheck(0,-1,-1,GRASS,DIRT)
BlockCheck(0,-1,0,Solid)
BlockCheckNot(0,-1,0,AIR)
#   BlockCheck(0,-1,0,WOOL)        Require any type of wool just below the object
#   BlockCheck(0,-1,0,WOOL:0)      Require white wool just below the object
#   BlockCheckNot(0,-1,0,WOOL:0)   Require that there is no white wool below the object
#   LightCheck(0,0,0,0,1)          Require almost complete darkness just below the object

#######################################################################
# +-----------------------------------------------------------------+ #
# |                             Branches                            | #
# +-----------------------------------------------------------------+ #
#######################################################################

# Branches are objects that will spawn when this object spawns when it is used in
# the CustomStructure resource. Branches can also have branches, making complex
# structures possible. See the wiki for more details.

# Regular Branches spawn each branch with an independent chance of spawning.
# Branch(x,y,z,branchName,rotation,chance[,anotherBranchName,rotation,chance[,...]][IndividualChance])
# branchName - name of the object to spawn.
# rotation - NORTH, SOUTH, EAST or WEST.
# IndividualChance - The chance each branch has to spawn, assumed to be 100 when left blank

# Weighted Branches spawn branches with a dependent chance of spawning.
# WeightedBranch(x,y,z,branchName,rotation,chance[,anotherBranchName,rotation,chance[,...]][MaxChanceOutOf])
# MaxChanceOutOf - The chance all branches have to spawn out of, assumed to be 100 when left blank
