[META]
version=2.0
spawnOnBlockType=2,3,3:1,3:2
spawnSunlight=True
spawnDarkness=True
spawnWater=False
spawnLava=False
underFill=False
randomRotation=True
dig=True
tree=True
branch=False
needsFoundation=True
rarity=100
collisionPercentage=20
spawnElevationMin=0
spawnElevationMax=240
spawnInBiome=Custom
[DATA]
-1,-1,-2:17.0
-1,-1,-1:17.0
-1,-1,0:17.0
-1,-1,1:17.0
-1,-1,2:17.0
-2,-5,3:18.0
-4,-4,3:18.0
-3,-4,3:18.0
-1,-4,3:18.0
1,-4,3:18.0
-5,-3,3:18.0
-4,-3,3:18.0
-3,-3,3:18.0
-2,-3,3:18.0
-5,-2,3:18.0
-4,-2,3:18.0
-3,-2,3:17.0
-2,-2,3:17.0
-1,-2,3:17.0
2,-2,3:18.0
3,-2,3:18.0
-6,-1,3:18.0
-4,-1,3:18.0
-1,-1,3:17.0
0,-1,3:17.0
2,-1,3:18.0
3,-1,3:18.0
-6,0,3:18.0
-4,0,3:18.0
-3,0,3:17.0
-2,0,3:17.0
-1,0,3:17.0
0,0,3:17.0
1,0,3:17.0
3,0,3:18.0
-5,1,3:18.0
-4,1,3:18.0
3,1,3:18.0
4,1,3:18.0
-6,2,3:18.0
-5,2,3:18.0
-3,2,3:18.0
1,2,3:18.0
2,2,3:18.0
3,2,3:18.0
4,2,3:18.0
1,3,3:18.0
-4,4,3:18.0
-3,4,3:18.0
-2,4,3:18.0
0,4,3:18.0
0,5,3:18.0
-4,-5,4:18.0
-3,-5,4:18.0
-2,-5,4:18.0
0,-5,4:18.0
-4,-4,4:18.0
-3,-4,4:17.0
-2,-4,4:18.0
-1,-4,4:18.0
0,-4,4:18.0
1,-4,4:18.0
2,-4,4:18.0
-5,-3,4:18.0
-4,-3,4:18.0
-3,-3,4:17.0
-2,-3,4:18.0
-1,-3,4:18.0
1,-3,4:18.0
2,-3,4:18.0
3,-3,4:18.0
-4,-2,4:18.0
-3,-2,4:17.0
-1,-2,4:18.0
1,-2,4:18.0
2,-2,4:18.0
-6,-1,4:18.0
-5,-1,4:18.0
-4,-1,4:18.0
-2,-1,4:18.0
-1,-1,4:18.0
0,-1,4:18.0
2,-1,4:18.0
3,-1,4:18.0
4,-1,4:18.0
-6,0,4:18.0
-5,0,4:18.0
-4,0,4:18.0
-3,0,4:17.0
-1,0,4:18.0
1,0,4:17.0
2,0,4:17.0
3,0,4:17.0
4,0,4:18.0
-6,1,4:18.0
-5,1,4:18.0
-4,1,4:18.0
-3,1,4:17.0
-2,1,4:18.0
2,1,4:18.0
3,1,4:18.0
4,1,4:18.0
-5,2,4:18.0
-4,2,4:18.0
-3,2,4:17.0
-2,2,4:18.0
1,2,4:18.0
2,2,4:18.0
3,2,4:18.0
-4,3,4:18.0
-3,3,4:18.0
-2,3,4:18.0
-1,3,4:18.0
0,3,4:18.0
1,3,4:18.0
2,3,4:18.0
-3,4,4:18.0
-2,4,4:18.0
-1,4,4:18.0
0,4,4:18.0
1,4,4:18.0
-2,5,4:18.0
-1,5,4:18.0
0,5,4:18.0
-3,-6,5:18.0
-4,-5,5:18.0
-3,-5,5:18.0
-2,-5,5:18.0
-5,-4,5:18.0
-4,-4,5:18.0
-3,-4,5:17.0
-2,-4,5:18.0
-1,-4,5:18.0
0,-4,5:18.0
1,-4,5:18.0
-4,-3,5:18.0
-3,-3,5:18.0
-2,-3,5:18.0
-1,-3,5:18.0
0,-3,5:18.0
1,-3,5:18.0
2,-3,5:18.0
-5,-2,5:18.0
-4,-2,5:18.0
-3,-2,5:18.0
-2,-2,5:18.0
-1,-2,5:18.0
0,-2,5:18.0
1,-2,5:18.0
2,-2,5:18.0
3,-2,5:18.0
-5,-1,5:18.0
-4,-1,5:18.0
-3,-1,5:18.0
-2,-1,5:18.0
-1,-1,5:18.0
0,-1,5:18.0
1,-1,5:18.0
2,-1,5:18.0
3,-1,5:18.0
4,-1,5:18.0
-5,0,5:18.0
-4,0,5:18.0
-3,0,5:18.0
-2,0,5:18.0
-1,0,5:18.0
0,0,5:18.0
1,0,5:18.0
2,0,5:18.0
3,0,5:17.0
4,0,5:18.0
5,0,5:18.0
-5,1,5:18.0
-4,1,5:18.0
-3,1,5:18.0
-2,1,5:18.0
1,1,5:18.0
2,1,5:18.0
3,1,5:18.0
4,1,5:18.0
-5,2,5:18.0
-4,2,5:18.0
-3,2,5:17.0
-2,2,5:18.0
-1,2,5:18.0
0,2,5:18.0
1,2,5:18.0
2,2,5:18.0
3,2,5:18.0
-4,3,5:18.0
-3,3,5:18.0
-2,3,5:18.0
-1,3,5:18.0
0,3,5:18.0
1,3,5:18.0
2,3,5:18.0
-3,4,5:18.0
-2,4,5:18.0
-1,4,5:18.0
0,4,5:18.0
1,4,5:18.0
-4,-5,6:18.0
-3,-5,6:18.0
-2,-5,6:18.0
-4,-4,6:18.0
-3,-4,6:18.0
-2,-4,6:18.0
-4,-3,6:18.0
-3,-3,6:18.0
-2,-3,6:18.0
-1,-3,6:18.0
0,-3,6:18.0
1,-3,6:18.0
-4,-2,6:18.0
-3,-2,6:18.0
-2,-2,6:18.0
-1,-2,6:18.0
0,-2,6:18.0
1,-2,6:18.0
2,-2,6:18.0
-4,-1,6:18.0
-3,-1,6:18.0
-2,-1,6:18.0
-1,-1,6:18.0
0,-1,6:18.0
1,-1,6:18.0
2,-1,6:18.0
3,-1,6:18.0
4,-1,6:18.0
-4,0,6:18.0
-3,0,6:18.0
-2,0,6:18.0
-1,0,6:18.0
0,0,6:18.0
1,0,6:18.0
2,0,6:18.0
3,0,6:18.0
4,0,6:18.0
-4,1,6:18.0
-3,1,6:18.0
-2,1,6:18.0
-1,1,6:18.0
0,1,6:18.0
1,1,6:18.0
2,1,6:18.0
3,1,6:18.0
4,1,6:18.0
-4,2,6:18.0
-3,2,6:18.0
-2,2,6:18.0
-1,2,6:18.0
0,2,6:18.0
1,2,6:18.0
2,2,6:18.0
-4,3,6:18.0
-3,3,6:18.0
-2,3,6:18.0
-1,3,6:18.0
0,3,6:18.0
1,3,6:18.0
-3,-4,7:18.0
-2,-2,7:18.0
-1,-2,7:18.0
0,-2,7:18.0
-3,-1,7:18.0
-2,-1,7:18.0
-1,-1,7:18.0
0,-1,7:18.0
1,-1,7:18.0
-3,0,7:18.0
-2,0,7:18.0
-1,0,7:18.0
0,0,7:18.0
1,0,7:18.0
3,0,7:18.0
-3,1,7:18.0
-2,1,7:18.0
-1,1,7:18.0
0,1,7:18.0
1,1,7:18.0
-3,2,7:18.0
-2,2,7:18.0
-1,2,7:18.0
0,2,7:18.0
-2,-1,8:18.0
-1,-1,8:18.0
0,-1,8:18.0
-2,0,8:18.0
-1,0,8:18.0
0,0,8:18.0
-2,1,8:18.0
-1,1,8:18.0
0,1,8:18.0
-1,0,9:18.0
