[META]
version=2.0
spawnOnBlockType=2,3
spawnSunlight=True
spawnDarkness=True
spawnWater=False
spawnLava=False
underFill=False
randomRotation=True
dig=True
tree=True
branch=False
needsFoundation=True
rarity=100
collisionPercentage=20
spawnElevationMin=0
spawnElevationMax=240
spawnInBiome=Custom
[DATA]
0,0,0:17.2
0,0,1:17.2
0,0,2:17.2
-1,-1,3:18.2
0,-1,3:18.2
1,-1,3:18.2
-1,0,3:18.2
0,0,3:17.2
1,0,3:18.2
-1,1,3:18.2
0,1,3:18.2
1,1,3:18.2
0,-2,4:18.2
-1,-1,4:18.2
0,-1,4:18.2
1,-1,4:18.2
-2,0,4:18.2
-1,0,4:18.2
0,0,4:17.2
1,0,4:18.2
2,0,4:18.2
-1,1,4:18.2
0,1,4:18.2
1,1,4:18.2
0,2,4:18.2
-1,-2,5:18.2
0,-2,5:18.2
1,-2,5:18.2
-2,-1,5:18.2
-1,-1,5:18.2
0,-1,5:18.2
1,-1,5:18.2
2,-1,5:18.2
-2,0,5:18.2
-1,0,5:18.2
0,0,5:17.2
1,0,5:18.2
2,0,5:18.2
-2,1,5:18.2
-1,1,5:18.2
0,1,5:18.2
1,1,5:18.2
2,1,5:18.2
-1,2,5:18.2
0,2,5:18.2
1,2,5:18.2
-1,-2,6:18.2
0,-2,6:18.2
1,-2,6:18.2
-2,-1,6:18.2
-1,-1,6:18.2
0,-1,6:18.2
1,-1,6:18.2
2,-1,6:18.2
-2,0,6:18.2
-1,0,6:18.2
0,0,6:17.2
1,0,6:18.2
2,0,6:18.2
-2,1,6:18.2
-1,1,6:18.2
0,1,6:18.2
1,1,6:18.2
2,1,6:18.2
-1,2,6:18.2
0,2,6:18.2
1,2,6:18.2
-1,-2,7:18.2
0,-2,7:18.2
1,-2,7:18.2
-2,-1,7:18.2
-1,-1,7:18.2
0,-1,7:18.2
1,-1,7:18.2
2,-1,7:18.2
-2,0,7:18.2
-1,0,7:18.2
0,0,7:17.2
1,0,7:18.2
2,0,7:18.2
-2,1,7:18.2
-1,1,7:18.2
0,1,7:18.2
1,1,7:18.2
2,1,7:18.2
-1,2,7:18.2
0,2,7:18.2
1,2,7:18.2
-1,-2,8:18.2
0,-2,8:18.2
1,-2,8:18.2
-2,-1,8:18.2
-1,-1,8:18.2
0,-1,8:18.2
1,-1,8:18.2
2,-1,8:18.2
-2,0,8:18.2
-1,0,8:18.2
0,0,8:17.2
1,0,8:18.2
2,0,8:18.2
-2,1,8:18.2
-1,1,8:18.2
0,1,8:18.2
1,1,8:18.2
2,1,8:18.2
-1,2,8:18.2
0,2,8:18.2
1,2,8:18.2
-1,-2,9:18.2
0,-2,9:18.2
1,-2,9:18.2
-2,-1,9:18.2
-1,-1,9:18.2
0,-1,9:18.2
1,-1,9:18.2
2,-1,9:18.2
-2,0,9:18.2
-1,0,9:18.2
0,0,9:17.2
1,0,9:18.2
2,0,9:18.2
-2,1,9:18.2
-1,1,9:18.2
0,1,9:18.2
1,1,9:18.2
2,1,9:18.2
-1,2,9:18.2
0,2,9:18.2
1,2,9:18.2
-1,-2,10:18.2
0,-2,10:18.2
1,-2,10:18.2
-2,-1,10:18.2
-1,-1,10:18.2
0,-1,10:18.2
1,-1,10:18.2
2,-1,10:18.2
-2,0,10:18.2
-1,0,10:18.2
0,0,10:17.2
1,0,10:18.2
2,0,10:18.2
-2,1,10:18.2
-1,1,10:18.2
0,1,10:18.2
1,1,10:18.2
2,1,10:18.2
-1,2,10:18.2
0,2,10:18.2
1,2,10:18.2
-1,-2,11:18.2
0,-2,11:18.2
1,-2,11:18.2
-2,-1,11:18.2
-1,-1,11:18.2
0,-1,11:18.2
1,-1,11:18.2
2,-1,11:18.2
-2,0,11:18.2
-1,0,11:18.2
0,0,11:17.2
1,0,11:18.2
2,0,11:18.2
-2,1,11:18.2
-1,1,11:18.2
0,1,11:18.2
1,1,11:18.2
2,1,11:18.2
-1,2,11:18.2
0,2,11:18.2
1,2,11:18.2
0,-2,12:18.2
-1,-1,12:18.2
0,-1,12:18.2
1,-1,12:18.2
-2,0,12:18.2
-1,0,12:18.2
0,0,12:17.2
1,0,12:18.2
2,0,12:18.2
-1,1,12:18.2
0,1,12:18.2
1,1,12:18.2
0,2,12:18.2
-1,-1,13:18.2
0,-1,13:18.2
1,-1,13:18.2
-1,0,13:18.2
0,0,13:17.2
1,0,13:18.2
-1,1,13:18.2
0,1,13:18.2
1,1,13:18.2
-1,-1,14:18.2
0,-1,14:18.2
1,-1,14:18.2
-1,0,14:18.2
0,0,14:17.2
1,0,14:18.2
-1,1,14:18.2
0,1,14:18.2
1,1,14:18.2
0,-1,15:18.2
-1,0,15:18.2
0,0,15:17.2
1,0,15:18.2
0,1,15:18.2
0,-1,16:18.2
-1,0,16:18.2
0,0,16:18.2
1,0,16:18.2
0,1,16:18.2
0,0,17:18.2
0,0,18:18.2
0,0,19:18.2
