[META]
version=2.0
spawnOnBlockType=3.1,2.1,2,3
spawnSunlight=True
spawnDarkness=True
spawnWater=False
spawnLava=False
underFill=False
randomRotation=True
dig=True
tree=True
branch=False
needsFoundation=True
rarity=100
collisionPercentage=20
spawnElevationMin=0
spawnElevationMax=240
spawnInBiome=Custom
[DATA]
-1,-1,0:17.1
0,-1,0:17.1
-1,0,0:17.1
0,0,0:17.1
-1,-1,1:17.1
0,-1,1:17.1
-1,0,1:17.1
0,0,1:17.1
-1,-1,2:17.1
0,-1,2:17.1
-1,0,2:17.1
0,0,2:17.1
-1,-1,3:17.1
0,-1,3:17.1
-1,0,3:17.1
0,0,3:17.1
-1,-1,4:17.1
0,-1,4:17.1
-1,0,4:17.1
0,0,4:17.1
-1,-1,5:17.1
0,-1,5:17.1
-1,0,5:17.1
0,0,5:17.1
-1,-1,6:17.1
0,-1,6:17.1
-1,0,6:17.1
0,0,6:17.1
-1,-1,7:17.1
0,-1,7:17.1
-1,0,7:17.1
0,0,7:17.1
-1,-1,8:17.1
0,-1,8:17.1
-1,0,8:17.1
0,0,8:17.1
-1,-1,9:17.1
0,-1,9:17.1
-1,0,9:17.1
0,0,9:17.1
-1,-1,10:17.1
0,-1,10:17.1
-1,0,10:17.1
0,0,10:17.1
-2,-3,11:18.1
-1,-3,11:18.1
0,-3,11:18.1
1,-3,11:18.1
-3,-2,11:18.1
-2,-2,11:18.1
-1,-2,11:18.1
0,-2,11:18.1
1,-2,11:18.1
2,-2,11:18.1
-3,-1,11:18.1
-2,-1,11:18.1
-1,-1,11:17.1
0,-1,11:17.1
1,-1,11:18.1
2,-1,11:18.1
-3,0,11:18.1
-2,0,11:18.1
-1,0,11:17.1
0,0,11:17.1
1,0,11:18.1
2,0,11:18.1
-3,1,11:18.1
-2,1,11:18.1
-1,1,11:18.1
0,1,11:18.1
1,1,11:18.1
2,1,11:18.1
-2,2,11:18.1
-1,2,11:18.1
0,2,11:18.1
1,2,11:18.1
-1,-2,12:18.1
0,-2,12:18.1
-2,-1,12:18.1
-1,-1,12:17.1
0,-1,12:17.1
1,-1,12:18.1
-2,0,12:18.1
-1,0,12:17.1
0,0,12:17.1
1,0,12:18.1
-1,1,12:18.1
0,1,12:18.1
-2,-3,13:18.1
-1,-3,13:18.1
0,-3,13:18.1
1,-3,13:18.1
-3,-2,13:18.1
-2,-2,13:18.1
-1,-2,13:18.1
0,-2,13:18.1
1,-2,13:18.1
2,-2,13:18.1
-3,-1,13:18.1
-2,-1,13:18.1
-1,-1,13:17.1
0,-1,13:17.1
1,-1,13:18.1
2,-1,13:18.1
-3,0,13:18.1
-2,0,13:18.1
-1,0,13:17.1
0,0,13:17.1
1,0,13:18.1
2,0,13:18.1
-3,1,13:18.1
-2,1,13:18.1
-1,1,13:18.1
0,1,13:18.1
1,1,13:18.1
2,1,13:18.1
-2,2,13:18.1
-1,2,13:18.1
0,2,13:18.1
1,2,13:18.1
-1,-2,14:18.1
0,-2,14:18.1
-2,-1,14:18.1
-1,-1,14:17.1
0,-1,14:17.1
1,-1,14:18.1
-2,0,14:18.1
-1,0,14:17.1
0,0,14:17.1
1,0,14:18.1
-1,1,14:18.1
0,1,14:18.1
-2,-3,15:18.1
-1,-3,15:18.1
0,-3,15:18.1
1,-3,15:18.1
-3,-2,15:18.1
-2,-2,15:18.1
-1,-2,15:18.1
0,-2,15:18.1
1,-2,15:18.1
2,-2,15:18.1
-3,-1,15:18.1
-2,-1,15:18.1
-1,-1,15:17.1
0,-1,15:17.1
1,-1,15:18.1
2,-1,15:18.1
-3,0,15:18.1
-2,0,15:18.1
-1,0,15:17.1
0,0,15:17.1
1,0,15:18.1
2,0,15:18.1
-3,1,15:18.1
-2,1,15:18.1
-1,1,15:18.1
0,1,15:18.1
1,1,15:18.1
2,1,15:18.1
-2,2,15:18.1
-1,2,15:18.1
0,2,15:18.1
1,2,15:18.1
-1,-2,16:18.1
0,-2,16:18.1
-2,-1,16:18.1
-1,-1,16:17.1
0,-1,16:17.1
1,-1,16:18.1
-2,0,16:18.1
-1,0,16:17.1
0,0,16:17.1
1,0,16:18.1
-1,1,16:18.1
0,1,16:18.1
-2,-3,17:18.1
-1,-3,17:18.1
0,-3,17:18.1
1,-3,17:18.1
-3,-2,17:18.1
-2,-2,17:18.1
-1,-2,17:18.1
0,-2,17:18.1
1,-2,17:18.1
2,-2,17:18.1
-3,-1,17:18.1
-2,-1,17:18.1
-1,-1,17:17.1
0,-1,17:17.1
1,-1,17:18.1
2,-1,17:18.1
-3,0,17:18.1
-2,0,17:18.1
-1,0,17:17.1
0,0,17:17.1
1,0,17:18.1
2,0,17:18.1
-3,1,17:18.1
-2,1,17:18.1
-1,1,17:18.1
0,1,17:18.1
1,1,17:18.1
2,1,17:18.1
-2,2,17:18.1
-1,2,17:18.1
0,2,17:18.1
1,2,17:18.1
-1,-2,18:18.1
0,-2,18:18.1
-2,-1,18:18.1
-1,-1,18:17.1
0,-1,18:17.1
1,-1,18:18.1
-2,0,18:18.1
-1,0,18:17.1
0,0,18:17.1
1,0,18:18.1
-1,1,18:18.1
0,1,18:18.1
-2,-3,19:18.1
-1,-3,19:18.1
0,-3,19:18.1
1,-3,19:18.1
-3,-2,19:18.1
-2,-2,19:18.1
-1,-2,19:18.1
0,-2,19:18.1
1,-2,19:18.1
2,-2,19:18.1
-3,-1,19:18.1
-2,-1,19:18.1
-1,-1,19:17.1
0,-1,19:17.1
1,-1,19:18.1
2,-1,19:18.1
-3,0,19:18.1
-2,0,19:18.1
-1,0,19:17.1
0,0,19:17.1
1,0,19:18.1
2,0,19:18.1
-3,1,19:18.1
-2,1,19:18.1
-1,1,19:18.1
0,1,19:18.1
1,1,19:18.1
2,1,19:18.1
-2,2,19:18.1
-1,2,19:18.1
0,2,19:18.1
1,2,19:18.1
-1,-2,20:18.1
0,-2,20:18.1
-2,-1,20:18.1
-1,-1,20:17.1
0,-1,20:17.1
1,-1,20:18.1
-2,0,20:18.1
-1,0,20:17.1
0,0,20:17.1
1,0,20:18.1
-1,1,20:18.1
0,1,20:18.1
-2,-3,21:18.1
-1,-3,21:18.1
0,-3,21:18.1
1,-3,21:18.1
-3,-2,21:18.1
-2,-2,21:18.1
-1,-2,21:18.1
0,-2,21:18.1
1,-2,21:18.1
2,-2,21:18.1
-3,-1,21:18.1
-2,-1,21:18.1
-1,-1,21:17.1
0,-1,21:17.1
1,-1,21:18.1
2,-1,21:18.1
-3,0,21:18.1
-2,0,21:18.1
-1,0,21:17.1
0,0,21:17.1
1,0,21:18.1
2,0,21:18.1
-3,1,21:18.1
-2,1,21:18.1
-1,1,21:18.1
0,1,21:18.1
1,1,21:18.1
2,1,21:18.1
-2,2,21:18.1
-1,2,21:18.1
0,2,21:18.1
1,2,21:18.1
-1,-2,22:18.1
0,-2,22:18.1
-2,-1,22:18.1
-1,-1,22:17.1
0,-1,22:17.1
1,-1,22:18.1
-2,0,22:18.1
-1,0,22:17.1
0,0,22:17.1
1,0,22:18.1
-1,1,22:18.1
0,1,22:18.1
-2,-3,23:18.1
-1,-3,23:18.1
0,-3,23:18.1
1,-3,23:18.1
-3,-2,23:18.1
-2,-2,23:18.1
-1,-2,23:18.1
0,-2,23:18.1
1,-2,23:18.1
2,-2,23:18.1
-3,-1,23:18.1
-2,-1,23:18.1
-1,-1,23:17.1
0,-1,23:17.1
1,-1,23:18.1
2,-1,23:18.1
-3,0,23:18.1
-2,0,23:18.1
-1,0,23:17.1
0,0,23:17.1
1,0,23:18.1
2,0,23:18.1
-3,1,23:18.1
-2,1,23:18.1
-1,1,23:18.1
0,1,23:18.1
1,1,23:18.1
2,1,23:18.1
-2,2,23:18.1
-1,2,23:18.1
0,2,23:18.1
1,2,23:18.1
-1,-2,24:18.1
0,-2,24:18.1
-2,-1,24:18.1
-1,-1,24:17.1
0,-1,24:17.1
1,-1,24:18.1
-2,0,24:18.1
-1,0,24:17.1
0,0,24:17.1
1,0,24:18.1
-1,1,24:18.1
0,1,24:18.1
-2,-3,25:18.1
-1,-3,25:18.1
0,-3,25:18.1
1,-3,25:18.1
-3,-2,25:18.1
-2,-2,25:18.1
-1,-2,25:18.1
0,-2,25:18.1
1,-2,25:18.1
2,-2,25:18.1
-3,-1,25:18.1
-2,-1,25:18.1
-1,-1,25:17.1
0,-1,25:17.1
1,-1,25:18.1
2,-1,25:18.1
-3,0,25:18.1
-2,0,25:18.1
-1,0,25:17.1
0,0,25:17.1
1,0,25:18.1
2,0,25:18.1
-3,1,25:18.1
-2,1,25:18.1
-1,1,25:18.1
0,1,25:18.1
1,1,25:18.1
2,1,25:18.1
-2,2,25:18.1
-1,2,25:18.1
0,2,25:18.1
1,2,25:18.1
-1,-2,26:18.1
0,-2,26:18.1
-2,-1,26:18.1
-1,-1,26:17.1
0,-1,26:17.1
1,-1,26:18.1
-2,0,26:18.1
-1,0,26:17.1
0,0,26:17.1
1,0,26:18.1
-1,1,26:18.1
0,1,26:18.1
-2,-3,27:18.1
-1,-3,27:18.1
0,-3,27:18.1
1,-3,27:18.1
-3,-2,27:18.1
-2,-2,27:18.1
-1,-2,27:18.1
0,-2,27:18.1
1,-2,27:18.1
2,-2,27:18.1
-3,-1,27:18.1
-2,-1,27:18.1
-1,-1,27:17.1
0,-1,27:17.1
1,-1,27:18.1
2,-1,27:18.1
-3,0,27:18.1
-2,0,27:18.1
-1,0,27:17.1
0,0,27:17.1
1,0,27:18.1
2,0,27:18.1
-3,1,27:18.1
-2,1,27:18.1
-1,1,27:18.1
0,1,27:18.1
1,1,27:18.1
2,1,27:18.1
-2,2,27:18.1
-1,2,27:18.1
0,2,27:18.1
1,2,27:18.1
-1,-2,28:18.1
0,-2,28:18.1
-2,-1,28:18.1
-1,-1,28:17.1
0,-1,28:17.1
1,-1,28:18.1
-2,0,28:18.1
-1,0,28:17.1
0,0,28:17.1
1,0,28:18.1
-1,1,28:18.1
0,1,28:18.1
-2,-3,29:18.1
-1,-3,29:18.1
0,-3,29:18.1
1,-3,29:18.1
-3,-2,29:18.1
-2,-2,29:18.1
-1,-2,29:18.1
0,-2,29:18.1
1,-2,29:18.1
2,-2,29:18.1
-3,-1,29:18.1
-2,-1,29:18.1
-1,-1,29:17.1
0,-1,29:17.1
1,-1,29:18.1
2,-1,29:18.1
-3,0,29:18.1
-2,0,29:18.1
-1,0,29:17.1
0,0,29:17.1
1,0,29:18.1
2,0,29:18.1
-3,1,29:18.1
-2,1,29:18.1
-1,1,29:18.1
0,1,29:18.1
1,1,29:18.1
2,1,29:18.1
-2,2,29:18.1
-1,2,29:18.1
0,2,29:18.1
1,2,29:18.1
-1,-2,30:18.1
0,-2,30:18.1
-2,-1,30:18.1
-1,-1,30:17.1
0,-1,30:17.1
1,-1,30:18.1
-2,0,30:18.1
-1,0,30:17.1
0,0,30:17.1
1,0,30:18.1
-1,1,30:18.1
0,1,30:18.1
-2,-3,31:18.1
-1,-3,31:18.1
0,-3,31:18.1
1,-3,31:18.1
-3,-2,31:18.1
-2,-2,31:18.1
-1,-2,31:18.1
0,-2,31:18.1
1,-2,31:18.1
2,-2,31:18.1
-3,-1,31:18.1
-2,-1,31:18.1
-1,-1,31:17.1
0,-1,31:17.1
1,-1,31:18.1
2,-1,31:18.1
-3,0,31:18.1
-2,0,31:18.1
-1,0,31:17.1
0,0,31:17.1
1,0,31:18.1
2,0,31:18.1
-3,1,31:18.1
-2,1,31:18.1
-1,1,31:18.1
0,1,31:18.1
1,1,31:18.1
2,1,31:18.1
-2,2,31:18.1
-1,2,31:18.1
0,2,31:18.1
1,2,31:18.1
-1,-2,32:18.1
0,-2,32:18.1
-2,-1,32:18.1
-1,-1,32:17.1
0,-1,32:17.1
1,-1,32:18.1
-2,0,32:18.1
-1,0,32:17.1
0,0,32:17.1
1,0,32:18.1
-1,1,32:18.1
0,1,32:18.1
-2,-3,33:18.1
-1,-3,33:18.1
0,-3,33:18.1
1,-3,33:18.1
-3,-2,33:18.1
-2,-2,33:18.1
-1,-2,33:18.1
0,-2,33:18.1
1,-2,33:18.1
2,-2,33:18.1
-3,-1,33:18.1
-2,-1,33:18.1
-1,-1,33:17.1
0,-1,33:17.1
1,-1,33:18.1
2,-1,33:18.1
-3,0,33:18.1
-2,0,33:18.1
-1,0,33:17.1
0,0,33:17.1
1,0,33:18.1
2,0,33:18.1
-3,1,33:18.1
-2,1,33:18.1
-1,1,33:18.1
0,1,33:18.1
1,1,33:18.1
2,1,33:18.1
-2,2,33:18.1
-1,2,33:18.1
0,2,33:18.1
1,2,33:18.1
-1,-2,34:18.1
0,-2,34:18.1
-2,-1,34:18.1
-1,-1,34:17.1
0,-1,34:17.1
1,-1,34:18.1
-2,0,34:18.1
-1,0,34:17.1
0,0,34:17.1
1,0,34:18.1
-1,1,34:18.1
0,1,34:18.1
-2,-3,35:18.1
-1,-3,35:18.1
0,-3,35:18.1
1,-3,35:18.1
-3,-2,35:18.1
-2,-2,35:18.1
-1,-2,35:18.1
0,-2,35:18.1
1,-2,35:18.1
2,-2,35:18.1
-3,-1,35:18.1
-2,-1,35:18.1
-1,-1,35:17.1
0,-1,35:17.1
1,-1,35:18.1
2,-1,35:18.1
-3,0,35:18.1
-2,0,35:18.1
-1,0,35:17.1
0,0,35:17.1
1,0,35:18.1
2,0,35:18.1
-3,1,35:18.1
-2,1,35:18.1
-1,1,35:18.1
0,1,35:18.1
1,1,35:18.1
2,1,35:18.1
-2,2,35:18.1
-1,2,35:18.1
0,2,35:18.1
1,2,35:18.1
-1,-2,36:18.1
0,-2,36:18.1
-2,-1,36:18.1
-1,-1,36:17.1
0,-1,36:17.1
1,-1,36:18.1
-2,0,36:18.1
-1,0,36:17.1
0,0,36:17.1
1,0,36:18.1
-1,1,36:18.1
0,1,36:18.1
-2,-3,37:18.1
-1,-3,37:18.1
0,-3,37:18.1
1,-3,37:18.1
-3,-2,37:18.1
-2,-2,37:18.1
-1,-2,37:18.1
0,-2,37:18.1
1,-2,37:18.1
2,-2,37:18.1
-3,-1,37:18.1
-2,-1,37:18.1
-1,-1,37:17.1
0,-1,37:17.1
1,-1,37:18.1
2,-1,37:18.1
-3,0,37:18.1
-2,0,37:18.1
-1,0,37:17.1
0,0,37:17.1
1,0,37:18.1
2,0,37:18.1
-3,1,37:18.1
-2,1,37:18.1
-1,1,37:18.1
0,1,37:18.1
1,1,37:18.1
2,1,37:18.1
-2,2,37:18.1
-1,2,37:18.1
0,2,37:18.1
1,2,37:18.1
-1,-2,38:18.1
0,-2,38:18.1
-2,-1,38:18.1
-1,-1,38:17.1
0,-1,38:17.1
1,-1,38:18.1
-2,0,38:18.1
-1,0,38:17.1
0,0,38:17.1
1,0,38:18.1
-1,1,38:18.1
0,1,38:18.1
-2,-3,39:18.1
-1,-3,39:18.1
0,-3,39:18.1
1,-3,39:18.1
-3,-2,39:18.1
-2,-2,39:18.1
-1,-2,39:18.1
0,-2,39:18.1
1,-2,39:18.1
2,-2,39:18.1
-3,-1,39:18.1
-2,-1,39:18.1
-1,-1,39:17.1
0,-1,39:17.1
1,-1,39:18.1
2,-1,39:18.1
-3,0,39:18.1
-2,0,39:18.1
-1,0,39:17.1
0,0,39:17.1
1,0,39:18.1
2,0,39:18.1
-3,1,39:18.1
-2,1,39:18.1
-1,1,39:18.1
0,1,39:18.1
1,1,39:18.1
2,1,39:18.1
-2,2,39:18.1
-1,2,39:18.1
0,2,39:18.1
1,2,39:18.1
-1,-2,40:18.1
0,-2,40:18.1
-2,-1,40:18.1
-1,-1,40:17.1
0,-1,40:17.1
1,-1,40:18.1
-2,0,40:18.1
-1,0,40:17.1
0,0,40:17.1
1,0,40:18.1
-1,1,40:18.1
0,1,40:18.1
-2,-3,41:18.1
-1,-3,41:18.1
0,-3,41:18.1
1,-3,41:18.1
-3,-2,41:18.1
-2,-2,41:18.1
-1,-2,41:18.1
0,-2,41:18.1
1,-2,41:18.1
2,-2,41:18.1
-3,-1,41:18.1
-2,-1,41:18.1
-1,-1,41:17.1
0,-1,41:17.1
1,-1,41:18.1
2,-1,41:18.1
-3,0,41:18.1
-2,0,41:18.1
-1,0,41:17.1
0,0,41:17.1
1,0,41:18.1
2,0,41:18.1
-3,1,41:18.1
-2,1,41:18.1
-1,1,41:18.1
0,1,41:18.1
1,1,41:18.1
2,1,41:18.1
-2,2,41:18.1
-1,2,41:18.1
0,2,41:18.1
1,2,41:18.1
-1,-2,42:18.1
0,-2,42:18.1
-2,-1,42:18.1
-1,-1,42:17.1
0,-1,42:17.1
1,-1,42:18.1
-2,0,42:18.1
-1,0,42:17.1
0,0,42:17.1
1,0,42:18.1
-1,1,42:18.1
0,1,42:18.1
-1,-1,43:18.1
0,-1,43:18.1
-1,0,43:18.1
0,0,43:18.1
-1,-2,44:18.1
0,-2,44:18.1
-2,-1,44:18.1
-1,-1,44:18.1
0,-1,44:18.1
1,-1,44:18.1
-2,0,44:18.1
-1,0,44:18.1
0,0,44:18.1
1,0,44:18.1
-1,1,44:18.1
0,1,44:18.1
-1,-1,45:18.1
0,-1,45:18.1
-1,0,45:18.1
0,0,45:18.1
0,0,46:78.0
-1,0,46:78.0
0,-1,46:78.0
-1,-1,46:78.0
0,1,45:78.0
-1,1,45:78.0
1,0,45:78.0
1,-1,45:78.0
0,-2,45:78.0
-1,-2,45:78.0
1,2,42:78.0
0,2,42:78.0
2,1,42:78.0
1,1,42:78.0
2,0,42:78.0
2,-1,42:78.0
2,-2,42:78.0
1,-2,42:78.0
-2,-2,42:78.0
-3,-2,42:78.0
1,-3,42:78.0
0,-3,42:78.0
-1,-3,42:78.0
-2,-3,42:78.0
